File: composites_properties_derivations/composite_tube_tests/comp_tube_4.csv
Specimen label,"4"
Force at Maximum Load,"16.19",kN
Tensile stress at Maximum Load,"102.25",MPa
Epsilon ONE Displacement at Maximum Load,"0.09",mm
Force at Break (Standard),"4.07",kN
Tensile stress at Break (Standard),"25.70",MPa
Epsilon ONE Displacement at Break (Standard),"0.02",mm
Slope (Chord 0.05 % - 0.2 %),"-----",MPa
Modulus (Automatic Young's),"70933.32",MPa

Specimen label,"4"
Thickness,"",mm
Width,"",mm
Length,"50.59",mm
Rate 1,"5.00",mm/min
Outer diameter,"19.05",mm
Wall thickness,"3.18",mm

Time,Displacement,Force,Tensile stress,Tensile strain (Epsilon ONE Displacement),Epsilon ONE Displacement
(s),(mm),(kN),(MPa),(%),(mm)
"0.0000","0.0000","0.0601","0.3798","-0.0015","-0.0008"
"0.1000","0.0023","0.1042","0.6579","-0.0010","-0.0005"
"0.2000","0.0059","0.1568","0.9903","-0.0013","-0.0006"
"0.3000","0.0191","0.1934","1.2212","0.0001","0.0000"
"0.4000","0.0271","0.2118","1.3379","0.0001","0.0000"
"0.5000","0.0358","0.2304","1.4551","0.0005","0.0003"
"0.6000","0.0439","0.2433","1.5363","-0.0002","-0.0001"
"0.7000","0.0523","0.2533","1.5998","0.0003","0.0002"
"0.8000","0.0607","0.2624","1.6570","-0.0003","-0.0002"
"0.9000","0.0689","0.2708","1.7102","0.0006","0.0003"
"1.0000","0.0772","0.2792","1.7630","0.0005","0.0003"
"1.1000","0.0858","0.2859","1.8052","0.0007","0.0003"
"1.2000","0.0938","0.2934","1.8530","0.0011","0.0006"
"1.3000","0.1021","0.2998","1.8936","0.0013","0.0007"
"1.4000","0.1106","0.3040","1.9198","0.0010","0.0005"
"1.5000","0.1188","0.3079","1.9444","0.0016","0.0008"
"1.6000","0.1271","0.3117","1.9688","0.0013","0.0007"
"1.7000","0.1358","0.3156","1.9928","0.0008","0.0004"
"1.8000","0.1439","0.3201","2.0218","0.0013","0.0007"
"1.9000","0.1521","0.3248","2.0514","0.0020","0.0010"
"2.0000","0.1607","0.3301","2.0845","0.0020","0.0010"
"2.1000","0.1687","0.3352","2.1169","0.0026","0.0013"
"2.2000","0.1773","0.3407","2.1519","0.0020","0.0010"
"2.3000","0.1856","0.3459","2.1847","0.0012","0.0006"
"2.4000","0.1938","0.3514","2.2190","0.0026","0.0013"
"2.5000","0.2020","0.3568","2.2534","0.0028","0.0014"
"2.6000","0.2105","0.3622","2.2873","0.0026","0.0013"
"2.7000","0.2188","0.3681","2.3249","0.0025","0.0012"
"2.8000","0.2275","0.3746","2.3655","0.0022","0.0011"
"2.9000","0.2357","0.3800","2.3996","0.0029","0.0015"
"3.0000","0.2440","0.3861","2.4386","0.0030","0.0015"
"3.1000","0.2524","0.3927","2.4798","0.0041","0.0021"
"3.2000","0.2607","0.3994","2.5222","0.0030","0.0015"
"3.3000","0.2689","0.4063","2.5661","0.0039","0.0020"
"3.4000","0.2777","0.4140","2.6144","0.0051","0.0026"
"3.5000","0.2857","0.4212","2.6601","0.0043","0.0022"
"3.6000","0.2939","0.4296","2.7130","0.0043","0.0022"
"3.7000","0.3024","0.4375","2.7631","0.0064","0.0033"
"3.8000","0.3107","0.4457","2.8145","0.0048","0.0024"
"3.9000","0.3191","0.4539","2.8667","0.0042","0.0021"
"4.0000","0.3276","0.4620","2.9174","0.0051","0.0026"
"4.1000","0.3358","0.4698","2.9671","0.0049","0.0025"
"4.2000","0.3441","0.4780","3.0189","0.0060","0.0030"
"4.3000","0.3525","0.4860","3.0691","0.0051","0.0026"
"4.4000","0.3607","0.4947","3.1239","0.0050","0.0026"
"4.5000","0.3691","0.5029","3.1759","0.0053","0.0027"
"4.6000","0.3775","0.5107","3.2254","0.0055","0.0028"
"4.7000","0.3856","0.5192","3.2790","0.0061","0.0031"
"4.8000","0.3939","0.5280","3.3346","0.0067","0.0034"
"4.9000","0.4022","0.5364","3.3874","0.0064","0.0033"
"5.0000","0.4105","0.5454","3.4442","0.0060","0.0030"
"5.1000","0.4191","0.5546","3.5024","0.0065","0.0033"
"5.2000","0.4274","0.5631","3.5564","0.0066","0.0033"
"5.3000","0.4356","0.5723","3.6144","0.0066","0.0033"
"5.4000","0.4440","0.5812","3.6702","0.0072","0.0037"
"5.5000","0.4522","0.5898","3.7246","0.0063","0.0032"
"5.6000","0.4604","0.5993","3.7848","0.0069","0.0035"
"5.7000","0.4691","0.6086","3.8434","0.0071","0.0036"
"5.8000","0.4771","0.6174","3.8990","0.0075","0.0038"
"5.9000","0.4855","0.6267","3.9580","0.0078","0.0040"
"6.0000","0.4937","0.6359","4.0162","0.0076","0.0039"
"6.1000","0.5020","0.6454","4.0761","0.0078","0.0039"
"6.2000","0.5105","0.6554","4.1390","0.0086","0.0043"
"6.3000","0.5191","0.6653","4.2018","0.0086","0.0043"
"6.4000","0.5272","0.6753","4.2646","0.0074","0.0037"
"6.5000","0.5357","0.6847","4.3240","0.0091","0.0046"
"6.6000","0.5438","0.6946","4.3864","0.0083","0.0042"
"6.7000","0.5522","0.7048","4.4511","0.0093","0.0047"
"6.8000","0.5606","0.7152","4.5168","0.0094","0.0048"
"6.9000","0.5691","0.7257","4.5829","0.0094","0.0047"
"7.0000","0.5772","0.7364","4.6503","0.0097","0.0049"
"7.1000","0.5856","0.7470","4.7176","0.0091","0.0046"
"7.2000","0.5938","0.7577","4.7851","0.0102","0.0052"
"7.3000","0.6023","0.7694","4.8592","0.0084","0.0042"
"7.4000","0.6108","0.7802","4.9275","0.0098","0.0049"
"7.5000","0.6191","0.7910","4.9957","0.0090","0.0046"
"7.6000","0.6274","0.8029","5.0706","0.0105","0.0053"
"7.7000","0.6358","0.8145","5.1441","0.0102","0.0052"
"7.8000","0.6440","0.8267","5.2206","0.0106","0.0053"
"7.9000","0.6523","0.8391","5.2990","0.0109","0.0055"
"8.0000","0.6609","0.8517","5.3790","0.0112","0.0057"
"8.1000","0.6691","0.8641","5.4569","0.0123","0.0062"
"8.2000","0.6773","0.8772","5.5399","0.0113","0.0057"
"8.3000","0.6857","0.8896","5.6181","0.0113","0.0057"
"8.4000","0.6939","0.9033","5.7047","0.0116","0.0059"
"8.5000","0.7024","0.9166","5.7886","0.0116","0.0059"
"8.6000","0.7109","0.9294","5.8692","0.0118","0.0060"
"8.7000","0.7190","0.9381","5.9242","0.0116","0.0059"
"8.8000","0.7274","0.9553","6.0330","0.0130","0.0066"
"8.9000","0.7356","0.9704","6.1286","0.0134","0.0068"
"9.0000","0.7439","0.9864","6.2291","0.0129","0.0065"
"9.1000","0.7524","1.0026","6.3316","0.0138","0.0070"
"9.2000","0.7607","1.0172","6.4238","0.0129","0.0065"
"9.3000","0.7689","1.0332","6.5248","0.0142","0.0072"
"9.4000","0.7772","1.0489","6.6243","0.0130","0.0066"
"9.5000","0.7854","1.0648","6.7247","0.0139","0.0070"
"9.6000","0.7938","1.0815","6.8299","0.0142","0.0072"
"9.7000","0.8023","1.0987","6.9385","0.0139","0.0070"
"9.8000","0.8107","1.1162","7.0492","0.0140","0.0071"
"9.9000","0.8189","1.1339","7.1606","0.0139","0.0070"
"10.0000","0.8273","1.1512","7.2704","0.0148","0.0075"
"10.1000","0.8355","1.1693","7.3843","0.0146","0.0074"
"10.2000","0.8439","1.1882","7.5040","0.0139","0.0071"
"10.3000","0.8523","1.2068","7.6213","0.0153","0.0077"
"10.4000","0.8606","1.2257","7.7408","0.0146","0.0074"
"10.5000","0.8688","1.2452","7.8640","0.0151","0.0076"
"10.6000","0.8772","1.2650","7.9890","0.0159","0.0081"
"10.7000","0.8853","1.2855","8.1185","0.0150","0.0076"
"10.8000","0.8939","1.3074","8.2564","0.0164","0.0083"
"10.9000","0.9024","1.3286","8.3906","0.0159","0.0080"
"11.0000","0.9106","1.3498","8.5245","0.0166","0.0084"
"11.1000","0.9191","1.3730","8.6707","0.0168","0.0085"
"11.2000","0.9273","1.3942","8.8046","0.0178","0.0090"
"11.3000","0.9356","1.4175","8.9517","0.0178","0.0090"
"11.4000","0.9440","1.4412","9.1015","0.0189","0.0096"
"11.5000","0.9526","1.4643","9.2475","0.0174","0.0088"
"11.6000","0.9607","1.4870","9.3905","0.0190","0.0096"
"11.7000","0.9691","1.5115","9.5456","0.0190","0.0096"
"11.8000","0.9772","1.5335","9.6847","0.0204","0.0103"
"11.9000","0.9856","1.5586","9.8432","0.0196","0.0099"
"12.0000","0.9942","1.5832","9.9986","0.0194","0.0098"
"12.1000","1.0025","1.6065","10.1452","0.0204","0.0103"
"12.2000","1.0107","1.6317","10.3048","0.0204","0.0103"
"12.3000","1.0193","1.6570","10.4642","0.0202","0.0102"
"12.4000","1.0273","1.6819","10.6219","0.0201","0.0102"
"12.5000","1.0357","1.7084","10.7892","0.0207","0.0105"
"12.6000","1.0442","1.7336","10.9482","0.0216","0.0109"
"12.7000","1.0524","1.7603","11.1170","0.0211","0.0107"
"12.8000","1.0607","1.7867","11.2832","0.0211","0.0107"
"12.9000","1.0690","1.8124","11.4456","0.0213","0.0108"
"13.0000","1.0771","1.8399","11.6195","0.0225","0.0114"
"13.1000","1.0856","1.8673","11.7926","0.0234","0.0118"
"13.2000","1.0941","1.8943","11.9633","0.0233","0.0118"
"13.3000","1.1023","1.9221","12.1387","0.0235","0.0119"
"13.4000","1.1107","1.9500","12.3145","0.0235","0.0119"
"13.5000","1.1190","1.9759","12.4785","0.0241","0.0122"
"13.6000","1.1271","2.0039","12.6551","0.0234","0.0118"
"13.7000","1.1357","2.0316","12.8301","0.0242","0.0122"
"13.8000","1.1439","2.0585","12.9997","0.0245","0.0124"
"13.9000","1.1523","2.0865","13.1765","0.0248","0.0126"
"14.0000","1.1606","2.1131","13.3445","0.0251","0.0127"
"14.1000","1.1687","2.1399","13.5143","0.0238","0.0121"
"14.2000","1.1770","2.1683","13.6935","0.0249","0.0126"
"14.3000","1.1856","2.1965","13.8717","0.0248","0.0125"
"14.4000","1.1938","2.2241","14.0458","0.0262","0.0132"
"14.5000","1.2022","2.2520","14.2223","0.0265","0.0134"
"14.6000","1.2107","2.2804","14.4015","0.0270","0.0137"
"14.7000","1.2188","2.3077","14.5736","0.0268","0.0136"
"14.8000","1.2272","2.3366","14.7560","0.0267","0.0135"
"14.9000","1.2357","2.3655","14.9390","0.0285","0.0144"
"15.0000","1.2440","2.3944","15.1214","0.0289","0.0146"
"15.1000","1.2523","2.4234","15.3047","0.0285","0.0144"
"15.2000","1.2606","2.4513","15.4804","0.0310","0.0157"
"15.3000","1.2687","2.4813","15.6702","0.0302","0.0153"
"15.4000","1.2772","2.5124","15.8668","0.0308","0.0156"
"15.5000","1.2856","2.5409","16.0466","0.0303","0.0153"
"15.6000","1.2940","2.5710","16.2364","0.0317","0.0160"
"15.7000","1.3025","2.6022","16.4339","0.0317","0.0160"
"15.8000","1.3107","2.6308","16.6139","0.0308","0.0156"
"15.9000","1.3190","2.6606","16.8024","0.0313","0.0158"
"16.0000","1.3275","2.6918","16.9997","0.0323","0.0164"
"16.1000","1.3358","2.7220","17.1900","0.0326","0.0165"
"16.2000","1.3441","2.7521","17.3802","0.0332","0.0168"
"16.3000","1.3525","2.7831","17.5758","0.0330","0.0167"
"16.4000","1.3606","2.8124","17.7609","0.0331","0.0167"
"16.5000","1.3689","2.8446","17.9642","0.0332","0.0168"
"16.6000","1.3774","2.8757","18.1608","0.0339","0.0172"
"16.7000","1.3859","2.9075","18.3618","0.0347","0.0175"
"16.8000","1.3942","2.9382","18.5553","0.0343","0.0174"
"16.9000","1.4025","2.9694","18.7525","0.0354","0.0179"
"17.0000","1.4107","2.9999","18.9452","0.0360","0.0182"
"17.1000","1.4190","3.0323","19.1496","0.0358","0.0181"
"17.2000","1.4274","3.0626","19.3410","0.0368","0.0186"
"17.3000","1.4357","3.0949","19.5454","0.0363","0.0184"
"17.4000","1.4440","3.1255","19.7386","0.0366","0.0185"
"17.5000","1.4523","3.1570","19.9376","0.0371","0.0188"
"17.6000","1.4604","3.1879","20.1323","0.0366","0.0185"
"17.7000","1.4688","3.2205","20.3383","0.0371","0.0188"
"17.8000","1.4773","3.2521","20.5381","0.0368","0.0186"
"17.9000","1.4856","3.2846","20.7431","0.0388","0.0196"
"18.0000","1.4940","3.3165","20.9446","0.0381","0.0193"
"18.1000","1.5023","3.3474","21.1398","0.0398","0.0201"
"18.2000","1.5104","3.3784","21.3355","0.0394","0.0199"
"18.3000","1.5188","3.4120","21.5478","0.0394","0.0200"
"18.4000","1.5274","3.4440","21.7500","0.0393","0.0199"
"18.5000","1.5355","3.4753","21.9475","0.0388","0.0196"
"18.6000","1.5440","3.5095","22.1636","0.0400","0.0202"
"18.7000","1.5520","3.5391","22.3502","0.0394","0.0199"
"18.8000","1.5603","3.5725","22.5611","0.0408","0.0207"
"18.9000","1.5690","3.6067","22.7773","0.0417","0.0211"
"19.0000","1.5772","3.6386","22.9791","0.0422","0.0213"
"19.1000","1.5856","3.6724","23.1921","0.0431","0.0218"
"19.2000","1.5941","3.7052","23.3995","0.0423","0.0214"
"19.3000","1.6022","3.7365","23.5971","0.0441","0.0223"
"19.4000","1.6106","3.7726","23.8253","0.0441","0.0223"
"19.5000","1.6190","3.8047","24.0280","0.0438","0.0222"
"19.6000","1.6274","3.8405","24.2536","0.0446","0.0226"
"19.7000","1.6357","3.8731","24.4594","0.0452","0.0229"
"19.8000","1.6441","3.9058","24.6661","0.0457","0.0231"
"19.9000","1.6521","3.9394","24.8785","0.0445","0.0225"
"20.0000","1.6606","3.9770","25.1158","0.0457","0.0231"
"20.1000","1.6690","4.0090","25.3180","0.0465","0.0235"
"20.2000","1.6775","4.0459","25.5510","0.0462","0.0234"
"20.3000","1.6859","4.0788","25.7585","0.0475","0.0240"
"20.4000","1.6942","4.1141","25.9814","0.0465","0.0235"
"20.5000","1.7023","4.1476","26.1935","0.0473","0.0239"
"20.6000","1.7108","4.1851","26.4300","0.0480","0.0243"
"20.7000","1.7191","4.2187","26.6421","0.0486","0.0246"
"20.8000","1.7275","4.2555","26.8748","0.0488","0.0247"
"20.9000","1.7359","4.2889","27.0854","0.0492","0.0249"
"21.0000","1.7439","4.3229","27.3005","0.0493","0.0249"
"21.1000","1.7522","4.3582","27.5231","0.0492","0.0249"
"21.2000","1.7607","4.3945","27.7522","0.0498","0.0252"
"21.3000","1.7690","4.4280","27.9643","0.0519","0.0263"
"21.4000","1.7774","4.4645","28.1944","0.0499","0.0252"
"21.5000","1.7858","4.4981","28.4066","0.0508","0.0257"
"21.6000","1.7939","4.5324","28.6231","0.0518","0.0262"
"21.7000","1.8022","4.5686","28.8518","0.0523","0.0264"
"21.8000","1.8107","4.6026","29.0669","0.0525","0.0266"
"21.9000","1.8189","4.6384","29.2930","0.0525","0.0265"
"22.0000","1.8273","4.6741","29.5180","0.0535","0.0271"
"22.1000","1.8356","4.7071","29.7265","0.0536","0.0271"
"22.2000","1.8436","4.7410","29.9406","0.0533","0.0269"
"22.3000","1.8521","4.7796","30.1848","0.0542","0.0274"
"22.4000","1.8605","4.8143","30.4035","0.0552","0.0279"
"22.5000","1.8688","4.8502","30.6304","0.0546","0.0276"
"22.6000","1.8774","4.8880","30.8689","0.0563","0.0285"
"22.7000","1.8855","4.9208","31.0765","0.0560","0.0283"
"22.8000","1.8937","4.9568","31.3033","0.0560","0.0283"
"22.9000","1.9023","4.9963","31.5531","0.0564","0.0285"
"23.0000","1.9104","5.0298","31.7643","0.0571","0.0289"
"23.1000","1.9189","5.0675","32.0028","0.0575","0.0291"
"23.2000","1.9274","5.1045","32.2362","0.0582","0.0295"
"23.3000","1.9355","5.1389","32.4537","0.0585","0.0296"
"23.4000","1.9437","5.1761","32.6885","0.0584","0.0296"
"23.5000","1.9523","5.2155","32.9372","0.0590","0.0299"
"23.6000","1.9606","5.2514","33.1639","0.0594","0.0300"
"23.7000","1.9691","5.2905","33.4111","0.0594","0.0300"
"23.8000","1.9774","5.3266","33.6393","0.0590","0.0298"
"23.9000","1.9858","5.3639","33.8743","0.0634","0.0321"
"24.0000","1.9940","5.4029","34.1206","0.0611","0.0309"
"24.1000","2.0024","5.4400","34.3549","0.0608","0.0308"
"24.2000","2.0108","5.4782","34.5964","0.0615","0.0311"
"24.3000","2.0192","5.5172","34.8428","0.0621","0.0314"
"24.4000","2.0275","5.5528","35.0673","0.0628","0.0318"
"24.5000","2.0357","5.5905","35.3055","0.0629","0.0318"
"24.6000","2.0440","5.6298","35.5539","0.0636","0.0322"
"24.7000","2.0524","5.6665","35.7856","0.0630","0.0319"
"24.8000","2.0607","5.7047","36.0270","0.0633","0.0320"
"24.9000","2.0694","5.7447","36.2796","0.0646","0.0327"
"25.0000","2.0775","5.7782","36.4911","0.0654","0.0331"
"25.1000","2.0857","5.8161","36.7306","0.0656","0.0332"
"25.2000","2.0941","5.8567","36.9867","0.0651","0.0330"
"25.3000","2.1024","5.8913","37.2053","0.0660","0.0334"
"25.4000","2.1106","5.9304","37.4520","0.0654","0.0331"
"25.5000","2.1193","5.9690","37.6959","0.0663","0.0335"
"25.6000","2.1273","6.0020","37.9044","0.0667","0.0337"
"25.7000","2.1353","6.0395","38.1411","0.0684","0.0346"
"25.8000","2.1439","6.0814","38.4060","0.0681","0.0344"
"25.9000","2.1522","6.1183","38.6387","0.0695","0.0352"
"26.0000","2.1606","6.1586","38.8930","0.0694","0.0351"
"26.1000","2.1690","6.1938","39.1155","0.0697","0.0353"
"26.2000","2.1772","6.2304","39.3467","0.0708","0.0358"
"26.3000","2.1854","6.2688","39.5893","0.0703","0.0356"
"26.4000","2.1939","6.3068","39.8294","0.0695","0.0352"
"26.5000","2.2021","6.3442","40.0657","0.0712","0.0360"
"26.6000","2.2108","6.3871","40.3362","0.0705","0.0357"
"26.7000","2.2189","6.4188","40.5366","0.0711","0.0360"
"26.8000","2.2271","6.4585","40.7873","0.0715","0.0362"
"26.9000","2.2353","6.4976","41.0339","0.0733","0.0371"
"27.0000","2.2438","6.5372","41.2843","0.0730","0.0369"
"27.1000","2.2521","6.5765","41.5324","0.0724","0.0366"
"27.2000","2.2608","6.6185","41.7974","0.0726","0.0367"
"27.3000","2.2689","6.6542","42.0231","0.0729","0.0369"
"27.4000","2.2772","6.6954","42.2836","0.0737","0.0373"
"27.5000","2.2857","6.7364","42.5424","0.0749","0.0379"
"27.6000","2.2939","6.7746","42.7836","0.0751","0.0380"
"27.7000","2.3024","6.8160","43.0452","0.0755","0.0382"
"27.8000","2.3108","6.8537","43.2828","0.0746","0.0377"
"27.9000","2.3191","6.8945","43.5405","0.0757","0.0383"
"28.0000","2.3273","6.9344","43.7927","0.0761","0.0385"
"28.1000","2.3357","6.9757","44.0533","0.0771","0.0390"
"28.2000","2.3440","7.0147","44.2998","0.0774","0.0392"
"28.3000","2.3525","7.0574","44.5695","0.0771","0.0390"
"28.4000","2.3609","7.0940","44.8007","0.0764","0.0386"
"28.5000","2.3691","7.1349","45.0587","0.0772","0.0390"
"28.6000","2.3774","7.1768","45.3236","0.0785","0.0397"
"28.7000","2.3858","7.2152","45.5662","0.0786","0.0398"
"28.8000","2.3941","7.2565","45.8268","0.0798","0.0404"
"28.9000","2.4026","7.2975","46.0859","0.0801","0.0405"
"29.0000","2.4108","7.3337","46.3143","0.0786","0.0398"
"29.1000","2.4189","7.3750","46.5751","0.0817","0.0413"
"29.2000","2.4272","7.4154","46.8301","0.0807","0.0408"
"29.3000","2.4354","7.4540","47.0741","0.0807","0.0408"
"29.4000","2.4439","7.4965","47.3427","0.0823","0.0416"
"29.5000","2.4525","7.5389","47.6101","0.0812","0.0411"
"29.6000","2.4607","7.5746","47.8355","0.0830","0.0420"
"29.7000","2.4689","7.6152","48.0922","0.0839","0.0424"
"29.8000","2.4773","7.6564","48.3526","0.0840","0.0425"
"29.9000","2.4855","7.6961","48.6029","0.0833","0.0421"
"30.0000","2.4939","7.7373","48.8633","0.0833","0.0421"
"30.1000","2.5024","7.7793","49.1286","0.0844","0.0427"
"30.2000","2.5104","7.8158","49.3587","0.0844","0.0427"
"30.3000","2.5188","7.8579","49.6249","0.0857","0.0433"
"30.4000","2.5270","7.8969","49.8711","0.0860","0.0435"
"30.5000","2.5354","7.9403","50.1450","0.0863","0.0436"
"30.6000","2.5438","7.9805","50.3992","0.0875","0.0442"
"30.7000","2.5524","8.0224","50.6639","0.0871","0.0441"
"30.8000","2.5605","8.0605","50.9042","0.0873","0.0441"
"30.9000","2.5689","8.1030","51.1729","0.0869","0.0440"
"31.0000","2.5772","8.1433","51.4270","0.0876","0.0443"
"31.1000","2.5855","8.1847","51.6888","0.0884","0.0447"
"31.2000","2.5940","8.2290","51.9684","0.0887","0.0449"
"31.3000","2.6023","8.2669","52.2075","0.0889","0.0450"
"31.4000","2.6106","8.3106","52.4837","0.0895","0.0453"
"31.5000","2.6189","8.3517","52.7431","0.0905","0.0458"
"31.6000","2.6271","8.3994","53.0446","0.0910","0.0460"
"31.7000","2.6356","8.4432","53.3210","0.0918","0.0464"
"31.8000","2.6442","8.4878","53.6027","0.0908","0.0459"
"31.9000","2.6524","8.5248","53.8366","0.0915","0.0463"
"32.0000","2.6607","8.5688","54.1142","0.0905","0.0458"
"32.1000","2.6691","8.6107","54.3791","0.0918","0.0464"
"32.2000","2.6773","8.6542","54.6534","0.0922","0.0467"
"32.3000","2.6856","8.6957","54.9157","0.0943","0.0477"
"32.4000","2.6943","8.7401","55.1962","0.0941","0.0476"
"32.5000","2.7024","8.7795","55.4450","0.0945","0.0478"
"32.6000","2.7107","8.8245","55.7294","0.0944","0.0478"
"32.7000","2.7190","8.8645","55.9819","0.0953","0.0482"
"32.8000","2.7272","8.9092","56.2641","0.0957","0.0484"
"32.9000","2.7357","8.9529","56.5402","0.0954","0.0483"
"33.0000","2.7443","8.9950","56.8058","0.0952","0.0481"
"33.1000","2.7524","9.0361","57.0655","0.0954","0.0483"
"33.2000","2.7608","9.0823","57.3573","0.0968","0.0490"
"33.3000","2.7690","9.1216","57.6056","0.0969","0.0490"
"33.4000","2.7773","9.1669","57.8918","0.0978","0.0495"
"33.5000","2.7858","9.2168","58.2069","0.0974","0.0493"
"33.6000","2.7942","9.2636","58.5022","0.0974","0.0493"
"33.7000","2.8021","9.3032","58.7526","0.0974","0.0493"
"33.8000","2.8106","9.3490","59.0413","0.0982","0.0497"
"33.9000","2.8187","9.3878","59.2863","0.0984","0.0498"
"34.0000","2.8271","9.4314","59.5620","0.1002","0.0507"
"34.1000","2.8358","9.4769","59.8493","0.0993","0.0503"
"34.2000","2.8440","9.5155","60.0931","0.0994","0.0503"
"34.3000","2.8522","9.5581","60.3620","0.1009","0.0510"
"34.4000","2.8606","9.5976","60.6115","0.1000","0.0506"
"34.5000","2.8687","9.6405","60.8822","0.1007","0.0509"
"34.6000","2.8773","9.6862","61.1709","0.1019","0.0516"
"34.7000","2.8856","9.7265","61.4256","0.1016","0.0514"
"34.8000","2.8940","9.7683","61.6898","0.1021","0.0517"
"34.9000","2.9021","9.8107","61.9571","0.1033","0.0523"
"35.0000","2.9104","9.8516","62.2155","0.1023","0.0518"
"35.1000","2.9187","9.8979","62.5077","0.1037","0.0525"
"35.2000","2.9273","9.9454","62.8079","0.1023","0.0518"
"35.3000","2.9357","9.9868","63.0696","0.1047","0.0530"
"35.4000","2.9439","10.0257","63.3151","0.1048","0.0530"
"35.5000","2.9523","10.0753","63.6281","0.1060","0.0536"
"35.6000","2.9604","10.1121","63.8607","0.1061","0.0537"
"35.7000","2.9688","10.1627","64.1804","0.1071","0.0542"
"35.8000","2.9774","10.2087","64.4709","0.1070","0.0541"
"35.9000","2.9857","10.2494","64.7281","0.1067","0.0540"
"36.0000","2.9940","10.2950","65.0160","0.1078","0.0545"
"36.1000","3.0023","10.3383","65.2892","0.1065","0.0539"
"36.2000","3.0105","10.3830","65.5716","0.1070","0.0541"
"36.3000","3.0189","10.4312","65.8762","0.1085","0.0549"
"36.4000","3.0274","10.4767","66.1631","0.1092","0.0552"
"36.5000","3.0358","10.5192","66.4320","0.1098","0.0555"
"36.6000","3.0441","10.5654","66.7235","0.1100","0.0556"
"36.7000","3.0525","10.6075","66.9892","0.1088","0.0550"
"36.8000","3.0606","10.6535","67.2796","0.1099","0.0556"
"36.9000","3.0691","10.6991","67.5680","0.1106","0.0560"
"37.0000","3.0775","10.7424","67.8413","0.1107","0.0560"
"37.1000","3.0858","10.7871","68.1238","0.1105","0.0559"
"37.2000","3.0941","10.8324","68.4100","0.1131","0.0572"
"37.3000","3.1024","10.8714","68.6562","0.1125","0.0569"
"37.4000","3.1105","10.9186","68.9538","0.1126","0.0570"
"37.5000","3.1191","10.9657","69.2515","0.1136","0.0575"
"37.6000","3.1275","11.0090","69.5250","0.1136","0.0575"
"37.7000","3.1357","11.0514","69.7930","0.1144","0.0579"
"37.8000","3.1442","11.0991","70.0939","0.1139","0.0576"
"37.9000","3.1522","11.1358","70.3257","0.1155","0.0584"
"38.0000","3.1605","11.1837","70.6284","0.1159","0.0586"
"38.1000","3.1691","11.2316","70.9306","0.1160","0.0587"
"38.2000","3.1774","11.2728","71.1911","0.1155","0.0584"
"38.3000","3.1856","11.3152","71.4585","0.1162","0.0588"
"38.4000","3.1939","11.3601","71.7420","0.1168","0.0591"
"38.5000","3.2020","11.4001","71.9949","0.1183","0.0599"
"38.6000","3.2104","11.4501","72.3107","0.1175","0.0595"
"38.7000","3.2189","11.4955","72.5972","0.1193","0.0604"
"38.8000","3.2273","11.5419","72.8904","0.1188","0.0601"
"38.9000","3.2355","11.5821","73.1444","0.1204","0.0609"
"39.0000","3.2440","11.6298","73.4453","0.1194","0.0604"
"39.1000","3.2521","11.6718","73.7109","0.1217","0.0616"
"39.2000","3.2605","11.7216","74.0255","0.1219","0.0617"
"39.3000","3.2690","11.7669","74.3114","0.1219","0.0617"
"39.4000","3.2773","11.8122","74.5975","0.1226","0.0620"
"39.5000","3.2856","11.8565","74.8770","0.1219","0.0617"
"39.6000","3.2939","11.9012","75.1591","0.1228","0.0621"
"39.7000","3.3021","11.9480","75.4550","0.1225","0.0620"
"39.8000","3.3106","11.9987","75.7751","0.1228","0.0621"
"39.9000","3.3189","12.0423","76.0503","0.1232","0.0623"
"40.0000","3.3273","12.0901","76.3525","0.1242","0.0629"
"40.1000","3.3359","12.1407","76.6722","0.1245","0.0630"
"40.2000","3.3440","12.1773","76.9030","0.1235","0.0625"
"40.3000","3.3523","12.2289","77.2289","0.1238","0.0626"
"40.4000","3.3608","12.2790","77.5456","0.1256","0.0636"
"40.5000","3.3691","12.3204","77.8067","0.1265","0.0640"
"40.6000","3.3774","12.3686","78.1111","0.1275","0.0645"
"40.7000","3.3859","12.4167","78.4152","0.1265","0.0640"
"40.8000","3.3939","12.4560","78.6634","0.1264","0.0639"
"40.9000","3.4023","12.5095","79.0012","0.1264","0.0639"
"41.0000","3.4108","12.5552","79.2896","0.1275","0.0645"
"41.1000","3.4192","12.6020","79.5849","0.1276","0.0646"
"41.2000","3.4275","12.6466","79.8671","0.1289","0.0652"
"41.3000","3.4359","12.6925","80.1570","0.1292","0.0653"
"41.4000","3.4439","12.7347","80.4229","0.1307","0.0661"
"41.5000","3.4524","12.7859","80.7467","0.1308","0.0662"
"41.6000","3.4609","12.8313","81.0334","0.1324","0.0670"
"41.7000","3.4691","12.8768","81.3206","0.1313","0.0664"
"41.8000","3.4774","12.9230","81.6125","0.1308","0.0662"
"41.9000","3.4857","12.9665","81.8868","0.1335","0.0676"
"42.0000","3.4937","13.0096","82.1590","0.1328","0.0672"
"42.1000","3.5023","13.0618","82.4891","0.1330","0.0673"
"42.2000","3.5106","13.1045","82.7583","0.1335","0.0675"
"42.3000","3.5190","13.1537","83.0695","0.1335","0.0676"
"42.4000","3.5274","13.1994","83.3577","0.1339","0.0677"
"42.5000","3.5355","13.2397","83.6122","0.1341","0.0679"
"42.6000","3.5437","13.2874","83.9138","0.1361","0.0688"
"42.7000","3.5523","13.3391","84.2402","0.1355","0.0686"
"42.8000","3.5605","13.3806","84.5023","0.1366","0.0691"
"42.9000","3.5689","13.4289","84.8076","0.1377","0.0697"
"43.0000","3.5773","13.4763","85.1069","0.1366","0.0691"
"43.1000","3.5853","13.5168","85.3625","0.1377","0.0697"
"43.2000","3.5937","13.5690","85.6919","0.1379","0.0698"
"43.3000","3.6022","13.6166","85.9926","0.1389","0.0703"
"43.4000","3.6105","13.6635","86.2888","0.1382","0.0699"
"43.5000","3.6189","13.7100","86.5826","0.1389","0.0703"
"43.6000","3.6273","13.7560","86.8729","0.1394","0.0705"
"43.7000","3.6355","13.8008","87.1562","0.1386","0.0701"
"43.8000","3.6439","13.8530","87.4855","0.1386","0.0701"
"43.9000","3.6523","13.9015","87.7918","0.1402","0.0709"
"44.0000","3.6606","13.9576","88.1462","0.1419","0.0718"
"44.1000","3.6691","14.0084","88.4671","0.1427","0.0722"
"44.2000","3.6772","14.0518","88.7411","0.1427","0.0722"
"44.3000","3.6855","14.1042","89.0717","0.1419","0.0718"
"44.4000","3.6940","14.1560","89.3989","0.1431","0.0724"
"44.5000","3.7023","14.2007","89.6813","0.1431","0.0724"
"44.6000","3.7108","14.2505","89.9960","0.1446","0.0732"
"44.7000","3.7192","14.2930","90.2646","0.1452","0.0735"
"44.8000","3.7275","14.3419","90.5732","0.1454","0.0735"
"44.9000","3.7357","14.3847","90.8432","0.1458","0.0738"
"45.0000","3.7441","14.4368","91.1726","0.1468","0.0743"
"45.1000","3.7525","14.4837","91.4689","0.1466","0.0742"
"45.2000","3.7609","14.5339","91.7856","0.1467","0.0742"
"45.3000","3.7691","14.5773","92.0596","0.1473","0.0745"
"45.4000","3.7774","14.6247","92.3591","0.1485","0.0751"
"45.5000","3.7855","14.6715","92.6548","0.1477","0.0747"
"45.6000","3.7940","14.7232","92.9811","0.1484","0.0751"
"45.7000","3.8023","14.7674","93.2606","0.1484","0.0751"
"45.8000","3.8109","14.8185","93.5833","0.1497","0.0757"
"45.9000","3.8191","14.8615","93.8548","0.1501","0.0759"
"46.0000","3.8274","14.9074","94.1441","0.1504","0.0761"
"46.1000","3.8355","14.9523","94.4279","0.1514","0.0766"
"46.2000","3.8440","15.0041","94.7554","0.1525","0.0771"
"46.3000","3.8524","15.0510","95.0515","0.1532","0.0775"
"46.4000","3.8608","15.0991","95.3549","0.1526","0.0772"
"46.5000","3.8689","15.1401","95.6141","0.1542","0.0780"
"46.6000","3.8770","15.1792","95.8606","0.1539","0.0778"
"46.7000","3.8854","15.2320","96.1940","0.1541","0.0779"
"46.8000","3.8939","15.2800","96.4973","0.1548","0.0783"
"46.9000","3.9023","15.3278","96.7993","0.1548","0.0783"
"47.0000","3.9106","15.3709","97.0714","0.1560","0.0789"
"47.1000","3.9189","15.4184","97.3717","0.1573","0.0796"
"47.2000","3.9270","15.4609","97.6402","0.1575","0.0797"
"47.3000","3.9356","15.5160","97.9876","0.1581","0.0800"
"47.4000","3.9439","15.5588","98.2582","0.1584","0.0801"
"47.5000","3.9523","15.6059","98.5558","0.1585","0.0802"
"47.6000","3.9606","15.6451","98.8033","0.1594","0.0807"
"47.7000","3.9688","15.6818","99.0351","0.1604","0.0811"
"47.8000","3.9769","15.7217","99.2868","0.1608","0.0813"
"47.9000","3.9856","15.7717","99.6028","0.1631","0.0825"
"48.0000","3.9939","15.8046","99.8103","0.1640","0.0830"
"48.1000","4.0025","15.8493","100.0930","0.1655","0.0837"
"48.2000","4.0106","15.8787","100.2782","0.1663","0.0841"
"48.3000","4.0190","15.9212","100.5469","0.1677","0.0848"
"48.4000","4.0273","15.9564","100.7694","0.1690","0.0855"
"48.5000","4.0357","15.9916","100.9911","0.1696","0.0858"
"48.6000","4.0440","16.0231","101.1907","0.1719","0.0869"
"48.7000","4.0526","16.0580","101.4106","0.1737","0.0879"
"48.8000","4.0607","16.0769","101.5298","0.1748","0.0884"
"48.9000","4.0689","16.1023","101.6907","0.1762","0.0892"
"49.0000","4.0774","16.1280","101.8530","0.1766","0.0894"
"49.1000","4.0858","16.1437","101.9520","0.1776","0.0899"
"49.2000","4.0942","16.1587","102.0466","0.1780","0.0900"
"49.3000","4.1026","16.1746","102.1470","0.1798","0.0910"
"49.4000","4.1108","16.1818","102.1924","0.1802","0.0911"
"49.5000","4.1190","16.1874","102.2283","0.1818","0.0920"
"49.6000","4.1275","16.1899","102.2439","0.1818","0.0920"
"49.7000","4.1357","16.1841","102.2069","0.1832","0.0927"
"49.8000","4.1441","16.1730","102.1367","0.1836","0.0929"
"49.9000","4.1525","16.1441","101.9545","0.1834","0.0928"
"50.0000","4.1606","16.0835","101.5717","0.1815","0.0918"
"50.1000","4.1687","15.9596","100.7896","0.1769","0.0895"
"50.2000","4.1773","15.6870","99.0677","0.1686","0.0853"
"50.3000","4.1857","15.2288","96.1740","0.1507","0.0763"
"50.4000","4.1942","14.8167","93.5718","0.1381","0.0699"
"50.5000","4.2025","13.9860","88.3252","0.1116","0.0564"
"50.6000","4.2108","13.5138","85.3436","0.0969","0.0490"
"50.7000","4.2188","13.3458","84.2822","0.0929","0.0470"
"50.8000","4.2272","13.2840","83.8923","0.0911","0.0461"
"50.9000","4.2355","13.2551","83.7096","0.0906","0.0458"
"51.0000","4.2441","13.2487","83.6695","0.0897","0.0454"
"51.1000","4.2521","13.2215","83.4978","0.0886","0.0448"
"51.2000","4.2606","13.1933","83.3193","0.0878","0.0444"
"51.3000","4.2686","13.1281","82.9074","0.0889","0.0450"
"51.4000","4.2772","13.0518","82.4257","0.0887","0.0449"
"51.5000","4.2855","12.9429","81.7378","0.0885","0.0448"
"51.6000","4.2942","12.8155","80.9336","0.0886","0.0448"
"51.7000","4.3022","12.6454","79.8591","0.0883","0.0447"
"51.8000","4.3106","12.4461","78.6007","0.0878","0.0444"
"51.9000","4.3189","12.1506","76.7342","0.0864","0.0437"
"52.0000","4.3275","11.3365","71.5930","0.0843","0.0426"
"52.1000","4.3384","4.5698","28.8598","0.0539","0.0273"
"52.2000","4.3438","4.6871","29.6004","0.0525","0.0266"
"52.3000","4.3524","4.6634","29.4504","0.0531","0.0269"
"52.4000","4.3606","4.6488","29.3585","0.0526","0.0266"
"52.5000","4.3689","4.6413","29.3112","0.0535","0.0270"
"52.6000","4.3774","4.6369","29.2834","0.0541","0.0274"
"52.7000","4.3858","4.6324","29.2552","0.0536","0.0271"
"52.8000","4.3941","4.6288","29.2320","0.0529","0.0267"
"52.9000","4.4025","4.6266","29.2184","0.0530","0.0268"
"53.0000","4.4108","4.6235","29.1987","0.0524","0.0265"
"53.1000","4.4190","4.6228","29.1946","0.0525","0.0266"
"53.2000","4.4274","4.6225","29.1921","0.0515","0.0261"
"53.3000","4.4358","4.6200","29.1769","0.0524","0.0265"
"53.4000","4.4442","4.6186","29.1675","0.0520","0.0263"
"53.5000","4.4524","4.6199","29.1760","0.0523","0.0265"
"53.6000","4.4607","4.6210","29.1829","0.0528","0.0267"
"53.7000","4.4690","4.6224","29.1921","0.0518","0.0262"
"53.8000","4.4773","4.6250","29.2082","0.0530","0.0268"
"53.9000","4.4859","4.6282","29.2285","0.0538","0.0272"
"54.0000","4.4941","4.6240","29.2019","0.0530","0.0268"
"54.1000","4.5023","4.6240","29.2021","0.0534","0.0270"
"54.2000","4.5107","4.6289","29.2325","0.0531","0.0268"
"54.3000","4.5188","4.6251","29.2090","0.0524","0.0265"
"54.4000","4.5272","4.6329","29.2581","0.0530","0.0268"
"54.5000","4.5359","4.6382","29.2914","0.0521","0.0263"
"54.6000","4.5440","4.6316","29.2497","0.0537","0.0272"
"54.7000","4.5522","4.6335","29.2617","0.0526","0.0266"
"54.8000","4.5605","4.6373","29.2857","0.0535","0.0271"
"54.9000","4.5688","4.6382","29.2917","0.0537","0.0272"
"55.0000","4.5772","4.6366","29.2812","0.0535","0.0271"
"55.1000","4.5858","4.6347","29.2693","0.0521","0.0263"
"55.2000","4.5939","4.6294","29.2358","0.0528","0.0267"
"55.3000","4.6023","4.6345","29.2681","0.0524","0.0265"
"55.4000","4.6105","4.6327","29.2569","0.0525","0.0266"
"55.5000","4.6189","4.6385","29.2933","0.0525","0.0266"
"55.6000","4.6273","4.6414","29.3118","0.0528","0.0267"
"55.7000","4.6356","4.6387","29.2945","0.0531","0.0268"
"55.8000","4.6438","4.6394","29.2989","0.0527","0.0267"
"55.9000","4.6523","4.6439","29.3278","0.0525","0.0266"
"56.0000","4.6604","4.6418","29.3140","0.0531","0.0268"
"56.1000","4.6689","4.6484","29.3561","0.0526","0.0266"
"56.2000","4.6774","4.6489","29.3593","0.0527","0.0267"
"56.3000","4.6856","4.6456","29.3380","0.0530","0.0268"
"56.4000","4.6940","4.6507","29.3703","0.0526","0.0266"
"56.5000","4.7024","4.6547","29.3957","0.0526","0.0266"
"56.6000","4.7106","4.6549","29.3969","0.0530","0.0268"
"56.7000","4.7191","4.6627","29.4460","0.0529","0.0268"
"56.8000","4.7275","4.6654","29.4631","0.0524","0.0265"
"56.9000","4.7357","4.6633","29.4500","0.0521","0.0263"
"57.0000","4.7441","4.6698","29.4909","0.0528","0.0267"
"57.1000","4.7523","4.6685","29.4827","0.0531","0.0269"
"57.2000","4.7606","4.6716","29.5022","0.0529","0.0268"
"57.3000","4.7691","4.6758","29.5292","0.0524","0.0265"
"57.4000","4.7774","4.6748","29.5230","0.0522","0.0264"
"57.5000","4.7857","4.6792","29.5506","0.0528","0.0267"
"57.6000","4.7942","4.6848","29.5856","0.0545","0.0276"
"57.7000","4.8024","4.6823","29.5701","0.0534","0.0270"
"57.8000","4.8107","4.6874","29.6020","0.0521","0.0264"
"57.9000","4.8191","4.6911","29.6257","0.0523","0.0265"
"58.0000","4.8274","4.6857","29.5915","0.0534","0.0270"
"58.1000","4.8356","4.6844","29.5833","0.0532","0.0269"
"58.2000","4.8440","4.6892","29.6136","0.0524","0.0265"
"58.3000","4.8522","4.6857","29.5915","0.0525","0.0266"
"58.4000","4.8605","4.6853","29.5892","0.0524","0.0265"
"58.5000","4.8691","4.6916","29.6290","0.0516","0.0261"
"58.6000","4.8773","4.6875","29.6031","0.0528","0.0267"
"58.7000","4.8856","4.6879","29.6054","0.0527","0.0267"
"58.8000","4.8941","4.6900","29.6185","0.0522","0.0264"
"58.9000","4.9021","4.6867","29.5981","0.0524","0.0265"
"59.0000","4.9105","4.6936","29.6415","0.0530","0.0268"
"59.1000","4.9190","4.6931","29.6380","0.0520","0.0263"
"59.2000","4.9272","4.6880","29.6062","0.0523","0.0264"
"59.3000","4.9355","4.6921","29.6316","0.0526","0.0266"
"59.4000","4.9438","4.6895","29.6158","0.0518","0.0262"
"59.5000","4.9519","4.6894","29.6150","0.0528","0.0267"
"59.6000","4.9607","4.6994","29.6783","0.0534","0.0270"
"59.7000","4.9689","4.6918","29.6299","0.0529","0.0268"
"59.8000","4.9772","4.6918","29.6298","0.0519","0.0262"
"59.9000","4.9856","4.6955","29.6534","0.0522","0.0264"
"60.0000","4.9938","4.6905","29.6216","0.0521","0.0263"
"60.1000","5.0022","4.6993","29.6773","0.0524","0.0265"
"60.2000","5.0107","4.7019","29.6936","0.0526","0.0266"
"60.3000","5.0191","4.7007","29.6863","0.0518","0.0262"
"60.4000","5.0273","4.7016","29.6917","0.0537","0.0272"
"60.5000","5.0357","4.7071","29.7265","0.0521","0.0263"
"60.6000","5.0438","4.7028","29.6996","0.0515","0.0260"
"60.7000","5.0523","4.7121","29.7582","0.0516","0.0261"
"60.8000","5.0609","4.7130","29.7642","0.0518","0.0262"
"60.9000","5.0691","4.7048","29.7119","0.0515","0.0261"
"61.0000","5.0774","4.7067","29.7239","0.0522","0.0264"
"61.1000","5.0859","4.7110","29.7512","0.0519","0.0262"
"61.2000","5.0940","4.7054","29.7160","0.0522","0.0264"
"61.3000","5.1024","4.7126","29.7616","0.0522","0.0264"
"61.4000","5.1109","4.7114","29.7536","0.0519","0.0263"
"61.5000","5.1191","4.7065","29.7228","0.0518","0.0262"
"61.6000","5.1274","4.7089","29.7382","0.0523","0.0264"
"61.7000","5.1358","4.7073","29.7278","0.0520","0.0263"
"61.8000","5.1439","4.7069","29.7256","0.0516","0.0261"
"61.9000","5.1525","4.7158","29.7816","0.0524","0.0265"
"62.0000","5.1609","4.7109","29.7508","0.0523","0.0265"
"62.1000","5.1690","4.7088","29.7374","0.0517","0.0262"
"62.2000","5.1775","4.7129","29.7630","0.0517","0.0262"
"62.3000","5.1858","4.7041","29.7076","0.0512","0.0259"
"62.4000","5.1939","4.7049","29.7131","0.0517","0.0261"
"62.5000","5.2024","4.7079","29.7320","0.0526","0.0266"
"62.6000","5.2107","4.7059","29.7190","0.0520","0.0263"
"62.7000","5.2190","4.7043","29.7091","0.0523","0.0265"
"62.8000","5.2274","4.7053","29.7151","0.0510","0.0258"
"62.9000","5.2353","4.6974","29.6652","0.0519","0.0263"
"63.0000","5.2438","4.7031","29.7013","0.0522","0.0264"
"63.1000","5.2523","4.7017","29.6923","0.0511","0.0258"
"63.2000","5.2605","4.6961","29.6572","0.0519","0.0263"
"63.3000","5.2690","4.7009","29.6874","0.0523","0.0264"
"63.4000","5.2773","4.6977","29.6675","0.0522","0.0264"
"63.5000","5.2854","4.6925","29.6342","0.0525","0.0265"
"63.6000","5.2939","4.6984","29.6716","0.0516","0.0261"
"63.7000","5.3022","4.6936","29.6416","0.0516","0.0261"
"63.8000","5.3106","4.6944","29.6462","0.0526","0.0266"
"63.9000","5.3189","4.6952","29.6512","0.0521","0.0263"
"64.0000","5.3271","4.6934","29.6398","0.0511","0.0259"
"64.1000","5.3354","4.6985","29.6720","0.0519","0.0262"
"64.2000","5.3439","4.7028","29.6994","0.0508","0.0257"
"64.3000","5.3523","4.6995","29.6785","0.0519","0.0263"
"64.4000","5.3607","4.6998","29.6808","0.0506","0.0256"
"64.5000","5.3691","4.7018","29.6931","0.0514","0.0260"
"64.6000","5.3772","4.6986","29.6728","0.0517","0.0262"
"64.7000","5.3856","4.7060","29.7197","0.0518","0.0262"
"64.8000","5.3941","4.7049","29.7130","0.0521","0.0264"
"64.9000","5.4023","4.7005","29.6852","0.0518","0.0262"
"65.0000","5.4107","4.7023","29.6962","0.0513","0.0259"
"65.1000","5.4191","4.7039","29.7068","0.0512","0.0259"
"65.2000","5.4272","4.6985","29.6722","0.0502","0.0254"
"65.3000","5.4356","4.7090","29.7389","0.0522","0.0264"
"65.4000","5.4442","4.7075","29.7290","0.0516","0.0261"
"65.5000","5.4524","4.7032","29.7020","0.0512","0.0259"
"65.6000","5.4608","4.7066","29.7236","0.0514","0.0260"
"65.7000","5.4693","4.7055","29.7167","0.0502","0.0254"
"65.8000","5.4773","4.7014","29.6908","0.0511","0.0258"
"65.9000","5.4858","4.7106","29.7491","0.0495","0.0250"
"66.0000","5.4942","4.7087","29.7365","0.0498","0.0252"
"66.1000","5.5024","4.7093","29.7405","0.0494","0.0250"
"66.2000","5.5108","4.7111","29.7517","0.0506","0.0256"
"66.3000","5.5190","4.7073","29.7277","0.0497","0.0252"
"66.4000","5.5271","4.7053","29.7153","0.0504","0.0255"
"66.5000","5.5356","4.7102","29.7462","0.0496","0.0251"
"66.6000","5.5440","4.7051","29.7140","0.0499","0.0253"
"66.7000","5.5523","4.7061","29.7202","0.0520","0.0263"
"66.8000","5.5608","4.7086","29.7360","0.0504","0.0255"
"66.9000","5.5690","4.7040","29.7072","0.0493","0.0249"
"67.0000","5.5771","4.7038","29.7059","0.0501","0.0253"
"67.1000","5.5856","4.7096","29.7425","0.0503","0.0254"
"67.2000","5.5938","4.7028","29.6992","0.0492","0.0249"
"67.3000","5.6023","4.7048","29.7118","0.0513","0.0259"
"67.4000","5.6107","4.7048","29.7123","0.0517","0.0262"
"67.5000","5.6186","4.6971","29.6635","0.0494","0.0250"
"67.6000","5.6271","4.7097","29.7430","0.0495","0.0250"
"67.7000","5.6356","4.7116","29.7553","0.0502","0.0254"
"67.8000","5.6438","4.7078","29.7310","0.0507","0.0256"
"67.9000","5.6522","4.7134","29.7666","0.0499","0.0252"
"68.0000","5.6608","4.7154","29.7788","0.0499","0.0252"
"68.1000","5.6687","4.7089","29.7378","0.0503","0.0255"
"68.2000","5.6772","4.7234","29.8296","0.0503","0.0254"
"68.3000","5.6857","4.7199","29.8075","0.0508","0.0257"
"68.4000","5.6939","4.7183","29.7972","0.0509","0.0257"
"68.5000","5.7023","4.7247","29.8376","0.0508","0.0257"
"68.6000","5.7106","4.7215","29.8177","0.0509","0.0257"
"68.7000","5.7186","4.7195","29.8051","0.0510","0.0258"
"68.8000","5.7274","4.7362","29.9102","0.0520","0.0263"
"68.9000","5.7357","4.7244","29.8358","0.0513","0.0260"
"69.0000","5.7441","4.7283","29.8607","0.0522","0.0264"
"69.1000","5.7526","4.7289","29.8641","0.0527","0.0267"
"69.2000","5.7607","4.7194","29.8041","0.0509","0.0258"
"69.3000","5.7689","4.7241","29.8340","0.0497","0.0252"
"69.4000","5.7776","4.7320","29.8839","0.0505","0.0256"
"69.5000","5.7858","4.7222","29.8218","0.0499","0.0252"
"69.6000","5.7942","4.7297","29.8693","0.0493","0.0250"
"69.7000","5.8026","4.7269","29.8514","0.0497","0.0251"
"69.8000","5.8106","4.7236","29.8311","0.0507","0.0257"
"69.9000","5.8189","4.7325","29.8873","0.0510","0.0258"
"70.0000","5.8275","4.7336","29.8940","0.0512","0.0259"
"70.1000","5.8357","4.7291","29.8656","0.0505","0.0256"
"70.2000","5.8442","4.7336","29.8939","0.0498","0.0252"
"70.3000","5.8526","4.7300","29.8711","0.0502","0.0254"
"70.4000","5.8607","4.7268","29.8512","0.0489","0.0247"
"70.5000","5.8690","4.7280","29.8590","0.0479","0.0242"
"70.6000","5.8774","4.7250","29.8394","0.0492","0.0249"
"70.7000","5.8856","4.7229","29.8263","0.0478","0.0242"
"70.8000","5.8941","4.7249","29.8392","0.0490","0.0248"
"70.9000","5.9023","4.7171","29.7899","0.0491","0.0249"
"71.0000","5.9104","4.7165","29.7859","0.0492","0.0249"
"71.1000","5.9189","4.7210","29.8143","0.0496","0.0251"
"71.2000","5.9271","4.7157","29.7811","0.0487","0.0247"
"71.3000","5.9355","4.7177","29.7938","0.0492","0.0249"
"71.4000","5.9440","4.7146","29.7743","0.0494","0.0250"
"71.5000","5.9521","4.7097","29.7432","0.0488","0.0247"
"71.6000","5.9604","4.7126","29.7612","0.0488","0.0247"
"71.7000","5.9689","4.7164","29.7854","0.0485","0.0246"
"71.8000","5.9771","4.7106","29.7488","0.0497","0.0251"
"71.9000","5.9856","4.7152","29.7778","0.0502","0.0254"
"72.0000","5.9939","4.7106","29.7485","0.0488","0.0247"
"72.1000","6.0021","4.7082","29.7338","0.0491","0.0248"
"72.2000","6.0102","4.7087","29.7370","0.0489","0.0247"
"72.3000","6.0189","4.7147","29.7745","0.0488","0.0247"
"72.4000","6.0271","4.7103","29.7467","0.0491","0.0249"
"72.5000","6.0357","4.7133","29.7658","0.0486","0.0246"
"72.6000","6.0440","4.7028","29.6997","0.0492","0.0249"
"72.7000","6.0523","4.7024","29.6969","0.0484","0.0245"
"72.8000","6.0607","4.7033","29.7025","0.0506","0.0256"
"72.9000","6.0690","4.7001","29.6824","0.0490","0.0248"
"73.0000","6.0773","4.6976","29.6667","0.0491","0.0248"
"73.1000","6.0859","4.7014","29.6904","0.0485","0.0245"
"73.2000","6.0941","4.6936","29.6416","0.0487","0.0246"
"73.3000","6.1023","4.6924","29.6336","0.0486","0.0246"
"73.4000","6.1107","4.6984","29.6716","0.0488","0.0247"
"73.5000","6.1191","4.6928","29.6365","0.0478","0.0242"
"73.6000","6.1274","4.6900","29.6184","0.0476","0.0241"
"73.7000","6.1360","4.6918","29.6303","0.0492","0.0249"
"73.8000","6.1441","4.6823","29.5697","0.0483","0.0245"
"73.9000","6.1524","4.6854","29.5899","0.0485","0.0245"
"74.0000","6.1607","4.6864","29.5962","0.0486","0.0246"
"74.1000","6.1692","4.6853","29.5891","0.0484","0.0245"
"74.2000","6.1774","4.6834","29.5768","0.0476","0.0241"
"74.3000","6.1858","4.6818","29.5669","0.0484","0.0245"
"74.4000","6.1940","4.6788","29.5482","0.0471","0.0238"
"74.5000","6.2022","4.6751","29.5246","0.0474","0.0240"
"74.6000","6.2105","4.6738","29.5164","0.0487","0.0246"
"74.7000","6.2191","4.6732","29.5124","0.0473","0.0240"
"74.8000","6.2274","4.6670","29.4734","0.0486","0.0246"
"74.9000","6.2358","4.6604","29.4316","0.0486","0.0246"
"75.0000","6.2439","4.6540","29.3913","0.0483","0.0244"
"75.1000","6.2522","4.6498","29.3649","0.0470","0.0238"
"75.2000","6.2606","4.6474","29.3495","0.0468","0.0237"
"75.3000","6.2688","4.6440","29.3279","0.0465","0.0235"
"75.4000","6.2773","4.6451","29.3350","0.0478","0.0242"
"75.5000","6.2856","4.6373","29.2860","0.0473","0.0240"
"75.6000","6.2937","4.6334","29.2612","0.0477","0.0241"
"75.7000","6.3021","4.6373","29.2860","0.0468","0.0237"
"75.8000","6.3105","4.6368","29.2824","0.0464","0.0235"
"75.9000","6.3188","4.6326","29.2562","0.0466","0.0236"
"76.0000","6.3275","4.6346","29.2686","0.0476","0.0241"
"76.1000","6.3356","4.6197","29.1744","0.0459","0.0232"
"76.2000","6.3439","4.6174","29.1603","0.0473","0.0239"
"76.3000","6.3523","4.6148","29.1441","0.0477","0.0242"
"76.4000","6.3605","4.6087","29.1051","0.0471","0.0238"
"76.5000","6.3689","4.6075","29.0974","0.0478","0.0242"
"76.6000","6.3776","4.6078","29.0994","0.0466","0.0236"
"76.7000","6.3855","4.5965","29.0285","0.0457","0.0231"
"76.8000","6.3938","4.6001","29.0507","0.0460","0.0233"
"76.9000","6.4023","4.5977","29.0357","0.0460","0.0233"
"77.0000","6.4106","4.5910","28.9936","0.0458","0.0232"
"77.1000","6.4192","4.5940","29.0125","0.0460","0.0233"
"77.2000","6.4275","4.5831","28.9435","0.0470","0.0238"
"77.3000","6.4357","4.5817","28.9344","0.0457","0.0231"
"77.4000","6.4441","4.5828","28.9416","0.0466","0.0236"
"77.5000","6.4524","4.5748","28.8914","0.0464","0.0235"
"77.6000","6.4607","4.5737","28.8841","0.0459","0.0232"
"77.7000","6.4692","4.5714","28.8698","0.0472","0.0239"
"77.8000","6.4774","4.5597","28.7955","0.0463","0.0234"
"77.9000","6.4856","4.5555","28.7692","0.0470","0.0238"
"78.0000","6.4940","4.5536","28.7573","0.0449","0.0227"
"78.1000","6.5023","4.5474","28.7179","0.0459","0.0232"
"78.2000","6.5107","4.5457","28.7076","0.0459","0.0232"
"78.3000","6.5193","4.5435","28.6933","0.0453","0.0229"
"78.4000","6.5275","4.5346","28.6370","0.0471","0.0238"
"78.5000","6.5356","4.5318","28.6198","0.0462","0.0234"
"78.6000","6.5440","4.5315","28.6175","0.0455","0.0230"
"78.7000","6.5523","4.5264","28.5855","0.0459","0.0232"
"78.8000","6.5606","4.5233","28.5661","0.0456","0.0230"
"78.9000","6.5692","4.5189","28.5379","0.0455","0.0230"
"79.0000","6.5772","4.5112","28.4893","0.0449","0.0227"
"79.1000","6.5856","4.5090","28.4759","0.0454","0.0230"
"79.2000","6.5938","4.5029","28.4374","0.0454","0.0230"
"79.3000","6.6021","4.4997","28.4168","0.0452","0.0229"
"79.4000","6.6106","4.4966","28.3973","0.0447","0.0226"
"79.5000","6.6192","4.4900","28.3557","0.0449","0.0227"
"79.6000","6.6272","4.4804","28.2950","0.0449","0.0227"
"79.7000","6.6356","4.4804","28.2952","0.0452","0.0229"
"79.8000","6.6438","4.4695","28.2262","0.0455","0.0230"
"79.9000","6.6521","4.4695","28.2264","0.0440","0.0222"
"80.0000","6.6607","4.4681","28.2176","0.0448","0.0226"
"80.1000","6.6689","4.4554","28.1368","0.0446","0.0226"
"80.2000","6.6772","4.4517","28.1137","0.0442","0.0224"
"80.3000","6.6855","4.4466","28.0814","0.0437","0.0221"
"80.4000","6.6937","4.4407","28.0445","0.0435","0.0220"
"80.5000","6.7022","4.4375","28.0240","0.0431","0.0218"
"80.6000","6.7108","4.4352","28.0094","0.0431","0.0218"
"80.7000","6.7190","4.4228","27.9314","0.0440","0.0223"
"80.8000","6.7273","4.4200","27.9137","0.0436","0.0221"
"80.9000","6.7356","4.4129","27.8687","0.0447","0.0226"
"81.0000","6.7439","4.4083","27.8393","0.0451","0.0228"
"81.1000","6.7523","4.4052","27.8198","0.0457","0.0231"
"81.2000","6.7608","4.3973","27.7703","0.0448","0.0226"
"81.3000","6.7690","4.3845","27.6893","0.0439","0.0222"
"81.4000","6.7773","4.3829","27.6791","0.0434","0.0220"
"81.5000","6.7856","4.3760","27.6355","0.0436","0.0221"
"81.6000","6.7939","4.3717","27.6088","0.0438","0.0222"
"81.7000","6.8024","4.3670","27.5791","0.0441","0.0223"
"81.8000","6.8109","4.3572","27.5168","0.0436","0.0221"
"81.9000","6.8191","4.3475","27.4555","0.0433","0.0219"
"82.0000","6.8275","4.3432","27.4287","0.0420","0.0213"
"82.1000","6.8357","4.3344","27.3730","0.0419","0.0212"
"82.2000","6.8441","4.3318","27.3568","0.0431","0.0218"
"82.3000","6.8526","4.3246","27.3113","0.0418","0.0212"
"82.4000","6.8609","4.3125","27.2349","0.0431","0.0218"
"82.5000","6.8691","4.3056","27.1913","0.0426","0.0216"
"82.6000","6.8774","4.2995","27.1525","0.0426","0.0215"
"82.7000","6.8855","4.2878","27.0789","0.0419","0.0212"
"82.8000","6.8940","4.2829","27.0474","0.0421","0.0213"
"82.9000","6.9025","4.2772","27.0119","0.0424","0.0215"
"83.0000","6.9107","4.2632","26.9233","0.0434","0.0220"
"83.1000","6.9190","4.2605","26.9060","0.0416","0.0211"
"83.2000","6.9274","4.2523","26.8548","0.0417","0.0211"
"83.3000","6.9355","4.2409","26.7824","0.0424","0.0214"
"83.4000","6.9439","4.2356","26.7488","0.0423","0.0214"
"83.5000","6.9525","4.2284","26.7037","0.0426","0.0215"
"83.6000","6.9605","4.2122","26.6013","0.0418","0.0212"
"83.7000","6.9688","4.2105","26.5903","0.0412","0.0209"
"83.8000","6.9772","4.1991","26.5185","0.0418","0.0211"
"83.9000","6.9852","4.1884","26.4510","0.0417","0.0211"
"84.0000","6.9941","4.1907","26.4657","0.0413","0.0209"
"84.1000","7.0023","4.1731","26.3545","0.0426","0.0216"
"84.2000","7.0105","4.1670","26.3160","0.0399","0.0202"
"84.3000","7.0190","4.1644","26.2991","0.0410","0.0207"
"84.4000","7.0271","4.1461","26.1836","0.0399","0.0202"
"84.5000","7.0354","4.1413","26.1538","0.0417","0.0211"
"84.6000","7.0441","4.1389","26.1386","0.0410","0.0208"
"84.7000","7.0523","4.1189","26.0118","0.0409","0.0207"
"84.8000","7.0605","4.1135","25.9778","0.0402","0.0203"
"84.9000","7.0690","4.1091","25.9503","0.0401","0.0203"
"85.0000","7.0771","4.0964","25.8698","0.0402","0.0204"
"85.1000","7.0855","4.0956","25.8650","0.0402","0.0203"
"85.2000","7.0942","4.0895","25.8262","0.0406","0.0205"
"85.3000","7.1023","4.0749","25.7341","0.0399","0.0202"
"85.4000","7.1108","4.0735","25.7255","0.0416","0.0211"
"85.5000","7.1192","4.0597","25.6385","0.0399","0.0202"
"85.5350","7.1217","4.0478","25.5627","0.0399","0.0202"