File: composites_properties_derivations/composite_tube_tests/comp_tube_7.csv
Specimen label,"7"
Force at Maximum Load,"13.38",kN
Tensile stress at Maximum Load,"84.48",MPa
Epsilon ONE Displacement at Maximum Load,"0.09",mm
Force at Break (Standard),"13.27",kN
Tensile stress at Break (Standard),"83.82",MPa
Epsilon ONE Displacement at Break (Standard),"0.09",mm
Slope (Chord 0.05 % - 0.2 %),"-----",MPa
Modulus (Automatic Young's),"56096.51",MPa

Specimen label,"7"
Thickness,"",mm
Width,"",mm
Length,"53.02",mm
Rate 1,"5.00",mm/min
Outer diameter,"19.05",mm
Wall thickness,"3.18",mm

Time,Displacement,Force,Tensile stress,Tensile strain (Epsilon ONE Displacement),Epsilon ONE Displacement
(s),(mm),(kN),(MPa),(%),(mm)
"0.0000","0.0000","0.0619","0.3910","0.0164","0.0087"
"0.0500","0.0001","0.0625","0.3946","0.0142","0.0075"
"0.1000","0.0011","0.0792","0.4999","0.0137","0.0072"
"0.1500","0.0029","0.1247","0.7874","0.0157","0.0083"
"0.2000","0.0039","0.1354","0.8552","0.0160","0.0085"
"0.2500","0.0098","0.1947","1.2298","0.0172","0.0091"
"0.3000","0.0175","0.2457","1.5516","0.0170","0.0090"
"0.3500","0.0216","0.2619","1.6542","0.0167","0.0089"
"0.4000","0.0254","0.2807","1.7725","0.0171","0.0091"
"0.4500","0.0297","0.2988","1.8870","0.0173","0.0092"
"0.5000","0.0340","0.3149","1.9885","0.0168","0.0089"
"0.5500","0.0381","0.3299","2.0831","0.0168","0.0089"
"0.6000","0.0422","0.3435","2.1692","0.0166","0.0088"
"0.6500","0.0464","0.3570","2.2548","0.0158","0.0084"
"0.7000","0.0507","0.3701","2.3372","0.0171","0.0091"
"0.7500","0.0546","0.3816","2.4098","0.0170","0.0090"
"0.8000","0.0587","0.3935","2.4853","0.0179","0.0095"
"0.8500","0.0628","0.4039","2.5508","0.0180","0.0095"
"0.9000","0.0670","0.4144","2.6168","0.0171","0.0090"
"0.9500","0.0713","0.4264","2.6927","0.0180","0.0095"
"1.0000","0.0757","0.4367","2.7577","0.0167","0.0088"
"1.0500","0.0797","0.4468","2.8214","0.0163","0.0086"
"1.1000","0.0839","0.4558","2.8786","0.0167","0.0089"
"1.1500","0.0880","0.4652","2.9379","0.0176","0.0093"
"1.2000","0.0922","0.4736","2.9912","0.0173","0.0092"
"1.2500","0.0965","0.4830","3.0502","0.0176","0.0093"
"1.3000","0.1007","0.4900","3.0947","0.0178","0.0094"
"1.3500","0.1046","0.4988","3.1501","0.0166","0.0088"
"1.4000","0.1088","0.5057","3.1935","0.0178","0.0094"
"1.4500","0.1128","0.5147","3.2505","0.0184","0.0097"
"1.5000","0.1172","0.5221","3.2971","0.0181","0.0096"
"1.5500","0.1214","0.5307","3.3518","0.0179","0.0095"
"1.6000","0.1256","0.5374","3.3937","0.0188","0.0100"
"1.6500","0.1297","0.5456","3.4458","0.0178","0.0094"
"1.7000","0.1339","0.5530","3.4923","0.0182","0.0097"
"1.7500","0.1380","0.5611","3.5435","0.0182","0.0097"
"1.8000","0.1423","0.5681","3.5874","0.0178","0.0094"
"1.8500","0.1463","0.5757","3.6356","0.0176","0.0093"
"1.9000","0.1505","0.5829","3.6812","0.0183","0.0097"
"1.9500","0.1543","0.5905","3.7291","0.0180","0.0095"
"2.0000","0.1588","0.5987","3.7807","0.0178","0.0094"
"2.0500","0.1628","0.6057","3.8254","0.0168","0.0089"
"2.1000","0.1673","0.6144","3.8799","0.0169","0.0089"
"2.1500","0.1713","0.6213","3.9235","0.0171","0.0091"
"2.2000","0.1757","0.6297","3.9766","0.0179","0.0095"
"2.2500","0.1796","0.6363","4.0186","0.0177","0.0094"
"2.3000","0.1840","0.6449","4.0727","0.0176","0.0093"
"2.3500","0.1880","0.6515","4.1146","0.0187","0.0099"
"2.4000","0.1925","0.6593","4.1638","0.0189","0.0100"
"2.4500","0.1964","0.6651","4.2001","0.0178","0.0095"
"2.5000","0.2005","0.6726","4.2478","0.0181","0.0096"
"2.5500","0.2045","0.6788","4.2867","0.0178","0.0094"
"2.6000","0.2089","0.6877","4.3433","0.0177","0.0094"
"2.6500","0.2130","0.6935","4.3797","0.0188","0.0100"
"2.7000","0.2174","0.7023","4.4350","0.0169","0.0090"
"2.7500","0.2213","0.7073","4.4670","0.0185","0.0098"
"2.8000","0.2256","0.7170","4.5279","0.0186","0.0098"
"2.8500","0.2297","0.7225","4.5628","0.0188","0.0100"
"2.9000","0.2340","0.7314","4.6188","0.0184","0.0098"
"2.9500","0.2380","0.7367","4.6527","0.0183","0.0097"
"3.0000","0.2422","0.7465","4.7144","0.0185","0.0098"
"3.0500","0.2462","0.7515","4.7460","0.0187","0.0099"
"3.1000","0.2503","0.7609","4.8055","0.0190","0.0101"
"3.1500","0.2545","0.7671","4.8447","0.0190","0.0101"
"3.2000","0.2587","0.7768","4.9059","0.0180","0.0096"
"3.2500","0.2630","0.7833","4.9467","0.0189","0.0100"
"3.3000","0.2672","0.7919","5.0009","0.0191","0.0101"
"3.3500","0.2713","0.7982","5.0410","0.0191","0.0101"
"3.4000","0.2754","0.8075","5.0999","0.0186","0.0099"
"3.4500","0.2797","0.8138","5.1393","0.0189","0.0100"
"3.5000","0.2838","0.8228","5.1965","0.0184","0.0098"
"3.5500","0.2882","0.8299","5.2412","0.0181","0.0096"
"3.6000","0.2923","0.8381","5.2930","0.0192","0.0102"
"3.6500","0.2964","0.8445","5.3334","0.0186","0.0099"
"3.7000","0.3003","0.8535","5.3899","0.0180","0.0095"
"3.7500","0.3047","0.8609","5.4368","0.0184","0.0097"
"3.8000","0.3087","0.8691","5.4887","0.0187","0.0099"
"3.8500","0.3132","0.8774","5.5413","0.0183","0.0097"
"3.9000","0.3172","0.8845","5.5856","0.0173","0.0092"
"3.9500","0.3215","0.8924","5.6360","0.0181","0.0096"
"4.0000","0.3254","0.8998","5.6827","0.0175","0.0093"
"4.0500","0.3297","0.9084","5.7366","0.0195","0.0104"
"4.1000","0.3338","0.9157","5.7830","0.0184","0.0098"
"4.1500","0.3382","0.9209","5.8155","0.0183","0.0097"
"4.2000","0.3420","0.9204","5.8125","0.0182","0.0096"
"4.2500","0.3462","0.9305","5.8762","0.0185","0.0098"
"4.3000","0.3501","0.9393","5.9322","0.0186","0.0099"
"4.3500","0.3546","0.9500","5.9998","0.0179","0.0095"
"4.4000","0.3588","0.9577","6.0479","0.0189","0.0100"
"4.4500","0.3631","0.9675","6.1097","0.0188","0.0100"
"4.5000","0.3670","0.9748","6.1563","0.0186","0.0099"
"4.5500","0.3714","0.9851","6.2213","0.0192","0.0102"
"4.6000","0.3754","0.9916","6.2622","0.0194","0.0103"
"4.6500","0.3798","1.0028","6.3331","0.0192","0.0102"
"4.7000","0.3840","1.0097","6.3764","0.0202","0.0107"
"4.7500","0.3882","1.0193","6.4372","0.0198","0.0105"
"4.8000","0.3920","1.0255","6.4762","0.0190","0.0101"
"4.8500","0.3963","1.0364","6.5454","0.0190","0.0100"
"4.9000","0.4004","1.0434","6.5891","0.0199","0.0105"
"4.9500","0.4047","1.0545","6.6597","0.0194","0.0103"
"5.0000","0.4089","1.0607","6.6986","0.0191","0.0101"
"5.0500","0.4131","1.0717","6.7680","0.0189","0.0100"
"5.1000","0.4171","1.0782","6.8094","0.0186","0.0099"
"5.1500","0.4214","1.0897","6.8818","0.0191","0.0101"
"5.2000","0.4255","1.0961","6.9222","0.0189","0.0100"
"5.2500","0.4298","1.1078","6.9961","0.0199","0.0106"
"5.3000","0.4339","1.1137","7.0331","0.0192","0.0102"
"5.3500","0.4379","1.1249","7.1038","0.0192","0.0102"
"5.4000","0.4420","1.1318","7.1474","0.0179","0.0095"
"5.4500","0.4460","1.1434","7.2207","0.0186","0.0098"
"5.5000","0.4504","1.1512","7.2704","0.0184","0.0098"
"5.5500","0.4546","1.1622","7.3395","0.0184","0.0097"
"5.6000","0.4590","1.1699","7.3881","0.0184","0.0097"
"5.6500","0.4630","1.1811","7.4590","0.0183","0.0097"
"5.7000","0.4674","1.1893","7.5110","0.0184","0.0098"
"5.7500","0.4713","1.1995","7.5755","0.0187","0.0099"
"5.8000","0.4758","1.2093","7.6369","0.0193","0.0102"
"5.8500","0.4797","1.2190","7.6982","0.0192","0.0102"
"5.9000","0.4841","1.2287","7.7595","0.0189","0.0100"
"5.9500","0.4879","1.2381","7.8191","0.0192","0.0102"
"6.0000","0.4923","1.2485","7.8849","0.0195","0.0103"
"6.0500","0.4962","1.2580","7.9447","0.0191","0.0101"
"6.1000","0.5007","1.2694","8.0168","0.0208","0.0110"
"6.1500","0.5047","1.2780","8.0712","0.0265","0.0140"
"6.2000","0.5091","1.2895","8.1438","0.0286","0.0152"
"6.2500","0.5129","1.2984","8.1995","0.0317","0.0168"
"6.3000","0.5174","1.3105","8.2764","0.0208","0.0110"
"6.3500","0.5213","1.3182","8.3246","0.0203","0.0107"
"6.4000","0.5257","1.3313","8.4075","0.0279","0.0148"
"6.4500","0.5296","1.3391","8.4568","0.0328","0.0174"
"6.5000","0.5340","1.3520","8.5380","0.0284","0.0150"
"6.5500","0.5377","1.3589","8.5820","0.0198","0.0105"
"6.6000","0.5422","1.3734","8.6736","0.0202","0.0107"
"6.6500","0.5462","1.3805","8.7181","0.0201","0.0107"
"6.7000","0.5506","1.3947","8.8079","0.0218","0.0116"
"6.7500","0.5547","1.4019","8.8536","0.0213","0.0113"
"6.8000","0.5590","1.4160","8.9423","0.0314","0.0167"
"6.8500","0.5630","1.4235","8.9898","0.0332","0.0176"
"6.9000","0.5674","1.4377","9.0794","0.0326","0.0173"
"6.9500","0.5713","1.4450","9.1255","0.0321","0.0170"
"7.0000","0.5758","1.4603","9.2223","0.0316","0.0168"
"7.0500","0.5798","1.4671","9.2654","0.0328","0.0174"
"7.1000","0.5840","1.4811","9.3533","0.0338","0.0179"
"7.1500","0.5879","1.4884","9.3995","0.0334","0.0177"
"7.2000","0.5921","1.5031","9.4924","0.0326","0.0173"
"7.2500","0.5963","1.5114","9.5452","0.0326","0.0173"
"7.3000","0.6006","1.5259","9.6367","0.0333","0.0177"
"7.3500","0.6049","1.5347","9.6922","0.0338","0.0179"
"7.4000","0.6090","1.5474","9.7724","0.0342","0.0181"
"7.4500","0.6130","1.5557","9.8244","0.0331","0.0175"
"7.5000","0.6171","1.5700","9.9153","0.0350","0.0186"
"7.5500","0.6215","1.5800","9.9779","0.0336","0.0178"
"7.6000","0.6256","1.5923","10.0558","0.0334","0.0177"
"7.6500","0.6297","1.6010","10.1108","0.0335","0.0177"
"7.7000","0.6336","1.6140","10.1926","0.0354","0.0188"
"7.7500","0.6379","1.6249","10.2615","0.0347","0.0184"
"7.8000","0.6419","1.6369","10.3377","0.0358","0.0190"
"7.8500","0.6465","1.6488","10.4129","0.0350","0.0186"
"7.9000","0.6505","1.6601","10.4840","0.0350","0.0186"
"7.9500","0.6548","1.6718","10.5577","0.0348","0.0185"
"8.0000","0.6587","1.6834","10.6309","0.0360","0.0191"
"8.0500","0.6632","1.6959","10.7100","0.0357","0.0189"
"8.1000","0.6672","1.7074","10.7827","0.0343","0.0182"
"8.1500","0.6717","1.7204","10.8647","0.0370","0.0196"
"8.2000","0.6756","1.7303","10.9272","0.0370","0.0196"
"8.2500","0.6798","1.7423","11.0034","0.0364","0.0193"
"8.3000","0.6835","1.7531","11.0714","0.0356","0.0189"
"8.3500","0.6880","1.7678","11.1641","0.0365","0.0193"
"8.4000","0.6921","1.7787","11.2327","0.0377","0.0200"
"8.4500","0.6966","1.7928","11.3219","0.0383","0.0203"
"8.5000","0.7004","1.8017","11.3784","0.0374","0.0198"
"8.5500","0.7048","1.8175","11.4778","0.0387","0.0205"
"8.6000","0.7087","1.8270","11.5382","0.0410","0.0218"
"8.6500","0.7131","1.8422","11.6340","0.0391","0.0207"
"8.7000","0.7171","1.8519","11.6951","0.0392","0.0208"
"8.7500","0.7216","1.8674","11.7934","0.0393","0.0208"
"8.8000","0.7254","1.8753","11.8433","0.0388","0.0206"
"8.8500","0.7296","1.8921","11.9489","0.0399","0.0212"
"8.9000","0.7334","1.8998","11.9976","0.0391","0.0207"
"8.9500","0.7378","1.9184","12.1151","0.0376","0.0199"
"9.0000","0.7421","1.9275","12.1725","0.0394","0.0209"
"9.0500","0.7464","1.9430","12.2704","0.0408","0.0216"
"9.1000","0.7504","1.9518","12.3264","0.0415","0.0220"
"9.1500","0.7547","1.9695","12.4381","0.0408","0.0216"
"9.2000","0.7590","1.9789","12.4971","0.0402","0.0213"
"9.2500","0.7633","1.9955","12.6022","0.0415","0.0220"
"9.3000","0.7674","2.0041","12.6566","0.0405","0.0215"
"9.3500","0.7715","2.0205","12.7597","0.0410","0.0217"
"9.4000","0.7755","2.0301","12.8207","0.0418","0.0222"
"9.4500","0.7796","2.0460","12.9213","0.0416","0.0220"
"9.5000","0.7837","2.0568","12.9893","0.0409","0.0217"
"9.5500","0.7879","2.0732","13.0929","0.0414","0.0219"
"9.6000","0.7923","2.0845","13.1640","0.0426","0.0226"
"9.6500","0.7964","2.0993","13.2577","0.0429","0.0228"
"9.7000","0.8006","2.1106","13.3288","0.0441","0.0234"
"9.7500","0.8046","2.1262","13.4273","0.0434","0.0230"
"9.8000","0.8090","2.1388","13.5073","0.0432","0.0229"
"9.8500","0.8131","2.1529","13.5963","0.0438","0.0233"
"9.9000","0.8174","2.1651","13.6730","0.0432","0.0229"
"9.9500","0.8212","2.1783","13.7563","0.0439","0.0233"
"10.0000","0.8255","2.1923","13.8449","0.0445","0.0236"
"10.0500","0.8293","2.2050","13.9252","0.0444","0.0236"
"10.1000","0.8338","2.2206","14.0235","0.0453","0.0240"
"10.1500","0.8379","2.2332","14.1031","0.0437","0.0232"
"10.2000","0.8424","2.2482","14.1983","0.0427","0.0226"
"10.2500","0.8462","2.2594","14.2689","0.0436","0.0231"
"10.3000","0.8506","2.2757","14.3718","0.0441","0.0234"
"10.3500","0.8546","2.2877","14.4478","0.0438","0.0232"
"10.4000","0.8592","2.3048","14.5554","0.0446","0.0236"
"10.4500","0.8631","2.3150","14.6201","0.0453","0.0240"
"10.5000","0.8674","2.3313","14.7227","0.0458","0.0243"
"10.5500","0.8712","2.3421","14.7911","0.0464","0.0246"
"10.6000","0.8756","2.3599","14.9037","0.0461","0.0244"
"10.6500","0.8795","2.3702","14.9686","0.0459","0.0243"
"10.7000","0.8840","2.3891","15.0878","0.0446","0.0236"
"10.7500","0.8880","2.3990","15.1505","0.0469","0.0249"
"10.8000","0.8923","2.4158","15.2562","0.0456","0.0242"
"10.8500","0.8962","2.4264","15.3232","0.0453","0.0240"
"10.9000","0.9006","2.4451","15.4416","0.0454","0.0241"
"10.9500","0.9046","2.4553","15.5058","0.0457","0.0242"
"11.0000","0.9090","2.4739","15.6233","0.0478","0.0254"
"11.0500","0.9131","2.4834","15.6836","0.0484","0.0257"
"11.1000","0.9172","2.5007","15.7928","0.0469","0.0248"
"11.1500","0.9211","2.5109","15.8568","0.0490","0.0260"
"11.2000","0.9253","2.5291","15.9719","0.0493","0.0261"
"11.2500","0.9295","2.5410","16.0474","0.0481","0.0255"
"11.3000","0.9338","2.5592","16.1621","0.0477","0.0253"
"11.3500","0.9380","2.5701","16.2308","0.0498","0.0264"
"11.4000","0.9422","2.5870","16.3374","0.0499","0.0265"
"11.4500","0.9463","2.5983","16.4093","0.0497","0.0264"
"11.5000","0.9504","2.6161","16.5216","0.0489","0.0259"
"11.5500","0.9548","2.6292","16.6044","0.0475","0.0252"
"11.6000","0.9590","2.6453","16.7060","0.0481","0.0255"
"11.6500","0.9632","2.6562","16.7749","0.0491","0.0260"
"11.7000","0.9671","2.6729","16.8804","0.0484","0.0257"
"11.7500","0.9713","2.6856","16.9601","0.0482","0.0256"
"11.8000","0.9753","2.7011","17.0584","0.0497","0.0264"
"11.8500","0.9798","2.7177","17.1631","0.0502","0.0266"
"11.9000","0.9839","2.7311","17.2474","0.0499","0.0264"
"11.9500","0.9880","2.7445","17.3322","0.0483","0.0256"
"12.0000","0.9920","2.7604","17.4329","0.0490","0.0260"
"12.0500","0.9964","2.7769","17.5368","0.0510","0.0270"
"12.1000","1.0004","2.7922","17.6333","0.0504","0.0267"
"12.1500","1.0049","2.8102","17.7472","0.0506","0.0268"
"12.2000","1.0089","2.8225","17.8250","0.0510","0.0270"
"12.2500","1.0131","2.8381","17.9231","0.0500","0.0265"
"12.3000","1.0169","2.8507","18.0031","0.0509","0.0270"
"12.3500","1.0213","2.8683","18.1140","0.0497","0.0263"
"12.4000","1.0252","2.8806","18.1919","0.0520","0.0276"
"12.4500","1.0298","2.9005","18.3175","0.0523","0.0277"
"12.5000","1.0337","2.9109","18.3832","0.0537","0.0285"
"12.5500","1.0381","2.9291","18.4980","0.0523","0.0277"
"12.6000","1.0420","2.9407","18.5712","0.0519","0.0275"
"12.6500","1.0465","2.9607","18.6975","0.0524","0.0278"
"12.7000","1.0505","2.9720","18.7689","0.0543","0.0288"
"12.7500","1.0549","2.9906","18.8865","0.0526","0.0279"
"12.8000","1.0589","3.0013","18.9541","0.0524","0.0278"
"12.8500","1.0632","3.0214","19.0812","0.0532","0.0282"
"12.9000","1.0671","3.0306","19.1390","0.0530","0.0281"
"12.9500","1.0713","3.0511","19.2684","0.0544","0.0288"
"13.0000","1.0754","3.0627","19.3417","0.0550","0.0292"
"13.0500","1.0798","3.0825","19.4668","0.0538","0.0285"
"13.1000","1.0838","3.0929","19.5327","0.0559","0.0297"
"13.1500","1.0881","3.1129","19.6588","0.0544","0.0289"
"13.2000","1.0922","3.1237","19.7271","0.0541","0.0287"
"13.2500","1.0964","3.1442","19.8567","0.0540","0.0286"
"13.3000","1.1007","3.1557","19.9290","0.0557","0.0296"
"13.3500","1.1049","3.1739","20.0439","0.0556","0.0295"
"13.4000","1.1089","3.1850","20.1142","0.0547","0.0290"
"13.4500","1.1130","3.2039","20.2336","0.0546","0.0290"
"13.5000","1.1171","3.2156","20.3076","0.0548","0.0290"
"13.5500","1.1211","3.2343","20.4254","0.0545","0.0289"
"13.6000","1.1255","3.2493","20.5200","0.0553","0.0293"
"13.6500","1.1296","3.2665","20.6290","0.0554","0.0294"
"13.7000","1.1339","3.2792","20.7092","0.0554","0.0294"
"13.7500","1.1379","3.2964","20.8179","0.0561","0.0297"
"13.8000","1.1423","3.3124","20.9186","0.0576","0.0305"
"13.8500","1.1464","3.3298","21.0285","0.0574","0.0304"
"13.9000","1.1509","3.3446","21.1221","0.0560","0.0297"
"13.9500","1.1548","3.3586","21.2106","0.0563","0.0298"
"14.0000","1.1590","3.3742","21.3089","0.0569","0.0302"
"14.0500","1.1629","3.3898","21.4076","0.0568","0.0301"
"14.1000","1.1672","3.4062","21.5112","0.0562","0.0298"
"14.1500","1.1712","3.4222","21.6122","0.0573","0.0304"
"14.2000","1.1758","3.4396","21.7223","0.0591","0.0313"
"14.2500","1.1796","3.4518","21.7993","0.0582","0.0309"
"14.3000","1.1839","3.4698","21.9127","0.0575","0.0305"
"14.3500","1.1878","3.4832","21.9975","0.0578","0.0306"
"14.4000","1.1923","3.5039","22.1279","0.0579","0.0307"
"14.4500","1.1965","3.5179","22.2168","0.0596","0.0316"
"14.5000","1.2009","3.5349","22.3237","0.0589","0.0312"
"14.5500","1.2046","3.5456","22.3915","0.0586","0.0311"
"14.6000","1.2089","3.5657","22.5182","0.0592","0.0314"
"14.6500","1.2127","3.5769","22.5892","0.0597","0.0316"
"14.7000","1.2171","3.6002","22.7362","0.0602","0.0319"
"14.7500","1.2212","3.6135","22.8203","0.0596","0.0316"
"14.8000","1.2256","3.6338","22.9486","0.0595","0.0316"
"14.8500","1.2295","3.6445","23.0161","0.0594","0.0315"
"14.9000","1.2339","3.6665","23.1551","0.0606","0.0321"
"14.9500","1.2379","3.6774","23.2236","0.0604","0.0320"
"15.0000","1.2424","3.7006","23.3702","0.0601","0.0319"
"15.0500","1.2465","3.7107","23.4341","0.0605","0.0321"
"15.1000","1.2507","3.7307","23.5607","0.0618","0.0328"
"15.1500","1.2546","3.7416","23.6291","0.0615","0.0326"
"15.2000","1.2588","3.7636","23.7682","0.0604","0.0320"
"15.2500","1.2629","3.7749","23.8395","0.0612","0.0325"
"15.3000","1.2672","3.7972","23.9802","0.0614","0.0325"
"15.3500","1.2714","3.8087","24.0528","0.0623","0.0331"
"15.4000","1.2755","3.8277","24.1728","0.0621","0.0329"
"15.4500","1.2796","3.8404","24.2531","0.0626","0.0332"
"15.5000","1.2837","3.8610","24.3834","0.0623","0.0330"
"15.5500","1.2881","3.8760","24.4779","0.0628","0.0333"
"15.6000","1.2924","3.8957","24.6025","0.0628","0.0333"
"15.6500","1.2966","3.9068","24.6725","0.0626","0.0332"
"15.7000","1.3005","3.9253","24.7895","0.0627","0.0333"
"15.7500","1.3046","3.9395","24.8793","0.0632","0.0335"
"15.8000","1.3086","3.9582","24.9974","0.0640","0.0339"
"15.8500","1.3129","3.9734","25.0933","0.0642","0.0340"
"15.9000","1.3170","3.9923","25.2122","0.0630","0.0334"
"15.9500","1.3214","4.0084","25.3143","0.0637","0.0338"
"16.0000","1.3254","4.0243","25.4146","0.0626","0.0332"
"16.0500","1.3296","4.0407","25.5183","0.0637","0.0338"
"16.1000","1.3337","4.0588","25.6323","0.0653","0.0346"
"16.1500","1.3382","4.0775","25.7503","0.0663","0.0351"
"16.2000","1.3423","4.0921","25.8425","0.0672","0.0356"
"16.2500","1.3465","4.1075","25.9400","0.0670","0.0355"
"16.3000","1.3504","4.1231","26.0387","0.0662","0.0351"
"16.3500","1.3548","4.1431","26.1647","0.0666","0.0353"
"16.4000","1.3587","4.1561","26.2471","0.0674","0.0358"
"16.4500","1.3631","4.1775","26.3819","0.0668","0.0354"
"16.5000","1.3671","4.1897","26.4591","0.0683","0.0362"
"16.5500","1.3714","4.2098","26.5858","0.0682","0.0362"
"16.6000","1.3753","4.2229","26.6690","0.0678","0.0360"
"16.6500","1.3798","4.2452","26.8096","0.0686","0.0364"
"16.7000","1.3839","4.2576","26.8881","0.0685","0.0363"
"16.7500","1.3883","4.2792","27.0246","0.0678","0.0360"
"16.8000","1.3922","4.2891","27.0867","0.0683","0.0362"
"16.8500","1.3965","4.3133","27.2397","0.0688","0.0365"
"16.9000","1.4004","4.3216","27.2919","0.0684","0.0363"
"16.9500","1.4047","4.3461","27.4470","0.0685","0.0363"
"17.0000","1.4087","4.3566","27.5131","0.0691","0.0366"
"17.0500","1.4130","4.3799","27.6603","0.0685","0.0363"
"17.1000","1.4170","4.3913","27.7320","0.0691","0.0367"
"17.1500","1.4213","4.4139","27.8748","0.0685","0.0363"
"17.2000","1.4254","4.4246","27.9427","0.0698","0.0370"
"17.2500","1.4298","4.4489","28.0960","0.0712","0.0378"
"17.3000","1.4340","4.4608","28.1715","0.0696","0.0369"
"17.3500","1.4383","4.4822","28.3065","0.0697","0.0369"
"17.4000","1.4422","4.4925","28.3711","0.0700","0.0371"
"17.4500","1.4464","4.5149","28.5131","0.0704","0.0373"
"17.5000","1.4505","4.5271","28.5901","0.0714","0.0379"
"17.5500","1.4547","4.5493","28.7302","0.0702","0.0372"
"17.6000","1.4589","4.5634","28.8189","0.0710","0.0376"
"17.6500","1.4631","4.5840","28.9491","0.0718","0.0381"
"17.7000","1.4672","4.5967","29.0296","0.0707","0.0375"
"17.7500","1.4712","4.6167","29.1559","0.0711","0.0377"
"17.8000","1.4756","4.6338","29.2637","0.0712","0.0378"
"17.8500","1.4798","4.6529","29.3845","0.0708","0.0375"
"17.9000","1.4841","4.6687","29.4839","0.0722","0.0383"
"17.9500","1.4881","4.6850","29.5869","0.0713","0.0378"
"18.0000","1.4922","4.6998","29.6805","0.0717","0.0380"
"18.0500","1.4961","4.7183","29.7975","0.0721","0.0383"
"18.1000","1.5004","4.7368","29.9144","0.0733","0.0389"
"18.1500","1.5045","4.7533","30.0181","0.0739","0.0392"
"18.2000","1.5088","4.7722","30.1380","0.0727","0.0386"
"18.2500","1.5127","4.7856","30.2226","0.0725","0.0384"
"18.3000","1.5171","4.8074","30.3600","0.0738","0.0391"
"18.3500","1.5211","4.8220","30.4525","0.0751","0.0398"
"18.4000","1.5256","4.8439","30.5905","0.0744","0.0395"
"18.4500","1.5297","4.8585","30.6826","0.0733","0.0389"
"18.5000","1.5342","4.8788","30.8109","0.0743","0.0394"
"18.5500","1.5380","4.8898","30.8804","0.0756","0.0401"
"18.6000","1.5423","4.9125","31.0240","0.0735","0.0390"
"18.6500","1.5462","4.9243","31.0984","0.0746","0.0395"
"18.7000","1.5506","4.9482","31.2491","0.0758","0.0402"
"18.7500","1.5546","4.9625","31.3395","0.0771","0.0409"
"18.8000","1.5590","4.9857","31.4859","0.0756","0.0401"
"18.8500","1.5628","4.9964","31.5536","0.0752","0.0399"
"18.9000","1.5672","5.0212","31.7106","0.0761","0.0404"
"18.9500","1.5712","5.0324","31.7808","0.0765","0.0405"
"19.0000","1.5756","5.0577","31.9411","0.0775","0.0411"
"19.0500","1.5798","5.0705","32.0213","0.0769","0.0408"
"19.1000","1.5841","5.0909","32.1506","0.0768","0.0407"
"19.1500","1.5878","5.1009","32.2133","0.0773","0.0410"
"19.2000","1.5921","5.1270","32.3787","0.0784","0.0416"
"19.2500","1.5961","5.1383","32.4497","0.0790","0.0419"
"19.3000","1.6005","5.1629","32.6054","0.0781","0.0414"
"19.3500","1.6045","5.1739","32.6745","0.0774","0.0411"
"19.4000","1.6087","5.1966","32.8181","0.0781","0.0414"
"19.4500","1.6128","5.2099","32.9021","0.0786","0.0417"
"19.5000","1.6171","5.2339","33.0537","0.0778","0.0412"
"19.5500","1.6212","5.2465","33.1332","0.0792","0.0420"
"19.6000","1.6256","5.2708","33.2863","0.0797","0.0423"
"19.6500","1.6299","5.2849","33.3758","0.0794","0.0421"
"19.7000","1.6340","5.3030","33.4902","0.0796","0.0422"
"19.7500","1.6380","5.3172","33.5797","0.0792","0.0420"
"19.8000","1.6421","5.3392","33.7186","0.0798","0.0423"
"19.8500","1.6464","5.3553","33.8203","0.0804","0.0427"
"19.9000","1.6506","5.3759","33.9506","0.0807","0.0428"
"19.9500","1.6548","5.3913","34.0475","0.0806","0.0427"
"20.0000","1.6588","5.4094","34.1621","0.0806","0.0427"
"20.0500","1.6631","5.4288","34.2845","0.0809","0.0429"
"20.1000","1.6671","5.4442","34.3814","0.0819","0.0434"
"20.1500","1.6714","5.4652","34.5144","0.0820","0.0435"
"20.2000","1.6755","5.4831","34.6271","0.0809","0.0429"
"20.2500","1.6799","5.5021","34.7473","0.0817","0.0433"
"20.3000","1.6838","5.5156","34.8326","0.0822","0.0436"
"20.3500","1.6881","5.5373","34.9694","0.0826","0.0438"
"20.4000","1.6920","5.5513","35.0582","0.0822","0.0436"
"20.4500","1.6964","5.5747","35.2060","0.0817","0.0433"
"20.5000","1.7004","5.5873","35.2857","0.0834","0.0442"
"20.5500","1.7047","5.6097","35.4268","0.0829","0.0440"
"20.6000","1.7086","5.6227","35.5091","0.0818","0.0434"
"20.6500","1.7131","5.6479","35.6682","0.0827","0.0438"
"20.7000","1.7170","5.6593","35.7402","0.0846","0.0448"
"20.7500","1.7216","5.6864","35.9110","0.0859","0.0456"
"20.8000","1.7256","5.6968","35.9771","0.0847","0.0449"
"20.8500","1.7299","5.7196","36.1208","0.0838","0.0444"
"20.9000","1.7338","5.7306","36.1902","0.0849","0.0450"
"20.9500","1.7382","5.7570","36.3572","0.0849","0.0450"
"21.0000","1.7421","5.7678","36.4252","0.0854","0.0453"
"21.0500","1.7466","5.7942","36.5923","0.0852","0.0452"
"21.1000","1.7505","5.8033","36.6494","0.0856","0.0454"
"21.1500","1.7547","5.8279","36.8046","0.0870","0.0461"
"21.2000","1.7587","5.8413","36.8896","0.0866","0.0459"
"21.2500","1.7630","5.8654","37.0416","0.0845","0.0448"
"21.3000","1.7671","5.8791","37.1279","0.0872","0.0462"
"21.3500","1.7716","5.9052","37.2927","0.0870","0.0461"
"21.4000","1.7756","5.9147","37.3529","0.0870","0.0461"
"21.4500","1.7798","5.9370","37.4940","0.0880","0.0467"
"21.5000","1.7837","5.9498","37.5749","0.0854","0.0453"
"21.5500","1.7879","5.9740","37.7274","0.0882","0.0468"
"21.6000","1.7922","5.9905","37.8314","0.0885","0.0470"
"21.6500","1.7964","6.0111","37.9619","0.0886","0.0470"
"21.7000","1.8004","6.0242","38.0448","0.0880","0.0467"
"21.7500","1.8044","6.0462","38.1835","0.0876","0.0465"
"21.8000","1.8087","6.0645","38.2988","0.0887","0.0470"
"21.8500","1.8128","6.0842","38.4232","0.0897","0.0476"
"21.9000","1.8173","6.1048","38.5533","0.0893","0.0473"
"21.9500","1.8215","6.1234","38.6709","0.0889","0.0472"
"22.0000","1.8257","6.1387","38.7676","0.0899","0.0477"
"22.0500","1.8296","6.1556","38.8744","0.0907","0.0481"
"22.1000","1.8340","6.1773","39.0115","0.0902","0.0478"
"22.1500","1.8379","6.1930","39.1108","0.0898","0.0476"
"22.2000","1.8424","6.2170","39.2618","0.0906","0.0480"
"22.2500","1.8463","6.2288","39.3368","0.0913","0.0484"
"22.3000","1.8506","6.2504","39.4728","0.0920","0.0488"
"22.3500","1.8544","6.2653","39.5670","0.0901","0.0478"
"22.4000","1.8589","6.2911","39.7301","0.0897","0.0476"
"22.4500","1.8629","6.3042","39.8130","0.0906","0.0480"
"22.5000","1.8675","6.3308","39.9809","0.0914","0.0484"
"22.5500","1.8715","6.3421","40.0519","0.0911","0.0483"
"22.6000","1.8757","6.3630","40.1839","0.0912","0.0483"
"22.6500","1.8794","6.3747","40.2582","0.0914","0.0484"
"22.7000","1.8839","6.4062","40.4568","0.0922","0.0489"
"22.7500","1.8879","6.4195","40.5409","0.0931","0.0493"
"22.8000","1.8923","6.4446","40.6995","0.0925","0.0490"
"22.8500","1.8960","6.4540","40.7591","0.0919","0.0488"
"22.9000","1.9004","6.4829","40.9415","0.0933","0.0495"
"22.9500","1.9044","6.4943","41.0131","0.0928","0.0492"
"23.0000","1.9089","6.5230","41.1946","0.0934","0.0495"
"23.0500","1.9131","6.5352","41.2719","0.0941","0.0499"
"23.1000","1.9175","6.5598","41.4267","0.0933","0.0495"
"23.1500","1.9214","6.5704","41.4937","0.0948","0.0503"
"23.2000","1.9257","6.5954","41.6519","0.0948","0.0503"
"23.2500","1.9296","6.6077","41.7292","0.0946","0.0501"
"23.3000","1.9340","6.6361","41.9088","0.0945","0.0501"
"23.3500","1.9381","6.6476","41.9813","0.0950","0.0504"
"23.4000","1.9423","6.6705","42.1264","0.0956","0.0507"
"23.4500","1.9462","6.6833","42.2067","0.0951","0.0504"
"23.5000","1.9505","6.7101","42.3759","0.0950","0.0503"
"23.5500","1.9547","6.7256","42.4740","0.0972","0.0515"
"23.6000","1.9590","6.7485","42.6184","0.0972","0.0515"
"23.6500","1.9631","6.7628","42.7093","0.0967","0.0513"
"23.7000","1.9673","6.7863","42.8577","0.0968","0.0513"
"23.7500","1.9715","6.8031","42.9638","0.0970","0.0514"
"23.8000","1.9756","6.8228","43.0879","0.0982","0.0521"
"23.8500","1.9796","6.8384","43.1866","0.0973","0.0516"
"23.9000","1.9838","6.8608","43.3277","0.0965","0.0511"
"23.9500","1.9881","6.8798","43.4476","0.0969","0.0514"
"24.0000","1.9920","6.8959","43.5496","0.0981","0.0520"
"24.0500","1.9962","6.9166","43.6802","0.0985","0.0522"
"24.1000","2.0003","6.9378","43.8141","0.0982","0.0521"
"24.1500","2.0048","6.9608","43.9593","0.0976","0.0517"
"24.2000","2.0089","6.9771","44.0624","0.0990","0.0525"
"24.2500","2.0132","6.9958","44.1804","0.1005","0.0533"
"24.3000","2.0172","7.0129","44.2887","0.0985","0.0522"
"24.3500","2.0216","7.0353","44.4297","0.0987","0.0523"
"24.4000","2.0254","7.0500","44.5226","0.0993","0.0527"
"24.4500","2.0299","7.0744","44.6766","0.0994","0.0527"
"24.5000","2.0338","7.0901","44.7759","0.1003","0.0532"
"24.5500","2.0382","7.1123","44.9164","0.1005","0.0533"
"24.6000","2.0419","7.1241","44.9907","0.1006","0.0534"
"24.6500","2.0463","7.1526","45.1706","0.1013","0.0537"
"24.7000","2.0503","7.1664","45.2575","0.1019","0.0540"
"24.7500","2.0548","7.1935","45.4288","0.1016","0.0539"
"24.8000","2.0589","7.2067","45.5123","0.1015","0.0538"
"24.8500","2.0633","7.2312","45.6673","0.1013","0.0537"
"24.9000","2.0671","7.2415","45.7320","0.1039","0.0551"
"24.9500","2.0714","7.2682","45.9007","0.1024","0.0543"
"25.0000","2.0754","7.2822","45.9889","0.1022","0.0542"
"25.0500","2.0798","7.3070","46.1460","0.1033","0.0548"
"25.1000","2.0836","7.3178","46.2140","0.1037","0.0550"
"25.1500","2.0879","7.3448","46.3845","0.1027","0.0545"
"25.2000","2.0919","7.3573","46.4632","0.1029","0.0546"
"25.2500","2.0963","7.3850","46.6386","0.1036","0.0549"
"25.3000","2.1004","7.3988","46.7254","0.1045","0.0554"
"25.3500","2.1047","7.4237","46.8828","0.1048","0.0556"
"25.4000","2.1089","7.4381","46.9739","0.1049","0.0556"
"25.4500","2.1131","7.4620","47.1248","0.1051","0.0557"
"25.5000","2.1171","7.4748","47.2053","0.1054","0.0559"
"25.5500","2.1214","7.5003","47.3666","0.1062","0.0563"
"25.6000","2.1256","7.5170","47.4717","0.1058","0.0561"
"25.6500","2.1299","7.5407","47.6218","0.1054","0.0559"
"25.7000","2.1338","7.5519","47.6925","0.1046","0.0555"
"25.7500","2.1378","7.5746","47.8360","0.1057","0.0561"
"25.8000","2.1421","7.5946","47.9622","0.1062","0.0563"
"25.8500","2.1463","7.6166","48.1012","0.1055","0.0559"
"25.9000","2.1505","7.6351","48.2181","0.1072","0.0569"
"25.9500","2.1547","7.6567","48.3541","0.1068","0.0566"
"26.0000","2.1589","7.6727","48.4555","0.1072","0.0569"
"26.0500","2.1630","7.6945","48.5926","0.1076","0.0571"
"26.1000","2.1672","7.7128","48.7082","0.1082","0.0574"
"26.1500","2.1712","7.7337","48.8405","0.1071","0.0568"
"26.2000","2.1756","7.7556","48.9790","0.1088","0.0577"
"26.2500","2.1797","7.7732","49.0897","0.1100","0.0583"
"26.3000","2.1837","7.7898","49.1947","0.1086","0.0576"
"26.3500","2.1876","7.8091","49.3166","0.1089","0.0577"
"26.4000","2.1921","7.8356","49.4839","0.1085","0.0575"
"26.4500","2.1962","7.8519","49.5868","0.1087","0.0576"
"26.5000","2.2007","7.8761","49.7396","0.1088","0.0577"
"26.5500","2.2047","7.8912","49.8349","0.1086","0.0576"
"26.6000","2.2090","7.9148","49.9842","0.1099","0.0583"
"26.6500","2.2130","7.9301","50.0810","0.1108","0.0588"
"26.7000","2.2173","7.9531","50.2262","0.1113","0.0590"
"26.7500","2.2213","7.9698","50.3318","0.1109","0.0588"
"26.8000","2.2258","7.9962","50.4980","0.1118","0.0593"
"26.8500","2.2295","8.0049","50.5531","0.1108","0.0587"
"26.9000","2.2338","8.0321","50.7248","0.1117","0.0592"
"26.9500","2.2378","8.0472","50.8200","0.1112","0.0589"
"27.0000","2.2423","8.0753","50.9976","0.1121","0.0594"
"27.0500","2.2464","8.0898","51.0893","0.1120","0.0594"
"27.1000","2.2508","8.1159","51.2539","0.1129","0.0598"
"27.1500","2.2547","8.1260","51.3182","0.1132","0.0600"
"27.2000","2.2591","8.1545","51.4980","0.1139","0.0604"
"27.2500","2.2630","8.1657","51.5688","0.1135","0.0602"
"27.3000","2.2673","8.1927","51.7391","0.1125","0.0596"
"27.3500","2.2713","8.2064","51.8254","0.1130","0.0599"
"27.4000","2.2756","8.2321","51.9882","0.1133","0.0601"
"27.4500","2.2794","8.2430","52.0572","0.1137","0.0603"
"27.5000","2.2837","8.2737","52.2507","0.1141","0.0605"
"27.5500","2.2878","8.2915","52.3632","0.1138","0.0603"
"27.6000","2.2921","8.3181","52.5311","0.1151","0.0610"
"27.6500","2.2964","8.3344","52.6343","0.1154","0.0612"
"27.7000","2.3006","8.3581","52.7836","0.1153","0.0611"
"27.7500","2.3047","8.3726","52.8751","0.1167","0.0619"
"27.8000","2.3090","8.3975","53.0326","0.1163","0.0617"
"27.8500","2.3131","8.4123","53.1258","0.1167","0.0619"
"27.9000","2.3173","8.4376","53.2860","0.1161","0.0616"
"27.9500","2.3215","8.4561","53.4027","0.1166","0.0618"
"28.0000","2.3256","8.4765","53.5314","0.1165","0.0618"
"28.0500","2.3297","8.4929","53.6348","0.1178","0.0625"
"28.1000","2.3337","8.5136","53.7658","0.1179","0.0625"
"28.1500","2.3380","8.5365","53.9106","0.1170","0.0620"
"28.2000","2.3421","8.5563","54.0353","0.1179","0.0625"
"28.2500","2.3465","8.5787","54.1766","0.1192","0.0632"
"28.3000","2.3505","8.5947","54.2778","0.1181","0.0626"
"28.3500","2.3548","8.6159","54.4118","0.1188","0.0630"
"28.4000","2.3588","8.6346","54.5298","0.1188","0.0630"
"28.4500","2.3631","8.6566","54.6691","0.1186","0.0629"
"28.5000","2.3671","8.6736","54.7762","0.1204","0.0638"
"28.5500","2.3715","8.6976","54.9279","0.1194","0.0633"
"28.6000","2.3753","8.7104","55.0087","0.1198","0.0635"
"28.6500","2.3796","8.7375","55.1797","0.1197","0.0635"
"28.7000","2.3835","8.7518","55.2704","0.1203","0.0638"
"28.7500","2.3880","8.7806","55.4517","0.1203","0.0638"
"28.8000","2.3921","8.7957","55.5475","0.1197","0.0635"
"28.8500","2.3965","8.8208","55.7057","0.1208","0.0640"
"28.9000","2.4004","8.8335","55.7862","0.1209","0.0641"
"28.9500","2.4048","8.8612","55.9608","0.1212","0.0643"
"29.0000","2.4087","8.8735","56.0386","0.1216","0.0645"
"29.0500","2.4132","8.9034","56.2274","0.1215","0.0644"
"29.1000","2.4173","8.9185","56.3227","0.1224","0.0649"
"29.1500","2.4216","8.9407","56.4630","0.1231","0.0653"
"29.2000","2.4253","8.9505","56.5250","0.1234","0.0654"
"29.2500","2.4296","8.9815","56.7206","0.1228","0.0651"
"29.3000","2.4337","8.9965","56.8155","0.1226","0.0650"
"29.3500","2.4381","9.0247","56.9937","0.1229","0.0652"
"29.4000","2.4422","9.0382","57.0788","0.1255","0.0665"
"29.4500","2.4465","9.0624","57.2317","0.1228","0.0651"
"29.5000","2.4505","9.0771","57.3243","0.1239","0.0657"
"29.5500","2.4548","9.1036","57.4918","0.1228","0.0651"
"29.6000","2.4588","9.1181","57.5835","0.1249","0.0662"
"29.6500","2.4632","9.1459","57.7590","0.1236","0.0656"
"29.7000","2.4673","9.1602","57.8495","0.1243","0.0659"
"29.7500","2.4713","9.1813","57.9824","0.1234","0.0654"
"29.8000","2.4752","9.1962","58.0764","0.1256","0.0666"
"29.8500","2.4794","9.2224","58.2422","0.1250","0.0663"
"29.9000","2.4838","9.2458","58.3898","0.1248","0.0662"
"29.9500","2.4881","9.2681","58.5309","0.1261","0.0669"
"30.0000","2.4922","9.2840","58.6310","0.1268","0.0672"
"30.0500","2.4963","9.3060","58.7702","0.1251","0.0663"
"30.1000","2.5006","9.3270","58.9026","0.1260","0.0668"
"30.1500","2.5047","9.3462","59.0238","0.1204","0.0639"
"30.2000","2.5091","9.3689","59.1671","0.1271","0.0674"
"30.2500","2.5132","9.3892","59.2957","0.1274","0.0676"
"30.3000","2.5173","9.4064","59.4038","0.1280","0.0679"
"30.3500","2.5212","9.4234","59.5113","0.1278","0.0678"
"30.4000","2.5254","9.4488","59.6715","0.1272","0.0675"
"30.4500","2.5295","9.4673","59.7884","0.1276","0.0677"
"30.5000","2.5340","9.4958","59.9684","0.1282","0.0680"
"30.5500","2.5381","9.5113","60.0663","0.1286","0.0682"
"30.6000","2.5424","9.5326","60.2008","0.1277","0.0677"
"30.6500","2.5463","9.5485","60.3014","0.1286","0.0682"
"30.7000","2.5507","9.5748","60.4673","0.1286","0.0682"
"30.7500","2.5545","9.5880","60.5509","0.1290","0.0684"
"30.8000","2.5591","9.6183","60.7422","0.1300","0.0689"
"30.8500","2.5630","9.6303","60.8182","0.1293","0.0685"
"30.9000","2.5672","9.6564","60.9827","0.1293","0.0686"
"30.9500","2.5711","9.6684","61.0588","0.1297","0.0687"
"31.0000","2.5755","9.6986","61.2496","0.1301","0.0690"
"31.0500","2.5795","9.7144","61.3494","0.1296","0.0687"
"31.1000","2.5840","9.7435","61.5329","0.1299","0.0689"
"31.1500","2.5879","9.7537","61.5971","0.1315","0.0697"
"31.2000","2.5923","9.7826","61.7800","0.1312","0.0696"
"31.2500","2.5963","9.7961","61.8650","0.1318","0.0699"
"31.3000","2.6007","9.8261","62.0545","0.1320","0.0700"
"31.3500","2.6048","9.8388","62.1350","0.1336","0.0708"
"31.4000","2.6091","9.8665","62.3096","0.1329","0.0705"
"31.4500","2.6130","9.8767","62.3739","0.1330","0.0705"
"31.5000","2.6172","9.9039","62.5457","0.1322","0.0701"
"31.5500","2.6211","9.9183","62.6370","0.1331","0.0706"
"31.6000","2.6255","9.9473","62.8203","0.1344","0.0713"
"31.6500","2.6297","9.9660","62.9379","0.1335","0.0708"
"31.7000","2.6340","9.9899","63.0888","0.1343","0.0712"
"31.7500","2.6380","10.0030","63.1714","0.1335","0.0708"
"31.8000","2.6422","10.0284","63.3321","0.1349","0.0715"
"31.8500","2.6463","10.0480","63.4559","0.1343","0.0712"
"31.9000","2.6505","10.0712","63.6023","0.1345","0.0713"
"31.9500","2.6548","10.0911","63.7278","0.1335","0.0708"
"32.0000","2.6589","10.1112","63.8549","0.1356","0.0719"
"32.0500","2.6629","10.1280","63.9615","0.1356","0.0719"
"32.1000","2.6669","10.1496","64.0973","0.1353","0.0717"
"32.1500","2.6712","10.1734","64.2478","0.1358","0.0720"
"32.2000","2.6753","10.1944","64.3805","0.1365","0.0724"
"32.2500","2.6797","10.2187","64.5339","0.1356","0.0719"
"32.3000","2.6838","10.2362","64.6447","0.1367","0.0725"
"32.3500","2.6880","10.2590","64.7884","0.1361","0.0722"
"32.4000","2.6921","10.2783","64.9106","0.1362","0.0722"
"32.4500","2.6964","10.3028","65.0651","0.1354","0.0718"
"32.5000","2.7005","10.3212","65.1811","0.1374","0.0729"
"32.5500","2.7049","10.3462","65.3393","0.1364","0.0723"
"32.6000","2.7087","10.3599","65.4254","0.1369","0.0726"
"32.6500","2.7130","10.3857","65.5884","0.1367","0.0725"
"32.7000","2.7169","10.4001","65.6797","0.1377","0.0730"
"32.7500","2.7214","10.4299","65.8676","0.1382","0.0733"
"32.8000","2.7255","10.4477","65.9803","0.1392","0.0738"
"32.8500","2.7299","10.4734","66.1423","0.1392","0.0738"
"32.9000","2.7337","10.4847","66.2141","0.1384","0.0734"
"32.9500","2.7381","10.5140","66.3991","0.1391","0.0738"
"33.0000","2.7420","10.5291","66.4944","0.1402","0.0744"
"33.0500","2.7465","10.5587","66.6812","0.1398","0.0741"
"33.1000","2.7505","10.5714","66.7615","0.1400","0.0743"
"33.1500","2.7547","10.5971","66.9235","0.1404","0.0744"
"33.2000","2.7586","10.6094","67.0013","0.1411","0.0748"
"33.2500","2.7630","10.6415","67.2041","0.1418","0.0752"
"33.3000","2.7668","10.6518","67.2690","0.1404","0.0745"
"33.3500","2.7713","10.6836","67.4700","0.1410","0.0748"
"33.4000","2.7754","10.7007","67.5779","0.1419","0.0752"
"33.4500","2.7797","10.7252","67.7325","0.1427","0.0757"
"33.5000","2.7837","10.7404","67.8289","0.1421","0.0754"
"33.5500","2.7882","10.7708","68.0205","0.1418","0.0752"
"33.6000","2.7923","10.7850","68.1104","0.1422","0.0754"
"33.6500","2.7966","10.8109","68.2738","0.1426","0.0756"
"33.7000","2.8005","10.8234","68.3529","0.1423","0.0755"
"33.7500","2.8048","10.8518","68.5322","0.1427","0.0756"
"33.8000","2.8089","10.8672","68.6291","0.1422","0.0754"
"33.8500","2.8130","10.8908","68.7787","0.1429","0.0758"
"33.9000","2.8171","10.9084","68.8897","0.1453","0.0770"
"33.9500","2.8213","10.9352","69.0587","0.1436","0.0761"
"34.0000","2.8256","10.9560","69.1902","0.1438","0.0763"
"34.0500","2.8297","10.9782","69.3305","0.1446","0.0767"
"34.1000","2.8339","10.9965","69.4462","0.1451","0.0769"
"34.1500","2.8381","11.0215","69.6036","0.1459","0.0774"
"34.2000","2.8423","11.0411","69.7275","0.1454","0.0771"
"34.2500","2.8464","11.0611","69.8542","0.1451","0.0769"
"34.3000","2.8506","11.0825","69.9894","0.1456","0.0772"
"34.3500","2.8546","11.1022","70.1132","0.1468","0.0779"
"34.4000","2.8588","11.1231","70.2456","0.1471","0.0780"
"34.4500","2.8627","11.1411","70.3593","0.1456","0.0772"
"34.5000","2.8671","11.1691","70.5359","0.1466","0.0777"
"34.5500","2.8712","11.1867","70.6470","0.1457","0.0773"
"34.6000","2.8756","11.2135","70.8161","0.1460","0.0774"
"34.6500","2.8795","11.2278","70.9066","0.1458","0.0773"
"34.7000","2.8840","11.2568","71.0897","0.1466","0.0777"
"34.7500","2.8881","11.2746","71.2024","0.1482","0.0786"
"34.8000","2.8925","11.2992","71.3576","0.1476","0.0783"
"34.8500","2.8963","11.3117","71.4364","0.1489","0.0790"
"34.9000","2.9008","11.3417","71.6262","0.1481","0.0785"
"34.9500","2.9047","11.3546","71.7076","0.1475","0.0782"
"35.0000","2.9090","11.3806","71.8714","0.1494","0.0792"
"35.0500","2.9128","11.3943","71.9581","0.1485","0.0788"
"35.1000","2.9172","11.4254","72.1544","0.1494","0.0792"
"35.1500","2.9212","11.4409","72.2523","0.1503","0.0797"
"35.2000","2.9257","11.4696","72.4335","0.1511","0.0801"
"35.2500","2.9296","11.4842","72.5257","0.1500","0.0795"
"35.3000","2.9341","11.5130","72.7081","0.1521","0.0807"
"35.3500","2.9381","11.5269","72.7956","0.1510","0.0801"
"35.4000","2.9424","11.5532","72.9618","0.1511","0.0801"
"35.4500","2.9463","11.5665","73.0457","0.1526","0.0809"
"35.5000","2.9506","11.5939","73.2184","0.1514","0.0803"
"35.5500","2.9544","11.6072","73.3026","0.1525","0.0809"
"35.6000","2.9587","11.6346","73.4761","0.1513","0.0802"
"35.6500","2.9628","11.6530","73.5918","0.1524","0.0808"
"35.7000","2.9672","11.6814","73.7715","0.1537","0.0815"
"35.7500","2.9713","11.6972","73.8711","0.1524","0.0808"
"35.8000","2.9755","11.7225","74.0308","0.1532","0.0812"
"35.8500","2.9796","11.7387","74.1334","0.1520","0.0806"
"35.9000","2.9840","11.7664","74.3083","0.1517","0.0804"
"35.9500","2.9882","11.7832","74.4139","0.1543","0.0818"
"36.0000","2.9923","11.8045","74.5490","0.1538","0.0816"
"36.0500","2.9964","11.8228","74.6645","0.1545","0.0819"
"36.1000","3.0005","11.8462","74.8120","0.1548","0.0821"
"36.1500","3.0046","11.8643","74.9262","0.1556","0.0825"
"36.2000","3.0086","11.8856","75.0610","0.1549","0.0821"
"36.2500","3.0130","11.9118","75.2263","0.1553","0.0823"
"36.3000","3.0173","11.9345","75.3699","0.1553","0.0823"
"36.3500","3.0215","11.9544","75.4954","0.1558","0.0826"
"36.4000","3.0255","11.9717","75.6046","0.1565","0.0830"
"36.4500","3.0298","11.9969","75.7636","0.1568","0.0831"
"36.5000","3.0339","12.0160","75.8841","0.1565","0.0830"
"36.5500","3.0382","12.0387","76.0281","0.1555","0.0825"
"36.6000","3.0421","12.0541","76.1251","0.1562","0.0828"
"36.6500","3.0464","12.0793","76.2843","0.1557","0.0826"
"36.7000","3.0503","12.0949","76.3824","0.1564","0.0829"
"36.7500","3.0545","12.1196","76.5386","0.1573","0.0834"
"36.8000","3.0585","12.1362","76.6432","0.1562","0.0828"
"36.8500","3.0631","12.1698","76.8556","0.1583","0.0839"
"36.9000","3.0671","12.1834","76.9414","0.1585","0.0841"
"36.9500","3.0714","12.2077","77.0948","0.1577","0.0836"
"37.0000","3.0753","12.2211","77.1800","0.1571","0.0833"
"37.0500","3.0799","12.2529","77.3805","0.1578","0.0837"
"37.1000","3.0840","12.2679","77.4753","0.1587","0.0842"
"37.1500","3.0883","12.2910","77.6213","0.1580","0.0838"
"37.2000","3.0921","12.3019","77.6899","0.1581","0.0838"
"37.2500","3.0965","12.3330","77.8865","0.1586","0.0841"
"37.3000","3.1004","12.3445","77.9590","0.1598","0.0847"
"37.3500","3.1047","12.3731","78.1394","0.1594","0.0845"
"37.4000","3.1088","12.3904","78.2489","0.1584","0.0840"
"37.4500","3.1132","12.4175","78.4202","0.1593","0.0845"
"37.5000","3.1171","12.4300","78.4989","0.1593","0.0845"
"37.5500","3.1214","12.4575","78.6723","0.1601","0.0849"
"37.6000","3.1255","12.4723","78.7659","0.1604","0.0851"
"37.6500","3.1299","12.5011","78.9480","0.1606","0.0851"
"37.7000","3.1339","12.5150","79.0358","0.1613","0.0856"
"37.7500","3.1381","12.5386","79.1847","0.1614","0.0856"
"37.8000","3.1420","12.5508","79.2618","0.1607","0.0852"
"37.8500","3.1463","12.5777","79.4318","0.1614","0.0856"
"37.9000","3.1503","12.5930","79.5282","0.1607","0.0852"
"37.9500","3.1545","12.6185","79.6895","0.1611","0.0854"
"38.0000","3.1589","12.6411","79.8324","0.1626","0.0862"
"38.0500","3.1630","12.6619","79.9631","0.1611","0.0854"
"38.1000","3.1672","12.6783","80.0669","0.1630","0.0864"
"38.1500","3.1713","12.6997","80.2019","0.1613","0.0855"
"38.2000","3.1756","12.7238","80.3544","0.1638","0.0869"
"38.2500","3.1799","12.7458","80.4932","0.1629","0.0864"
"38.3000","3.1840","12.7615","80.5922","0.1632","0.0865"
"38.3500","3.1880","12.7786","80.7004","0.1640","0.0870"
"38.4000","3.1923","12.8023","80.8500","0.1651","0.0875"
"38.4500","3.1962","12.8186","80.9530","0.1649","0.0874"
"38.5000","3.2006","12.8437","81.1115","0.1648","0.0874"
"38.5500","3.2046","12.8602","81.2157","0.1651","0.0875"
"38.6000","3.2090","12.8872","81.3866","0.1649","0.0875"
"38.6500","3.2129","12.8989","81.4604","0.1650","0.0875"
"38.7000","3.2172","12.9236","81.6164","0.1663","0.0882"
"38.7500","3.2212","12.9381","81.7080","0.1662","0.0881"
"38.8000","3.2257","12.9674","81.8928","0.1656","0.0878"
"38.8500","3.2297","12.9799","81.9718","0.1662","0.0881"
"38.9000","3.2340","13.0036","82.1214","0.1678","0.0890"
"38.9500","3.2378","13.0145","82.1905","0.1675","0.0888"
"39.0000","3.2422","13.0412","82.3587","0.1667","0.0884"
"39.0500","3.2460","13.0511","82.4217","0.1672","0.0886"
"39.1000","3.2504","13.0812","82.6111","0.1674","0.0887"
"39.1500","3.2545","13.0977","82.7156","0.1680","0.0891"
"39.2000","3.2589","13.1238","82.8804","0.1677","0.0889"
"39.2500","3.2628","13.1341","82.9452","0.1672","0.0887"
"39.3000","3.2672","13.1612","83.1168","0.1692","0.0897"
"39.3500","3.2712","13.1733","83.1931","0.1685","0.0893"
"39.4000","3.2758","13.2031","83.3812","0.1702","0.0902"
"39.4500","3.2797","13.2119","83.4370","0.1691","0.0897"
"39.5000","3.2840","13.2338","83.5750","0.1694","0.0898"
"39.5500","3.2880","13.2456","83.6498","0.1704","0.0904"
"39.6000","3.2923","13.2683","83.7931","0.1713","0.0908"
"39.6500","3.2961","13.2771","83.8484","0.1715","0.0909"
"39.7000","3.3006","13.3036","84.0160","0.1727","0.0916"
"39.7500","3.3046","13.3134","84.0779","0.1726","0.0915"
"39.8000","3.3089","13.3333","84.2034","0.1736","0.0921"
"39.8500","3.3129","13.3422","84.2595","0.1723","0.0914"
"39.9000","3.3172","13.3586","84.3631","0.1731","0.0918"
"39.9500","3.3214","13.3668","84.4148","0.1722","0.0913"
"40.0000","3.3257","13.3768","84.4785","0.1757","0.0932"
"40.0500","3.3296","13.3618","84.3837","0.1763","0.0935"
"40.1000","3.3338","13.3273","84.1656","0.1767","0.0937"
"40.1500","3.3381","13.2001","83.3625","0.1791","0.0950"
"40.2000","3.3423","11.1244","70.2536","0.1904","0.1010"
"40.2240","3.3455","3.2006","20.2130","1.8674","0.9902"