File: composites_properties_derivations/composite_tube_tests/comp_tube_8.csv
Specimen label,"8"
Force at Maximum Load,"11.79",kN
Tensile stress at Maximum Load,"74.46",MPa
Epsilon ONE Displacement at Maximum Load,"0.09",mm
Force at Break (Standard),"4.61",kN
Tensile stress at Break (Standard),"29.14",MPa
Epsilon ONE Displacement at Break (Standard),"0.06",mm
Slope (Chord 0.05 % - 0.2 %),"-----",MPa
Modulus (Automatic Young's),"52839.44",MPa

Specimen label,"8"
Thickness,"",mm
Width,"",mm
Length,"53.55",mm
Rate 1,"5.00",mm/min
Outer diameter,"19.05",mm
Wall thickness,"3.18",mm

Time,Displacement,Force,Tensile stress,Tensile strain (Epsilon ONE Displacement),Epsilon ONE Displacement
(s),(mm),(kN),(MPa),(%),(mm)
"0.0000","0.0000","0.0730","0.4612","0.0002","0.0001"
"0.0600","0.0002","0.0746","0.4709","-0.0005","-0.0003"
"0.1200","0.0019","0.1125","0.7107","0.0002","0.0001"
"0.1800","0.0037","0.1608","1.0154","0.0006","0.0003"
"0.2400","0.0074","0.2421","1.5291","0.0022","0.0012"
"0.3000","0.0163","0.3460","2.1853","0.0034","0.0018"
"0.3600","0.0218","0.3890","2.4566","0.0039","0.0021"
"0.4200","0.0267","0.4120","2.6016","0.0045","0.0024"
"0.4800","0.0315","0.4271","2.6971","0.0039","0.0021"
"0.5400","0.0366","0.4412","2.7865","0.0037","0.0020"
"0.6000","0.0417","0.4530","2.8607","0.0048","0.0026"
"0.6600","0.0469","0.4642","2.9316","0.0056","0.0030"
"0.7200","0.0518","0.4748","2.9988","0.0057","0.0031"
"0.7800","0.0567","0.4851","3.0637","0.0071","0.0038"
"0.8400","0.0618","0.4968","3.1372","0.0060","0.0032"
"0.9000","0.0668","0.5076","3.2053","0.0073","0.0039"
"0.9600","0.0718","0.5185","3.2744","0.0080","0.0043"
"1.0200","0.0767","0.5294","3.3434","0.0084","0.0045"
"1.0800","0.0815","0.5405","3.4135","0.0068","0.0036"
"1.1400","0.0865","0.5519","3.4854","0.0068","0.0036"
"1.2000","0.0917","0.5638","3.5609","0.0072","0.0039"
"1.2600","0.0968","0.5751","3.6316","0.0084","0.0045"
"1.3200","0.1017","0.5867","3.7050","0.0078","0.0042"
"1.3800","0.1066","0.5990","3.7825","0.0080","0.0043"
"1.4400","0.1117","0.6104","3.8548","0.0089","0.0048"
"1.5000","0.1168","0.6236","3.9381","0.0085","0.0045"
"1.5600","0.1217","0.6346","4.0078","0.0098","0.0052"
"1.6200","0.1267","0.6475","4.0890","0.0096","0.0051"
"1.6800","0.1316","0.6599","4.1673","0.0097","0.0052"
"1.7400","0.1367","0.6721","4.2446","0.0090","0.0048"
"1.8000","0.1419","0.6866","4.3363","0.0099","0.0053"
"1.8600","0.1467","0.6980","4.4078","0.0101","0.0054"
"1.9200","0.1518","0.7122","4.4978","0.0097","0.0052"
"1.9800","0.1566","0.7251","4.5789","0.0098","0.0052"
"2.0400","0.1618","0.7285","4.6006","0.0102","0.0054"
"2.1000","0.1668","0.7477","4.7222","0.0118","0.0063"
"2.1600","0.1716","0.7584","4.7896","0.0115","0.0062"
"2.2200","0.1767","0.7730","4.8818","0.0130","0.0070"
"2.2800","0.1813","0.7845","4.9543","0.0120","0.0064"
"2.3400","0.1866","0.8002","5.0532","0.0126","0.0068"
"2.4000","0.1917","0.8140","5.1403","0.0127","0.0068"
"2.4600","0.1967","0.8263","5.2181","0.0130","0.0070"
"2.5200","0.2018","0.8421","5.3181","0.0144","0.0077"
"2.5800","0.2066","0.8549","5.3989","0.0135","0.0072"
"2.6400","0.2119","0.8714","5.5034","0.0134","0.0072"
"2.7000","0.2168","0.8857","5.5934","0.0142","0.0076"
"2.7600","0.2218","0.9001","5.6846","0.0145","0.0078"
"2.8200","0.2267","0.9096","5.7445","0.0162","0.0087"
"2.8800","0.2315","0.9239","5.8347","0.0161","0.0086"
"2.9400","0.2368","0.9421","5.9496","0.0157","0.0084"
"3.0000","0.2417","0.9558","6.0362","0.0168","0.0090"
"3.0600","0.2468","0.9707","6.1305","0.0167","0.0090"
"3.1200","0.2516","0.9876","6.2369","0.0168","0.0090"
"3.1800","0.2568","1.0018","6.3268","0.0167","0.0090"
"3.2400","0.2619","1.0144","6.4060","0.0174","0.0093"
"3.3000","0.2667","1.0305","6.5081","0.0176","0.0094"
"3.3600","0.2718","1.0486","6.6224","0.0174","0.0093"
"3.4200","0.2764","1.0659","6.7316","0.0177","0.0095"
"3.4800","0.2816","1.0835","6.8427","0.0176","0.0094"
"3.5400","0.2867","1.1040","6.9718","0.0179","0.0096"
"3.6000","0.2916","1.1151","7.0419","0.0196","0.0105"
"3.6600","0.2968","1.1317","7.1473","0.0191","0.0102"
"3.7200","0.3016","1.1486","7.2539","0.0195","0.0104"
"3.7800","0.3070","1.1671","7.3703","0.0190","0.0102"
"3.8400","0.3119","1.1855","7.4871","0.0197","0.0106"
"3.9000","0.3168","1.2008","7.5837","0.0208","0.0111"
"3.9600","0.3219","1.2197","7.7025","0.0198","0.0106"
"4.0200","0.3265","1.2331","7.7875","0.0195","0.0105"
"4.0800","0.3317","1.2537","7.9176","0.0199","0.0107"
"4.1400","0.3366","1.2717","8.0310","0.0204","0.0109"
"4.2000","0.3418","1.2886","8.1377","0.0207","0.0111"
"4.2600","0.3467","1.3080","8.2603","0.0201","0.0108"
"4.3200","0.3517","1.3243","8.3632","0.0218","0.0116"
"4.3800","0.3569","1.3445","8.4912","0.0220","0.0118"
"4.4400","0.3617","1.3612","8.5961","0.0224","0.0120"
"4.5000","0.3667","1.3794","8.7114","0.0215","0.0115"
"4.5600","0.3715","1.3992","8.8366","0.0224","0.0120"
"4.6200","0.3765","1.4162","8.9436","0.0223","0.0119"
"4.6800","0.3817","1.4390","9.0880","0.0219","0.0118"
"4.7400","0.3866","1.4551","9.1896","0.0225","0.0120"
"4.8000","0.3918","1.4751","9.3154","0.0221","0.0118"
"4.8600","0.3966","1.4953","9.4430","0.0226","0.0121"
"4.9200","0.4018","1.5128","9.5538","0.0223","0.0119"
"4.9800","0.4069","1.5342","9.6888","0.0223","0.0120"
"5.0400","0.4117","1.5493","9.7846","0.0234","0.0126"
"5.1000","0.4168","1.5709","9.9206","0.0227","0.0122"
"5.1600","0.4215","1.5882","10.0298","0.0224","0.0120"
"5.2200","0.4267","1.6078","10.1539","0.0239","0.0128"
"5.2800","0.4319","1.6296","10.2914","0.0234","0.0125"
"5.3400","0.4367","1.6439","10.3814","0.0246","0.0132"
"5.4000","0.4418","1.6665","10.5246","0.0247","0.0132"
"5.4600","0.4466","1.6834","10.6309","0.0256","0.0137"
"5.5200","0.4519","1.7040","10.7610","0.0252","0.0135"
"5.5800","0.4568","1.7233","10.8828","0.0254","0.0136"
"5.6400","0.4616","1.7386","10.9799","0.0255","0.0136"
"5.7000","0.4666","1.7610","11.1211","0.0254","0.0136"
"5.7600","0.4713","1.7765","11.2191","0.0253","0.0136"
"5.8200","0.4768","1.7999","11.3666","0.0256","0.0137"
"5.8800","0.4817","1.8169","11.4740","0.0249","0.0133"
"5.9400","0.4867","1.8335","11.5793","0.0259","0.0139"
"6.0000","0.4917","1.8562","11.7226","0.0268","0.0143"
"6.0600","0.4968","1.8721","11.8230","0.0265","0.0142"
"6.1200","0.5021","1.8933","11.9569","0.0282","0.0151"
"6.1800","0.5067","1.9086","12.0534","0.0283","0.0152"
"6.2400","0.5118","1.9284","12.1781","0.0286","0.0153"
"6.3000","0.5166","1.9477","12.3000","0.0290","0.0155"
"6.3600","0.5217","1.9647","12.4078","0.0295","0.0158"
"6.4200","0.5269","1.9872","12.5494","0.0298","0.0160"
"6.4800","0.5316","2.0008","12.6357","0.0303","0.0162"
"6.5400","0.5368","2.0225","12.7729","0.0299","0.0160"
"6.6000","0.5416","2.0412","12.8911","0.0304","0.0163"
"6.6600","0.5469","2.0594","13.0054","0.0304","0.0163"
"6.7200","0.5519","2.0801","13.1367","0.0309","0.0166"
"6.7800","0.5565","2.0929","13.2169","0.0308","0.0165"
"6.8400","0.5617","2.1171","13.3700","0.0310","0.0166"
"6.9000","0.5664","2.1323","13.4659","0.0310","0.0166"
"6.9600","0.5718","2.1530","13.5967","0.0318","0.0170"
"7.0200","0.5768","2.1726","13.7203","0.0316","0.0169"
"7.0800","0.5816","2.1865","13.8087","0.0319","0.0171"
"7.1400","0.5868","2.2109","13.9622","0.0338","0.0181"
"7.2000","0.5917","2.2253","14.0535","0.0330","0.0177"
"7.2600","0.5970","2.2459","14.1834","0.0335","0.0179"
"7.3200","0.6017","2.2632","14.2928","0.0343","0.0184"
"7.3800","0.6067","2.2792","14.3936","0.0335","0.0179"
"7.4400","0.6118","2.3025","14.5409","0.0346","0.0185"
"7.5000","0.6166","2.3153","14.6218","0.0353","0.0189"
"7.5600","0.6219","2.3384","14.7678","0.0364","0.0195"
"7.6200","0.6266","2.3528","14.8587","0.0367","0.0196"
"7.6800","0.6317","2.3722","14.9811","0.0379","0.0203"
"7.7400","0.6366","2.3928","15.1112","0.0374","0.0200"
"7.8000","0.6418","2.4077","15.2052","0.0378","0.0203"
"7.8600","0.6469","2.4299","15.3455","0.0379","0.0203"
"7.9200","0.6516","2.4429","15.4273","0.0394","0.0211"
"7.9800","0.6567","2.4632","15.5556","0.0402","0.0215"
"8.0400","0.6614","2.4805","15.6653","0.0403","0.0216"
"8.1000","0.6666","2.4990","15.7819","0.0409","0.0219"
"8.1600","0.6717","2.5199","15.9140","0.0413","0.0221"
"8.2200","0.6765","2.5331","15.9971","0.0420","0.0225"
"8.2800","0.6818","2.5562","16.1433","0.0421","0.0226"
"8.3400","0.6866","2.5719","16.2425","0.0430","0.0230"
"8.4000","0.6919","2.5916","16.3670","0.0433","0.0232"
"8.4600","0.6969","2.6107","16.4874","0.0436","0.0233"
"8.5200","0.7016","2.6248","16.5763","0.0440","0.0235"
"8.5800","0.7068","2.6481","16.7234","0.0443","0.0237"
"8.6400","0.7115","2.6625","16.8143","0.0439","0.0235"
"8.7000","0.7169","2.6838","16.9489","0.0452","0.0242"
"8.7600","0.7216","2.7026","17.0676","0.0465","0.0249"
"8.8200","0.7266","2.7177","17.1631","0.0467","0.0250"
"8.8800","0.7317","2.7419","17.3156","0.0467","0.0250"
"8.9400","0.7367","2.7567","17.4095","0.0476","0.0255"
"9.0000","0.7420","2.7775","17.5406","0.0469","0.0251"
"9.0600","0.7466","2.7950","17.6514","0.0489","0.0262"
"9.1200","0.7518","2.8134","17.7672","0.0493","0.0264"
"9.1800","0.7567","2.8337","17.8956","0.0498","0.0267"
"9.2400","0.7614","2.8477","17.9842","0.0498","0.0267"
"9.3000","0.7667","2.8722","18.1387","0.0507","0.0272"
"9.3600","0.7714","2.8878","18.2375","0.0496","0.0266"
"9.4200","0.7766","2.9070","18.3585","0.0501","0.0268"
"9.4800","0.7816","2.9292","18.4986","0.0513","0.0275"
"9.5400","0.7869","2.9453","18.6001","0.0511","0.0274"
"9.6000","0.7920","2.9666","18.7350","0.0536","0.0287"
"9.6600","0.7966","2.9811","18.8267","0.0529","0.0283"
"9.7200","0.8019","3.0034","18.9675","0.0544","0.0291"
"9.7800","0.8066","3.0208","19.0772","0.0531","0.0284"
"9.8400","0.8117","3.0385","19.1889","0.0551","0.0295"
"9.9000","0.8168","3.0611","19.3316","0.0546","0.0292"
"9.9600","0.8215","3.0740","19.4132","0.0550","0.0295"
"10.0200","0.8268","3.0979","19.5639","0.0550","0.0295"
"10.0800","0.8317","3.1151","19.6726","0.0569","0.0305"
"10.1400","0.8369","3.1326","19.7836","0.0560","0.0300"
"10.2000","0.8418","3.1537","19.9162","0.0572","0.0306"
"10.2600","0.8466","3.1665","19.9974","0.0582","0.0312"
"10.3200","0.8518","3.1909","20.1514","0.0582","0.0312"
"10.3800","0.8565","3.2045","20.2370","0.0581","0.0311"
"10.4400","0.8617","3.2246","20.3645","0.0589","0.0315"
"10.5000","0.8666","3.2449","20.4924","0.0581","0.0311"
"10.5600","0.8717","3.2592","20.5831","0.0583","0.0312"
"10.6200","0.8768","3.2834","20.7356","0.0593","0.0318"
"10.6800","0.8817","3.2964","20.8175","0.0577","0.0309"
"10.7400","0.8869","3.3186","20.9581","0.0590","0.0316"
"10.8000","0.8917","3.3352","21.0627","0.0592","0.0317"
"10.8600","0.8968","3.3525","21.1721","0.0599","0.0321"
"10.9200","0.9018","3.3749","21.3137","0.0604","0.0323"
"10.9800","0.9066","3.3871","21.3903","0.0597","0.0320"
"11.0400","0.9118","3.4117","21.5456","0.0611","0.0327"
"11.1000","0.9166","3.4261","21.6367","0.0607","0.0325"
"11.1600","0.9218","3.4463","21.7642","0.0605","0.0324"
"11.2200","0.9268","3.4660","21.8887","0.0606","0.0325"
"11.2800","0.9318","3.4806","21.9809","0.0620","0.0332"
"11.3400","0.9369","3.5028","22.1214","0.0619","0.0332"
"11.4000","0.9416","3.5164","22.2072","0.0619","0.0332"
"11.4600","0.9468","3.5386","22.3472","0.0623","0.0334"
"11.5200","0.9515","3.5553","22.4526","0.0624","0.0334"
"11.5800","0.9567","3.5735","22.5679","0.0641","0.0343"
"11.6400","0.9616","3.5952","22.7045","0.0631","0.0338"
"11.7000","0.9665","3.6093","22.7938","0.0624","0.0334"
"11.7600","0.9718","3.6330","22.9432","0.0629","0.0337"
"11.8200","0.9767","3.6495","23.0474","0.0646","0.0346"
"11.8800","0.9819","3.6680","23.1644","0.0637","0.0341"
"11.9400","0.9868","3.6882","23.2922","0.0629","0.0337"
"12.0000","0.9916","3.7024","23.3819","0.0635","0.0340"
"12.0600","0.9968","3.7263","23.5329","0.0638","0.0342"
"12.1200","1.0016","3.7401","23.6199","0.0645","0.0345"
"12.1800","1.0068","3.7606","23.7495","0.0650","0.0348"
"12.2400","1.0116","3.7783","23.8607","0.0645","0.0345"
"12.3000","1.0166","3.7947","23.9644","0.0646","0.0346"
"12.3600","1.0218","3.8193","24.1197","0.0648","0.0347"
"12.4200","1.0269","3.8339","24.2123","0.0647","0.0347"
"12.4800","1.0320","3.8535","24.3357","0.0655","0.0350"
"12.5400","1.0366","3.8697","24.4380","0.0652","0.0349"
"12.6000","1.0417","3.8882","24.5551","0.0660","0.0354"
"12.6600","1.0467","3.9107","24.6975","0.0663","0.0355"
"12.7200","1.0516","3.9244","24.7837","0.0650","0.0348"
"12.7800","1.0567","3.9484","24.9354","0.0661","0.0354"
"12.8400","1.0615","3.9634","25.0300","0.0663","0.0355"
"12.9000","1.0667","3.9850","25.1664","0.0664","0.0356"
"12.9600","1.0718","4.0058","25.2979","0.0666","0.0357"
"13.0200","1.0770","4.0219","25.3994","0.0664","0.0356"
"13.0800","1.0819","4.0431","25.5331","0.0676","0.0362"
"13.1400","1.0866","4.0569","25.6204","0.0674","0.0361"
"13.2000","1.0918","4.0816","25.7763","0.0676","0.0362"
"13.2600","1.0967","4.0989","25.8855","0.0681","0.0365"
"13.3200","1.1018","4.1166","25.9975","0.0677","0.0363"
"13.3800","1.1067","4.1384","26.1349","0.0678","0.0363"
"13.4400","1.1116","4.1538","26.2326","0.0684","0.0366"
"13.5000","1.1168","4.1777","26.3834","0.0681","0.0365"
"13.5600","1.1218","4.1953","26.4947","0.0697","0.0373"
"13.6200","1.1270","4.2136","26.6102","0.0690","0.0370"
"13.6800","1.1317","4.2331","26.7332","0.0701","0.0376"
"13.7400","1.1366","4.2498","26.8387","0.0688","0.0368"
"13.8000","1.1418","4.2760","27.0044","0.0697","0.0373"
"13.8600","1.1466","4.2886","27.0834","0.0701","0.0376"
"13.9200","1.1517","4.3124","27.2339","0.0699","0.0374"
"13.9800","1.1565","4.3310","27.3517","0.0684","0.0366"
"14.0400","1.1617","4.3501","27.4722","0.0701","0.0375"
"14.1000","1.1668","4.3741","27.6236","0.0703","0.0376"
"14.1600","1.1717","4.3877","27.7096","0.0707","0.0379"
"14.2200","1.1769","4.4122","27.8642","0.0706","0.0378"
"14.2800","1.1816","4.4276","27.9618","0.0707","0.0379"
"14.3400","1.1868","4.4504","28.1058","0.0713","0.0382"
"14.4000","1.1918","4.4712","28.2367","0.0716","0.0383"
"14.4600","1.1967","4.4861","28.3312","0.0718","0.0384"
"14.5200","1.2017","4.5106","28.4859","0.0722","0.0387"
"14.5800","1.2065","4.5293","28.6036","0.0735","0.0394"
"14.6400","1.2119","4.5545","28.7630","0.0734","0.0393"
"14.7000","1.2168","4.5722","28.8745","0.0736","0.0394"
"14.7600","1.2218","4.5899","28.9866","0.0736","0.0394"
"14.8200","1.2267","4.6125","29.1291","0.0736","0.0394"
"14.8800","1.2316","4.6283","29.2293","0.0738","0.0395"
"14.9400","1.2368","4.6540","29.3914","0.0738","0.0395"
"15.0000","1.2416","4.6686","29.4835","0.0739","0.0395"
"15.0600","1.2466","4.6905","29.6215","0.0747","0.0400"
"15.1200","1.2515","4.7112","29.7525","0.0747","0.0400"
"15.1800","1.2565","4.7293","29.8666","0.0762","0.0408"
"15.2400","1.2618","4.7554","30.0316","0.0750","0.0402"
"15.3000","1.2667","4.7701","30.1246","0.0758","0.0406"
"15.3600","1.2718","4.7921","30.2633","0.0771","0.0413"
"15.4200","1.2766","4.8121","30.3898","0.0767","0.0411"
"15.4800","1.2817","4.8311","30.5095","0.0770","0.0412"
"15.5400","1.2869","4.8564","30.6692","0.0772","0.0413"
"15.6000","1.2917","4.8697","30.7538","0.0767","0.0411"
"15.6600","1.2968","4.8955","30.9163","0.0778","0.0417"
"15.7200","1.3016","4.9125","31.0239","0.0777","0.0416"
"15.7800","1.3067","4.9336","31.1569","0.0777","0.0416"
"15.8400","1.3117","4.9580","31.3110","0.0785","0.0421"
"15.9000","1.3168","4.9739","31.4113","0.0783","0.0420"
"15.9600","1.3219","4.9978","31.5628","0.0797","0.0427"
"16.0200","1.3265","5.0134","31.6611","0.0784","0.0420"
"16.0800","1.3317","5.0368","31.8089","0.0793","0.0425"
"16.1400","1.3367","5.0592","31.9505","0.0790","0.0423"
"16.2000","1.3416","5.0742","32.0448","0.0804","0.0431"
"16.2600","1.3467","5.1020","32.2208","0.0799","0.0428"
"16.3200","1.3515","5.1164","32.3116","0.0808","0.0433"
"16.3800","1.3567","5.1428","32.4783","0.0804","0.0431"
"16.4400","1.3617","5.1626","32.6033","0.0807","0.0432"
"16.5000","1.3668","5.1799","32.7127","0.0806","0.0432"
"16.5600","1.3718","5.2052","32.8721","0.0818","0.0438"
"16.6200","1.3766","5.2206","32.9694","0.0815","0.0436"
"16.6800","1.3820","5.2495","33.1522","0.0809","0.0433"
"16.7400","1.3868","5.2641","33.2445","0.0805","0.0431"
"16.8000","1.3917","5.2837","33.3679","0.0809","0.0433"
"16.8600","1.3966","5.3079","33.5207","0.0828","0.0443"
"16.9200","1.4016","5.3261","33.6361","0.0813","0.0435"
"16.9800","1.4069","5.3537","33.8099","0.0823","0.0441"
"17.0400","1.4118","5.3690","33.9066","0.0827","0.0443"
"17.1000","1.4169","5.3932","34.0595","0.0828","0.0443"
"17.1600","1.4216","5.4110","34.1717","0.0829","0.0444"
"17.2200","1.4267","5.4319","34.3040","0.0839","0.0449"
"17.2800","1.4318","5.4582","34.4703","0.0829","0.0444"
"17.3400","1.4365","5.4707","34.5488","0.0831","0.0445"
"17.4000","1.4417","5.4989","34.7268","0.0840","0.0450"
"17.4600","1.4464","5.5158","34.8341","0.0831","0.0445"
"17.5200","1.4518","5.5412","34.9944","0.0837","0.0448"
"17.5800","1.4569","5.5641","35.1389","0.0850","0.0455"
"17.6400","1.4617","5.5779","35.2259","0.0854","0.0457"
"17.7000","1.4670","5.6081","35.4169","0.0858","0.0459"
"17.7600","1.4717","5.6224","35.5069","0.0859","0.0460"
"17.8200","1.4768","5.6462","35.6576","0.0867","0.0464"
"17.8800","1.4817","5.6690","35.8013","0.0874","0.0468"
"17.9400","1.4866","5.6856","35.9060","0.0864","0.0463"
"18.0000","1.4917","5.7131","36.0801","0.0858","0.0459"
"18.0600","1.4965","5.7294","36.1828","0.0867","0.0464"
"18.1200","1.5018","5.7577","36.3618","0.0865","0.0463"
"18.1800","1.5067","5.7750","36.4705","0.0869","0.0465"
"18.2400","1.5119","5.7981","36.6168","0.0879","0.0470"
"18.3000","1.5169","5.8212","36.7625","0.0886","0.0474"
"18.3600","1.5216","5.8362","36.8572","0.0879","0.0470"
"18.4200","1.5268","5.8664","37.0480","0.0886","0.0474"
"18.4800","1.5315","5.8798","37.1328","0.0887","0.0475"
"18.5400","1.5366","5.9050","37.2920","0.0881","0.0472"
"18.6000","1.5415","5.9272","37.4316","0.0894","0.0479"
"18.6600","1.5466","5.9487","37.5680","0.0889","0.0476"
"18.7200","1.5518","5.9760","37.7402","0.0901","0.0483"
"18.7800","1.5567","5.9901","37.8294","0.0908","0.0486"
"18.8400","1.5619","6.0175","38.0021","0.0907","0.0486"
"18.9000","1.5667","6.0360","38.1192","0.0906","0.0485"
"18.9600","1.5718","6.0574","38.2539","0.0911","0.0488"
"19.0200","1.5769","6.0851","38.4289","0.0913","0.0489"
"19.0800","1.5816","6.0972","38.5057","0.0921","0.0493"
"19.1400","1.5867","6.1257","38.6856","0.0920","0.0492"
"19.2000","1.5914","6.1432","38.7962","0.0920","0.0493"
"19.2600","1.5967","6.1698","38.9638","0.0927","0.0496"
"19.3200","1.6018","6.1935","39.1139","0.0928","0.0497"
"19.3800","1.6067","6.2104","39.2206","0.0934","0.0500"
"19.4400","1.6119","6.2381","39.3956","0.0932","0.0499"
"19.5000","1.6165","6.2512","39.4784","0.0931","0.0499"
"19.5600","1.6218","6.2825","39.6760","0.0949","0.0508"
"19.6200","1.6268","6.3027","39.8034","0.0941","0.0504"
"19.6800","1.6315","6.3180","39.9001","0.0945","0.0506"
"19.7400","1.6366","6.3492","40.0970","0.0951","0.0509"
"19.8000","1.6414","6.3653","40.1984","0.0955","0.0512"
"19.8600","1.6469","6.3961","40.3929","0.0966","0.0517"
"19.9200","1.6518","6.4132","40.5014","0.0966","0.0517"
"19.9800","1.6568","6.4350","40.6388","0.0965","0.0517"
"20.0400","1.6618","6.4596","40.7940","0.0971","0.0520"
"20.1000","1.6667","6.4774","40.9064","0.0969","0.0519"
"20.1600","1.6720","6.5073","41.0957","0.0982","0.0526"
"20.2200","1.6767","6.5209","41.1812","0.0982","0.0526"
"20.2800","1.6817","6.5462","41.3410","0.0984","0.0527"
"20.3400","1.6866","6.5698","41.4899","0.0982","0.0526"
"20.4000","1.6918","6.5919","41.6299","0.0989","0.0529"
"20.4600","1.6969","6.6176","41.7920","0.0986","0.0528"
"20.5200","1.7016","6.6327","41.8875","0.0984","0.0527"
"20.5800","1.7069","6.6622","42.0734","0.0985","0.0528"
"20.6400","1.7117","6.6797","42.1844","0.1006","0.0539"
"20.7000","1.7168","6.7036","42.3353","0.0998","0.0534"
"20.7600","1.7218","6.7278","42.4878","0.1002","0.0536"
"20.8200","1.7265","6.7420","42.5776","0.1007","0.0539"
"20.8800","1.7316","6.7732","42.7749","0.1008","0.0540"
"20.9400","1.7364","6.7904","42.8835","0.1022","0.0547"
"21.0000","1.7419","6.8199","43.0695","0.1024","0.0548"
"21.0600","1.7468","6.8402","43.1979","0.1021","0.0547"
"21.1200","1.7517","6.8569","43.3032","0.1025","0.0549"
"21.1800","1.7568","6.8872","43.4944","0.1028","0.0550"
"21.2400","1.7617","6.9045","43.6041","0.1024","0.0548"
"21.3000","1.7670","6.9313","43.7731","0.1033","0.0553"
"21.3600","1.7717","6.9500","43.8912","0.1034","0.0554"
"21.4200","1.7766","6.9699","44.0169","0.1041","0.0557"
"21.4800","1.7816","6.9981","44.1948","0.1035","0.0554"
"21.5400","1.7866","7.0168","44.3132","0.1043","0.0559"
"21.6000","1.7919","7.0454","44.4937","0.1039","0.0556"
"21.6600","1.7967","7.0628","44.6035","0.1045","0.0560"
"21.7200","1.8018","7.0880","44.7628","0.1042","0.0558"
"21.7800","1.8068","7.1113","44.9101","0.1046","0.0560"
"21.8400","1.8117","7.1292","45.0227","0.1059","0.0567"
"21.9000","1.8168","7.1579","45.2039","0.1062","0.0569"
"21.9600","1.8215","7.1721","45.2937","0.1069","0.0572"
"22.0200","1.8266","7.2007","45.4745","0.1071","0.0574"
"22.0800","1.8315","7.2229","45.6147","0.1080","0.0578"
"22.1400","1.8368","7.2472","45.7683","0.1082","0.0579"
"22.2000","1.8418","7.2720","45.9245","0.1076","0.0576"
"22.2600","1.8466","7.2886","46.0293","0.1077","0.0577"
"22.3200","1.8519","7.3179","46.2144","0.1086","0.0581"
"22.3800","1.8567","7.3356","46.3266","0.1093","0.0585"
"22.4400","1.8619","7.3623","46.4948","0.1094","0.0586"
"22.5000","1.8668","7.3850","46.6384","0.1089","0.0583"
"22.5600","1.8715","7.3997","46.7310","0.1102","0.0590"
"22.6200","1.8766","7.4323","46.9373","0.1116","0.0597"
"22.6800","1.8816","7.4508","47.0541","0.1097","0.0588"
"22.7400","1.8869","7.4784","47.2283","0.1100","0.0589"
"22.8000","1.8917","7.4987","47.3566","0.1109","0.0594"
"22.8600","1.8967","7.5191","47.4851","0.1105","0.0592"
"22.9200","1.9018","7.5476","47.6652","0.1115","0.0597"
"22.9800","1.9066","7.5645","47.7720","0.1117","0.0598"
"23.0400","1.9119","7.5941","47.9591","0.1114","0.0596"
"23.1000","1.9166","7.6107","48.0635","0.1124","0.0602"
"23.1600","1.9214","7.6316","48.1956","0.1133","0.0606"
"23.2200","1.9265","7.6613","48.3833","0.1137","0.0609"
"23.2800","1.9316","7.6830","48.5205","0.1138","0.0609"
"23.3400","1.9370","7.7125","48.7069","0.1139","0.0610"
"23.4000","1.9416","7.7270","48.7981","0.1142","0.0611"
"23.4600","1.9468","7.7556","48.9790","0.1144","0.0613"
"23.5200","1.9518","7.7784","49.1226","0.1139","0.0610"
"23.5800","1.9568","7.7998","49.2582","0.1148","0.0615"
"23.6400","1.9620","7.8290","49.4421","0.1157","0.0620"
"23.7000","1.9665","7.8404","49.5146","0.1149","0.0615"
"23.7600","1.9717","7.8726","49.7176","0.1151","0.0616"
"23.8200","1.9765","7.8930","49.8464","0.1147","0.0614"
"23.8800","1.9819","7.9216","50.0272","0.1155","0.0619"
"23.9400","1.9868","7.9444","50.1709","0.1158","0.0620"
"24.0000","1.9916","7.9610","50.2762","0.1165","0.0624"
"24.0600","1.9969","7.9946","50.4884","0.1165","0.0624"
"24.1200","2.0016","8.0096","50.5831","0.1158","0.0620"
"24.1800","2.0070","8.0401","50.7755","0.1159","0.0621"
"24.2400","2.0117","8.0591","50.8955","0.1168","0.0625"
"24.3000","2.0165","8.0789","51.0205","0.1167","0.0625"
"24.3600","2.0216","8.1109","51.2226","0.1184","0.0634"
"24.4200","2.0265","8.1297","51.3411","0.1171","0.0627"
"24.4800","2.0319","8.1619","51.5448","0.1185","0.0634"
"24.5400","2.0366","8.1787","51.6509","0.1187","0.0636"
"24.6000","2.0417","8.2034","51.8066","0.1191","0.0638"
"24.6600","2.0469","8.2325","51.9903","0.1198","0.0641"
"24.7200","2.0517","8.2485","52.0916","0.1185","0.0635"
"24.7800","2.0570","8.2812","52.2982","0.1195","0.0640"
"24.8400","2.0616","8.2961","52.3922","0.1204","0.0645"
"24.9000","2.0667","8.3221","52.5561","0.1205","0.0645"
"24.9600","2.0716","8.3483","52.7218","0.1217","0.0652"
"25.0200","2.0767","8.3723","52.8737","0.1210","0.0648"
"25.0800","2.0819","8.3997","53.0463","0.1217","0.0652"
"25.1400","2.0865","8.4159","53.1491","0.1225","0.0656"
"25.2000","2.0919","8.4482","53.3530","0.1230","0.0659"
"25.2600","2.0967","8.4685","53.4807","0.1237","0.0662"
"25.3200","2.1018","8.4925","53.6323","0.1245","0.0667"
"25.3800","2.1068","8.5179","53.7932","0.1238","0.0663"
"25.4400","2.1114","8.5327","53.8867","0.1234","0.0661"
"25.5000","2.1166","8.5684","54.1118","0.1241","0.0664"
"25.5600","2.1215","8.5884","54.2382","0.1245","0.0667"
"25.6200","2.1268","8.6156","54.4100","0.1259","0.0674"
"25.6800","2.1317","8.6398","54.5626","0.1258","0.0673"
"25.7400","2.1366","8.6591","54.6848","0.1253","0.0671"
"25.8000","2.1418","8.6917","54.8906","0.1247","0.0668"
"25.8600","2.1466","8.7098","55.0047","0.1255","0.0672"
"25.9200","2.1520","8.7400","55.1958","0.1255","0.0672"
"25.9800","2.1568","8.7601","55.3222","0.1261","0.0675"
"26.0400","2.1615","8.7778","55.4345","0.1267","0.0679"
"26.1000","2.1666","8.8121","55.6506","0.1269","0.0680"
"26.1600","2.1716","8.8326","55.7807","0.1281","0.0686"
"26.2200","2.1770","8.8627","55.9703","0.1275","0.0683"
"26.2800","2.1817","8.8815","56.0891","0.1283","0.0687"
"26.3400","2.1868","8.9059","56.2433","0.1285","0.0688"
"26.4000","2.1918","8.9344","56.4235","0.1284","0.0687"
"26.4600","2.1967","8.9535","56.5436","0.1278","0.0684"
"26.5200","2.2019","8.9837","56.7347","0.1291","0.0691"
"26.5800","2.2065","9.0006","56.8412","0.1301","0.0697"
"26.6400","2.2115","9.0266","57.0057","0.1310","0.0701"
"26.7000","2.2164","9.0552","57.1863","0.1314","0.0704"
"26.7600","2.2218","9.0828","57.3604","0.1317","0.0705"
"26.8200","2.2269","9.1080","57.5196","0.1318","0.0706"
"26.8800","2.2315","9.1245","57.6236","0.1327","0.0710"
"26.9400","2.2369","9.1581","57.8358","0.1335","0.0715"
"27.0000","2.2419","9.1821","57.9873","0.1331","0.0713"
"27.0600","2.2469","9.2009","58.1063","0.1328","0.0711"
"27.1200","2.2518","9.2297","58.2882","0.1321","0.0707"
"27.1800","2.2565","9.2458","58.3899","0.1336","0.0716"
"27.2400","2.2617","9.2790","58.5993","0.1333","0.0714"
"27.3000","2.2666","9.3021","58.7456","0.1341","0.0718"
"27.3600","2.2720","9.3311","58.9283","0.1348","0.0722"
"27.4200","2.2768","9.3523","59.0623","0.1351","0.0723"
"27.4800","2.2816","9.3712","59.1816","0.1361","0.0729"
"27.5400","2.2870","9.4073","59.4095","0.1353","0.0725"
"27.6000","2.2918","9.4238","59.5140","0.1372","0.0735"
"27.6600","2.2969","9.4504","59.6818","0.1365","0.0731"
"27.7200","2.3016","9.4714","59.8143","0.1364","0.0730"
"27.7800","2.3065","9.4944","59.9597","0.1373","0.0735"
"27.8400","2.3116","9.5282","60.1731","0.1381","0.0740"
"27.9000","2.3166","9.5494","60.3072","0.1381","0.0739"
"27.9600","2.3219","9.5791","60.4948","0.1385","0.0742"
"28.0200","2.3266","9.5964","60.6038","0.1397","0.0748"
"28.0800","2.3318","9.6251","60.7850","0.1391","0.0745"
"28.1400","2.3369","9.6548","60.9729","0.1391","0.0745"
"28.2000","2.3418","9.6720","61.0813","0.1399","0.0749"
"28.2600","2.3469","9.7001","61.2587","0.1407","0.0753"
"28.3200","2.3515","9.7183","61.3736","0.1396","0.0748"
"28.3800","2.3567","9.7475","61.5585","0.1411","0.0755"
"28.4400","2.3616","9.7737","61.7235","0.1406","0.0753"
"28.5000","2.3668","9.7974","61.8732","0.1407","0.0754"
"28.5600","2.3718","9.8248","62.0463","0.1414","0.0757"
"28.6200","2.3765","9.8421","62.1555","0.1425","0.0763"
"28.6800","2.3818","9.8759","62.3689","0.1416","0.0758"
"28.7400","2.3868","9.8981","62.5091","0.1426","0.0764"
"28.8000","2.3918","9.9205","62.6506","0.1432","0.0767"
"28.8600","2.3967","9.9467","62.8160","0.1436","0.0769"
"28.9200","2.4015","9.9652","62.9332","0.1442","0.0772"
"28.9800","2.4066","9.9980","63.1399","0.1442","0.0772"
"29.0400","2.4115","10.0187","63.2709","0.1446","0.0774"
"29.1000","2.4167","10.0470","63.4493","0.1441","0.0772"
"29.1600","2.4216","10.0697","63.5927","0.1444","0.0773"
"29.2200","2.4266","10.0939","63.7461","0.1453","0.0778"
"29.2800","2.4319","10.1264","63.9509","0.1450","0.0776"
"29.3400","2.4368","10.1420","64.0499","0.1463","0.0783"
"29.4000","2.4419","10.1704","64.2290","0.1466","0.0785"
"29.4600","2.4466","10.1911","64.3595","0.1466","0.0785"
"29.5200","2.4516","10.2159","64.5162","0.1471","0.0788"
"29.5800","2.4567","10.2462","64.7077","0.1469","0.0787"
"29.6400","2.4617","10.2668","64.8378","0.1479","0.0792"
"29.7000","2.4668","10.2954","65.0186","0.1485","0.0795"
"29.7600","2.4715","10.3129","65.1289","0.1491","0.0799"
"29.8200","2.4768","10.3454","65.3343","0.1503","0.0805"
"29.8800","2.4819","10.3708","65.4942","0.1509","0.0808"
"29.9400","2.4867","10.3881","65.6038","0.1506","0.0806"
"30.0000","2.4918","10.4195","65.8024","0.1511","0.0809"
"30.0600","2.4964","10.4356","65.9039","0.1515","0.0811"
"30.1200","2.5015","10.4644","66.0856","0.1513","0.0810"
"30.1800","2.5065","10.4915","66.2565","0.1524","0.0816"
"30.2400","2.5117","10.5175","66.4211","0.1524","0.0816"
"30.3000","2.5167","10.5435","66.5853","0.1528","0.0818"
"30.3600","2.5215","10.5623","66.7039","0.1531","0.0820"
"30.4200","2.5269","10.5963","66.9186","0.1534","0.0821"
"30.4800","2.5319","10.6192","67.0634","0.1533","0.0821"
"30.5400","2.5368","10.6370","67.1758","0.1547","0.0829"
"30.6000","2.5418","10.6658","67.3577","0.1547","0.0828"
"30.6600","2.5466","10.6846","67.4764","0.1557","0.0834"
"30.7200","2.5517","10.7157","67.6724","0.1559","0.0835"
"30.7800","2.5567","10.7381","67.8143","0.1564","0.0838"
"30.8400","2.5618","10.7659","67.9898","0.1569","0.0840"
"30.9000","2.5667","10.7878","68.1281","0.1572","0.0842"
"30.9600","2.5717","10.8111","68.2750","0.1578","0.0845"
"31.0200","2.5769","10.8440","68.4828","0.1573","0.0842"
"31.0800","2.5818","10.8596","68.5816","0.1583","0.0848"
"31.1400","2.5868","10.8890","68.7668","0.1599","0.0856"
"31.2000","2.5915","10.9067","68.8791","0.1591","0.0852"
"31.2600","2.5966","10.9333","69.0470","0.1590","0.0851"
"31.3200","2.6016","10.9620","69.2279","0.1601","0.0857"
"31.3800","2.6066","10.9835","69.3642","0.1609","0.0862"
"31.4400","2.6118","11.0141","69.5570","0.1610","0.0862"
"31.5000","2.6166","11.0319","69.6697","0.1616","0.0865"
"31.5600","2.6218","11.0601","69.8477","0.1616","0.0865"
"31.6200","2.6269","11.0874","70.0202","0.1625","0.0870"
"31.6800","2.6318","11.1043","70.1266","0.1628","0.0872"
"31.7400","2.6368","11.1329","70.3074","0.1638","0.0877"
"31.8000","2.6416","11.1501","70.4159","0.1625","0.0870"
"31.8600","2.6467","11.1800","70.6047","0.1632","0.0874"
"31.9200","2.6516","11.2016","70.7409","0.1644","0.0880"
"31.9800","2.6567","11.2281","70.9089","0.1643","0.0880"
"32.0400","2.6619","11.2566","71.0883","0.1639","0.0878"
"32.1000","2.6667","11.2725","71.1887","0.1648","0.0882"
"32.1600","2.6719","11.3044","71.3902","0.1659","0.0888"
"32.2200","2.6767","11.3228","71.5067","0.1652","0.0885"
"32.2800","2.6817","11.3452","71.6479","0.1657","0.0887"
"32.3400","2.6867","11.3716","71.8149","0.1666","0.0892"
"32.4000","2.6916","11.3916","71.9410","0.1674","0.0897"
"32.4600","2.6966","11.4182","72.1089","0.1673","0.0896"
"32.5200","2.7013","11.4354","72.2180","0.1675","0.0897"
"32.5800","2.7067","11.4704","72.4387","0.1679","0.0899"
"32.6400","2.7117","11.4902","72.5637","0.1681","0.0900"
"32.7000","2.7168","11.5119","72.7007","0.1684","0.0902"
"32.7600","2.7220","11.5401","72.8788","0.1688","0.0904"
"32.8200","2.7267","11.5533","72.9624","0.1680","0.0900"
"32.8800","2.7318","11.5799","73.1303","0.1699","0.0910"
"32.9400","2.7366","11.5972","73.2395","0.1704","0.0913"
"33.0000","2.7417","11.6226","73.4003","0.1711","0.0916"
"33.0600","2.7467","11.6463","73.5497","0.1714","0.0918"
"33.1200","2.7516","11.6639","73.6609","0.1719","0.0921"
"33.1800","2.7568","11.6926","73.8422","0.1731","0.0927"
"33.2400","2.7616","11.7041","73.9144","0.1727","0.0925"
"33.3000","2.7668","11.7319","74.0900","0.1728","0.0925"
"33.3600","2.7719","11.7513","74.2126","0.1743","0.0933"
"33.4200","2.7767","11.7612","74.2753","0.1745","0.0935"
"33.4800","2.7818","11.7816","74.4039","0.1749","0.0936"
"33.5400","2.7864","11.7793","74.3897","0.1748","0.0936"
"33.6000","2.7916","11.7876","74.4421","0.1762","0.0943"
"33.6600","2.7965","11.7185","74.0058","0.1772","0.0949"
"33.7200","2.8018","11.2122","70.8082","0.1753","0.0939"
"33.7800","2.8072","10.5133","66.3947","0.1682","0.0901"
"33.8400","2.8120","9.9904","63.0924","0.1724","0.0923"
"33.9000","2.8173","9.6606","61.0091","0.1738","0.0931"
"33.9600","2.8221","9.3273","58.9048","0.1741","0.0932"
"34.0200","2.8270","8.9112","56.2767","0.1774","0.0950"
"34.0800","2.8320","8.4232","53.1951","0.1824","0.0977"
"34.1400","2.8369","7.8226","49.4021","0.1829","0.0979"
"34.2000","2.8423","6.7189","42.4315","0.1701","0.0911"
"34.2600","2.8475","4.9115","31.0178","0.1330","0.0712"
"34.3200","2.8525","4.2486","26.8308","0.1030","0.0551"
"34.3800","2.8569","4.1859","26.4354","0.1014","0.0543"
"34.4400","2.8617","4.1531","26.2281","0.1011","0.0541"
"34.5000","2.8670","4.1463","26.1847","0.1005","0.0538"
"34.5600","2.8718","4.1318","26.0937","0.0995","0.0533"
"34.6200","2.8769","4.1344","26.1100","0.0988","0.0529"
"34.6800","2.8815","4.1280","26.0697","0.1003","0.0537"
"34.7400","2.8867","4.1328","26.0999","0.0994","0.0532"
"34.8000","2.8917","4.1384","26.1350","0.0988","0.0529"
"34.8600","2.8966","4.1338","26.1063","0.0995","0.0533"
"34.9200","2.9018","4.1427","26.1622","0.0989","0.0529"
"34.9800","2.9065","4.1372","26.1273","0.0993","0.0532"
"35.0400","2.9120","4.1506","26.2120","0.0994","0.0532"
"35.1000","2.9170","4.1485","26.1988","0.1004","0.0538"
"35.1600","2.9218","4.1435","26.1672","0.1007","0.0539"
"35.2200","2.9268","4.1519","26.2204","0.0990","0.0530"
"35.2800","2.9316","4.1479","26.1951","0.0988","0.0529"
"35.3400","2.9369","4.1580","26.2591","0.0992","0.0531"
"35.4000","2.9417","4.1545","26.2368","0.1010","0.0541"
"35.4600","2.9467","4.1576","26.2565","0.0997","0.0534"
"35.5200","2.9517","4.1637","26.2948","0.0997","0.0534"
"35.5800","2.9566","4.1634","26.2928","0.0999","0.0535"
"35.6400","2.9619","4.1750","26.3661","0.0992","0.0531"
"35.7000","2.9667","4.1698","26.3335","0.0998","0.0534"
"35.7600","2.9718","4.1747","26.3642","0.1005","0.0538"
"35.8200","2.9766","4.1779","26.3844","0.1009","0.0540"
"35.8800","2.9816","4.1795","26.3947","0.1008","0.0540"
"35.9400","2.9867","4.1889","26.4543","0.1010","0.0541"
"36.0000","2.9915","4.1848","26.4285","0.0999","0.0535"
"36.0600","2.9967","4.1939","26.4858","0.1012","0.0542"
"36.1200","3.0016","4.1929","26.4792","0.1011","0.0541"
"36.1800","3.0068","4.1985","26.5145","0.0996","0.0533"
"36.2400","3.0119","4.2057","26.5601","0.1011","0.0541"
"36.3000","3.0167","4.2020","26.5368","0.1017","0.0545"
"36.3600","3.0219","4.2127","26.6044","0.1013","0.0542"
"36.4200","3.0266","4.2082","26.5762","0.1007","0.0539"
"36.4800","3.0318","4.2173","26.6332","0.1023","0.0548"
"36.5400","3.0367","4.2219","26.6625","0.1018","0.0545"
"36.6000","3.0416","4.2216","26.6604","0.1021","0.0547"
"36.6600","3.0468","4.2309","26.7194","0.1013","0.0543"
"36.7200","3.0515","4.2259","26.6877","0.1027","0.0550"
"36.7800","3.0569","4.2404","26.7796","0.1020","0.0546"
"36.8400","3.0619","4.2432","26.7970","0.1025","0.0549"
"36.9000","3.0667","4.2423","26.7911","0.1018","0.0545"
"36.9600","3.0717","4.2524","26.8551","0.1027","0.0550"
"37.0200","3.0765","4.2514","26.8486","0.1020","0.0546"
"37.0800","3.0818","4.2615","26.9124","0.1030","0.0552"
"37.1400","3.0865","4.2608","26.9080","0.1016","0.0544"
"37.2000","3.0916","4.2684","26.9564","0.1025","0.0549"
"37.2600","3.0966","4.2751","26.9983","0.1035","0.0554"
"37.3200","3.1015","4.2756","27.0019","0.1032","0.0553"
"37.3800","3.1070","4.2914","27.1011","0.1036","0.0555"
"37.4400","3.1119","4.2892","27.0873","0.1029","0.0551"
"37.5000","3.1168","4.2900","27.0922","0.1038","0.0556"
"37.5600","3.1216","4.2919","27.1049","0.1034","0.0554"
"37.6200","3.1267","4.2969","27.1364","0.1030","0.0552"
"37.6800","3.1319","4.3055","27.1908","0.1028","0.0551"
"37.7400","3.1365","4.2989","27.1486","0.1040","0.0557"
"37.8000","3.1418","4.3121","27.2322","0.1032","0.0553"
"37.8600","3.1466","4.3118","27.2301","0.1044","0.0559"
"37.9200","3.1518","4.3172","27.2646","0.1043","0.0558"
"37.9800","3.1569","4.3210","27.2885","0.1039","0.0557"
"38.0400","3.1616","4.3130","27.2376","0.1046","0.0560"
"38.1000","3.1669","4.3241","27.3080","0.1048","0.0561"
"38.1600","3.1716","4.3205","27.2849","0.1052","0.0563"
"38.2200","3.1768","4.3299","27.3444","0.1053","0.0564"
"38.2800","3.1816","4.3305","27.3481","0.1050","0.0562"
"38.3400","3.1865","4.3296","27.3423","0.1050","0.0562"
"38.4000","3.1917","4.3382","27.3968","0.1053","0.0564"
"38.4600","3.1966","4.3286","27.3361","0.1050","0.0562"
"38.5200","3.2020","4.3347","27.3751","0.1062","0.0569"
"38.5800","3.2068","4.3266","27.3234","0.1040","0.0557"
"38.6400","3.2118","4.3205","27.2854","0.1063","0.0569"
"38.7000","3.2168","4.3204","27.2849","0.1056","0.0566"
"38.7600","3.2217","4.3111","27.2255","0.1049","0.0562"
"38.8200","3.2269","4.3161","27.2575","0.1054","0.0565"
"38.8800","3.2316","4.3062","27.1948","0.1055","0.0565"
"38.9400","3.2367","4.3097","27.2170","0.1051","0.0563"
"39.0000","3.2416","4.3099","27.2180","0.1043","0.0559"
"39.0600","3.2467","4.3066","27.1973","0.1057","0.0566"
"39.1200","3.2519","4.3121","27.2319","0.1055","0.0565"
"39.1800","3.2567","4.3039","27.1805","0.1053","0.0564"
"39.2400","3.2618","4.3070","27.1999","0.1071","0.0574"
"39.3000","3.2666","4.3057","27.1915","0.1064","0.0570"
"39.3600","3.2717","4.3054","27.1898","0.1062","0.0569"
"39.4200","3.2766","4.2842","27.0559","0.1057","0.0566"
"39.4800","3.2815","4.2628","26.9205","0.1050","0.0562"
"39.5400","3.2867","4.2632","26.9233","0.1063","0.0569"
"39.6000","3.2915","4.2560","26.8780","0.1048","0.0561"
"39.6600","3.2968","4.2601","26.9038","0.1056","0.0565"
"39.7200","3.3018","4.2622","26.9168","0.1062","0.0569"
"39.7800","3.3067","4.2598","26.9016","0.1069","0.0572"
"39.8400","3.3119","4.2680","26.9539","0.1055","0.0565"
"39.9000","3.3166","4.2618","26.9143","0.1064","0.0570"
"39.9600","3.3218","4.2703","26.9681","0.1057","0.0566"
"40.0200","3.3266","4.2694","26.9622","0.1070","0.0573"
"40.0800","3.3316","4.2725","26.9820","0.1059","0.0567"
"40.1400","3.3368","4.2821","27.0430","0.1064","0.0570"
"40.2000","3.3416","4.2762","27.0054","0.1071","0.0573"
"40.2600","3.3470","4.2882","27.0809","0.1073","0.0575"
"40.3200","3.3518","4.2832","27.0494","0.1071","0.0574"
"40.3800","3.3568","4.2873","27.0755","0.1071","0.0574"
"40.4400","3.3618","4.2921","27.1057","0.1071","0.0574"
"40.5000","3.3665","4.2900","27.0924","0.1070","0.0573"
"40.5600","3.3718","4.3047","27.1856","0.1079","0.0578"
"40.6200","3.3764","4.2990","27.1496","0.1076","0.0576"
"40.6800","3.3817","4.3130","27.2381","0.1080","0.0578"
"40.7400","3.3866","4.3155","27.2535","0.1084","0.0581"
"40.8000","3.3917","4.3162","27.2583","0.1081","0.0579"
"40.8600","3.3970","4.3250","27.3136","0.1078","0.0577"
"40.9200","3.4017","4.3171","27.2638","0.1083","0.0580"
"40.9800","3.4069","4.3249","27.3127","0.1082","0.0579"
"41.0400","3.4116","4.3241","27.3080","0.1084","0.0580"
"41.1000","3.4168","4.3314","27.3542","0.1096","0.0587"
"41.1600","3.4218","4.3366","27.3867","0.1094","0.0586"
"41.2200","3.4266","4.3354","27.3793","0.1097","0.0587"
"41.2800","3.4318","4.3478","27.4574","0.1090","0.0584"
"41.3400","3.4366","4.3455","27.4431","0.1094","0.0586"
"41.4000","3.4420","4.3578","27.5206","0.1099","0.0589"
"41.4600","3.4469","4.3600","27.5349","0.1103","0.0591"
"41.5200","3.4517","4.3574","27.5180","0.1110","0.0594"
"41.5800","3.4568","4.3669","27.5779","0.1105","0.0592"
"41.6400","3.4615","4.3648","27.5647","0.1111","0.0595"
"41.7000","3.4669","4.3765","27.6387","0.1117","0.0598"
"41.7600","3.4716","4.3702","27.5988","0.1123","0.0602"
"41.8200","3.4765","4.3725","27.6136","0.1127","0.0603"
"41.8800","3.4817","4.3824","27.6759","0.1122","0.0601"
"41.9400","3.4868","4.3841","27.6869","0.1138","0.0609"
"42.0000","3.4921","4.3918","27.7354","0.1139","0.0610"
"42.0600","3.4967","4.3868","27.7038","0.1137","0.0609"
"42.1200","3.5018","4.3955","27.7585","0.1145","0.0613"
"42.1800","3.5067","4.4008","27.7920","0.1138","0.0609"
"42.2400","3.5117","4.4021","27.8006","0.1136","0.0608"
"42.3000","3.5170","4.4114","27.8595","0.1150","0.0616"
"42.3600","3.5215","4.4030","27.8060","0.1147","0.0614"
"42.4200","3.5267","4.4140","27.8759","0.1146","0.0614"
"42.4800","3.5316","4.4160","27.8884","0.1142","0.0612"
"42.5400","3.5369","4.4247","27.9433","0.1144","0.0613"
"42.6000","3.5420","4.4301","27.9772","0.1147","0.0614"
"42.6600","3.5466","4.4233","27.9343","0.1151","0.0616"
"42.7200","3.5518","4.4350","28.0080","0.1148","0.0615"
"42.7800","3.5566","4.4329","27.9947","0.1148","0.0614"
"42.8400","3.5617","4.4388","28.0320","0.1158","0.0620"
"42.9000","3.5666","4.4415","28.0491","0.1154","0.0618"
"42.9600","3.5714","4.4394","28.0358","0.1148","0.0615"
"43.0200","3.5767","4.4507","28.1072","0.1159","0.0620"
"43.0800","3.5816","4.4486","28.0941","0.1151","0.0616"
"43.1400","3.5869","4.4567","28.1451","0.1155","0.0618"
"43.2000","3.5917","4.4546","28.1318","0.1154","0.0618"
"43.2600","3.5966","4.4536","28.1256","0.1157","0.0620"
"43.3200","3.6018","4.4649","28.1973","0.1157","0.0619"
"43.3800","3.6067","4.4606","28.1697","0.1155","0.0618"
"43.4400","3.6119","4.4648","28.1964","0.1148","0.0615"
"43.5000","3.6165","4.4543","28.1299","0.1156","0.0619"
"43.5600","3.6216","4.4572","28.1486","0.1149","0.0616"
"43.6200","3.6267","4.4642","28.1927","0.1160","0.0621"
"43.6800","3.6317","4.4619","28.1783","0.1154","0.0618"
"43.7400","3.6370","4.4700","28.2295","0.1159","0.0621"
"43.8000","3.6417","4.4626","28.1824","0.1150","0.0616"
"43.8600","3.6467","4.4655","28.2007","0.1156","0.0619"
"43.9200","3.6517","4.4681","28.2174","0.1151","0.0616"
"43.9800","3.6567","4.4679","28.2161","0.1159","0.0621"
"44.0400","3.6617","4.4697","28.2274","0.1146","0.0614"
"44.1000","3.6663","4.4627","28.1833","0.1149","0.0615"
"44.1600","3.6716","4.4772","28.2747","0.1141","0.0611"
"44.2200","3.6766","4.4769","28.2728","0.1150","0.0616"
"44.2800","3.6818","4.4766","28.2711","0.1155","0.0619"
"44.3400","3.6869","4.4793","28.2880","0.1149","0.0615"
"44.4000","3.6916","4.4729","28.2474","0.1155","0.0618"
"44.4600","3.6969","4.4816","28.3028","0.1151","0.0616"
"44.5200","3.7017","4.4803","28.2946","0.1155","0.0619"
"44.5800","3.7069","4.4850","28.3237","0.1150","0.0616"
"44.6400","3.7117","4.4841","28.3181","0.1148","0.0615"
"44.7000","3.7165","4.4823","28.3070","0.1146","0.0614"
"44.7600","3.7218","4.4947","28.3854","0.1150","0.0616"
"44.8200","3.7267","4.4920","28.3685","0.1155","0.0619"
"44.8800","3.7319","4.4959","28.3930","0.1154","0.0618"
"44.9400","3.7368","4.4950","28.3870","0.1146","0.0614"
"45.0000","3.7417","4.4945","28.3839","0.1146","0.0614"
"45.0600","3.7468","4.5011","28.4255","0.1143","0.0612"
"45.1200","3.7517","4.4994","28.4151","0.1147","0.0614"
"45.1800","3.7568","4.5050","28.4502","0.1141","0.0611"
"45.2400","3.7615","4.5007","28.4233","0.1142","0.0611"
"45.3000","3.7666","4.5060","28.4568","0.1141","0.0611"
"45.3600","3.7717","4.5106","28.4857","0.1142","0.0611"
"45.4200","3.7768","4.5094","28.4781","0.1144","0.0613"
"45.4800","3.7819","4.5139","28.5065","0.1148","0.0615"
"45.5400","3.7866","4.5095","28.4786","0.1136","0.0608"
"45.6000","3.7919","4.5174","28.5289","0.1143","0.0612"
"45.6600","3.7969","4.5190","28.5385","0.1151","0.0616"
"45.7200","3.8018","4.5171","28.5267","0.1153","0.0618"
"45.7800","3.8069","4.5232","28.5653","0.1149","0.0615"
"45.8400","3.8115","4.5184","28.5348","0.1150","0.0616"
"45.9000","3.8168","4.5305","28.6113","0.1144","0.0612"
"45.9600","3.8217","4.5311","28.6154","0.1141","0.0611"
"46.0200","3.8268","4.5338","28.6323","0.1141","0.0611"
"46.0800","3.8318","4.5376","28.6560","0.1157","0.0619"
"46.1400","3.8367","4.5350","28.6398","0.1149","0.0615"
"46.2000","3.8419","4.5445","28.6995","0.1150","0.0616"
"46.2600","3.8467","4.5415","28.6809","0.1159","0.0621"
"46.3200","3.8517","4.5442","28.6977","0.1155","0.0618"
"46.3800","3.8565","4.5469","28.7147","0.1151","0.0616"
"46.4400","3.8615","4.5480","28.7219","0.1152","0.0617"
"46.5000","3.8666","4.5550","28.7663","0.1147","0.0614"
"46.5600","3.8716","4.5540","28.7598","0.1143","0.0612"
"46.6200","3.8768","4.5603","28.7995","0.1146","0.0614"
"46.6800","3.8817","4.5574","28.7814","0.1147","0.0614"
"46.7400","3.8868","4.5611","28.8045","0.1149","0.0615"
"46.8000","3.8919","4.5681","28.8487","0.1156","0.0619"
"46.8600","3.8967","4.5640","28.8231","0.1140","0.0611"
"46.9200","3.9019","4.5712","28.8682","0.1143","0.0612"
"46.9800","3.9065","4.5646","28.8270","0.1145","0.0613"
"47.0400","3.9117","4.5730","28.8800","0.1145","0.0613"
"47.1000","3.9166","4.5766","28.9025","0.1145","0.0613"
"47.1600","3.9216","4.5764","28.9010","0.1137","0.0609"
"47.2200","3.9269","4.5866","28.9658","0.1141","0.0611"
"47.2800","3.9317","4.5808","28.9289","0.1135","0.0608"
"47.3400","3.9369","4.5881","28.9753","0.1137","0.0609"
"47.4000","3.9418","4.5893","28.9825","0.1145","0.0613"
"47.4600","3.9468","4.5904","28.9894","0.1141","0.0611"
"47.5200","3.9517","4.5937","29.0103","0.1143","0.0612"
"47.5800","3.9563","4.5900","28.9874","0.1146","0.0614"
"47.6400","3.9617","4.6037","29.0735","0.1140","0.0610"
"47.7000","3.9667","4.6051","29.0822","0.1138","0.0609"
"47.7390","3.9703","4.6141","29.1391","0.1136","0.0608"