File: composites_properties_derivations/composite_tube_tests/comp_tube_3.csv
Specimen label,"3"
Force at Maximum Load,"14.58",kN
Tensile stress at Maximum Load,"92.07",MPa
Epsilon ONE Displacement at Maximum Load,"0.08",mm
Force at Break (Standard),"14.48",kN
Tensile stress at Break (Standard),"91.48",MPa
Epsilon ONE Displacement at Break (Standard),"0.08",mm
Slope (Chord 0.05 % - 0.2 %),"-----",MPa
Modulus (Automatic Young's),"73211.20",MPa

Specimen label,"3"
Thickness,"",mm
Width,"",mm
Length,"53.31",mm
Rate 1,"5.00",mm/min
Outer diameter,"19.05",mm
Wall thickness,"3.18",mm

Time,Displacement,Force,Tensile stress,Tensile strain (Epsilon ONE Displacement),Epsilon ONE Displacement
(s),(mm),(kN),(MPa),(%),(mm)
"0.0000","0.0018","0.0500","0.3160","-0.0010","-0.0006"
"0.0600","0.0023","0.0601","0.3795","0.0001","0.0001"
"0.1200","0.0044","0.0908","0.5734","0.0002","0.0001"
"0.1800","0.0064","0.0986","0.6226","0.0010","0.0005"
"0.2400","0.0158","0.1056","0.6669","0.0006","0.0003"
"0.3000","0.0220","0.1076","0.6792","0.0007","0.0003"
"0.3600","0.0262","0.1097","0.6930","0.0004","0.0002"
"0.4200","0.0314","0.1128","0.7126","0.0004","0.0002"
"0.4800","0.0364","0.1105","0.6976","0.0000","0.0000"
"0.5400","0.0416","0.1151","0.7269","0.0000","0.0000"
"0.6000","0.0467","0.1160","0.7323","0.0009","0.0005"
"0.6600","0.0516","0.1184","0.7480","0.0005","0.0003"
"0.7200","0.0567","0.1206","0.7614","0.0005","0.0003"
"0.7800","0.0616","0.1223","0.7721","-0.0005","-0.0003"
"0.8400","0.0668","0.1241","0.7835","0.0002","0.0001"
"0.9000","0.0717","0.1258","0.7945","0.0006","0.0003"
"0.9600","0.0765","0.1269","0.8014","0.0006","0.0003"
"1.0200","0.0815","0.1289","0.8140","0.0000","0.0000"
"1.0800","0.0864","0.1300","0.8210","0.0006","0.0003"
"1.1400","0.0918","0.1316","0.8310","0.0010","0.0005"
"1.2000","0.0965","0.1330","0.8399","-0.0001","-0.0001"
"1.2600","0.1016","0.1344","0.8485","0.0007","0.0004"
"1.3200","0.1065","0.1359","0.8582","0.0007","0.0004"
"1.3800","0.1115","0.1370","0.8653","0.0008","0.0004"
"1.4400","0.1167","0.1384","0.8739","0.0006","0.0003"
"1.5000","0.1214","0.1391","0.8782","0.0009","0.0005"
"1.5600","0.1265","0.1405","0.8871","0.0007","0.0004"
"1.6200","0.1313","0.1418","0.8956","0.0015","0.0008"
"1.6800","0.1366","0.1427","0.9012","0.0009","0.0005"
"1.7400","0.1418","0.1438","0.9083","0.0009","0.0005"
"1.8000","0.1466","0.1444","0.9119","0.0013","0.0007"
"1.8600","0.1518","0.1454","0.9184","0.0013","0.0007"
"1.9200","0.1565","0.1464","0.9247","0.0013","0.0007"
"1.9800","0.1618","0.1472","0.9298","0.0011","0.0006"
"2.0400","0.1668","0.1481","0.9351","0.0013","0.0007"
"2.1000","0.1716","0.1485","0.9378","0.0010","0.0005"
"2.1600","0.1766","0.1498","0.9458","0.0009","0.0005"
"2.2200","0.1813","0.1503","0.9493","0.0011","0.0006"
"2.2800","0.1868","0.1509","0.9529","0.0009","0.0005"
"2.3400","0.1916","0.1522","0.9614","0.0003","0.0002"
"2.4000","0.1965","0.1527","0.9644","0.0009","0.0005"
"2.4600","0.2017","0.1541","0.9735","0.0014","0.0007"
"2.5200","0.2065","0.1546","0.9762","0.0012","0.0006"
"2.5800","0.2119","0.1555","0.9820","0.0011","0.0006"
"2.6400","0.2165","0.1564","0.9874","0.0018","0.0009"
"2.7000","0.2215","0.1570","0.9914","0.0012","0.0006"
"2.7600","0.2264","0.1584","1.0006","0.0013","0.0007"
"2.8200","0.2314","0.1591","1.0045","0.0010","0.0006"
"2.8800","0.2369","0.1602","1.0118","0.0007","0.0004"
"2.9400","0.2415","0.1609","1.0164","0.0014","0.0007"
"3.0000","0.2467","0.1616","1.0208","0.0010","0.0005"
"3.0600","0.2516","0.1632","1.0309","0.0010","0.0006"
"3.1200","0.2566","0.1636","1.0330","0.0023","0.0012"
"3.1800","0.2619","0.1653","1.0437","0.0013","0.0007"
"3.2400","0.2665","0.1656","1.0460","0.0009","0.0005"
"3.3000","0.2716","0.1665","1.0512","0.0016","0.0009"
"3.3600","0.2763","0.1682","1.0622","0.0031","0.0016"
"3.4200","0.2817","0.1687","1.0655","0.0023","0.0012"
"3.4800","0.2868","0.1704","1.0758","0.0018","0.0009"
"3.5400","0.2915","0.1711","1.0803","0.0022","0.0012"
"3.6000","0.2967","0.1728","1.0913","0.0022","0.0012"
"3.6600","0.3015","0.1741","1.0992","0.0024","0.0013"
"3.7200","0.3068","0.1750","1.1050","0.0012","0.0007"
"3.7800","0.3117","0.1767","1.1156","0.0014","0.0007"
"3.8400","0.3164","0.1770","1.1181","0.0019","0.0010"
"3.9000","0.3215","0.1792","1.1317","0.0029","0.0015"
"3.9600","0.3264","0.1803","1.1389","0.0019","0.0010"
"4.0200","0.3319","0.1790","1.1306","0.0014","0.0008"
"4.0800","0.3367","0.1819","1.1488","0.0028","0.0015"
"4.1400","0.3415","0.1826","1.1530","0.0023","0.0012"
"4.2000","0.3467","0.1845","1.1651","0.0018","0.0010"
"4.2600","0.3518","0.1853","1.1704","0.0017","0.0009"
"4.3200","0.3569","0.1865","1.1781","0.0014","0.0007"
"4.3800","0.3615","0.1882","1.1886","0.0012","0.0006"
"4.4400","0.3666","0.1889","1.1932","0.0013","0.0007"
"4.5000","0.3715","0.1910","1.2062","0.0010","0.0006"
"4.5600","0.3765","0.1916","1.2101","0.0013","0.0007"
"4.6200","0.3818","0.1932","1.2199","0.0017","0.0009"
"4.6800","0.3865","0.1944","1.2276","0.0015","0.0008"
"4.7400","0.3917","0.1956","1.2351","0.0009","0.0005"
"4.8000","0.3967","0.1975","1.2475","0.0012","0.0006"
"4.8600","0.4017","0.1981","1.2512","0.0014","0.0007"
"4.9200","0.4068","0.2001","1.2636","0.0016","0.0008"
"4.9800","0.4113","0.2011","1.2699","0.0012","0.0006"
"5.0400","0.4165","0.2027","1.2803","0.0023","0.0012"
"5.1000","0.4213","0.2044","1.2907","0.0024","0.0013"
"5.1600","0.4265","0.2055","1.2977","0.0022","0.0012"
"5.2200","0.4316","0.2077","1.3120","0.0023","0.0012"
"5.2800","0.4364","0.2087","1.3180","0.0030","0.0016"
"5.3400","0.4418","0.2089","1.3190","0.0019","0.0010"
"5.4000","0.4466","0.2106","1.3300","0.0030","0.0016"
"5.4600","0.4518","0.2118","1.3374","0.0032","0.0017"
"5.5200","0.4566","0.2139","1.3510","0.0026","0.0014"
"5.5800","0.4614","0.2149","1.3572","0.0029","0.0015"
"5.6400","0.4667","0.2171","1.3708","0.0024","0.0013"
"5.7000","0.4715","0.2180","1.3767","0.0033","0.0018"
"5.7600","0.4768","0.2190","1.3830","0.0032","0.0017"
"5.8200","0.4814","0.2209","1.3951","0.0027","0.0015"
"5.8800","0.4865","0.2219","1.4013","0.0025","0.0014"
"5.9400","0.4917","0.2240","1.4145","0.0033","0.0018"
"6.0000","0.4966","0.2253","1.4230","0.0025","0.0013"
"6.0600","0.5018","0.2267","1.4316","0.0041","0.0022"
"6.1200","0.5064","0.2286","1.4434","0.0022","0.0012"
"6.1800","0.5114","0.2295","1.4494","0.0022","0.0012"
"6.2400","0.5164","0.2318","1.4639","0.0035","0.0018"
"6.3000","0.5215","0.2328","1.4702","0.0027","0.0014"
"6.3600","0.5267","0.2347","1.4825","0.0033","0.0017"
"6.4200","0.5313","0.2363","1.4922","0.0020","0.0011"
"6.4800","0.5367","0.2376","1.5003","0.0020","0.0011"
"6.5400","0.5417","0.2397","1.5138","0.0017","0.0009"
"6.6000","0.5467","0.2403","1.5176","0.0023","0.0012"
"6.6600","0.5518","0.2420","1.5285","0.0014","0.0007"
"6.7200","0.5565","0.2435","1.5378","0.0012","0.0006"
"6.7800","0.5617","0.2449","1.5468","0.0032","0.0017"
"6.8400","0.5664","0.2469","1.5595","0.0032","0.0017"
"6.9000","0.5718","0.2476","1.5637","0.0021","0.0011"
"6.9600","0.5767","0.2497","1.5771","0.0032","0.0017"
"7.0200","0.5815","0.2510","1.5851","0.0016","0.0009"
"7.0800","0.5868","0.2532","1.5993","0.0015","0.0008"
"7.1400","0.5917","0.2544","1.6065","0.0021","0.0011"
"7.2000","0.5968","0.2559","1.6164","0.0015","0.0008"
"7.2600","0.6015","0.2581","1.6302","0.0027","0.0014"
"7.3200","0.6063","0.2590","1.6355","0.0016","0.0009"
"7.3800","0.6114","0.2616","1.6519","0.0021","0.0011"
"7.4400","0.6164","0.2630","1.6610","0.0022","0.0012"
"7.5000","0.6218","0.2646","1.6709","0.0029","0.0015"
"7.5600","0.6265","0.2670","1.6865","0.0026","0.0014"
"7.6200","0.6316","0.2679","1.6918","0.0032","0.0017"
"7.6800","0.6368","0.2705","1.7081","0.0030","0.0016"
"7.7400","0.6418","0.2715","1.7149","0.0029","0.0015"
"7.8000","0.6469","0.2734","1.7265","0.0026","0.0014"
"7.8600","0.6514","0.2753","1.7388","0.0037","0.0020"
"7.9200","0.6566","0.2767","1.7473","0.0027","0.0014"
"7.9800","0.6615","0.2794","1.7646","0.0033","0.0017"
"8.0400","0.6667","0.2805","1.7713","0.0037","0.0020"
"8.1000","0.6718","0.2829","1.7865","0.0030","0.0016"
"8.1600","0.6764","0.2842","1.7950","0.0032","0.0017"
"8.2200","0.6817","0.2863","1.8084","0.0024","0.0013"
"8.2800","0.6867","0.2889","1.8248","0.0034","0.0018"
"8.3400","0.6917","0.2899","1.8310","0.0026","0.0014"
"8.4000","0.6966","0.2926","1.8480","0.0034","0.0018"
"8.4600","0.7013","0.2942","1.8577","0.0023","0.0012"
"8.5200","0.7065","0.2966","1.8732","0.0043","0.0023"
"8.5800","0.7114","0.2985","1.8853","0.0042","0.0023"
"8.6400","0.7166","0.3002","1.8958","0.0044","0.0024"
"8.7000","0.7216","0.3030","1.9138","0.0052","0.0028"
"8.7600","0.7265","0.3040","1.9199","0.0042","0.0023"
"8.8200","0.7316","0.3070","1.9387","0.0024","0.0013"
"8.8800","0.7366","0.3091","1.9518","0.0037","0.0020"
"8.9400","0.7418","0.3107","1.9623","0.0040","0.0021"
"9.0000","0.7465","0.3133","1.9783","0.0040","0.0022"
"9.0600","0.7515","0.3145","1.9860","0.0045","0.0024"
"9.1200","0.7566","0.3175","2.0051","0.0045","0.0024"
"9.1800","0.7616","0.3194","2.0173","0.0044","0.0023"
"9.2400","0.7668","0.3215","2.0306","0.0041","0.0022"
"9.3000","0.7714","0.3242","2.0476","0.0050","0.0027"
"9.3600","0.7766","0.3262","2.0599","0.0039","0.0021"
"9.4200","0.7816","0.3298","2.0828","0.0041","0.0022"
"9.4800","0.7866","0.3317","2.0945","0.0033","0.0017"
"9.5400","0.7917","0.3349","2.1149","0.0034","0.0018"
"9.6000","0.7964","0.3374","2.1309","0.0031","0.0016"
"9.6600","0.8015","0.3397","2.1452","0.0048","0.0026"
"9.7200","0.8064","0.3436","2.1699","0.0037","0.0020"
"9.7800","0.8117","0.3454","2.1810","0.0043","0.0023"
"9.8400","0.8167","0.3489","2.2035","0.0050","0.0027"
"9.9000","0.8214","0.3516","2.2206","0.0039","0.0021"
"9.9600","0.8267","0.3551","2.2425","0.0039","0.0021"
"10.0200","0.8317","0.3590","2.2673","0.0041","0.0022"
"10.0800","0.8369","0.3613","2.2818","0.0048","0.0026"
"10.1400","0.8418","0.3655","2.3086","0.0047","0.0025"
"10.2000","0.8465","0.3682","2.3251","0.0035","0.0019"
"10.2600","0.8516","0.3731","2.3562","0.0051","0.0027"
"10.3200","0.8565","0.3775","2.3841","0.0049","0.0026"
"10.3800","0.8618","0.3819","2.4116","0.0044","0.0023"
"10.4400","0.8666","0.3888","2.4553","0.0044","0.0024"
"10.5000","0.8715","0.3946","2.4923","0.0048","0.0025"
"10.5600","0.8768","0.4031","2.5456","0.0046","0.0025"
"10.6200","0.8817","0.4101","2.5896","0.0040","0.0021"
"10.6800","0.8868","0.4181","2.6403","0.0042","0.0022"
"10.7400","0.8915","0.4265","2.6936","0.0050","0.0027"
"10.8000","0.8965","0.4333","2.7362","0.0042","0.0022"
"10.8600","0.9015","0.4432","2.7991","0.0058","0.0031"
"10.9200","0.9066","0.4506","2.8459","0.0042","0.0023"
"10.9800","0.9117","0.4594","2.9012","0.0047","0.0025"
"11.0400","0.9164","0.4683","2.9574","0.0046","0.0025"
"11.1000","0.9217","0.4771","3.0130","0.0051","0.0027"
"11.1600","0.9268","0.4880","3.0821","0.0051","0.0027"
"11.2200","0.9317","0.4964","3.1352","0.0061","0.0032"
"11.2800","0.9368","0.5077","3.2062","0.0056","0.0030"
"11.3400","0.9415","0.5173","3.2671","0.0064","0.0034"
"11.4000","0.9468","0.5284","3.3370","0.0066","0.0035"
"11.4600","0.9516","0.5405","3.4137","0.0062","0.0033"
"11.5200","0.9566","0.5507","3.4776","0.0067","0.0036"
"11.5800","0.9616","0.5642","3.5629","0.0068","0.0036"
"11.6400","0.9664","0.5755","3.6343","0.0074","0.0039"
"11.7000","0.9718","0.5899","3.7256","0.0070","0.0037"
"11.7600","0.9768","0.6027","3.8065","0.0072","0.0038"
"11.8200","0.9817","0.6146","3.8813","0.0071","0.0038"
"11.8800","0.9865","0.6293","3.9741","0.0071","0.0038"
"11.9400","0.9914","0.6413","4.0499","0.0075","0.0040"
"12.0000","0.9965","0.6578","4.1539","0.0071","0.0038"
"12.0600","1.0014","0.6699","4.2306","0.0074","0.0039"
"12.1200","1.0066","0.6858","4.3308","0.0071","0.0038"
"12.1800","1.0114","0.7026","4.4372","0.0080","0.0043"
"12.2400","1.0165","0.7183","4.5363","0.0080","0.0043"
"12.3000","1.0218","0.7372","4.6557","0.0091","0.0049"
"12.3600","1.0267","0.7532","4.7568","0.0083","0.0044"
"12.4200","1.0318","0.7716","4.8732","0.0093","0.0050"
"12.4800","1.0365","0.7902","4.9906","0.0086","0.0046"
"12.5400","1.0416","0.8057","5.0884","0.0090","0.0048"
"12.6000","1.0466","0.8259","5.2155","0.0101","0.0054"
"12.6600","1.0516","0.8424","5.3203","0.0102","0.0054"
"12.7200","1.0567","0.8627","5.4480","0.0108","0.0057"
"12.7800","1.0614","0.8804","5.5598","0.0103","0.0055"
"12.8400","1.0667","0.9001","5.6844","0.0112","0.0060"
"12.9000","1.0717","0.9201","5.8110","0.0108","0.0058"
"12.9600","1.0766","0.9365","5.9142","0.0124","0.0066"
"13.0200","1.0816","0.9577","6.0485","0.0110","0.0059"
"13.0800","1.0863","0.9751","6.1582","0.0117","0.0062"
"13.1400","1.0915","0.9956","6.2872","0.0120","0.0064"
"13.2000","1.0964","1.0158","6.4148","0.0124","0.0066"
"13.2600","1.1015","1.0343","6.5316","0.0123","0.0065"
"13.3200","1.1065","1.0559","6.6686","0.0126","0.0067"
"13.3800","1.1115","1.0736","6.7803","0.0132","0.0070"
"13.4400","1.1168","1.0957","6.9197","0.0133","0.0071"
"13.5000","1.1218","1.1150","7.0414","0.0139","0.0074"
"13.5600","1.1267","1.1322","7.1500","0.0135","0.0072"
"13.6200","1.1316","1.1544","7.2904","0.0138","0.0074"
"13.6800","1.1365","1.1707","7.3934","0.0153","0.0081"
"13.7400","1.1417","1.1946","7.5441","0.0149","0.0080"
"13.8000","1.1465","1.2111","7.6484","0.0151","0.0081"
"13.8600","1.1516","1.2315","7.7772","0.0163","0.0087"
"13.9200","1.1564","1.2523","7.9086","0.0159","0.0085"
"13.9800","1.1616","1.2711","8.0272","0.0160","0.0085"
"14.0400","1.1669","1.2946","8.1757","0.0166","0.0089"
"14.1000","1.1716","1.3104","8.2757","0.0161","0.0086"
"14.1600","1.1767","1.3320","8.4122","0.0170","0.0091"
"14.2200","1.1814","1.3508","8.5309","0.0169","0.0090"
"14.2800","1.1865","1.3701","8.6525","0.0167","0.0089"
"14.3400","1.1915","1.3929","8.7968","0.0174","0.0093"
"14.4000","1.1964","1.4080","8.8917","0.0179","0.0095"
"14.4600","1.2016","1.4199","8.9673","0.0179","0.0096"
"14.5200","1.2064","1.4418","9.1051","0.0180","0.0096"
"14.5800","1.2117","1.4659","9.2576","0.0171","0.0091"
"14.6400","1.2168","1.4894","9.4062","0.0182","0.0097"
"14.7000","1.2217","1.5058","9.5093","0.0178","0.0095"
"14.7600","1.2267","1.5302","9.6635","0.0190","0.0101"
"14.8200","1.2315","1.5459","9.7628","0.0189","0.0101"
"14.8800","1.2367","1.5661","9.8901","0.0189","0.0101"
"14.9400","1.2415","1.5868","10.0211","0.0192","0.0102"
"15.0000","1.2466","1.6057","10.1407","0.0196","0.0105"
"15.0600","1.2516","1.6297","10.2921","0.0204","0.0109"
"15.1200","1.2565","1.6452","10.3897","0.0203","0.0108"
"15.1800","1.2617","1.6695","10.5433","0.0212","0.0113"
"15.2400","1.2667","1.6874","10.6562","0.0202","0.0107"
"15.3000","1.2717","1.7071","10.7810","0.0209","0.0111"
"15.3600","1.2765","1.7291","10.9196","0.0217","0.0116"
"15.4200","1.2814","1.7464","11.0291","0.0217","0.0115"
"15.4800","1.2866","1.7710","11.1846","0.0213","0.0114"
"15.5400","1.2914","1.7872","11.2865","0.0213","0.0114"
"15.6000","1.2966","1.8095","11.4272","0.0221","0.0118"
"15.6600","1.3014","1.8296","11.5546","0.0226","0.0120"
"15.7200","1.3066","1.8489","11.6763","0.0219","0.0117"
"15.7800","1.3117","1.8728","11.8270","0.0222","0.0118"
"15.8400","1.3166","1.8889","11.9291","0.0226","0.0120"
"15.9000","1.3218","1.9117","12.0732","0.0225","0.0120"
"15.9600","1.3265","1.9307","12.1926","0.0229","0.0122"
"16.0200","1.3316","1.9501","12.3155","0.0244","0.0130"
"16.0800","1.3365","1.9722","12.4550","0.0232","0.0124"
"16.1400","1.3415","1.9891","12.5614","0.0248","0.0132"
"16.2000","1.3467","2.0129","12.7120","0.0244","0.0130"
"16.2600","1.3514","2.0291","12.8144","0.0250","0.0133"
"16.3200","1.3567","2.0511","12.9533","0.0250","0.0133"
"16.3800","1.3617","2.0723","13.0874","0.0251","0.0134"
"16.4400","1.3666","2.0880","13.1862","0.0256","0.0137"
"16.5000","1.3716","2.1117","13.3360","0.0252","0.0134"
"16.5600","1.3763","2.1276","13.4362","0.0255","0.0136"
"16.6200","1.3815","2.1497","13.5761","0.0264","0.0141"
"16.6800","1.3863","2.1688","13.6968","0.0263","0.0140"
"16.7400","1.3915","2.1873","13.8137","0.0273","0.0145"
"16.8000","1.3966","2.2109","13.9623","0.0266","0.0142"
"16.8600","1.4015","2.2264","14.0604","0.0267","0.0142"
"16.9200","1.4069","2.2505","14.2125","0.0277","0.0148"
"16.9800","1.4117","2.2674","14.3192","0.0277","0.0147"
"17.0400","1.4167","2.2858","14.4352","0.0279","0.0149"
"17.1000","1.4216","2.3084","14.5782","0.0287","0.0153"
"17.1600","1.4266","2.3243","14.6787","0.0286","0.0153"
"17.2200","1.4318","2.3486","14.8318","0.0285","0.0152"
"17.2800","1.4365","2.3633","14.9247","0.0292","0.0156"
"17.3400","1.4417","2.3859","15.0675","0.0303","0.0162"
"17.4000","1.4465","2.4050","15.1882","0.0296","0.0158"
"17.4600","1.4516","2.4232","15.3031","0.0300","0.0160"
"17.5200","1.4568","2.4478","15.4587","0.0305","0.0162"
"17.5800","1.4616","2.4611","15.5425","0.0311","0.0166"
"17.6400","1.4667","2.4848","15.6921","0.0310","0.0165"
"17.7000","1.4713","2.5014","15.7971","0.0311","0.0166"
"17.7600","1.4766","2.5231","15.9339","0.0314","0.0168"
"17.8200","1.4816","2.5440","16.0659","0.0315","0.0168"
"17.8800","1.4865","2.5592","16.1618","0.0313","0.0167"
"17.9400","1.4916","2.5845","16.3218","0.0316","0.0168"
"18.0000","1.4964","2.5995","16.4166","0.0318","0.0169"
"18.0600","1.5019","2.6233","16.5667","0.0326","0.0174"
"18.1200","1.5067","2.6424","16.6875","0.0331","0.0177"
"18.1800","1.5116","2.6584","16.7884","0.0337","0.0179"
"18.2400","1.5167","2.6830","16.9441","0.0336","0.0179"
"18.3000","1.5214","2.6977","17.0366","0.0345","0.0184"
"18.3600","1.5269","2.7224","17.1930","0.0342","0.0182"
"18.4200","1.5315","2.7379","17.2904","0.0343","0.0183"
"18.4800","1.5366","2.7575","17.4144","0.0354","0.0189"
"18.5400","1.5415","2.7801","17.5570","0.0354","0.0189"
"18.6000","1.5465","2.7968","17.6623","0.0357","0.0190"
"18.6600","1.5519","2.8213","17.8171","0.0360","0.0192"
"18.7200","1.5566","2.8354","17.9063","0.0355","0.0189"
"18.7800","1.5617","2.8560","18.0365","0.0364","0.0194"
"18.8400","1.5664","2.8764","18.1650","0.0364","0.0194"
"18.9000","1.5716","2.8943","18.2783","0.0359","0.0191"
"18.9600","1.5766","2.9172","18.4231","0.0369","0.0197"
"19.0200","1.5813","2.9304","18.5062","0.0372","0.0198"
"19.0800","1.5866","2.9562","18.6691","0.0374","0.0199"
"19.1400","1.5914","2.9722","18.7702","0.0377","0.0201"
"19.2000","1.5968","2.9929","18.9008","0.0378","0.0202"
"19.2600","1.6018","3.0148","19.0392","0.0378","0.0202"
"19.3200","1.6065","3.0273","19.1184","0.0382","0.0204"
"19.3800","1.6117","3.0538","19.2854","0.0390","0.0208"
"19.4400","1.6165","3.0683","19.3771","0.0391","0.0209"
"19.5000","1.6218","3.0894","19.5106","0.0397","0.0212"
"19.5600","1.6264","3.1085","19.6309","0.0405","0.0216"
"19.6200","1.6314","3.1245","19.7323","0.0400","0.0213"
"19.6800","1.6365","3.1495","19.8899","0.0409","0.0218"
"19.7400","1.6414","3.1632","19.9763","0.0403","0.0215"
"19.8000","1.6468","3.1866","20.1246","0.0409","0.0218"
"19.8600","1.6516","3.2032","20.2290","0.0404","0.0216"
"19.9200","1.6566","3.2206","20.3392","0.0413","0.0220"
"19.9800","1.6616","3.2442","20.4878","0.0414","0.0221"
"20.0400","1.6665","3.2578","20.5740","0.0420","0.0224"
"20.1000","1.6717","3.2808","20.7190","0.0416","0.0222"
"20.1600","1.6762","3.2959","20.8145","0.0420","0.0224"
"20.2200","1.6815","3.3174","20.9501","0.0422","0.0225"
"20.2800","1.6865","3.3390","21.0866","0.0422","0.0225"
"20.3400","1.6916","3.3549","21.1874","0.0426","0.0227"
"20.4000","1.6969","3.3781","21.3334","0.0434","0.0231"
"20.4600","1.7016","3.3930","21.4278","0.0427","0.0227"
"20.5200","1.7067","3.4137","21.5584","0.0427","0.0228"
"20.5800","1.7115","3.4341","21.6870","0.0429","0.0229"
"20.6400","1.7169","3.4531","21.8071","0.0443","0.0236"
"20.7000","1.7217","3.4722","21.9278","0.0442","0.0236"
"20.7600","1.7263","3.4870","22.0211","0.0438","0.0234"
"20.8200","1.7317","3.5137","22.1899","0.0435","0.0232"
"20.8800","1.7365","3.5288","22.2853","0.0443","0.0236"
"20.9400","1.7418","3.5481","22.4073","0.0449","0.0239"
"21.0000","1.7468","3.5710","22.5521","0.0451","0.0241"
"21.0600","1.7516","3.5839","22.6330","0.0457","0.0244"
"21.1200","1.7567","3.6096","22.7957","0.0460","0.0245"
"21.1800","1.7614","3.6239","22.8858","0.0457","0.0243"
"21.2400","1.7667","3.6470","23.0318","0.0461","0.0246"
"21.3000","1.7713","3.6641","23.1396","0.0467","0.0249"
"21.3600","1.7764","3.6831","23.2600","0.0457","0.0243"
"21.4200","1.7816","3.7084","23.4194","0.0464","0.0247"
"21.4800","1.7865","3.7222","23.5065","0.0459","0.0245"
"21.5400","1.7918","3.7469","23.6625","0.0464","0.0247"
"21.6000","1.7966","3.7647","23.7751","0.0465","0.0248"
"21.6600","1.8016","3.7824","23.8868","0.0468","0.0249"
"21.7200","1.8066","3.8071","24.0428","0.0468","0.0250"
"21.7800","1.8116","3.8227","24.1414","0.0472","0.0251"
"21.8400","1.8168","3.8464","24.2911","0.0472","0.0252"
"21.9000","1.8214","3.8620","24.3898","0.0474","0.0253"
"21.9600","1.8266","3.8839","24.5278","0.0479","0.0256"
"22.0200","1.8315","3.9069","24.6733","0.0490","0.0261"
"22.0800","1.8367","3.9239","24.7808","0.0475","0.0253"
"22.1400","1.8418","3.9476","24.9302","0.0473","0.0252"
"22.2000","1.8465","3.9626","25.0246","0.0483","0.0257"
"22.2600","1.8516","3.9859","25.1719","0.0489","0.0261"
"22.3200","1.8564","4.0058","25.2976","0.0495","0.0264"
"22.3800","1.8616","4.0245","25.4160","0.0495","0.0264"
"22.4400","1.8665","4.0483","25.5661","0.0492","0.0263"
"22.5000","1.8714","4.0643","25.6672","0.0495","0.0264"
"22.5600","1.8766","4.0904","25.8317","0.0497","0.0265"
"22.6200","1.8814","4.1076","25.9407","0.0496","0.0265"
"22.6800","1.8867","4.1300","26.0824","0.0500","0.0267"
"22.7400","1.8916","4.1515","26.2179","0.0503","0.0268"
"22.8000","1.8965","4.1669","26.3152","0.0509","0.0272"
"22.8600","1.9017","4.1940","26.4863","0.0515","0.0274"
"22.9200","1.9065","4.2099","26.5864","0.0513","0.0273"
"22.9800","1.9117","4.2328","26.7314","0.0523","0.0279"
"23.0400","1.9165","4.2533","26.8609","0.0519","0.0277"
"23.1000","1.9216","4.2713","26.9743","0.0516","0.0275"
"23.1600","1.9267","4.2979","27.1427","0.0527","0.0281"
"23.2200","1.9314","4.3113","27.2271","0.0528","0.0281"
"23.2800","1.9367","4.3389","27.4012","0.0533","0.0284"
"23.3400","1.9415","4.3566","27.5134","0.0534","0.0285"
"23.4000","1.9466","4.3759","27.6347","0.0537","0.0286"
"23.4600","1.9516","4.4016","27.7976","0.0538","0.0287"
"23.5200","1.9565","4.4156","27.8860","0.0544","0.0290"
"23.5800","1.9616","4.4430","28.0586","0.0544","0.0290"
"23.6400","1.9663","4.4585","28.1564","0.0545","0.0290"
"23.7000","1.9716","4.4837","28.3155","0.0543","0.0290"
"23.7600","1.9765","4.5053","28.4523","0.0551","0.0294"
"23.8200","1.9816","4.5232","28.5651","0.0539","0.0287"
"23.8800","1.9867","4.5501","28.7352","0.0544","0.0290"
"23.9400","1.9916","4.5659","28.8350","0.0547","0.0292"
"24.0000","1.9969","4.5905","28.9901","0.0546","0.0291"
"24.0600","2.0017","4.6103","29.1155","0.0556","0.0296"
"24.1200","2.0068","4.6291","29.2338","0.0556","0.0297"
"24.1800","2.0117","4.6536","29.3886","0.0563","0.0300"
"24.2400","2.0164","4.6688","29.4848","0.0560","0.0299"
"24.3000","2.0217","4.6987","29.6735","0.0564","0.0301"
"24.3600","2.0266","4.7153","29.7782","0.0560","0.0299"
"24.4200","2.0318","4.7375","29.9186","0.0564","0.0301"
"24.4800","2.0366","4.7603","30.0628","0.0561","0.0299"
"24.5400","2.0416","4.7763","30.1638","0.0580","0.0309"
"24.6000","2.0467","4.8053","30.3468","0.0580","0.0309"
"24.6600","2.0515","4.8206","30.4434","0.0581","0.0310"
"24.7200","2.0568","4.8449","30.5970","0.0570","0.0304"
"24.7800","2.0613","4.8636","30.7152","0.0577","0.0308"
"24.8400","2.0664","4.8852","30.8511","0.0593","0.0316"
"24.9000","2.0715","4.9128","31.0258","0.0587","0.0313"
"24.9600","2.0766","4.9300","31.1345","0.0592","0.0315"
"25.0200","2.0818","4.9541","31.2866","0.0592","0.0316"
"25.0800","2.0865","4.9723","31.4016","0.0605","0.0322"
"25.1400","2.0917","4.9954","31.5472","0.0597","0.0318"
"25.2000","2.0967","5.0194","31.6986","0.0605","0.0323"
"25.2600","2.1017","5.0360","31.8038","0.0593","0.0316"
"25.3200","2.1068","5.0619","31.9671","0.0604","0.0322"
"25.3800","2.1113","5.0768","32.0611","0.0601","0.0320"
"25.4400","2.1165","5.1041","32.2338","0.0615","0.0328"
"25.5000","2.1216","5.1271","32.3793","0.0614","0.0328"
"25.5600","2.1268","5.1463","32.5003","0.0616","0.0329"
"25.6200","2.1318","5.1700","32.6501","0.0612","0.0327"
"25.6800","2.1364","5.1860","32.7509","0.0614","0.0327"
"25.7400","2.1416","5.2146","32.9314","0.0616","0.0328"
"25.8000","2.1465","5.2332","33.0489","0.0620","0.0330"
"25.8600","2.1516","5.2543","33.1821","0.0620","0.0330"
"25.9200","2.1564","5.2770","33.3255","0.0616","0.0328"
"25.9800","2.1613","5.2961","33.4463","0.0622","0.0332"
"26.0400","2.1664","5.3243","33.6242","0.0621","0.0331"
"26.1000","2.1716","5.3440","33.7489","0.0630","0.0336"
"26.1600","2.1768","5.3657","33.8862","0.0632","0.0337"
"26.2200","2.1815","5.3864","34.0167","0.0625","0.0333"
"26.2800","2.1866","5.4069","34.1462","0.0641","0.0341"
"26.3400","2.1917","5.4344","34.3200","0.0655","0.0349"
"26.4000","2.1967","5.4502","34.4196","0.0645","0.0344"
"26.4600","2.2018","5.4757","34.5805","0.0654","0.0349"
"26.5200","2.2063","5.4933","34.6916","0.0659","0.0351"
"26.5800","2.2115","5.5181","34.8482","0.0661","0.0352"
"26.6400","2.2166","5.5442","35.0134","0.0664","0.0354"
"26.7000","2.2216","5.5594","35.1089","0.0660","0.0352"
"26.7600","2.2267","5.5880","35.2898","0.0667","0.0356"
"26.8200","2.2315","5.6050","35.3972","0.0667","0.0356"
"26.8800","2.2366","5.6293","35.5509","0.0670","0.0357"
"26.9400","2.2416","5.6539","35.7059","0.0674","0.0359"
"27.0000","2.2466","5.6700","35.8075","0.0674","0.0360"
"27.0600","2.2515","5.6967","35.9764","0.0681","0.0363"
"27.1200","2.2562","5.7131","36.0800","0.0670","0.0357"
"27.1800","2.2616","5.7454","36.2835","0.0678","0.0361"
"27.2400","2.2666","5.7631","36.3954","0.0676","0.0360"
"27.3000","2.2717","5.7830","36.5214","0.0678","0.0361"
"27.3600","2.2767","5.8103","36.6935","0.0677","0.0361"
"27.4200","2.2816","5.8272","36.8006","0.0675","0.0360"
"27.4800","2.2868","5.8555","36.9791","0.0686","0.0366"
"27.5400","2.2917","5.8740","37.0958","0.0688","0.0367"
"27.6000","2.2967","5.8957","37.2329","0.0688","0.0367"
"27.6600","2.3014","5.9196","37.3836","0.0686","0.0365"
"27.7200","2.3064","5.9395","37.5095","0.0687","0.0366"
"27.7800","2.3117","5.9711","37.7089","0.0690","0.0368"
"27.8400","2.3167","5.9859","37.8029","0.0707","0.0377"
"27.9000","2.3217","6.0097","37.9527","0.0706","0.0376"
"27.9600","2.3265","6.0332","38.1012","0.0702","0.0374"
"28.0200","2.3316","6.0541","38.2335","0.0709","0.0378"
"28.0800","2.3367","6.0845","38.4254","0.0711","0.0379"
"28.1400","2.3416","6.0998","38.5220","0.0715","0.0381"
"28.2000","2.3466","6.1275","38.6971","0.0714","0.0380"
"28.2600","2.3512","6.1448","38.8060","0.0717","0.0382"
"28.3200","2.3565","6.1735","38.9874","0.0719","0.0383"
"28.3800","2.3616","6.1990","39.1486","0.0716","0.0382"
"28.4400","2.3667","6.2165","39.2590","0.0722","0.0385"
"28.5000","2.3718","6.2433","39.4282","0.0725","0.0387"
"28.5600","2.3764","6.2599","39.5333","0.0726","0.0387"
"28.6200","2.3818","6.2890","39.7168","0.0730","0.0389"
"28.6800","2.3867","6.3115","39.8591","0.0729","0.0388"
"28.7400","2.3917","6.3292","39.9709","0.0730","0.0389"
"28.8000","2.3966","6.3575","40.1496","0.0726","0.0387"
"28.8600","2.4013","6.3735","40.2505","0.0733","0.0391"
"28.9200","2.4066","6.4052","40.4504","0.0738","0.0393"
"28.9800","2.4116","6.4259","40.5811","0.0742","0.0396"
"29.0400","2.4167","6.4467","40.7125","0.0737","0.0393"
"29.1000","2.4216","6.4729","40.8783","0.0746","0.0397"
"29.1600","2.4265","6.4908","40.9911","0.0751","0.0401"
"29.2200","2.4317","6.5210","41.1818","0.0745","0.0397"
"29.2800","2.4366","6.5390","41.2959","0.0744","0.0397"
"29.3400","2.4415","6.5606","41.4320","0.0762","0.0406"
"29.4000","2.4462","6.5837","41.5782","0.0750","0.0400"
"29.4600","2.4513","6.6069","41.7243","0.0766","0.0409"
"29.5200","2.4566","6.6381","41.9217","0.0764","0.0407"
"29.5800","2.4616","6.6543","42.0235","0.0762","0.0406"
"29.6400","2.4667","6.6806","42.1898","0.0774","0.0413"
"29.7000","2.4714","6.7018","42.3237","0.0759","0.0404"
"29.7600","2.4767","6.7272","42.4844","0.0779","0.0416"
"29.8200","2.4818","6.7546","42.6573","0.0780","0.0416"
"29.8800","2.4866","6.7685","42.7452","0.0778","0.0415"
"29.9400","2.4917","6.8002","42.9451","0.0780","0.0416"
"30.0000","2.4963","6.8159","43.0446","0.0784","0.0418"
"30.0600","2.5015","6.8438","43.2204","0.0785","0.0418"
"30.1200","2.5066","6.8719","43.3979","0.0790","0.0421"
"30.1800","2.5116","6.8868","43.4919","0.0792","0.0422"
"30.2400","2.5167","6.9167","43.6812","0.0785","0.0418"
"30.3000","2.5214","6.9338","43.7891","0.0794","0.0423"
"30.3600","2.5267","6.9638","43.9781","0.0798","0.0425"
"30.4200","2.5316","6.9848","44.1109","0.0790","0.0421"
"30.4800","2.5365","7.0031","44.2266","0.0800","0.0427"
"30.5400","2.5415","7.0332","44.4165","0.0801","0.0427"
"30.6000","2.5462","7.0476","44.5073","0.0801","0.0427"
"30.6600","2.5516","7.0832","44.7324","0.0800","0.0427"
"30.7200","2.5566","7.1020","44.8510","0.0804","0.0429"
"30.7800","2.5616","7.1226","44.9812","0.0816","0.0435"
"30.8400","2.5665","7.1491","45.1486","0.0811","0.0432"
"30.9000","2.5716","7.1697","45.2784","0.0812","0.0433"
"30.9600","2.5769","7.2005","45.4732","0.0822","0.0438"
"31.0200","2.5817","7.2163","45.5727","0.0823","0.0439"
"31.0800","2.5868","7.2419","45.7349","0.0818","0.0436"
"31.1400","2.5915","7.2655","45.8834","0.0822","0.0438"
"31.2000","2.5966","7.2873","46.0211","0.0830","0.0443"
"31.2600","2.6018","7.3188","46.2200","0.0829","0.0442"
"31.3200","2.6065","7.3323","46.3053","0.0836","0.0445"
"31.3800","2.6117","7.3625","46.4962","0.0832","0.0443"
"31.4400","2.6165","7.3844","46.6347","0.0834","0.0444"
"31.5000","2.6217","7.4079","46.7831","0.0839","0.0447"
"31.5600","2.6267","7.4349","46.9533","0.0838","0.0447"
"31.6200","2.6316","7.4508","47.0541","0.0842","0.0449"
"31.6800","2.6367","7.4821","47.2515","0.0843","0.0450"
"31.7400","2.6412","7.4967","47.3439","0.0848","0.0452"
"31.8000","2.6466","7.5295","47.5508","0.0847","0.0452"
"31.8600","2.6516","7.5539","47.7050","0.0862","0.0460"
"31.9200","2.6565","7.5704","47.8089","0.0853","0.0455"
"31.9800","2.6616","7.6022","48.0101","0.0862","0.0460"
"32.0400","2.6664","7.6192","48.1175","0.0858","0.0457"
"32.1000","2.6719","7.6522","48.3257","0.0859","0.0458"
"32.1600","2.6768","7.6721","48.4518","0.0862","0.0460"
"32.2200","2.6817","7.6900","48.5647","0.0868","0.0463"
"32.2800","2.6866","7.7206","48.7577","0.0870","0.0464"
"32.3400","2.6913","7.7358","48.8540","0.0880","0.0469"
"32.4000","2.6967","7.7724","49.0847","0.0875","0.0466"
"32.4600","2.7016","7.7888","49.1882","0.0874","0.0466"
"32.5200","2.7066","7.8133","49.3429","0.0883","0.0471"
"32.5800","2.7116","7.8400","49.5115","0.0889","0.0474"
"32.6400","2.7166","7.8597","49.6364","0.0891","0.0475"
"32.7000","2.7218","7.8913","49.8359","0.0893","0.0476"
"32.7600","2.7266","7.9062","49.9301","0.0894","0.0477"
"32.8200","2.7316","7.9328","50.0977","0.0891","0.0475"
"32.8800","2.7362","7.9541","50.2325","0.0902","0.0481"
"32.9400","2.7414","7.9819","50.4082","0.0905","0.0483"
"33.0000","2.7466","8.0109","50.5909","0.0903","0.0481"
"33.0600","2.7515","8.0276","50.6968","0.0904","0.0482"
"33.1200","2.7566","8.0573","50.8839","0.0906","0.0483"
"33.1800","2.7614","8.0786","51.0184","0.0900","0.0480"
"33.2400","2.7669","8.1076","51.2016","0.0908","0.0484"
"33.3000","2.7718","8.1301","51.3437","0.0906","0.0483"
"33.3600","2.7765","8.1468","51.4494","0.0911","0.0486"
"33.4200","2.7816","8.1790","51.6529","0.0911","0.0486"
"33.4800","2.7863","8.1947","51.7519","0.0922","0.0492"
"33.5400","2.7917","8.2288","51.9672","0.0919","0.0490"
"33.6000","2.7966","8.2510","52.1074","0.0917","0.0489"
"33.6600","2.8015","8.2694","52.2235","0.0923","0.0492"
"33.7200","2.8066","8.3016","52.4272","0.0922","0.0491"
"33.7800","2.8116","8.3202","52.5445","0.0921","0.0491"
"33.8400","2.8169","8.3497","52.7308","0.0921","0.0491"
"33.9000","2.8215","8.3672","52.8414","0.0920","0.0490"
"33.9600","2.8265","8.3921","52.9984","0.0924","0.0493"
"34.0200","2.8314","8.4207","53.1788","0.0926","0.0494"
"34.0800","2.8363","8.4380","53.2886","0.0935","0.0499"
"34.1400","2.8416","8.4743","53.5173","0.0930","0.0496"
"34.2000","2.8465","8.4911","53.6237","0.0932","0.0497"
"34.2600","2.8516","8.5173","53.7890","0.0931","0.0496"
"34.3200","2.8565","8.5440","53.9579","0.0947","0.0505"
"34.3800","2.8617","8.5675","54.1064","0.0948","0.0505"
"34.4400","2.8669","8.5953","54.2820","0.0944","0.0504"
"34.5000","2.8715","8.6103","54.3764","0.0954","0.0509"
"34.5600","2.8767","8.6411","54.5713","0.0955","0.0509"
"34.6200","2.8815","8.6624","54.7057","0.0954","0.0509"
"34.6800","2.8865","8.6873","54.8628","0.0959","0.0511"
"34.7400","2.8917","8.7182","55.0576","0.0954","0.0509"
"34.8000","2.8966","8.7347","55.1620","0.0957","0.0510"
"34.8600","2.9017","8.7655","55.3567","0.0961","0.0512"
"34.9200","2.9065","8.7855","55.4827","0.0958","0.0511"
"34.9800","2.9118","8.8151","55.6697","0.0966","0.0515"
"35.0400","2.9166","8.8364","55.8045","0.0973","0.0519"
"35.1000","2.9215","8.8570","55.9344","0.0963","0.0514"
"35.1600","2.9265","8.8920","56.1556","0.0966","0.0515"
"35.2200","2.9313","8.9089","56.2624","0.0982","0.0524"
"35.2800","2.9366","8.9448","56.4889","0.0984","0.0525"
"35.3400","2.9415","8.9645","56.6131","0.0980","0.0523"
"35.4000","2.9466","8.9875","56.7585","0.0989","0.0527"
"35.4600","2.9516","9.0185","56.9543","0.0985","0.0525"
"35.5200","2.9566","9.0369","57.0708","0.0983","0.0524"
"35.5800","2.9619","9.0691","57.2738","0.0995","0.0531"
"35.6400","2.9665","9.0833","57.3638","0.0999","0.0533"
"35.7000","2.9716","9.1116","57.5420","0.1002","0.0534"
"35.7600","2.9765","9.1381","57.7100","0.0994","0.0530"
"35.8200","2.9815","9.1593","57.8434","0.0996","0.0531"
"35.8800","2.9868","9.1933","58.0583","0.1013","0.0540"
"35.9400","2.9914","9.2052","58.1332","0.1004","0.0535"
"36.0000","2.9966","9.2384","58.3428","0.1012","0.0539"
"36.0600","3.0015","9.2614","58.4880","0.1026","0.0547"
"36.1200","3.0068","9.2883","58.6580","0.1019","0.0543"
"36.1800","3.0118","9.3138","58.8190","0.1017","0.0542"
"36.2400","3.0163","9.3270","58.9027","0.1016","0.0542"
"36.3000","3.0216","9.3640","59.1364","0.1019","0.0543"
"36.3600","3.0263","9.3795","59.2343","0.1028","0.0548"
"36.4200","3.0315","9.4122","59.4409","0.1033","0.0551"
"36.4800","3.0365","9.4376","59.6013","0.1034","0.0551"
"36.5400","3.0414","9.4567","59.7217","0.1034","0.0551"
"36.6000","3.0466","9.4904","59.9347","0.1034","0.0551"
"36.6600","3.0515","9.5083","60.0476","0.1035","0.0552"
"36.7200","3.0568","9.5401","60.2484","0.1040","0.0555"
"36.7800","3.0616","9.5603","60.3763","0.1043","0.0556"
"36.8400","3.0666","9.5831","60.5201","0.1043","0.0556"
"36.9000","3.0716","9.6134","60.7111","0.1044","0.0556"
"36.9600","3.0763","9.6291","60.8103","0.1047","0.0558"
"37.0200","3.0818","9.6685","61.0592","0.1050","0.0560"
"37.0800","3.0867","9.6862","61.1709","0.1061","0.0566"
"37.1400","3.0915","9.7052","61.2911","0.1060","0.0565"
"37.2000","3.0965","9.7390","61.5046","0.1061","0.0566"
"37.2600","3.1017","9.7611","61.6440","0.1061","0.0565"
"37.3200","3.1068","9.7889","61.8197","0.1064","0.0567"
"37.3800","3.1114","9.8052","61.9225","0.1067","0.0569"
"37.4400","3.1166","9.8367","62.1216","0.1067","0.0569"
"37.5000","3.1215","9.8610","62.2752","0.1070","0.0570"
"37.5600","3.1263","9.8797","62.3931","0.1079","0.0575"
"37.6200","3.1316","9.9173","62.6307","0.1078","0.0575"
"37.6800","3.1364","9.9326","62.7270","0.1073","0.0572"
"37.7400","3.1416","9.9634","62.9217","0.1079","0.0575"
"37.8000","3.1465","9.9876","63.0743","0.1080","0.0576"
"37.8600","3.1518","10.0144","63.2437","0.1081","0.0576"
"37.9200","3.1568","10.0395","63.4024","0.1080","0.0576"
"37.9800","3.1615","10.0560","63.5063","0.1082","0.0577"
"38.0400","3.1668","10.0902","63.7222","0.1078","0.0575"
"38.1000","3.1714","10.1079","63.8342","0.1090","0.0581"
"38.1600","3.1766","10.1373","64.0197","0.1093","0.0583"
"38.2200","3.1816","10.1645","64.1916","0.1087","0.0580"
"38.2800","3.1866","10.1864","64.3301","0.1092","0.0582"
"38.3400","3.1917","10.2163","64.5187","0.1104","0.0589"
"38.4000","3.1965","10.2371","64.6500","0.1103","0.0588"
"38.4600","3.2020","10.2698","64.8564","0.1103","0.0588"
"38.5200","3.2067","10.2881","64.9720","0.1102","0.0588"
"38.5800","3.2115","10.3091","65.1049","0.1103","0.0588"
"38.6400","3.2166","10.3426","65.3164","0.1108","0.0591"
"38.7000","3.2213","10.3586","65.4176","0.1116","0.0595"
"38.7600","3.2267","10.3968","65.6586","0.1116","0.0595"
"38.8200","3.2315","10.4151","65.7746","0.1121","0.0598"
"38.8800","3.2366","10.4416","65.9418","0.1114","0.0594"
"38.9400","3.2416","10.4712","66.1284","0.1115","0.0594"
"39.0000","3.2467","10.4926","66.2639","0.1114","0.0594"
"39.0600","3.2519","10.5238","66.4609","0.1115","0.0594"
"39.1200","3.2565","10.5398","66.5615","0.1115","0.0595"
"39.1800","3.2616","10.5692","66.7474","0.1128","0.0602"
"39.2400","3.2665","10.5950","66.9102","0.1134","0.0604"
"39.3000","3.2715","10.6185","67.0586","0.1128","0.0601"
"39.3600","3.2768","10.6522","67.2716","0.1123","0.0599"
"39.4200","3.2815","10.6679","67.3710","0.1137","0.0606"
"39.4800","3.2866","10.6996","67.5713","0.1143","0.0609"
"39.5400","3.2916","10.7246","67.7291","0.1139","0.0607"
"39.6000","3.2968","10.7521","67.9025","0.1139","0.0607"
"39.6600","3.3017","10.7763","68.0553","0.1143","0.0609"
"39.7200","3.3064","10.7944","68.1695","0.1146","0.0611"
"39.7800","3.3116","10.8292","68.3897","0.1153","0.0615"
"39.8400","3.3163","10.8478","68.5067","0.1155","0.0616"
"39.9000","3.3216","10.8796","68.7076","0.1154","0.0615"
"39.9600","3.3264","10.9031","68.8561","0.1157","0.0617"
"40.0200","3.3314","10.9273","69.0088","0.1157","0.0617"
"40.0800","3.3366","10.9601","69.2158","0.1162","0.0620"
"40.1400","3.3416","10.9803","69.3438","0.1154","0.0615"
"40.2000","3.3468","11.0107","69.5356","0.1168","0.0623"
"40.2600","3.3516","11.0311","69.6643","0.1159","0.0618"
"40.3200","3.3566","11.0566","69.8254","0.1162","0.0619"
"40.3800","3.3617","11.0883","70.0260","0.1166","0.0622"
"40.4400","3.3665","11.1050","70.1310","0.1171","0.0624"
"40.5000","3.3717","11.1391","70.3464","0.1169","0.0623"
"40.5600","3.3764","11.1600","70.4786","0.1178","0.0628"
"40.6200","3.3816","11.1877","70.6533","0.1174","0.0626"
"40.6800","3.3866","11.2178","70.8435","0.1179","0.0628"
"40.7400","3.3917","11.2420","70.9967","0.1189","0.0634"
"40.8000","3.3968","11.2698","71.1718","0.1180","0.0629"
"40.8600","3.4013","11.2852","71.2690","0.1183","0.0631"
"40.9200","3.4066","11.3207","71.4937","0.1182","0.0630"
"40.9800","3.4115","11.3445","71.6436","0.1195","0.0637"
"41.0400","3.4164","11.3685","71.7954","0.1196","0.0637"
"41.1000","3.4215","11.4039","72.0191","0.1200","0.0640"
"41.1600","3.4263","11.4231","72.1403","0.1207","0.0643"
"41.2200","3.4316","11.4580","72.3604","0.1206","0.0643"
"41.2800","3.4366","11.4813","72.5074","0.1206","0.0643"
"41.3400","3.4419","11.5090","72.6829","0.1216","0.0648"
"41.4000","3.4467","11.5321","72.8288","0.1218","0.0649"
"41.4600","3.4515","11.5518","72.9531","0.1219","0.0650"
"41.5200","3.4568","11.5897","73.1921","0.1217","0.0649"
"41.5800","3.4615","11.6060","73.2953","0.1222","0.0651"
"41.6400","3.4666","11.6349","73.4775","0.1224","0.0653"
"41.7000","3.4714","11.6610","73.6427","0.1218","0.0649"
"41.7600","3.4766","11.6879","73.8124","0.1227","0.0654"
"41.8200","3.4817","11.7179","74.0018","0.1227","0.0654"
"41.8800","3.4866","11.7395","74.1383","0.1229","0.0655"
"41.9400","3.4918","11.7710","74.3371","0.1234","0.0658"
"42.0000","3.4965","11.7895","74.4539","0.1227","0.0654"
"42.0600","3.5015","11.8162","74.6225","0.1230","0.0656"
"42.1200","3.5065","11.8471","74.8177","0.1248","0.0665"
"42.1800","3.5114","11.8665","74.9401","0.1237","0.0659"
"42.2400","3.5165","11.9001","75.1522","0.1237","0.0659"
"42.3000","3.5213","11.9197","75.2763","0.1238","0.0660"
"42.3600","3.5266","11.9539","75.4924","0.1247","0.0665"
"42.4200","3.5317","11.9797","75.6555","0.1242","0.0662"
"42.4800","3.5367","12.0018","75.7950","0.1249","0.0666"
"42.5400","3.5418","12.0330","75.9920","0.1238","0.0660"
"42.6000","3.5465","12.0486","76.0902","0.1257","0.0670"
"42.6600","3.5517","12.0834","76.3103","0.1258","0.0671"
"42.7200","3.5566","12.1074","76.4614","0.1258","0.0671"
"42.7800","3.5615","12.1317","76.6151","0.1271","0.0678"
"42.8400","3.5665","12.1633","76.8144","0.1270","0.0677"
"42.9000","3.5715","12.1859","76.9572","0.1274","0.0679"
"42.9600","3.5767","12.2181","77.1609","0.1274","0.0679"
"43.0200","3.5816","12.2415","77.3083","0.1283","0.0684"
"43.0800","3.5867","12.2675","77.4728","0.1282","0.0683"
"43.1400","3.5916","12.2935","77.6370","0.1287","0.0686"
"43.2000","3.5964","12.3148","77.7713","0.1293","0.0689"
"43.2600","3.6016","12.3482","77.9823","0.1295","0.0691"
"43.3200","3.6064","12.3691","78.1145","0.1297","0.0691"
"43.3800","3.6115","12.3986","78.3009","0.1299","0.0692"
"43.4400","3.6163","12.4236","78.4583","0.1294","0.0690"
"43.5000","3.6215","12.4537","78.6484","0.1300","0.0693"
"43.5600","3.6267","12.4843","78.8418","0.1312","0.0699"
"43.6200","3.6316","12.5043","78.9682","0.1306","0.0696"
"43.6800","3.6368","12.5350","79.1623","0.1295","0.0690"
"43.7400","3.6415","12.5544","79.2848","0.1304","0.0695"
"43.8000","3.6466","12.5843","79.4736","0.1304","0.0695"
"43.8600","3.6517","12.6145","79.6642","0.1300","0.0693"
"43.9200","3.6565","12.6331","79.7814","0.1316","0.0701"
"43.9800","3.6616","12.6676","79.9996","0.1308","0.0697"
"44.0400","3.6663","12.6867","80.1202","0.1317","0.0702"
"44.1000","3.6717","12.7232","80.3506","0.1322","0.0705"
"44.1600","3.6767","12.7500","80.5200","0.1320","0.0704"
"44.2200","3.6817","12.7704","80.6490","0.1326","0.0707"
"44.2800","3.6867","12.8015","80.8451","0.1325","0.0706"
"44.3400","3.6914","12.8193","80.9574","0.1321","0.0704"
"44.4000","3.6966","12.8531","81.1708","0.1335","0.0712"
"44.4600","3.7014","12.8772","81.3229","0.1331","0.0710"
"44.5200","3.7064","12.9013","81.4750","0.1348","0.0719"
"44.5800","3.7115","12.9356","81.6917","0.1347","0.0718"
"44.6400","3.7165","12.9576","81.8307","0.1349","0.0719"
"44.7000","3.7217","12.9918","82.0469","0.1344","0.0716"
"44.7600","3.7265","13.0122","82.1757","0.1352","0.0721"
"44.8200","3.7318","13.0441","82.3769","0.1349","0.0719"
"44.8800","3.7367","13.0697","82.5388","0.1354","0.0722"
"44.9400","3.7416","13.0906","82.6706","0.1351","0.0720"
"45.0000","3.7468","13.1265","82.8978","0.1358","0.0724"
"45.0600","3.7515","13.1430","83.0015","0.1356","0.0723"
"45.1200","3.7566","13.1771","83.2172","0.1365","0.0728"
"45.1800","3.7615","13.2024","83.3771","0.1370","0.0731"
"45.2400","3.7667","13.2314","83.5600","0.1371","0.0731"
"45.3000","3.7718","13.2616","83.7509","0.1385","0.0738"
"45.3600","3.7766","13.2799","83.8663","0.1376","0.0733"
"45.4200","3.7819","13.3165","84.0975","0.1376","0.0734"
"45.4800","3.7866","13.3341","84.2086","0.1381","0.0736"
"45.5400","3.7917","13.3637","84.3958","0.1386","0.0739"
"45.6000","3.7966","13.3923","84.5759","0.1385","0.0738"
"45.6600","3.8014","13.4133","84.7086","0.1390","0.0741"
"45.7200","3.8065","13.4466","84.9191","0.1401","0.0747"
"45.7800","3.8113","13.4695","85.0636","0.1402","0.0748"
"45.8400","3.8166","13.5045","85.2848","0.1403","0.0748"
"45.9000","3.8216","13.5291","85.4399","0.1401","0.0747"
"45.9600","3.8267","13.5565","85.6134","0.1400","0.0747"
"46.0200","3.8319","13.5883","85.8138","0.1406","0.0750"
"46.0800","3.8364","13.6019","85.8996","0.1406","0.0750"
"46.1400","3.8418","13.6417","86.1512","0.1409","0.0751"
"46.2000","3.8467","13.6641","86.2926","0.1411","0.0752"
"46.2600","3.8515","13.6865","86.4339","0.1416","0.0755"
"46.3200","3.8565","13.7190","86.6391","0.1418","0.0756"
"46.3800","3.8614","13.7421","86.7854","0.1419","0.0757"
"46.4400","3.8667","13.7788","87.0172","0.1413","0.0753"
"46.5000","3.8716","13.7998","87.1495","0.1429","0.0762"
"46.5600","3.8769","13.8315","87.3496","0.1427","0.0761"
"46.6200","3.8816","13.8522","87.4803","0.1437","0.0766"
"46.6800","3.8865","13.8746","87.6222","0.1441","0.0768"
"46.7400","3.8917","13.9120","87.8581","0.1447","0.0772"
"46.8000","3.8964","13.9293","87.9672","0.1444","0.0770"
"46.8600","3.9015","13.9615","88.1711","0.1453","0.0775"
"46.9200","3.9063","13.9863","88.3275","0.1456","0.0776"
"46.9800","3.9115","14.0182","88.5287","0.1450","0.0773"
"47.0400","3.9167","14.0493","88.7254","0.1461","0.0779"
"47.1000","3.9216","14.0694","88.8519","0.1459","0.0778"
"47.1600","3.9268","14.1027","89.0628","0.1466","0.0781"
"47.2200","3.9314","14.1181","89.1597","0.1457","0.0777"
"47.2800","3.9367","14.1539","89.3860","0.1467","0.0782"
"47.3400","3.9418","14.1832","89.5706","0.1467","0.0782"
"47.4000","3.9464","14.1975","89.6615","0.1470","0.0784"
"47.4600","3.9515","14.2338","89.8903","0.1472","0.0785"
"47.5200","3.9564","14.2557","90.0287","0.1470","0.0784"
"47.5800","3.9618","14.2928","90.2633","0.1473","0.0785"
"47.6400","3.9667","14.3138","90.3960","0.1474","0.0786"
"47.7000","3.9716","14.3367","90.5406","0.1488","0.0793"
"47.7600","3.9767","14.3685","90.7410","0.1494","0.0797"
"47.8200","3.9814","14.3847","90.8433","0.1488","0.0793"
"47.8800","3.9868","14.4227","91.0834","0.1491","0.0795"
"47.9400","3.9915","14.4385","91.1831","0.1492","0.0796"
"48.0000","3.9963","14.4624","91.3340","0.1503","0.0801"
"48.0600","4.0013","14.4943","91.5353","0.1511","0.0806"
"48.1200","4.0064","14.5181","91.6862","0.1498","0.0798"
"48.1800","4.0118","14.5490","91.8812","0.1508","0.0804"
"48.2400","4.0165","14.5597","91.9487","0.1524","0.0812"
"48.3000","4.0218","14.5753","92.0473","0.1527","0.0814"
"48.3600","4.0268","13.4774","85.1134","0.1600","0.0853"
"48.4180","4.0341","3.5626","22.4988","0.0699","0.0373"