File: composites_properties_derivations/composite_tube_tests/comp_tube_6.csv
Specimen label,"6"
Force at Maximum Load,"4.15",kN
Tensile stress at Maximum Load,"32.77",MPa
Epsilon ONE Displacement at Maximum Load,"0.02",mm
Force at Break (Standard),"1.14",kN
Tensile stress at Break (Standard),"8.97",MPa
Epsilon ONE Displacement at Break (Standard),"-0.01",mm
Slope (Chord 0.05 % - 0.2 %),"-----",MPa
Modulus (Automatic Young's),"59169.34",MPa

Specimen label,"6"
Thickness,"",mm
Width,"",mm
Length,"50.29",mm
Rate 1,"5.00",mm/min
Outer diameter,"15.88",mm
Wall thickness,"3.18",mm

Time,Displacement,Force,Tensile stress,Tensile strain (Epsilon ONE Displacement),Epsilon ONE Displacement
(s),(mm),(kN),(MPa),(%),(mm)
"0.0000","0.0000","0.0675","0.5328","-0.0028","-0.0014"
"0.0400","0.0001","0.0680","0.5366","-0.0018","-0.0009"
"0.0800","0.0010","0.0825","0.6512","-0.0021","-0.0011"
"0.1200","0.0031","0.1254","0.9896","-0.0024","-0.0012"
"0.1600","0.0038","0.1377","1.0871","0.0002","0.0001"
"0.2000","0.0054","0.1650","1.3024","-0.0005","-0.0003"
"0.2400","0.0102","0.2373","1.8729","-0.0009","-0.0004"
"0.2800","0.0157","0.2875","2.2693","0.0007","0.0004"
"0.3200","0.0200","0.2953","2.3312","-0.0001","0.0000"
"0.3600","0.0236","0.3076","2.4285","-0.0013","-0.0006"
"0.4000","0.0267","0.3183","2.5128","0.0002","0.0001"
"0.4400","0.0300","0.3276","2.5862","0.0001","0.0001"
"0.4800","0.0335","0.3393","2.6785","0.0014","0.0007"
"0.5200","0.0367","0.3514","2.7741","0.0008","0.0004"
"0.5600","0.0402","0.3647","2.8789","0.0008","0.0004"
"0.6000","0.0435","0.3772","2.9774","-0.0006","-0.0003"
"0.6400","0.0469","0.3912","3.0881","-0.0003","-0.0002"
"0.6800","0.0504","0.4049","3.1965","0.0001","0.0001"
"0.7200","0.0536","0.4181","3.3001","-0.0010","-0.0005"
"0.7600","0.0569","0.4329","3.4177","-0.0011","-0.0005"
"0.8000","0.0602","0.4463","3.5233","-0.0010","-0.0005"
"0.8400","0.0635","0.4595","3.6270","-0.0010","-0.0005"
"0.8800","0.0669","0.4709","3.7173","-0.0013","-0.0006"
"0.9200","0.0701","0.4800","3.7889","-0.0020","-0.0010"
"0.9600","0.0735","0.4887","3.8576","-0.0028","-0.0014"
"1.0000","0.0768","0.4957","3.9134","-0.0014","-0.0007"
"1.0400","0.0801","0.5027","3.9681","-0.0018","-0.0009"
"1.0800","0.0835","0.5030","3.9705","-0.0018","-0.0009"
"1.1200","0.0867","0.5100","4.0258","-0.0020","-0.0010"
"1.1600","0.0901","0.5178","4.0872","-0.0016","-0.0008"
"1.2000","0.0936","0.5242","4.1379","-0.0013","-0.0007"
"1.2400","0.0970","0.5302","4.1858","-0.0021","-0.0010"
"1.2800","0.1004","0.5360","4.2315","-0.0018","-0.0009"
"1.3200","0.1036","0.5415","4.2743","-0.0006","-0.0003"
"1.3600","0.1069","0.5474","4.3214","-0.0015","-0.0007"
"1.4000","0.1103","0.5530","4.3652","-0.0023","-0.0012"
"1.4400","0.1135","0.5582","4.4064","-0.0008","-0.0004"
"1.4800","0.1170","0.5642","4.4541","-0.0008","-0.0004"
"1.5200","0.1204","0.5691","4.4923","-0.0024","-0.0012"
"1.5600","0.1236","0.5742","4.5328","-0.0024","-0.0012"
"1.6000","0.1268","0.5793","4.5734","-0.0016","-0.0008"
"1.6400","0.1300","0.5843","4.6124","-0.0019","-0.0009"
"1.6800","0.1334","0.5902","4.6588","-0.0016","-0.0008"
"1.7200","0.1367","0.5948","4.6953","-0.0023","-0.0012"
"1.7600","0.1401","0.6006","4.7409","-0.0014","-0.0007"
"1.8000","0.1436","0.6060","4.7836","-0.0029","-0.0015"
"1.8400","0.1470","0.6105","4.8196","-0.0021","-0.0011"
"1.8800","0.1503","0.6158","4.8616","-0.0026","-0.0013"
"1.9200","0.1535","0.6204","4.8975","-0.0024","-0.0012"
"1.9600","0.1568","0.6257","4.9390","-0.0021","-0.0011"
"2.0000","0.1601","0.6304","4.9765","-0.0009","-0.0005"
"2.0400","0.1635","0.6357","5.0179","-0.0010","-0.0005"
"2.0800","0.1670","0.6410","5.0603","-0.0006","-0.0003"
"2.1200","0.1701","0.6450","5.0915","-0.0008","-0.0004"
"2.1600","0.1734","0.6506","5.1357","-0.0014","-0.0007"
"2.2000","0.1767","0.6547","5.1686","-0.0019","-0.0010"
"2.2400","0.1799","0.6596","5.2068","-0.0018","-0.0009"
"2.2800","0.1834","0.6650","5.2493","-0.0005","-0.0002"
"2.3200","0.1867","0.6694","5.2843","-0.0006","-0.0003"
"2.3600","0.1902","0.6755","5.3323","-0.0010","-0.0005"
"2.4000","0.1937","0.6792","5.3618","-0.0014","-0.0007"
"2.4400","0.1968","0.6841","5.4004","-0.0011","-0.0005"
"2.4800","0.2003","0.6896","5.4441","-0.0003","-0.0002"
"2.5200","0.2035","0.6933","5.4729","-0.0009","-0.0005"
"2.5600","0.2068","0.6990","5.5184","-0.0020","-0.0010"
"2.6000","0.2102","0.7034","5.5525","-0.0013","-0.0007"
"2.6400","0.2135","0.7085","5.5930","-0.0008","-0.0004"
"2.6800","0.2170","0.7137","5.6339","-0.0004","-0.0002"
"2.7200","0.2201","0.7172","5.6613","-0.0007","-0.0004"
"2.7600","0.2233","0.7231","5.7082","-0.0008","-0.0004"
"2.8000","0.2268","0.7277","5.7444","-0.0024","-0.0012"
"2.8400","0.2299","0.7319","5.7779","-0.0014","-0.0007"
"2.8800","0.2334","0.7382","5.8277","-0.0019","-0.0010"
"2.9200","0.2369","0.7425","5.8611","-0.0010","-0.0005"
"2.9600","0.2402","0.7479","5.9041","0.0007","0.0003"
"3.0000","0.2437","0.7531","5.9448","-0.0001","-0.0001"
"3.0400","0.2468","0.7571","5.9764","-0.0017","-0.0008"
"3.0800","0.2502","0.7631","6.0242","0.0006","0.0003"
"3.1200","0.2535","0.7671","6.0559","-0.0011","-0.0005"
"3.1600","0.2566","0.7726","6.0991","-0.0006","-0.0003"
"3.2000","0.2602","0.7790","6.1491","-0.0001","-0.0001"
"3.2400","0.2635","0.7824","6.1764","-0.0002","-0.0001"
"3.2800","0.2667","0.7885","6.2247","0.0005","0.0002"
"3.3200","0.2700","0.7931","6.2609","-0.0003","-0.0002"
"3.3600","0.2731","0.7978","6.2982","-0.0001","0.0000"
"3.4000","0.2767","0.8054","6.3579","0.0009","0.0005"
"3.4400","0.2801","0.8089","6.3852","0.0007","0.0004"
"3.4800","0.2833","0.8151","6.4341","0.0019","0.0009"
"3.5200","0.2870","0.8208","6.4796","0.0016","0.0008"
"3.5600","0.2902","0.8251","6.5135","0.0009","0.0005"
"3.6000","0.2936","0.8324","6.5709","0.0009","0.0004"
"3.6400","0.2969","0.8367","6.6049","0.0006","0.0003"
"3.6800","0.3001","0.8436","6.6596","0.0020","0.0010"
"3.7200","0.3036","0.8494","6.7053","0.0017","0.0009"
"3.7600","0.3068","0.8545","6.7453","0.0011","0.0006"
"3.8000","0.3103","0.8627","6.8105","0.0013","0.0007"
"3.8400","0.3137","0.8666","6.8406","0.0007","0.0003"
"3.8800","0.3167","0.8728","6.8901","0.0019","0.0010"
"3.9200","0.3202","0.8796","6.9437","0.0018","0.0009"
"3.9600","0.3232","0.8840","6.9787","0.0015","0.0008"
"4.0000","0.3266","0.8924","7.0448","0.0016","0.0008"
"4.0400","0.3301","0.8971","7.0816","0.0016","0.0008"
"4.0800","0.3334","0.9011","7.1135","0.0017","0.0009"
"4.1200","0.3370","0.9055","7.1479","0.0019","0.0010"
"4.1600","0.3402","0.9097","7.1810","0.0025","0.0013"
"4.2000","0.3435","0.9180","7.2467","0.0028","0.0014"
"4.2400","0.3469","0.9231","7.2871","0.0033","0.0016"
"4.2800","0.3499","0.9300","7.3415","0.0038","0.0019"
"4.3200","0.3535","0.9379","7.4040","0.0034","0.0017"
"4.3600","0.3568","0.9427","7.4416","0.0037","0.0018"
"4.4000","0.3602","0.9504","7.5024","0.0036","0.0018"
"4.4400","0.3635","0.9555","7.5428","0.0040","0.0020"
"4.4800","0.3665","0.9611","7.5870","0.0048","0.0024"
"4.5200","0.3700","0.9697","7.6551","0.0040","0.0020"
"4.5600","0.3733","0.9742","7.6906","0.0045","0.0023"
"4.6000","0.3766","0.9819","7.7514","0.0045","0.0023"
"4.6400","0.3803","0.9888","7.8054","0.0038","0.0019"
"4.6800","0.3836","0.9940","7.8471","0.0045","0.0023"
"4.7200","0.3870","1.0020","7.9095","0.0041","0.0021"
"4.7600","0.3903","1.0065","7.9456","0.0047","0.0024"
"4.8000","0.3933","1.0132","7.9983","0.0038","0.0019"
"4.8400","0.3969","1.0210","8.0596","0.0041","0.0020"
"4.8800","0.4001","1.0257","8.0973","0.0035","0.0018"
"4.9200","0.4036","1.0343","8.1645","0.0048","0.0024"
"4.9600","0.4071","1.0395","8.2055","0.0038","0.0019"
"5.0000","0.4102","1.0454","8.2524","0.0041","0.0020"
"5.0400","0.4136","1.0528","8.3107","0.0049","0.0025"
"5.0800","0.4167","1.0577","8.3497","0.0050","0.0025"
"5.1200","0.4200","1.0661","8.4160","0.0051","0.0026"
"5.1600","0.4236","1.0725","8.4660","0.0052","0.0026"
"5.2000","0.4268","1.0783","8.5120","0.0049","0.0024"
"5.2400","0.4304","1.0865","8.5771","0.0065","0.0033"
"5.2800","0.4336","1.0910","8.6127","0.0051","0.0026"
"5.3200","0.4368","1.0991","8.6763","0.0053","0.0027"
"5.3600","0.4403","1.1057","8.7282","0.0055","0.0028"
"5.4000","0.4434","1.1113","8.7727","0.0042","0.0021"
"5.4400","0.4469","1.1203","8.8435","0.0059","0.0030"
"5.4800","0.4503","1.1252","8.8828","0.0061","0.0031"
"5.5200","0.4535","1.1323","8.9383","0.0064","0.0032"
"5.5600","0.4570","1.1397","8.9969","0.0057","0.0029"
"5.6000","0.4600","1.1445","9.0350","0.0069","0.0035"
"5.6400","0.4633","1.1534","9.1053","0.0066","0.0033"
"5.6800","0.4667","1.1588","9.1475","0.0061","0.0031"
"5.7200","0.4699","1.1660","9.2042","0.0059","0.0030"
"5.7600","0.4736","1.1750","9.2755","0.0058","0.0029"
"5.8000","0.4769","1.1796","9.3118","0.0073","0.0037"
"5.8400","0.4802","1.1882","9.3801","0.0069","0.0035"
"5.8800","0.4836","1.1936","9.4225","0.0067","0.0034"
"5.9200","0.4867","1.2004","9.4762","0.0068","0.0034"
"5.9600","0.4903","1.2098","9.5500","0.0082","0.0041"
"6.0000","0.4935","1.2143","9.5862","0.0071","0.0036"
"6.0400","0.4969","1.2238","9.6606","0.0075","0.0037"
"6.0800","0.5004","1.2296","9.7064","0.0080","0.0040"
"6.1200","0.5035","1.2357","9.7551","0.0074","0.0037"
"6.1600","0.5069","1.2446","9.8250","0.0070","0.0035"
"6.2000","0.5101","1.2493","9.8621","0.0076","0.0038"
"6.2400","0.5132","1.2576","9.9280","0.0078","0.0039"
"6.2800","0.5169","1.2663","9.9965","0.0085","0.0043"
"6.3200","0.5201","1.2715","10.0377","0.0081","0.0041"
"6.3600","0.5235","1.2810","10.1127","0.0094","0.0047"
"6.4000","0.5269","1.2868","10.1585","0.0091","0.0046"
"6.4400","0.5301","1.2946","10.2197","0.0081","0.0041"
"6.4800","0.5336","1.3031","10.2867","0.0090","0.0045"
"6.5200","0.5368","1.3086","10.3306","0.0086","0.0043"
"6.5600","0.5402","1.3183","10.4069","0.0084","0.0042"
"6.6000","0.5437","1.3245","10.4557","0.0087","0.0044"
"6.6400","0.5468","1.3316","10.5118","0.0100","0.0050"
"6.6800","0.5503","1.3406","10.5827","0.0103","0.0052"
"6.7200","0.5534","1.3460","10.6252","0.0100","0.0050"
"6.7600","0.5566","1.3551","10.6974","0.0102","0.0051"
"6.8000","0.5601","1.3627","10.7570","0.0110","0.0055"
"6.8400","0.5632","1.3693","10.8091","0.0105","0.0053"
"6.8800","0.5668","1.3796","10.8904","0.0106","0.0053"
"6.9200","0.5702","1.3856","10.9378","0.0110","0.0055"
"6.9600","0.5735","1.3944","11.0072","0.0098","0.0049"
"7.0000","0.5770","1.4025","11.0712","0.0104","0.0052"
"7.0400","0.5801","1.4083","11.1174","0.0110","0.0056"
"7.0800","0.5835","1.4188","11.2005","0.0118","0.0059"
"7.1200","0.5869","1.4253","11.2513","0.0114","0.0057"
"7.1600","0.5901","1.4337","11.3177","0.0109","0.0055"
"7.2000","0.5937","1.4429","11.3908","0.0118","0.0059"
"7.2400","0.5968","1.4482","11.4319","0.0118","0.0059"
"7.2800","0.6002","1.4587","11.5151","0.0113","0.0057"
"7.3200","0.6035","1.4643","11.5593","0.0106","0.0053"
"7.3600","0.6065","1.4722","11.6216","0.0113","0.0057"
"7.4000","0.6101","1.4833","11.7093","0.0120","0.0060"
"7.4400","0.6134","1.4889","11.7532","0.0108","0.0055"
"7.4800","0.6168","1.4989","11.8324","0.0107","0.0054"
"7.5200","0.6203","1.5065","11.8927","0.0119","0.0060"
"7.5600","0.6234","1.5130","11.9436","0.0130","0.0065"
"7.6000","0.6269","1.5235","12.0264","0.0135","0.0068"
"7.6400","0.6301","1.5288","12.0685","0.0140","0.0071"
"7.6800","0.6333","1.5389","12.1479","0.0141","0.0071"
"7.7200","0.6369","1.5473","12.2144","0.0138","0.0069"
"7.7600","0.6401","1.5535","12.2632","0.0137","0.0069"
"7.8000","0.6436","1.5644","12.3493","0.0151","0.0076"
"7.8400","0.6469","1.5701","12.3945","0.0131","0.0066"
"7.8800","0.6501","1.5792","12.4666","0.0139","0.0070"
"7.9200","0.6535","1.5872","12.5291","0.0141","0.0071"
"7.9600","0.6564","1.5934","12.5783","0.0142","0.0071"
"8.0000","0.6599","1.6055","12.6740","0.0152","0.0076"
"8.0400","0.6634","1.6125","12.7296","0.0151","0.0076"
"8.0800","0.6667","1.6214","12.7995","0.0147","0.0074"
"8.1200","0.6704","1.6315","12.8790","0.0158","0.0079"
"8.1600","0.6735","1.6366","12.9199","0.0153","0.0077"
"8.2000","0.6768","1.6473","13.0039","0.0152","0.0076"
"8.2400","0.6802","1.6553","13.0670","0.0164","0.0082"
"8.2800","0.6834","1.6632","13.1292","0.0161","0.0081"
"8.3200","0.6870","1.6742","13.2164","0.0159","0.0080"
"8.3600","0.6903","1.6801","13.2630","0.0162","0.0081"
"8.4000","0.6936","1.6912","13.3502","0.0172","0.0087"
"8.4400","0.6971","1.6983","13.4062","0.0181","0.0091"
"8.4800","0.7000","1.7049","13.4586","0.0178","0.0089"
"8.5200","0.7035","1.7169","13.5533","0.0170","0.0085"
"8.5600","0.7067","1.7230","13.6018","0.0169","0.0085"
"8.6000","0.7099","1.7328","13.6791","0.0177","0.0089"
"8.6400","0.7137","1.7439","13.7668","0.0177","0.0089"
"8.6800","0.7169","1.7495","13.8103","0.0191","0.0096"
"8.7200","0.7203","1.7607","13.8989","0.0189","0.0095"
"8.7600","0.7236","1.7673","13.9509","0.0187","0.0094"
"8.8000","0.7267","1.7763","14.0223","0.0196","0.0099"
"8.8400","0.7303","1.7878","14.1130","0.0204","0.0102"
"8.8800","0.7335","1.7929","14.1530","0.0202","0.0102"
"8.9200","0.7369","1.8052","14.2506","0.0197","0.0099"
"8.9600","0.7404","1.8131","14.3125","0.0188","0.0094"
"9.0000","0.7434","1.8202","14.3687","0.0191","0.0096"
"9.0400","0.7469","1.8316","14.4590","0.0196","0.0098"
"9.0800","0.7500","1.8371","14.5023","0.0194","0.0098"
"9.1200","0.7532","1.8485","14.5926","0.0200","0.0101"
"9.1600","0.7567","1.8576","14.6639","0.0206","0.0103"
"9.2000","0.7598","1.8651","14.7236","0.0198","0.0100"
"9.2400","0.7635","1.8785","14.8293","0.0204","0.0102"
"9.2800","0.7669","1.8840","14.8724","0.0207","0.0104"
"9.3200","0.7701","1.8937","14.9491","0.0201","0.0101"
"9.3600","0.7736","1.9034","15.0253","0.0209","0.0105"
"9.4000","0.7767","1.9109","15.0851","0.0212","0.0107"
"9.4400","0.7802","1.9233","15.1826","0.0218","0.0109"
"9.4800","0.7835","1.9293","15.2299","0.0224","0.0112"
"9.5200","0.7868","1.9401","15.3156","0.0212","0.0107"
"9.5600","0.7904","1.9508","15.4001","0.0223","0.0112"
"9.6000","0.7935","1.9562","15.4424","0.0231","0.0116"
"9.6400","0.7969","1.9688","15.5419","0.0232","0.0117"
"9.6800","0.8001","1.9753","15.5929","0.0227","0.0114"
"9.7200","0.8032","1.9849","15.6687","0.0230","0.0115"
"9.7600","0.8068","1.9971","15.7653","0.0236","0.0119"
"9.8000","0.8101","2.0031","15.8127","0.0238","0.0120"
"9.8400","0.8135","2.0154","15.9100","0.0236","0.0119"
"9.8800","0.8169","2.0234","15.9727","0.0239","0.0120"
"9.9200","0.8200","2.0314","16.0361","0.0228","0.0115"
"9.9600","0.8236","2.0446","16.1406","0.0233","0.0117"
"10.0000","0.8268","2.0506","16.1874","0.0240","0.0120"
"10.0400","0.8302","2.0619","16.2772","0.0252","0.0127"
"10.0800","0.8337","2.0716","16.3532","0.0246","0.0124"
"10.1200","0.8369","2.0795","16.4158","0.0241","0.0121"
"10.1600","0.8403","2.0906","16.5032","0.0249","0.0125"
"10.2000","0.8434","2.0965","16.5498","0.0252","0.0127"
"10.2400","0.8465","2.1073","16.6349","0.0246","0.0124"
"10.2800","0.8501","2.1195","16.7312","0.0264","0.0133"
"10.3200","0.8533","2.1257","16.7805","0.0248","0.0125"
"10.3600","0.8567","2.1389","16.8844","0.0269","0.0135"
"10.4000","0.8602","2.1464","16.9437","0.0274","0.0138"
"10.4400","0.8634","2.1559","17.0186","0.0268","0.0135"
"10.4800","0.8670","2.1674","17.1099","0.0279","0.0140"
"10.5200","0.8701","2.1736","17.1588","0.0272","0.0137"
"10.5600","0.8735","2.1867","17.2618","0.0276","0.0139"
"10.6000","0.8769","2.1946","17.3242","0.0270","0.0136"
"10.6400","0.8800","2.2040","17.3983","0.0276","0.0139"
"10.6800","0.8838","2.2176","17.5058","0.0281","0.0141"
"10.7200","0.8870","2.2228","17.5473","0.0287","0.0144"
"10.7600","0.8903","2.2346","17.6405","0.0276","0.0139"
"10.8000","0.8936","2.2428","17.7052","0.0280","0.0141"
"10.8400","0.8965","2.2508","17.7677","0.0288","0.0145"
"10.8800","0.9001","2.2654","17.8834","0.0284","0.0143"
"10.9200","0.9034","2.2715","17.9317","0.0301","0.0152"
"10.9600","0.9068","2.2841","18.0307","0.0297","0.0150"
"11.0000","0.9104","2.2937","18.1065","0.0304","0.0153"
"11.0400","0.9134","2.2996","18.1530","0.0311","0.0157"
"11.0800","0.9169","2.3140","18.2673","0.0302","0.0152"
"11.1200","0.9202","2.3203","18.3163","0.0309","0.0156"
"11.1600","0.9234","2.3313","18.4034","0.0303","0.0153"
"11.2000","0.9269","2.3425","18.4920","0.0302","0.0152"
"11.2400","0.9301","2.3493","18.5453","0.0313","0.0157"
"11.2800","0.9337","2.3633","18.6563","0.0313","0.0158"
"11.3200","0.9369","2.3688","18.6996","0.0307","0.0154"
"11.3600","0.9399","2.3790","18.7800","0.0313","0.0157"
"11.4000","0.9434","2.3912","18.8761","0.0316","0.0159"
"11.4400","0.9464","2.3968","18.9208","0.0321","0.0162"
"11.4800","0.9498","2.4115","19.0364","0.0318","0.0160"
"11.5200","0.9535","2.4216","19.1166","0.0324","0.0163"
"11.5600","0.9568","2.4302","19.1839","0.0324","0.0163"
"11.6000","0.9604","2.4412","19.2713","0.0322","0.0162"
"11.6400","0.9633","2.4464","19.3124","0.0318","0.0160"
"11.6800","0.9667","2.4613","19.4295","0.0328","0.0165"
"11.7200","0.9703","2.4713","19.5091","0.0323","0.0163"
"11.7600","0.9735","2.4792","19.5707","0.0329","0.0165"
"11.8000","0.9771","2.4926","19.6770","0.0329","0.0166"
"11.8400","0.9804","2.4983","19.7222","0.0336","0.0169"
"11.8800","0.9836","2.5099","19.8131","0.0336","0.0169"
"11.9200","0.9870","2.5198","19.8913","0.0328","0.0165"
"11.9600","0.9899","2.5266","19.9451","0.0339","0.0171"
"12.0000","0.9934","2.5410","20.0589","0.0348","0.0175"
"12.0400","0.9967","2.5488","20.1208","0.0356","0.0179"
"12.0800","1.0000","2.5600","20.2092","0.0353","0.0178"
"12.1200","1.0038","2.5727","20.3095","0.0360","0.0181"
"12.1600","1.0070","2.5783","20.3532","0.0353","0.0178"
"12.2000","1.0103","2.5910","20.4536","0.0370","0.0186"
"12.2400","1.0135","2.5986","20.5133","0.0355","0.0179"
"12.2800","1.0166","2.6086","20.5925","0.0366","0.0184"
"12.3200","1.0203","2.6236","20.7112","0.0363","0.0183"
"12.3600","1.0236","2.6300","20.7614","0.0363","0.0182"
"12.4000","1.0270","2.6423","20.8588","0.0367","0.0184"
"12.4400","1.0304","2.6506","20.9238","0.0361","0.0181"
"12.4800","1.0334","2.6584","20.9858","0.0364","0.0183"
"12.5200","1.0368","2.6726","21.0976","0.0378","0.0190"
"12.5600","1.0399","2.6782","21.1417","0.0379","0.0191"
"12.6000","1.0431","2.6913","21.2455","0.0374","0.0188"
"12.6400","1.0468","2.7040","21.3454","0.0367","0.0184"
"12.6800","1.0500","2.7109","21.4000","0.0366","0.0184"
"12.7200","1.0536","2.7251","21.5121","0.0366","0.0184"
"12.7600","1.0569","2.7306","21.5559","0.0367","0.0185"
"12.8000","1.0600","2.7424","21.6484","0.0374","0.0188"
"12.8400","1.0636","2.7550","21.7481","0.0373","0.0188"
"12.8800","1.0667","2.7617","21.8010","0.0370","0.0186"
"12.9200","1.0703","2.7770","21.9217","0.0389","0.0196"
"12.9600","1.0737","2.7843","21.9792","0.0385","0.0194"
"13.0000","1.0769","2.7939","22.0555","0.0376","0.0189"
"13.0400","1.0804","2.8062","22.1524","0.0395","0.0198"
"13.0800","1.0834","2.8119","22.1971","0.0405","0.0204"
"13.1200","1.0868","2.8268","22.3149","0.0412","0.0207"
"13.1600","1.0902","2.8353","22.3822","0.0420","0.0211"
"13.2000","1.0933","2.8444","22.4541","0.0423","0.0213"
"13.2400","1.0969","2.8590","22.5689","0.0422","0.0212"
"13.2800","1.1002","2.8655","22.6205","0.0430","0.0216"
"13.3200","1.1035","2.8779","22.7186","0.0416","0.0209"
"13.3600","1.1069","2.8876","22.7948","0.0416","0.0209"
"13.4000","1.1099","2.8956","22.8581","0.0414","0.0208"
"13.4400","1.1135","2.9110","22.9797","0.0428","0.0215"
"13.4800","1.1169","2.9190","23.0429","0.0429","0.0216"
"13.5200","1.1202","2.9301","23.1307","0.0427","0.0215"
"13.5600","1.1237","2.9412","23.2179","0.0438","0.0220"
"13.6000","1.1268","2.9486","23.2764","0.0437","0.0220"
"13.6400","1.1302","2.9624","23.3858","0.0432","0.0218"
"13.6800","1.1334","2.9701","23.4466","0.0435","0.0219"
"13.7200","1.1365","2.9807","23.5298","0.0432","0.0217"
"13.7600","1.1401","2.9949","23.6417","0.0430","0.0216"
"13.8000","1.1434","3.0017","23.6959","0.0419","0.0211"
"13.8400","1.1468","3.0151","23.8019","0.0425","0.0214"
"13.8800","1.1502","3.0248","23.8782","0.0434","0.0218"
"13.9200","1.1533","3.0328","23.9413","0.0438","0.0220"
"13.9600","1.1568","3.0478","24.0593","0.0441","0.0222"
"14.0000","1.1601","3.0548","24.1151","0.0444","0.0223"
"14.0400","1.1635","3.0684","24.2225","0.0454","0.0228"
"14.0800","1.1670","3.0793","24.3083","0.0453","0.0228"
"14.1200","1.1702","3.0865","24.3655","0.0452","0.0227"
"14.1600","1.1737","3.1016","24.4844","0.0457","0.0230"
"14.2000","1.1769","3.1072","24.5284","0.0455","0.0229"
"14.2400","1.1800","3.1194","24.6252","0.0458","0.0230"
"14.2800","1.1836","3.1323","24.7269","0.0456","0.0229"
"14.3200","1.1867","3.1389","24.7785","0.0451","0.0227"
"14.3600","1.1902","3.1545","24.9020","0.0448","0.0225"
"14.4000","1.1935","3.1623","24.9638","0.0454","0.0229"
"14.4400","1.1968","3.1734","25.0510","0.0455","0.0229"
"14.4800","1.2003","3.1851","25.1438","0.0457","0.0230"
"14.5200","1.2033","3.1908","25.1887","0.0456","0.0230"
"14.5600","1.2067","3.2068","25.3149","0.0457","0.0230"
"14.6000","1.2102","3.2167","25.3929","0.0449","0.0226"
"14.6400","1.2135","3.2266","25.4714","0.0447","0.0225"
"14.6800","1.2170","3.2397","25.5748","0.0454","0.0228"
"14.7200","1.2202","3.2461","25.6253","0.0447","0.0225"
"14.7600","1.2235","3.2596","25.7318","0.0467","0.0235"
"14.8000","1.2268","3.2688","25.8039","0.0473","0.0238"
"14.8400","1.2299","3.2778","25.8751","0.0468","0.0236"
"14.8800","1.2334","3.2927","25.9930","0.0472","0.0237"
"14.9200","1.2365","3.2992","26.0439","0.0478","0.0240"
"14.9600","1.2399","3.3136","26.1577","0.0476","0.0240"
"15.0000","1.2435","3.3254","26.2510","0.0480","0.0241"
"15.0400","1.2467","3.3322","26.3045","0.0471","0.0237"
"15.0800","1.2501","3.3464","26.4164","0.0487","0.0245"
"15.1200","1.2534","3.3536","26.4738","0.0487","0.0245"
"15.1600","1.2567","3.3670","26.5795","0.0486","0.0245"
"15.2000","1.2603","3.3795","26.6783","0.0488","0.0246"
"15.2400","1.2636","3.3875","26.7415","0.0473","0.0238"
"15.2800","1.2671","3.4017","26.8532","0.0481","0.0242"
"15.3200","1.2703","3.4079","26.9023","0.0476","0.0239"
"15.3600","1.2734","3.4192","26.9914","0.0471","0.0237"
"15.4000","1.2770","3.4333","27.1030","0.0482","0.0242"
"15.4400","1.2801","3.4391","27.1486","0.0489","0.0246"
"15.4800","1.2834","3.4533","27.2604","0.0489","0.0246"
"15.5200","1.2868","3.4642","27.3471","0.0490","0.0246"
"15.5600","1.2901","3.4742","27.4255","0.0493","0.0248"
"15.6000","1.2937","3.4880","27.5350","0.0492","0.0247"
"15.6400","1.2968","3.4937","27.5795","0.0495","0.0249"
"15.6800","1.3001","3.5075","27.6887","0.0499","0.0251"
"15.7200","1.3036","3.5187","27.7771","0.0501","0.0252"
"15.7600","1.3067","3.5268","27.8411","0.0497","0.0250"
"15.8000","1.3103","3.5438","27.9748","0.0509","0.0256"
"15.8400","1.3137","3.5509","28.0314","0.0506","0.0255"
"15.8800","1.3169","3.5611","28.1120","0.0517","0.0260"
"15.9200","1.3203","3.5732","28.2074","0.0517","0.0260"
"15.9600","1.3233","3.5799","28.2601","0.0516","0.0259"
"16.0000","1.3267","3.5955","28.3829","0.0518","0.0261"
"16.0400","1.3300","3.6037","28.4479","0.0520","0.0261"
"16.0800","1.3331","3.6141","28.5298","0.0519","0.0261"
"16.1200","1.3369","3.6310","28.6631","0.0521","0.0262"
"16.1600","1.3401","3.6367","28.7082","0.0523","0.0263"
"16.2000","1.3435","3.6509","28.8202","0.0524","0.0263"
"16.2400","1.3469","3.6600","28.8927","0.0527","0.0265"
"16.2800","1.3500","3.6696","28.9682","0.0521","0.0262"
"16.3200","1.3536","3.6842","29.0838","0.0523","0.0263"
"16.3600","1.3567","3.6907","29.1347","0.0525","0.0264"
"16.4000","1.3603","3.7067","29.2610","0.0532","0.0268"
"16.4400","1.3638","3.7163","29.3369","0.0531","0.0267"
"16.4800","1.3669","3.7229","29.3891","0.0520","0.0262"
"16.5200","1.3703","3.7376","29.5046","0.0529","0.0266"
"16.5600","1.3734","3.7441","29.5564","0.0534","0.0268"
"16.6000","1.3767","3.7585","29.6698","0.0527","0.0265"
"16.6400","1.3802","3.7702","29.7624","0.0539","0.0271"
"16.6800","1.3833","3.7773","29.8188","0.0542","0.0273"
"16.7200","1.3869","3.7937","29.9476","0.0538","0.0270"
"16.7600","1.3902","3.8009","30.0049","0.0532","0.0268"
"16.8000","1.3935","3.8132","30.1017","0.0538","0.0270"
"16.8400","1.3970","3.8254","30.1978","0.0523","0.0263"
"16.8800","1.4001","3.8311","30.2428","0.0529","0.0266"
"16.9200","1.4035","3.8469","30.3679","0.0530","0.0267"
"16.9600","1.4069","3.8563","30.4419","0.0538","0.0271"
"17.0000","1.4101","3.8655","30.5146","0.0532","0.0267"
"17.0400","1.4136","3.8788","30.6194","0.0526","0.0265"
"17.0800","1.4167","3.8856","30.6734","0.0522","0.0262"
"17.1200","1.4201","3.8996","30.7841","0.0534","0.0268"
"17.1600","1.4235","3.9095","30.8616","0.0539","0.0271"
"17.2000","1.4266","3.9175","30.9248","0.0530","0.0267"
"17.2400","1.4301","3.9324","31.0430","0.0545","0.0274"
"17.2800","1.4333","3.9391","31.0958","0.0550","0.0277"
"17.3200","1.4366","3.9523","31.1999","0.0551","0.0277"
"17.3600","1.4402","3.9650","31.3000","0.0541","0.0272"
"17.4000","1.4434","3.9722","31.3573","0.0535","0.0269"
"17.4400","1.4469","3.9861","31.4665","0.0525","0.0264"
"17.4800","1.4502","3.9925","31.5169","0.0536","0.0269"
"17.5200","1.4534","4.0038","31.6064","0.0545","0.0274"
"17.5600","1.4571","4.0169","31.7101","0.0542","0.0273"
"17.6000","1.4602","4.0228","31.7562","0.0531","0.0267"
"17.6400","1.4636","4.0369","31.8679","0.0530","0.0267"
"17.6800","1.4669","4.0433","31.9186","0.0543","0.0273"
"17.7200","1.4700","4.0538","32.0007","0.0538","0.0270"
"17.7600","1.4736","4.0662","32.0992","0.0528","0.0265"
"17.8000","1.4767","4.0698","32.1275","0.0526","0.0265"
"17.8400","1.4801","4.0848","32.2459","0.0526","0.0264"
"17.8800","1.4836","4.0930","32.3108","0.0528","0.0266"
"17.9200","1.4867","4.0989","32.3569","0.0533","0.0268"
"17.9600","1.4902","4.1129","32.4675","0.0523","0.0263"
"18.0000","1.4934","4.1171","32.5011","0.0511","0.0257"
"18.0400","1.4968","4.1297","32.6000","0.0524","0.0264"
"18.0800","1.5002","4.1379","32.6648","0.0508","0.0255"
"18.1200","1.5035","4.1429","32.7042","0.0494","0.0249"
"18.1600","1.5071","4.1510","32.7682","0.0494","0.0249"
"18.2000","1.5103","4.1410","32.6894","0.0484","0.0243"
"18.2400","1.5135","4.1366","32.6547","0.0465","0.0234"
"18.2800","1.5169","4.1320","32.6183","0.0460","0.0231"
"18.3200","1.5199","4.1205","32.5275","0.0443","0.0223"
"18.3600","1.5234","4.1199","32.5229","0.0424","0.0213"
"18.4000","1.5266","4.1088","32.4351","0.0398","0.0200"
"18.4400","1.5300","4.0968","32.3408","0.0379","0.0190"
"18.4800","1.5336","4.0779","32.1916","0.0348","0.0175"
"18.5200","1.5367","4.0347","31.8501","0.0347","0.0175"
"18.5600","1.5402","3.9790","31.4106","0.0331","0.0167"
"18.6000","1.5435","3.8837","30.6585","0.0324","0.0163"
"18.6400","1.5468","3.7535","29.6307","0.0301","0.0151"
"18.6800","1.5504","3.6155","28.5414","0.0288","0.0145"
"18.7200","1.5538","3.4669","27.3684","0.0267","0.0134"
"18.7600","1.5573","3.3390","26.3581","0.0252","0.0127"
"18.8000","1.5604","3.2249","25.4577","0.0226","0.0114"
"18.8400","1.5635","3.1195","24.6256","0.0224","0.0113"
"18.8800","1.5670","3.0192","23.8341","0.0209","0.0105"
"18.9200","1.5702","2.9130","22.9953","0.0189","0.0095"
"18.9600","1.5735","2.8284","22.3276","0.0184","0.0093"
"19.0000","1.5770","2.7610","21.7957","0.0169","0.0085"
"19.0400","1.5801","2.7025","21.3338","0.0152","0.0076"
"19.0800","1.5836","2.6602","20.9995","0.0139","0.0070"
"19.1200","1.5868","2.6140","20.6356","0.0132","0.0067"
"19.1600","1.5901","2.5534","20.1566","0.0109","0.0055"
"19.2000","1.5936","2.4806","19.5819","0.0086","0.0043"
"19.2400","1.5968","2.4152","19.0655","0.0057","0.0028"
"19.2800","1.6005","2.3716","18.7218","0.0044","0.0022"
"19.3200","1.6039","2.3311","18.4020","0.0025","0.0012"
"19.3600","1.6069","2.2976","18.1372","0.0013","0.0007"
"19.4000","1.6103","2.2729","17.9428","0.0014","0.0007"
"19.4400","1.6133","2.2452","17.7235","-0.0002","-0.0001"
"19.4800","1.6167","2.2234","17.5515","-0.0005","-0.0002"
"19.5200","1.6201","2.1951","17.3280","-0.0001","-0.0001"
"19.5600","1.6233","2.1723","17.1486","-0.0003","-0.0001"
"19.6000","1.6270","2.1574","17.0304","-0.0004","-0.0002"
"19.6400","1.6301","2.1276","16.7957","-0.0016","-0.0008"
"19.6800","1.6335","2.0896","16.4954","-0.0027","-0.0014"
"19.7200","1.6369","2.0463","16.1536","-0.0036","-0.0018"
"19.7600","1.6399","2.0041","15.8209","-0.0050","-0.0025"
"19.8000","1.6436","1.9571","15.4494","-0.0036","-0.0018"
"19.8400","1.6470","1.8938","14.9496","-0.0049","-0.0024"
"19.8800","1.6504","1.7842","14.0848","-0.0046","-0.0023"
"19.9200","1.6539","1.6147","12.7466","-0.0035","-0.0018"
"19.9600","1.6568","1.5138","11.9498","-0.0047","-0.0024"
"20.0000","1.6603","1.4728","11.6265","-0.0046","-0.0023"
"20.0400","1.6635","1.4479","11.4299","-0.0042","-0.0021"
"20.0800","1.6668","1.4323","11.3066","-0.0063","-0.0032"
"20.1200","1.6703","1.4200","11.2093","-0.0055","-0.0028"
"20.1600","1.6735","1.4104","11.1341","-0.0048","-0.0024"
"20.2000","1.6769","1.4065","11.1034","-0.0050","-0.0025"
"20.2400","1.6802","1.3999","11.0513","-0.0067","-0.0034"
"20.2800","1.6833","1.3976","11.0328","-0.0045","-0.0023"
"20.3200","1.6869","1.3981","11.0368","-0.0042","-0.0021"
"20.3600","1.6900","1.3942","11.0058","-0.0055","-0.0028"
"20.4000","1.6935","1.3977","11.0338","-0.0053","-0.0027"
"20.4400","1.6970","1.3973","11.0302","-0.0053","-0.0027"
"20.4800","1.7002","1.3942","11.0056","-0.0056","-0.0028"
"20.5200","1.7036","1.3959","11.0193","-0.0048","-0.0024"
"20.5600","1.7067","1.3927","10.9941","-0.0047","-0.0024"
"20.6000","1.7101","1.3952","11.0139","-0.0040","-0.0020"
"20.6400","1.7135","1.3935","11.0004","-0.0046","-0.0023"
"20.6800","1.7166","1.3863","10.9435","-0.0050","-0.0025"
"20.7200","1.7202","1.3888","10.9634","-0.0044","-0.0022"
"20.7600","1.7235","1.3858","10.9394","-0.0040","-0.0020"
"20.8000","1.7267","1.3849","10.9323","-0.0031","-0.0016"
"20.8400","1.7302","1.3864","10.9441","-0.0033","-0.0017"
"20.8800","1.7333","1.3830","10.9178","-0.0046","-0.0023"
"20.9200","1.7368","1.3863","10.9434","-0.0039","-0.0020"
"20.9600","1.7402","1.3850","10.9334","-0.0036","-0.0018"
"21.0000","1.7435","1.3855","10.9373","-0.0039","-0.0020"
"21.0400","1.7471","1.3819","10.9086","-0.0035","-0.0017"
"21.0800","1.7502","1.3682","10.8010","-0.0035","-0.0018"
"21.1200","1.7536","1.3633","10.7620","-0.0043","-0.0021"
"21.1600","1.7569","1.3579","10.7191","-0.0035","-0.0018"
"21.2000","1.7600","1.3537","10.6865","-0.0031","-0.0016"
"21.2400","1.7635","1.3556","10.7009","-0.0050","-0.0025"
"21.2800","1.7667","1.3496","10.6538","-0.0047","-0.0024"
"21.3200","1.7702","1.3507","10.6626","-0.0034","-0.0017"
"21.3600","1.7736","1.3494","10.6525","-0.0037","-0.0018"
"21.4000","1.7766","1.3458","10.6239","-0.0035","-0.0018"
"21.4400","1.7802","1.3488","10.6479","-0.0026","-0.0013"
"21.4800","1.7834","1.3447","10.6154","-0.0043","-0.0022"
"21.5200","1.7866","1.3454","10.6206","-0.0026","-0.0013"
"21.5600","1.7903","1.3469","10.6323","-0.0038","-0.0019"
"21.6000","1.7936","1.3434","10.6046","-0.0040","-0.0020"
"21.6400","1.7970","1.3439","10.6092","-0.0031","-0.0016"
"21.6800","1.8001","1.3379","10.5613","-0.0029","-0.0015"
"21.7200","1.8033","1.3374","10.5575","-0.0026","-0.0013"
"21.7600","1.8069","1.3298","10.4977","-0.0041","-0.0021"
"21.8000","1.8100","1.3061","10.3106","-0.0046","-0.0023"
"21.8400","1.8135","1.3043","10.2966","-0.0056","-0.0028"
"21.8800","1.8168","1.2895","10.1796","-0.0046","-0.0023"
"21.9200","1.8200","1.2610","9.9542","-0.0065","-0.0033"
"21.9600","1.8235","1.2512","9.8773","-0.0087","-0.0044"
"22.0000","1.8266","1.2382","9.7742","-0.0084","-0.0042"
"22.0400","1.8301","1.2300","9.7101","-0.0104","-0.0052"
"22.0800","1.8335","1.2201","9.6315","-0.0093","-0.0047"
"22.1200","1.8367","1.2135","9.5796","-0.0099","-0.0050"
"22.1600","1.8404","1.2106","9.5564","-0.0100","-0.0050"
"22.2000","1.8437","1.2031","9.4971","-0.0088","-0.0044"
"22.2400","1.8470","1.1999","9.4722","-0.0111","-0.0056"
"22.2800","1.8503","1.1940","9.4257","-0.0114","-0.0057"
"22.3200","1.8533","1.1897","9.3914","-0.0124","-0.0062"
"22.3600","1.8569","1.1892","9.3878","-0.0121","-0.0061"
"22.4000","1.8602","1.1827","9.3365","-0.0118","-0.0060"
"22.4400","1.8636","1.1806","9.3197","-0.0121","-0.0061"
"22.4800","1.8670","1.1768","9.2900","-0.0118","-0.0059"
"22.5200","1.8700","1.1706","9.2408","-0.0131","-0.0066"
"22.5600","1.8735","1.1712","9.2455","-0.0132","-0.0067"
"22.6000","1.8768","1.1661","9.2053","-0.0136","-0.0068"
"22.6400","1.8800","1.1620","9.1731","-0.0139","-0.0070"
"22.6800","1.8835","1.1617","9.1702","-0.0136","-0.0068"
"22.7200","1.8868","1.1565","9.1296","-0.0144","-0.0073"
"22.7600","1.8904","1.1559","9.1249","-0.0148","-0.0075"
"22.8000","1.8937","1.1497","9.0755","-0.0147","-0.0074"
"22.8400","1.8967","1.1455","9.0428","-0.0149","-0.0075"
"22.8800","1.9003","1.1460","9.0464","-0.0147","-0.0074"
"22.9200","1.9035","1.1388","8.9896","-0.0143","-0.0072"
"22.9600","1.9068","1.1376","8.9806","-0.0148","-0.0075"
"23.0000","1.9103","1.1336","8.9488","-0.0166","-0.0084"
"23.0400","1.9134","1.1277","8.9021","-0.0160","-0.0080"
"23.0800","1.9169","1.1267","8.8947","-0.0164","-0.0083"
"23.1200","1.9200","1.1203","8.8434","-0.0166","-0.0083"
"23.1600","1.9233","1.1198","8.8395","-0.0176","-0.0089"
"23.2000","1.9269","1.1176","8.8223","-0.0175","-0.0088"
"23.2400","1.9300","1.1092","8.7558","-0.0177","-0.0089"
"23.2800","1.9336","1.1111","8.7713","-0.0189","-0.0095"
"23.3200","1.9370","1.1080","8.7468","-0.0197","-0.0099"
"23.3600","1.9403","1.1065","8.7348","-0.0173","-0.0087"
"23.4000","1.9438","1.1053","8.7250","-0.0181","-0.0091"
"23.4400","1.9468","1.1007","8.6894","-0.0182","-0.0091"
"23.4800","1.9502","1.1034","8.7104","-0.0192","-0.0097"
"23.5200","1.9535","1.0996","8.6806","-0.0192","-0.0097"
"23.5600","1.9568","1.0990","8.6759","-0.0194","-0.0098"
"23.6000","1.9603","1.1007","8.6892","-0.0199","-0.0100"
"23.6400","1.9634","1.0961","8.6524","-0.0181","-0.0091"
"23.6800","1.9668","1.0988","8.6741","-0.0185","-0.0093"
"23.7200","1.9701","1.0980","8.6680","-0.0181","-0.0091"
"23.7600","1.9732","1.0966","8.6564","-0.0188","-0.0095"
"23.8000","1.9768","1.1007","8.6891","-0.0195","-0.0098"
"23.8400","1.9801","1.0981","8.6683","-0.0198","-0.0100"
"23.8800","1.9836","1.1005","8.6875","-0.0212","-0.0107"
"23.9200","1.9871","1.1004","8.6866","-0.0198","-0.0100"
"23.9600","1.9902","1.0973","8.6620","-0.0181","-0.0091"
"24.0000","1.9937","1.1001","8.6840","-0.0172","-0.0087"
"24.0400","1.9968","1.0969","8.6592","-0.0189","-0.0095"
"24.0800","2.0000","1.0973","8.6624","-0.0182","-0.0091"
"24.1200","2.0035","1.0994","8.6789","-0.0187","-0.0094"
"24.1600","2.0066","1.0970","8.6596","-0.0192","-0.0096"
"24.2000","2.0100","1.0997","8.6808","-0.0192","-0.0096"
"24.2400","2.0134","1.0991","8.6761","-0.0179","-0.0090"
"24.2800","2.0166","1.0992","8.6775","-0.0193","-0.0097"
"24.3200","2.0201","1.1023","8.7019","-0.0202","-0.0102"
"24.3600","2.0233","1.0992","8.6772","-0.0192","-0.0096"
"24.4000","2.0267","1.1029","8.7065","-0.0191","-0.0096"
"24.4400","2.0302","1.1029","8.7067","-0.0210","-0.0106"
"24.4800","2.0334","1.1018","8.6978","-0.0212","-0.0106"
"24.5200","2.0371","1.1047","8.7207","-0.0187","-0.0094"
"24.5600","2.0402","1.1005","8.6877","-0.0182","-0.0092"
"24.6000","2.0435","1.1017","8.6973","-0.0202","-0.0101"
"24.6400","2.0470","1.1020","8.6991","-0.0209","-0.0105"
"24.6800","2.0500","1.0991","8.6768","-0.0189","-0.0095"
"24.7200","2.0536","1.1039","8.7141","-0.0181","-0.0091"
"24.7600","2.0568","1.1002","8.6854","-0.0197","-0.0099"
"24.8000","2.0601","1.1010","8.6917","-0.0194","-0.0098"
"24.8400","2.0636","1.1027","8.7046","-0.0194","-0.0098"
"24.8800","2.0666","1.0996","8.6801","-0.0184","-0.0092"
"24.9200","2.0702","1.1039","8.7139","-0.0181","-0.0091"
"24.9600","2.0735","1.1010","8.6918","-0.0175","-0.0088"
"25.0000","2.0767","1.1009","8.6909","-0.0168","-0.0085"
"25.0400","2.0804","1.1049","8.7221","-0.0173","-0.0087"
"25.0800","2.0835","1.1007","8.6888","-0.0184","-0.0093"
"25.1200","2.0870","1.1034","8.7101","-0.0185","-0.0093"
"25.1600","2.0903","1.1009","8.6903","-0.0183","-0.0092"
"25.2000","2.0934","1.1000","8.6831","-0.0190","-0.0096"
"25.2400","2.0969","1.1041","8.7155","-0.0203","-0.0102"
"25.2800","2.1000","1.1006","8.6883","-0.0191","-0.0096"
"25.3200","2.1035","1.1055","8.7273","-0.0185","-0.0093"
"25.3600","2.1069","1.1050","8.7228","-0.0195","-0.0098"
"25.4000","2.1098","1.1024","8.7022","-0.0191","-0.0096"
"25.4400","2.1134","1.1087","8.7521","-0.0176","-0.0088"
"25.4800","2.1167","1.1065","8.7349","-0.0201","-0.0101"
"25.5200","2.1200","1.1093","8.7568","-0.0188","-0.0095"
"25.5600","2.1235","1.1105","8.7665","-0.0179","-0.0090"
"25.6000","2.1268","1.1091","8.7555","-0.0183","-0.0092"
"25.6400","2.1304","1.1138","8.7921","-0.0182","-0.0092"
"25.6800","2.1336","1.1103","8.7650","-0.0185","-0.0093"
"25.7200","2.1368","1.1101","8.7631","-0.0173","-0.0087"
"25.7600","2.1402","1.1120","8.7781","-0.0189","-0.0095"
"25.8000","2.1433","1.1098","8.7610","-0.0187","-0.0094"
"25.8400","2.1469","1.1159","8.8088","-0.0174","-0.0088"
"25.8800","2.1503","1.1148","8.8003","-0.0192","-0.0097"
"25.9200","2.1535","1.1142","8.7956","-0.0186","-0.0094"
"25.9600","2.1570","1.1168","8.8160","-0.0172","-0.0087"
"26.0000","2.1601","1.1134","8.7897","-0.0177","-0.0089"
"26.0400","2.1635","1.1172","8.8195","-0.0186","-0.0093"
"26.0800","2.1668","1.1170","8.8179","-0.0181","-0.0091"
"26.1200","2.1700","1.1166","8.8143","-0.0190","-0.0096"
"26.1600","2.1737","1.1224","8.8600","-0.0185","-0.0093"
"26.2000","2.1770","1.1196","8.8380","-0.0190","-0.0096"
"26.2400","2.1804","1.1219","8.8564","-0.0183","-0.0092"
"26.2800","2.1837","1.1200","8.8412","-0.0180","-0.0091"
"26.3200","2.1866","1.1167","8.8155","-0.0179","-0.0090"
"26.3600","2.1902","1.1226","8.8622","-0.0182","-0.0092"
"26.4000","2.1934","1.1204","8.8445","-0.0179","-0.0090"
"26.4400","2.1968","1.1227","8.8627","-0.0173","-0.0087"
"26.4800","2.2004","1.1248","8.8794","-0.0158","-0.0080"
"26.5200","2.2034","1.1202","8.8429","-0.0175","-0.0088"
"26.5600","2.2068","1.1233","8.8674","-0.0187","-0.0094"
"26.6000","2.2100","1.1202","8.8429","-0.0183","-0.0092"
"26.6400","2.2131","1.1212","8.8507","-0.0176","-0.0088"
"26.6800","2.2169","1.1275","8.9005","-0.0180","-0.0090"
"26.7200","2.2202","1.1247","8.8789","-0.0183","-0.0092"
"26.7600","2.2238","1.1285","8.9086","-0.0176","-0.0089"
"26.8000","2.2271","1.1245","8.8773","-0.0174","-0.0088"
"26.8400","2.2302","1.1235","8.8691","-0.0186","-0.0094"
"26.8800","2.2337","1.1271","8.8972","-0.0176","-0.0089"
"26.9200","2.2367","1.1227","8.8626","-0.0189","-0.0095"
"26.9600","2.2401","1.1270","8.8970","-0.0189","-0.0095"
"27.0000","2.2436","1.1276","8.9011","-0.0173","-0.0087"
"27.0400","2.2469","1.1277","8.9021","-0.0172","-0.0086"
"27.0800","2.2505","1.1314","8.9316","-0.0175","-0.0088"
"27.1200","2.2534","1.1255","8.8850","-0.0190","-0.0096"
"27.1600","2.2566","1.1284","8.9080","-0.0180","-0.0091"
"27.2000","2.2601","1.1301","8.9210","-0.0181","-0.0091"
"27.2400","2.2632","1.1282","8.9059","-0.0172","-0.0087"
"27.2800","2.2669","1.1350","8.9596","-0.0170","-0.0085"
"27.3200","2.2703","1.1338","8.9500","-0.0190","-0.0095"
"27.3600","2.2737","1.1345","8.9557","-0.0193","-0.0097"
"27.4000","2.2771","1.1336","8.9487","-0.0175","-0.0088"
"27.4400","2.2801","1.1290","8.9123","-0.0172","-0.0086"
"27.4800","2.2835","1.1330","8.9443","-0.0177","-0.0089"
"27.5200","2.2868","1.1307","8.9257","-0.0184","-0.0092"
"27.5600","2.2900","1.1310","8.9286","-0.0196","-0.0099"
"27.6000","2.2936","1.1345","8.9559","-0.0187","-0.0094"
"27.6400","2.2968","1.1303","8.9228","-0.0171","-0.0086"
"27.6800","2.3001","1.1318","8.9347","-0.0174","-0.0087"
"27.7200","2.3034","1.1297","8.9183","-0.0177","-0.0089"
"27.7600","2.3065","1.1278","8.9030","-0.0176","-0.0089"
"27.8000","2.3100","1.1324","8.9396","-0.0181","-0.0091"
"27.8400","2.3133","1.1294","8.9159","-0.0174","-0.0087"
"27.8800","2.3168","1.1323","8.9383","-0.0191","-0.0096"
"27.9200","2.3204","1.1329","8.9432","-0.0176","-0.0088"
"27.9600","2.3235","1.1296","8.9174","-0.0181","-0.0091"
"28.0000","2.3270","1.1316","8.9329","-0.0198","-0.0100"
"28.0400","2.3301","1.1275","8.9003","-0.0185","-0.0093"
"28.0800","2.3333","1.1297","8.9182","-0.0176","-0.0089"
"28.1200","2.3369","1.1326","8.9410","-0.0178","-0.0090"
"28.1600","2.3402","1.1300","8.9202","-0.0186","-0.0094"
"28.2000","2.3438","1.1334","8.9473","-0.0187","-0.0094"
"28.2400","2.3469","1.1281","8.9051","-0.0191","-0.0096"
"28.2800","2.3500","1.1263","8.8909","-0.0178","-0.0089"
"28.3200","2.3535","1.1290","8.9125","-0.0186","-0.0093"
"28.3600","2.3565","1.1254","8.8844","-0.0189","-0.0095"
"28.4000","2.3601","1.1302","8.9223","-0.0175","-0.0088"
"28.4400","2.3635","1.1297","8.9178","-0.0185","-0.0093"
"28.4800","2.3668","1.1290","8.9126","-0.0188","-0.0095"
"28.5200","2.3704","1.1310","8.9283","-0.0181","-0.0091"
"28.5600","2.3735","1.1255","8.8845","-0.0182","-0.0092"
"28.6000","2.3769","1.1277","8.9024","-0.0185","-0.0093"
"28.6400","2.3801","1.1248","8.8792","-0.0178","-0.0089"
"28.6800","2.3832","1.1231","8.8662","-0.0189","-0.0095"
"28.7200","2.3869","1.1281","8.9057","-0.0191","-0.0096"
"28.7600","2.3902","1.1243","8.8754","-0.0173","-0.0087"
"28.8000","2.3936","1.1252","8.8821","-0.0172","-0.0087"
"28.8400","2.3968","1.1215","8.8535","-0.0168","-0.0084"
"28.8800","2.3997","1.1187","8.8312","-0.0178","-0.0089"
"28.9200","2.4033","1.1254","8.8836","-0.0170","-0.0085"
"28.9600","2.4066","1.1231","8.8657","-0.0168","-0.0085"
"29.0000","2.4100","1.1254","8.8837","-0.0176","-0.0089"
"29.0400","2.4137","1.1282","8.9063","-0.0181","-0.0091"
"29.0800","2.4169","1.1247","8.8788","-0.0179","-0.0090"
"29.1200","2.4204","1.1271","8.8976","-0.0174","-0.0088"
"29.1600","2.4236","1.1237","8.8706","-0.0179","-0.0090"
"29.2000","2.4268","1.1237","8.8705","-0.0172","-0.0087"
"29.2400","2.4303","1.1256","8.8860","-0.0181","-0.0091"
"29.2800","2.4334","1.1218","8.8558","-0.0171","-0.0086"
"29.3200","2.4370","1.1268","8.8948","-0.0171","-0.0086"
"29.3600","2.4404","1.1253","8.8834","-0.0165","-0.0083"
"29.4000","2.4435","1.1222","8.8586","-0.0156","-0.0079"
"29.4400","2.4469","1.1248","8.8797","-0.0168","-0.0084"
"29.4800","2.4500","1.1224","8.8606","-0.0161","-0.0081"
"29.5200","2.4534","1.1264","8.8922","-0.0170","-0.0085"
"29.5600","2.4569","1.1275","8.9007","-0.0167","-0.0084"
"29.6000","2.4602","1.1267","8.8942","-0.0167","-0.0084"
"29.6400","2.4638","1.1308","8.9269","-0.0169","-0.0085"
"29.6800","2.4669","1.1261","8.8892","-0.0164","-0.0083"
"29.7200","2.4702","1.1276","8.9011","-0.0165","-0.0083"
"29.7600","2.4736","1.1289","8.9116","-0.0157","-0.0079"
"29.8000","2.4766","1.1251","8.8815","-0.0166","-0.0084"
"29.8400","2.4802","1.1297","8.9180","-0.0160","-0.0081"
"29.8800","2.4835","1.1283","8.9070","-0.0154","-0.0077"
"29.9200","2.4869","1.1294","8.9158","-0.0152","-0.0077"
"29.9600","2.4903","1.1301","8.9211","-0.0154","-0.0077"
"30.0000","2.4933","1.1258","8.8868","-0.0169","-0.0085"
"30.0400","2.4967","1.1309","8.9275","-0.0154","-0.0078"
"30.0800","2.5001","1.1297","8.9177","-0.0149","-0.0075"
"30.1200","2.5032","1.1285","8.9085","-0.0143","-0.0072"
"30.1600","2.5069","1.1337","8.9493","-0.0158","-0.0079"
"30.2000","2.5102","1.1308","8.9268","-0.0147","-0.0074"
"30.2400","2.5137","1.1323","8.9387","-0.0147","-0.0074"
"30.2800","2.5169","1.1294","8.9158","-0.0174","-0.0088"
"30.3200","2.5200","1.1284","8.9080","-0.0172","-0.0086"
"30.3600","2.5237","1.1337","8.9492","-0.0161","-0.0081"
"30.4000","2.5269","1.1299","8.9198","-0.0170","-0.0085"
"30.4400","2.5302","1.1319","8.9355","-0.0164","-0.0083"
"30.4800","2.5338","1.1333","8.9467","-0.0171","-0.0086"
"30.5200","2.5369","1.1300","8.9202","-0.0178","-0.0090"
"30.5600","2.5403","1.1334","8.9470","-0.0165","-0.0083"
"30.6000","2.5434","1.1297","8.9176","-0.0166","-0.0084"
"30.6400","2.5466","1.1320","8.9360","-0.0166","-0.0084"
"30.6800","2.5502","1.1357","8.9650","-0.0179","-0.0090"
"30.7200","2.5533","1.1333","8.9465","-0.0177","-0.0089"
"30.7600","2.5570","1.1389","8.9904","-0.0175","-0.0088"
"30.8000","2.5603","1.1362","8.9696","-0.0156","-0.0079"
"30.8400","2.5635","1.1351","8.9606","-0.0161","-0.0081"
"30.8800","2.5670","1.1380","8.9837","-0.0171","-0.0086"
"30.9200","2.5701","1.1353","8.9623","-0.0166","-0.0083"
"30.9600","2.5735","1.1391","8.9923","-0.0162","-0.0082"
"31.0000","2.5769","1.1388","8.9899","-0.0167","-0.0084"
"31.0400","2.5801","1.1382","8.9850","-0.0171","-0.0086"
"31.0800","2.5836","1.1407","9.0045","-0.0169","-0.0085"
"31.1200","2.5867","1.1362","8.9694","-0.0164","-0.0083"
"31.1600","2.5900","1.1384","8.9865","-0.0164","-0.0083"
"31.2000","2.5934","1.1395","8.9956","-0.0173","-0.0087"
"31.2400","2.5965","1.1372","8.9769","-0.0170","-0.0085"
"31.2800","2.6000","1.1418","9.0137","-0.0163","-0.0082"
"31.3200","2.6034","1.1405","9.0032","-0.0164","-0.0083"
"31.3600","2.6068","1.1423","9.0174","-0.0161","-0.0081"
"31.4000","2.6103","1.1422","9.0164","-0.0156","-0.0079"
"31.4400","2.6133","1.1382","8.9852","-0.0155","-0.0078"
"31.4800","2.6169","1.1429","9.0221","-0.0158","-0.0080"
"31.5200","2.6202","1.1411","9.0076","-0.0161","-0.0081"
"31.5600","2.6235","1.1409","9.0060","-0.0170","-0.0086"
"31.6000","2.6271","1.1425","9.0191","-0.0164","-0.0083"
"31.6400","2.6302","1.1388","8.9895","-0.0148","-0.0074"
"31.6800","2.6337","1.1416","9.0117","-0.0157","-0.0079"
"31.7200","2.6369","1.1381","8.9839","-0.0156","-0.0078"
"31.7600","2.6399","1.1369","8.9750","-0.0163","-0.0082"
"31.8000","2.6435","1.1421","9.0160","-0.0170","-0.0085"
"31.8400","2.6466","1.1390","8.9917","-0.0168","-0.0085"
"31.8800","2.6501","1.1422","9.0167","-0.0165","-0.0083"
"31.9200","2.6536","1.1424","9.0184","-0.0161","-0.0081"
"31.9600","2.6567","1.1394","8.9946","-0.0163","-0.0082"
"32.0000","2.6603","1.1434","9.0263","-0.0175","-0.0088"
"32.0400","2.6635","1.1405","9.0034","-0.0171","-0.0086"
"32.0800","2.6668","1.1419","9.0142","-0.0157","-0.0079"
"32.1200","2.6703","1.1418","9.0135","-0.0161","-0.0081"
"32.1600","2.6734","1.1389","8.9904","-0.0166","-0.0084"
"32.2000","2.6770","1.1430","9.0231","-0.0171","-0.0086"
"32.2400","2.6803","1.1393","8.9941","-0.0166","-0.0083"
"32.2800","2.6834","1.1384","8.9869","-0.0154","-0.0077"
"32.3200","2.6867","1.1396","8.9960","-0.0170","-0.0086"
"32.3600","2.6898","1.1368","8.9743","-0.0162","-0.0082"
"32.4000","2.6933","1.1416","9.0121","-0.0162","-0.0081"
"32.4400","2.6967","1.1409","9.0068","-0.0164","-0.0082"
"32.4800","2.7001","1.1415","9.0115","-0.0171","-0.0086"
"32.5200","2.7038","1.1442","9.0324","-0.0162","-0.0081"
"32.5600","2.7069","1.1390","8.9916","-0.0177","-0.0089"
"32.6000","2.7103","1.1411","9.0081","-0.0173","-0.0087"
"32.6400","2.7136","1.1398","8.9975","-0.0179","-0.0090"
"32.6800","2.7168","1.1382","8.9848","-0.0160","-0.0081"
"32.7200","2.7203","1.1404","9.0028","-0.0163","-0.0082"
"32.7600","2.7235","1.1365","8.9715","-0.0160","-0.0081"
"32.8000","2.7269","1.1394","8.9945","-0.0166","-0.0083"
"32.8400","2.7303","1.1377","8.9813","-0.0154","-0.0077"
"32.8800","2.7333","1.1337","8.9493","-0.0158","-0.0079"
"32.9200","2.7368","1.1368","8.9744","-0.0157","-0.0079"
"32.9600","2.7400","1.1339","8.9510","-0.0164","-0.0082"
"33.0000","2.7433","1.1356","8.9648","-0.0178","-0.0089"
"33.0400","2.7470","1.1388","8.9897","-0.0176","-0.0089"
"33.0800","2.7503","1.1353","8.9623","-0.0178","-0.0089"
"33.1200","2.7538","1.1367","8.9734","-0.0178","-0.0089"
"33.1600","2.7569","1.1317","8.9338","-0.0174","-0.0087"
"33.2000","2.7601","1.1321","8.9369","-0.0170","-0.0086"
"33.2400","2.7637","1.1342","8.9531","-0.0171","-0.0086"
"33.2800","2.7667","1.1289","8.9114","-0.0172","-0.0087"
"33.3200","2.7702","1.1330","8.9439","-0.0165","-0.0083"
"33.3600","2.7737","1.1320","8.9361","-0.0158","-0.0079"
"33.4000","2.7768","1.1292","8.9137","-0.0156","-0.0079"
"33.4400","2.7802","1.1313","8.9306","-0.0170","-0.0086"
"33.4800","2.7833","1.1272","8.8984","-0.0175","-0.0088"
"33.5200","2.7866","1.1310","8.9285","-0.0161","-0.0081"
"33.5600","2.7901","1.1318","8.9349","-0.0162","-0.0081"
"33.6000","2.7933","1.1306","8.9251","-0.0170","-0.0086"
"33.6400","2.7970","1.1354","8.9628","-0.0160","-0.0080"
"33.6800","2.8002","1.1312","8.9298","-0.0177","-0.0089"
"33.7200","2.8035","1.1330","8.9440","-0.0167","-0.0084"
"33.7600","2.8070","1.1338","8.9507","-0.0172","-0.0087"
"33.8000","2.8101","1.1321","8.9372","-0.0176","-0.0088"
"33.8400","2.8137","1.1367","8.9731","-0.0160","-0.0081"
"33.8800","2.8170","1.1329","8.9433","-0.0165","-0.0083"
"33.8940","2.8181","1.1322","8.9373","-0.0169","-0.0085"