File: composites_properties_derivations/composite_tube_tests/comp_tube_5.csv
Specimen label,"5"
Force at Maximum Load,"8.11",kN
Tensile stress at Maximum Load,"64.02",MPa
Epsilon ONE Displacement at Maximum Load,"0.05",mm
Force at Break (Standard),"2.79",kN
Tensile stress at Break (Standard),"22.00",MPa
Epsilon ONE Displacement at Break (Standard),"-0.09",mm
Slope (Chord 0.05 % - 0.2 %),"-----",MPa
Modulus (Automatic Young's),"58992.92",MPa

Specimen label,"5"
Thickness,"",mm
Width,"",mm
Length,"50.32",mm
Rate 1,"5.00",mm/min
Outer diameter,"15.88",mm
Wall thickness,"3.18",mm

Time,Displacement,Force,Tensile stress,Tensile strain (Epsilon ONE Displacement),Epsilon ONE Displacement
(s),(mm),(kN),(MPa),(%),(mm)
"0.0000","0.0005","0.0500","0.3949","-0.0022","-0.0011"
"0.0800","0.0020","0.0753","0.5943","-0.0005","-0.0003"
"0.1600","0.0042","0.1130","0.8918","-0.0006","-0.0003"
"0.2400","0.0139","0.1836","1.4491","0.0008","0.0004"
"0.3200","0.0219","0.1860","1.4683","-0.0001","-0.0001"
"0.4000","0.0286","0.1912","1.5097","0.0006","0.0003"
"0.4800","0.0351","0.1958","1.5455","-0.0009","-0.0005"
"0.5600","0.0420","0.1993","1.5735","0.0011","0.0006"
"0.6400","0.0487","0.2017","1.5920","0.0004","0.0002"
"0.7200","0.0552","0.2049","1.6173","0.0007","0.0003"
"0.8000","0.0617","0.2083","1.6446","0.0020","0.0010"
"0.8800","0.0686","0.2111","1.6667","0.0010","0.0005"
"0.9600","0.0754","0.2136","1.6858","0.0016","0.0008"
"1.0400","0.0820","0.2173","1.7152","-0.0002","-0.0001"
"1.1200","0.0885","0.2209","1.7440","0.0011","0.0006"
"1.2000","0.0952","0.2239","1.7676","0.0003","0.0002"
"1.2800","0.1016","0.2265","1.7878","0.0019","0.0009"
"1.3600","0.1085","0.2294","1.8107","-0.0001","-0.0001"
"1.4400","0.1154","0.2326","1.8360","-0.0002","-0.0001"
"1.5200","0.1220","0.2353","1.8574","0.0007","0.0003"
"1.6000","0.1284","0.2373","1.8734","-0.0004","-0.0002"
"1.6800","0.1353","0.2395","1.8905","0.0005","0.0003"
"1.7600","0.1423","0.2415","1.9062","-0.0007","-0.0003"
"1.8400","0.1486","0.2440","1.9265","0.0008","0.0004"
"1.9200","0.1550","0.2457","1.9395","0.0009","0.0005"
"2.0000","0.1620","0.2468","1.9483","0.0010","0.0005"
"2.0800","0.1687","0.2476","1.9546","0.0003","0.0002"
"2.1600","0.1754","0.2498","1.9717","0.0008","0.0004"
"2.2400","0.1819","0.2516","1.9860","0.0014","0.0007"
"2.3200","0.1886","0.2527","1.9946","0.0000","0.0000"
"2.4000","0.1950","0.2531","1.9980","0.0021","0.0010"
"2.4800","0.2018","0.2551","2.0136","0.0004","0.0002"
"2.5600","0.2087","0.2568","2.0275","0.0006","0.0003"
"2.6400","0.2153","0.2578","2.0350","-0.0004","-0.0002"
"2.7200","0.2219","0.2585","2.0408","0.0004","0.0002"
"2.8000","0.2287","0.2591","2.0454","0.0006","0.0003"
"2.8800","0.2355","0.2604","2.0560","0.0013","0.0007"
"2.9600","0.2420","0.2616","2.0653","0.0005","0.0003"
"3.0400","0.2484","0.2622","2.0699","-0.0001","0.0000"
"3.1200","0.2553","0.2627","2.0740","0.0006","0.0003"
"3.2000","0.2621","0.2634","2.0792","0.0006","0.0003"
"3.2800","0.2687","0.2651","2.0925","0.0008","0.0004"
"3.3600","0.2753","0.2662","2.1014","0.0009","0.0005"
"3.4400","0.2819","0.2662","2.1013","0.0028","0.0014"
"3.5200","0.2885","0.2667","2.1056","0.0013","0.0007"
"3.6000","0.2952","0.2684","2.1190","0.0007","0.0004"
"3.6800","0.3018","0.2702","2.1327","-0.0002","-0.0001"
"3.7600","0.3086","0.2704","2.1348","0.0007","0.0003"
"3.8400","0.3151","0.2710","2.1394","0.0006","0.0003"
"3.9200","0.3220","0.2721","2.1476","0.0013","0.0007"
"4.0000","0.3288","0.2736","2.1600","0.0003","0.0001"
"4.0800","0.3354","0.2747","2.1688","0.0002","0.0001"
"4.1600","0.3417","0.2754","2.1742","0.0006","0.0003"
"4.2400","0.3485","0.2761","2.1797","0.0003","0.0002"
"4.3200","0.3555","0.2778","2.1926","0.0023","0.0011"
"4.4000","0.3620","0.2788","2.2011","0.0023","0.0012"
"4.4800","0.3685","0.2800","2.2104","0.0008","0.0004"
"4.5600","0.3752","0.2809","2.2172","0.0000","0.0000"
"4.6400","0.3820","0.2817","2.2240","0.0009","0.0004"
"4.7200","0.3885","0.2836","2.2391","0.0003","0.0002"
"4.8000","0.3950","0.2851","2.2505","0.0013","0.0007"
"4.8800","0.4018","0.2856","2.2548","0.0006","0.0003"
"4.9600","0.4086","0.2864","2.2608","-0.0001","0.0000"
"5.0400","0.4153","0.2880","2.2738","0.0003","0.0001"
"5.1200","0.4220","0.2898","2.2880","-0.0003","-0.0001"
"5.2000","0.4287","0.2908","2.2953","-0.0018","-0.0009"
"5.2800","0.4351","0.2914","2.3001","-0.0017","-0.0009"
"5.3600","0.4419","0.2927","2.3105","0.0002","0.0001"
"5.4400","0.4487","0.2943","2.3234","0.0003","0.0002"
"5.5200","0.4553","0.2959","2.3358","-0.0005","-0.0002"
"5.6000","0.4619","0.2967","2.3425","-0.0016","-0.0008"
"5.6800","0.4686","0.2973","2.3472","0.0000","0.0000"
"5.7600","0.4754","0.2988","2.3585","-0.0021","-0.0010"
"5.8400","0.4819","0.3005","2.3721","-0.0018","-0.0009"
"5.9200","0.4882","0.3018","2.3828","-0.0006","-0.0003"
"6.0000","0.4951","0.3027","2.3899","-0.0017","-0.0008"
"6.0800","0.5020","0.3033","2.3945","-0.0012","-0.0006"
"6.1600","0.5088","0.3052","2.4091","-0.0014","-0.0007"
"6.2400","0.5153","0.3050","2.4077","-0.0021","-0.0010"
"6.3200","0.5220","0.3073","2.4260","-0.0026","-0.0013"
"6.4000","0.5286","0.3075","2.4276","-0.0023","-0.0012"
"6.4800","0.5353","0.3093","2.4418","-0.0035","-0.0018"
"6.5600","0.5420","0.3115","2.4589","-0.0037","-0.0019"
"6.6400","0.5487","0.3124","2.4658","-0.0046","-0.0023"
"6.7200","0.5551","0.3128","2.4696","-0.0015","-0.0008"
"6.8000","0.5620","0.3137","2.4760","-0.0016","-0.0008"
"6.8800","0.5688","0.3156","2.4912","-0.0036","-0.0018"
"6.9600","0.5753","0.3173","2.5051","-0.0027","-0.0014"
"7.0400","0.5816","0.3183","2.5125","-0.0052","-0.0026"
"7.1200","0.5885","0.3184","2.5133","-0.0061","-0.0031"
"7.2000","0.5954","0.3197","2.5237","-0.0036","-0.0018"
"7.2800","0.6021","0.3216","2.5385","-0.0041","-0.0021"
"7.3600","0.6086","0.3232","2.5518","-0.0039","-0.0019"
"7.4400","0.6152","0.3236","2.5543","-0.0053","-0.0027"
"7.5200","0.6221","0.3242","2.5596","-0.0050","-0.0025"
"7.6000","0.6287","0.3253","2.5683","-0.0055","-0.0028"
"7.6800","0.6352","0.3274","2.5847","-0.0066","-0.0033"
"7.7600","0.6418","0.3285","2.5936","-0.0069","-0.0035"
"7.8400","0.6487","0.3288","2.5959","-0.0064","-0.0032"
"7.9200","0.6553","0.3299","2.6040","-0.0068","-0.0034"
"8.0000","0.6621","0.3320","2.6211","-0.0076","-0.0038"
"8.0800","0.6687","0.3332","2.6304","-0.0067","-0.0034"
"8.1600","0.6750","0.3338","2.6350","-0.0085","-0.0043"
"8.2400","0.6817","0.3346","2.6413","-0.0086","-0.0043"
"8.3200","0.6887","0.3364","2.6558","-0.0065","-0.0033"
"8.4000","0.6954","0.3381","2.6689","-0.0071","-0.0036"
"8.4800","0.7018","0.3392","2.6778","-0.0070","-0.0035"
"8.5600","0.7085","0.3400","2.6837","-0.0098","-0.0049"
"8.6400","0.7156","0.3409","2.6912","-0.0075","-0.0038"
"8.7200","0.7221","0.3428","2.7062","-0.0098","-0.0049"
"8.8000","0.7284","0.3449","2.7224","-0.0098","-0.0049"
"8.8800","0.7351","0.3460","2.7317","-0.0090","-0.0045"
"8.9600","0.7420","0.3465","2.7355","-0.0103","-0.0052"
"9.0400","0.7487","0.3483","2.7492","-0.0106","-0.0053"
"9.1200","0.7554","0.3507","2.7687","-0.0097","-0.0049"
"9.2000","0.7620","0.3520","2.7791","-0.0105","-0.0053"
"9.2800","0.7684","0.3524","2.7823","-0.0123","-0.0062"
"9.3600","0.7750","0.3529","2.7860","-0.0122","-0.0061"
"9.4400","0.7819","0.3556","2.8071","-0.0120","-0.0060"
"9.5200","0.7887","0.3573","2.8208","-0.0123","-0.0062"
"9.6000","0.7951","0.3582","2.8280","-0.0118","-0.0059"
"9.6800","0.8020","0.3592","2.8354","-0.0116","-0.0058"
"9.7600","0.8089","0.3604","2.8450","-0.0117","-0.0059"
"9.8400","0.8155","0.3627","2.8633","-0.0126","-0.0064"
"9.9200","0.8218","0.3643","2.8758","-0.0137","-0.0069"
"10.0000","0.8283","0.3650","2.8815","-0.0125","-0.0063"
"10.0800","0.8354","0.3660","2.8889","-0.0133","-0.0067"
"10.1600","0.8420","0.3677","2.9026","-0.0152","-0.0076"
"10.2400","0.8487","0.3703","2.9230","-0.0146","-0.0074"
"10.3200","0.8553","0.3708","2.9273","-0.0124","-0.0062"
"10.4000","0.8619","0.3714","2.9319","-0.0146","-0.0074"
"10.4800","0.8685","0.3728","2.9428","-0.0163","-0.0082"
"10.5600","0.8752","0.3750","2.9600","-0.0155","-0.0078"
"10.6400","0.8819","0.3765","2.9720","-0.0170","-0.0085"
"10.7200","0.8885","0.3769","2.9752","-0.0195","-0.0098"
"10.8000","0.8952","0.3774","2.9795","-0.0169","-0.0085"
"10.8800","0.9022","0.3795","2.9956","-0.0182","-0.0091"
"10.9600","0.9088","0.3810","3.0076","-0.0191","-0.0096"
"11.0400","0.9151","0.3823","3.0180","-0.0215","-0.0108"
"11.1200","0.9217","0.3830","3.0236","-0.0219","-0.0110"
"11.2000","0.9287","0.3843","3.0337","-0.0199","-0.0100"
"11.2800","0.9354","0.3861","3.0481","-0.0214","-0.0108"
"11.3600","0.9419","0.3883","3.0653","-0.0203","-0.0102"
"11.4400","0.9485","0.3893","3.0732","-0.0211","-0.0106"
"11.5200","0.9554","0.3900","3.0787","-0.0215","-0.0108"
"11.6000","0.9619","0.3923","3.0970","-0.0224","-0.0113"
"11.6800","0.9684","0.3948","3.1162","-0.0211","-0.0106"
"11.7600","0.9751","0.3964","3.1289","-0.0226","-0.0114"
"11.8400","0.9819","0.3966","3.1306","-0.0243","-0.0122"
"11.9200","0.9886","0.3984","3.1453","-0.0253","-0.0127"
"12.0000","0.9954","0.4010","3.1652","-0.0252","-0.0127"
"12.0800","1.0022","0.4027","3.1786","-0.0247","-0.0125"
"12.1600","1.0085","0.4034","3.1845","-0.0253","-0.0127"
"12.2400","1.0151","0.4045","3.1929","-0.0252","-0.0127"
"12.3200","1.0220","0.4044","3.1926","-0.0290","-0.0146"
"12.4000","1.0287","0.4083","3.2235","-0.0289","-0.0145"
"12.4800","1.0351","0.4105","3.2403","-0.0275","-0.0138"
"12.5600","1.0417","0.4114","3.2476","-0.0300","-0.0151"
"12.6400","1.0488","0.4130","3.2602","-0.0299","-0.0151"
"12.7200","1.0554","0.4153","3.2782","-0.0291","-0.0146"
"12.8000","1.0618","0.4176","3.2967","-0.0285","-0.0144"
"12.8800","1.0682","0.4193","3.3100","-0.0300","-0.0151"
"12.9600","1.0753","0.4203","3.3180","-0.0319","-0.0160"
"13.0400","1.0819","0.4225","3.3353","-0.0339","-0.0171"
"13.1200","1.0886","0.4255","3.3589","-0.0325","-0.0163"
"13.2000","1.0954","0.4273","3.3732","-0.0345","-0.0173"
"13.2800","1.1019","0.4280","3.3786","-0.0331","-0.0166"
"13.3600","1.1087","0.4296","3.3909","-0.0356","-0.0179"
"13.4400","1.1153","0.4320","3.4102","-0.0394","-0.0198"
"13.5200","1.1220","0.4344","3.4295","-0.0359","-0.0181"
"13.6000","1.1285","0.4359","3.4407","-0.0357","-0.0180"
"13.6800","1.1352","0.4367","3.4476","-0.0342","-0.0172"
"13.7600","1.1422","0.4390","3.4654","-0.0385","-0.0194"
"13.8400","1.1489","0.4411","3.4818","-0.0396","-0.0199"
"13.9200","1.1552","0.4433","3.4998","-0.0408","-0.0206"
"14.0000","1.1617","0.4439","3.5044","-0.0421","-0.0212"
"14.0800","1.1686","0.4458","3.5192","-0.0414","-0.0208"
"14.1600","1.1754","0.4481","3.5373","-0.0443","-0.0223"
"14.2400","1.1819","0.4510","3.5601","-0.0449","-0.0226"
"14.3200","1.1886","0.4523","3.5708","-0.0432","-0.0218"
"14.4000","1.1955","0.4531","3.5765","-0.0462","-0.0232"
"14.4800","1.2020","0.4550","3.5918","-0.0465","-0.0234"
"14.5600","1.2086","0.4580","3.6154","-0.0460","-0.0231"
"14.6400","1.2153","0.4610","3.6391","-0.0512","-0.0257"
"14.7200","1.2219","0.4616","3.6438","-0.0494","-0.0249"
"14.8000","1.2285","0.4628","3.6530","-0.0492","-0.0247"
"14.8800","1.2354","0.4660","3.6785","-0.0490","-0.0246"
"14.9600","1.2423","0.4683","3.6966","-0.0514","-0.0259"
"15.0400","1.2485","0.4701","3.7108","-0.0526","-0.0265"
"15.1200","1.2550","0.4710","3.7181","-0.0537","-0.0270"
"15.2000","1.2618","0.4734","3.7373","-0.0548","-0.0276"
"15.2800","1.2687","0.4771","3.7665","-0.0536","-0.0270"
"15.3600","1.2752","0.4805","3.7931","-0.0542","-0.0273"
"15.4400","1.2818","0.4828","3.8114","-0.0533","-0.0268"
"15.5200","1.2888","0.4850","3.8287","-0.0563","-0.0283"
"15.6000","1.2954","0.4882","3.8535","-0.0569","-0.0286"
"15.6800","1.3019","0.4923","3.8865","-0.0567","-0.0285"
"15.7600","1.3085","0.4951","3.9086","-0.0563","-0.0283"
"15.8400","1.3152","0.4970","3.9231","-0.0568","-0.0286"
"15.9200","1.3219","0.4998","3.9452","-0.0570","-0.0287"
"16.0000","1.3287","0.5040","3.9787","-0.0565","-0.0284"
"16.0800","1.3355","0.5072","4.0042","-0.0575","-0.0289"
"16.1600","1.3419","0.5094","4.0215","-0.0584","-0.0294"
"16.2400","1.3484","0.5120","4.0420","-0.0593","-0.0298"
"16.3200","1.3552","0.5156","4.0701","-0.0611","-0.0308"
"16.4000","1.3620","0.5195","4.1012","-0.0608","-0.0306"
"16.4800","1.3684","0.5223","4.1227","-0.0602","-0.0303"
"16.5600","1.3750","0.5246","4.1412","-0.0612","-0.0308"
"16.6400","1.3821","0.5276","4.1649","-0.0632","-0.0318"
"16.7200","1.3889","0.5311","4.1926","-0.0631","-0.0317"
"16.8000","1.3953","0.5352","4.2250","-0.0645","-0.0325"
"16.8800","1.4018","0.5372","4.2406","-0.0641","-0.0323"
"16.9600","1.4085","0.5396","4.2599","-0.0649","-0.0327"
"17.0400","1.4153","0.5427","4.2844","-0.0659","-0.0332"
"17.1200","1.4220","0.5470","4.3180","-0.0658","-0.0331"
"17.2000","1.4287","0.5504","4.3448","-0.0681","-0.0342"
"17.2800","1.4352","0.5518","4.3558","-0.0667","-0.0336"
"17.3600","1.4420","0.5544","4.3769","-0.0684","-0.0344"
"17.4400","1.4487","0.5592","4.4144","-0.0679","-0.0342"
"17.5200","1.4552","0.5633","4.4466","-0.0694","-0.0349"
"17.6000","1.4618","0.5663","4.4703","-0.0690","-0.0347"
"17.6800","1.4684","0.5684","4.4870","-0.0701","-0.0353"
"17.7600","1.4754","0.5727","4.5210","-0.0688","-0.0346"
"17.8400","1.4822","0.5775","4.5587","-0.0700","-0.0352"
"17.9200","1.4886","0.5817","4.5923","-0.0713","-0.0359"
"18.0000","1.4951","0.5849","4.6171","-0.0708","-0.0356"
"18.0800","1.5020","0.5883","4.6443","-0.0714","-0.0359"
"18.1600","1.5087","0.5926","4.6784","-0.0718","-0.0361"
"18.2400","1.5153","0.5982","4.7219","-0.0714","-0.0359"
"18.3200","1.5219","0.6019","4.7511","-0.0741","-0.0373"
"18.4000","1.5287","0.6052","4.7778","-0.0745","-0.0375"
"18.4800","1.5353","0.6087","4.8051","-0.0751","-0.0378"
"18.5600","1.5419","0.6145","4.8510","-0.0735","-0.0370"
"18.6400","1.5484","0.6193","4.8886","-0.0745","-0.0375"
"18.7200","1.5550","0.6221","4.9107","-0.0747","-0.0376"
"18.8000","1.5617","0.6261","4.9424","-0.0756","-0.0381"
"18.8800","1.5686","0.6313","4.9832","-0.0750","-0.0378"
"18.9600","1.5755","0.6361","5.0213","-0.0756","-0.0381"
"19.0400","1.5819","0.6397","5.0497","-0.0776","-0.0390"
"19.1200","1.5884","0.6426","5.0725","-0.0776","-0.0390"
"19.2000","1.5953","0.6473","5.1098","-0.0781","-0.0393"
"19.2800","1.6021","0.6518","5.1454","-0.0771","-0.0388"
"19.3600","1.6085","0.6572","5.1883","-0.0773","-0.0389"
"19.4400","1.6151","0.6609","5.2173","-0.0767","-0.0386"
"19.5200","1.6220","0.6649","5.2492","-0.0786","-0.0395"
"19.6000","1.6287","0.6691","5.2818","-0.0773","-0.0389"
"19.6800","1.6353","0.6760","5.3366","-0.0794","-0.0399"
"19.7600","1.6418","0.6813","5.3783","-0.0796","-0.0400"
"19.8400","1.6484","0.6843","5.4019","-0.0798","-0.0402"
"19.9200","1.6551","0.6894","5.4419","-0.0804","-0.0405"
"20.0000","1.6619","0.6957","5.4920","-0.0817","-0.0411"
"20.0800","1.6687","0.7025","5.5460","-0.0810","-0.0408"
"20.1600","1.6754","0.7060","5.5732","-0.0816","-0.0411"
"20.2400","1.6818","0.7110","5.6127","-0.0815","-0.0410"
"20.3200","1.6886","0.7164","5.6553","-0.0827","-0.0416"
"20.4000","1.6955","0.7237","5.7131","-0.0835","-0.0420"
"20.4800","1.7019","0.7291","5.7559","-0.0836","-0.0420"
"20.5600","1.7085","0.7334","5.7893","-0.0839","-0.0422"
"20.6400","1.7153","0.7389","5.8328","-0.0845","-0.0425"
"20.7200","1.7222","0.7450","5.8814","-0.0844","-0.0425"
"20.8000","1.7286","0.7518","5.9347","-0.0848","-0.0427"
"20.8800","1.7351","0.7568","5.9740","-0.0858","-0.0432"
"20.9600","1.7419","0.7621","6.0161","-0.0853","-0.0429"
"21.0400","1.7486","0.7679","6.0619","-0.0848","-0.0427"
"21.1200","1.7553","0.7763","6.1278","-0.0857","-0.0431"
"21.2000","1.7618","0.7833","6.1837","-0.0856","-0.0431"
"21.2800","1.7687","0.7884","6.2236","-0.0867","-0.0436"
"21.3600","1.7753","0.7940","6.2680","-0.0873","-0.0439"
"21.4400","1.7821","0.8024","6.3339","-0.0874","-0.0440"
"21.5200","1.7888","0.8105","6.3980","-0.0871","-0.0438"
"21.6000","1.7952","0.8162","6.4429","-0.0877","-0.0441"
"21.6800","1.8017","0.8228","6.4956","-0.0899","-0.0452"
"21.7600","1.8086","0.8302","6.5539","-0.0883","-0.0444"
"21.8400","1.8156","0.8389","6.6226","-0.0890","-0.0448"
"21.9200","1.8220","0.8463","6.6805","-0.0893","-0.0449"
"22.0000","1.8284","0.8526","6.7305","-0.0906","-0.0456"
"22.0800","1.8352","0.8597","6.7866","-0.0909","-0.0457"
"22.1600","1.8419","0.8682","6.8533","-0.0918","-0.0462"
"22.2400","1.8484","0.8781","6.9320","-0.0910","-0.0458"
"22.3200","1.8550","0.8857","6.9916","-0.0918","-0.0462"
"22.4000","1.8619","0.8942","7.0592","-0.0929","-0.0467"
"22.4800","1.8688","0.9027","7.1257","-0.0914","-0.0460"
"22.5600","1.8754","0.9138","7.2136","-0.0914","-0.0460"
"22.6400","1.8819","0.9237","7.2916","-0.0925","-0.0466"
"22.7200","1.8886","0.9313","7.3517","-0.0925","-0.0465"
"22.8000","1.8951","0.9396","7.4177","-0.0933","-0.0470"
"22.8800","1.9019","0.9510","7.5075","-0.0928","-0.0467"
"22.9600","1.9088","0.9631","7.6031","-0.0921","-0.0463"
"23.0400","1.9154","0.9714","7.6682","-0.0938","-0.0472"
"23.1200","1.9217","0.9742","7.6906","-0.0942","-0.0474"
"23.2000","1.9286","0.9600","7.5785","-0.0957","-0.0482"
"23.2800","1.9354","0.9792","7.7299","-0.0940","-0.0473"
"23.3600","1.9418","0.9934","7.8420","-0.0944","-0.0475"
"23.4400","1.9483","1.0023","7.9126","-0.0941","-0.0473"
"23.5200","1.9553","1.0109","7.9798","-0.0948","-0.0477"
"23.6000","1.9622","1.0204","8.0554","-0.0939","-0.0472"
"23.6800","1.9688","1.0310","8.1392","-0.0930","-0.0468"
"23.7600","1.9753","1.0416","8.2227","-0.0937","-0.0472"
"23.8400","1.9819","1.0493","8.2833","-0.0931","-0.0469"
"23.9200","1.9885","1.0590","8.3598","-0.0951","-0.0478"
"24.0000","1.9953","1.0711","8.4554","-0.0941","-0.0473"
"24.0800","2.0021","1.0826","8.5459","-0.0955","-0.0480"
"24.1600","2.0085","1.0917","8.6184","-0.0953","-0.0479"
"24.2400","2.0154","1.1009","8.6905","-0.0958","-0.0482"
"24.3200","2.0220","1.1111","8.7710","-0.0968","-0.0487"
"24.4000","2.0287","1.1247","8.8787","-0.0960","-0.0483"
"24.4800","2.0351","1.1352","8.9611","-0.0964","-0.0485"
"24.5600","2.0416","1.1450","9.0388","-0.0963","-0.0485"
"24.6400","2.0487","1.1560","9.1256","-0.0954","-0.0480"
"24.7200","2.0555","1.1685","9.2244","-0.0959","-0.0483"
"24.8000","2.0621","1.1822","9.3324","-0.0959","-0.0482"
"24.8800","2.0686","1.1931","9.4186","-0.0952","-0.0479"
"24.9600","2.0752","1.2035","9.5003","-0.0952","-0.0479"
"25.0400","2.0820","1.2148","9.5899","-0.0960","-0.0483"
"25.1200","2.0886","1.2295","9.7056","-0.0955","-0.0481"
"25.2000","2.0952","1.2427","9.8098","-0.0957","-0.0482"
"25.2800","2.1019","1.2528","9.8900","-0.0948","-0.0477"
"25.3600","2.1086","1.2638","9.9767","-0.0947","-0.0477"
"25.4400","2.1153","1.2778","10.0871","-0.0943","-0.0475"
"25.5200","2.1220","1.2912","10.1931","-0.0954","-0.0480"
"25.6000","2.1284","1.3030","10.2864","-0.0960","-0.0483"
"25.6800","2.1350","1.3139","10.3723","-0.0957","-0.0482"
"25.7600","2.1419","1.3278","10.4815","-0.0958","-0.0482"
"25.8400","2.1487","1.3420","10.5935","-0.0948","-0.0477"
"25.9200","2.1553","1.3559","10.7033","-0.0944","-0.0475"
"26.0000","2.1618","1.3672","10.7932","-0.0941","-0.0473"
"26.0800","2.1686","1.3797","10.8919","-0.0960","-0.0483"
"26.1600","2.1754","1.3939","11.0035","-0.0956","-0.0481"
"26.2400","2.1819","1.4100","11.1307","-0.0947","-0.0476"
"26.3200","2.1884","1.4236","11.2383","-0.0936","-0.0471"
"26.4000","2.1952","1.4358","11.3347","-0.0946","-0.0476"
"26.4800","2.2019","1.4497","11.4439","-0.0932","-0.0469"
"26.5600","2.2087","1.4661","11.5732","-0.0946","-0.0476"
"26.6400","2.2153","1.4822","11.7006","-0.0942","-0.0474"
"26.7200","2.2219","1.4949","11.8007","-0.0948","-0.0477"
"26.8000","2.2283","1.5070","11.8962","-0.0954","-0.0480"
"26.8800","2.2352","1.5237","12.0281","-0.0948","-0.0477"
"26.9600","2.2420","1.5410","12.1648","-0.0939","-0.0473"
"27.0400","2.2487","1.5553","12.2775","-0.0944","-0.0475"
"27.1200","2.2552","1.5686","12.3827","-0.0938","-0.0472"
"27.2000","2.2619","1.5828","12.4949","-0.0940","-0.0473"
"27.2800","2.2689","1.6002","12.6322","-0.0936","-0.0471"
"27.3600","2.2753","1.6149","12.7480","-0.0939","-0.0472"
"27.4400","2.2817","1.6290","12.8598","-0.0928","-0.0467"
"27.5200","2.2886","1.6433","12.9721","-0.0928","-0.0467"
"27.6000","2.2955","1.6580","13.0887","-0.0923","-0.0465"
"27.6800","2.3022","1.6757","13.2282","-0.0931","-0.0468"
"27.7600","2.3086","1.6904","13.3442","-0.0934","-0.0470"
"27.8400","2.3152","1.7038","13.4497","-0.0925","-0.0465"
"27.9200","2.3218","1.7180","13.5621","-0.0913","-0.0459"
"28.0000","2.3285","1.7359","13.7038","-0.0912","-0.0459"
"28.0800","2.3352","1.7541","13.8474","-0.0902","-0.0454"
"28.1600","2.3419","1.7684","13.9601","-0.0897","-0.0451"
"28.2400","2.3486","1.7827","14.0729","-0.0894","-0.0450"
"28.3200","2.3553","1.7989","14.2008","-0.0866","-0.0436"
"28.4000","2.3622","1.8182","14.3532","-0.0872","-0.0439"
"28.4800","2.3687","1.8339","14.4767","-0.0861","-0.0433"
"28.5600","2.3750","1.8473","14.5827","-0.0864","-0.0435"
"28.6400","2.3818","1.8638","14.7129","-0.0847","-0.0426"
"28.7200","2.3888","1.8832","14.8660","-0.0831","-0.0418"
"28.8000","2.3953","1.8998","14.9974","-0.0828","-0.0417"
"28.8800","2.4019","1.9165","15.1292","-0.0824","-0.0415"
"28.9600","2.4085","1.9309","15.2426","-0.0805","-0.0405"
"29.0400","2.4153","1.9478","15.3762","-0.0794","-0.0399"
"29.1200","2.4219","1.9667","15.5252","-0.0785","-0.0395"
"29.2000","2.4284","1.9841","15.6626","-0.0779","-0.0392"
"29.2800","2.4352","1.9999","15.7874","-0.0774","-0.0389"
"29.3600","2.4419","2.0150","15.9066","-0.0744","-0.0375"
"29.4400","2.4486","2.0349","16.0633","-0.0746","-0.0375"
"29.5200","2.4554","2.0546","16.2189","-0.0736","-0.0371"
"29.6000","2.4621","2.0700","16.3410","-0.0723","-0.0364"
"29.6800","2.4684","2.0847","16.4571","-0.0719","-0.0362"
"29.7600","2.4752","2.1037","16.6067","-0.0707","-0.0356"
"29.8400","2.4821","2.1252","16.7769","-0.0696","-0.0350"
"29.9200","2.4887","2.1425","16.9128","-0.0692","-0.0348"
"30.0000","2.4951","2.1586","17.0401","-0.0677","-0.0341"
"30.0800","2.5019","2.1754","17.1725","-0.0652","-0.0328"
"30.1600","2.5088","2.1960","17.3351","-0.0663","-0.0334"
"30.2400","2.5153","2.2144","17.4810","-0.0644","-0.0324"
"30.3200","2.5216","2.2329","17.6271","-0.0632","-0.0318"
"30.4000","2.5284","2.2509","17.7689","-0.0634","-0.0319"
"30.4800","2.5353","2.2684","17.9067","-0.0623","-0.0313"
"30.5600","2.5421","2.2895","18.0732","-0.0601","-0.0302"
"30.6400","2.5487","2.3096","18.2320","-0.0587","-0.0295"
"30.7200","2.5554","2.3269","18.3688","-0.0589","-0.0296"
"30.8000","2.5619","2.3416","18.4850","-0.0578","-0.0291"
"30.8800","2.5685","2.3627","18.6512","-0.0565","-0.0284"
"30.9600","2.5753","2.3848","18.8255","-0.0561","-0.0282"
"31.0400","2.5821","2.4033","18.9716","-0.0541","-0.0272"
"31.1200","2.5885","2.4188","19.0940","-0.0542","-0.0273"
"31.2000","2.5952","2.4377","19.2432","-0.0524","-0.0264"
"31.2800","2.6022","2.4606","19.4243","-0.0516","-0.0260"
"31.3600","2.6087","2.4796","19.5745","-0.0504","-0.0253"
"31.4400","2.6150","2.4962","19.7052","-0.0491","-0.0247"
"31.5200","2.6217","2.5148","19.8524","-0.0491","-0.0247"
"31.6000","2.6287","2.5354","20.0144","-0.0465","-0.0234"
"31.6800","2.6353","2.5571","20.1857","-0.0456","-0.0229"
"31.7600","2.6420","2.5775","20.3472","-0.0447","-0.0225"
"31.8400","2.6486","2.5943","20.4795","-0.0440","-0.0221"
"31.9200","2.6553","2.6120","20.6197","-0.0429","-0.0216"
"32.0000","2.6619","2.6345","20.7972","-0.0410","-0.0206"
"32.0800","2.6686","2.6569","20.9742","-0.0412","-0.0207"
"32.1600","2.6753","2.6756","21.1217","-0.0395","-0.0199"
"32.2400","2.6818","2.6918","21.2490","-0.0403","-0.0203"
"32.3200","2.6886","2.7141","21.4256","-0.0387","-0.0195"
"32.4000","2.6954","2.7367","21.6036","-0.0362","-0.0182"
"32.4800","2.7020","2.7560","21.7565","-0.0340","-0.0171"
"32.5600","2.7083","2.7731","21.8910","-0.0341","-0.0172"
"32.6400","2.7150","2.7942","22.0574","-0.0328","-0.0165"
"32.7200","2.7220","2.8172","22.2395","-0.0327","-0.0165"
"32.8000","2.7286","2.8379","22.4029","-0.0312","-0.0157"
"32.8800","2.7352","2.8581","22.5619","-0.0309","-0.0155"
"32.9600","2.7418","2.8756","22.7003","-0.0301","-0.0152"
"33.0400","2.7487","2.8976","22.8737","-0.0277","-0.0139"
"33.1200","2.7553","2.9198","23.0493","-0.0272","-0.0137"
"33.2000","2.7618","2.9410","23.2163","-0.0270","-0.0136"
"33.2800","2.7685","2.9603","23.3692","-0.0246","-0.0124"
"33.3600","2.7752","2.9783","23.5109","-0.0231","-0.0116"
"33.4400","2.7820","3.0015","23.6945","-0.0230","-0.0116"
"33.5200","2.7887","3.0257","23.8854","-0.0219","-0.0110"
"33.6000","2.7953","3.0457","24.0434","-0.0198","-0.0100"
"33.6800","2.8016","3.0619","24.1709","-0.0195","-0.0098"
"33.7600","2.8084","3.0837","24.3428","-0.0172","-0.0087"
"33.8400","2.8152","3.1093","24.5455","-0.0159","-0.0080"
"33.9200","2.8220","3.1305","24.7125","-0.0146","-0.0074"
"34.0000","2.8285","3.1499","24.8659","-0.0122","-0.0061"
"34.0800","2.8352","3.1692","25.0176","-0.0135","-0.0068"
"34.1600","2.8421","3.1918","25.1964","-0.0114","-0.0057"
"34.2400","2.8488","3.2153","25.3816","-0.0100","-0.0050"
"34.3200","2.8553","3.2354","25.5410","-0.0102","-0.0052"
"34.4000","2.8617","3.2537","25.6851","-0.0072","-0.0036"
"34.4800","2.8687","3.2768","25.8674","-0.0065","-0.0033"
"34.5600","2.8754","3.2992","26.0441","-0.0056","-0.0028"
"34.6400","2.8821","3.3239","26.2391","-0.0030","-0.0015"
"34.7200","2.8886","3.3426","26.3869","-0.0041","-0.0021"
"34.8000","2.8952","3.3614","26.5349","-0.0014","-0.0007"
"34.8800","2.9018","3.3832","26.7071","0.0002","0.0001"
"34.9600","2.9085","3.4099","26.9179","0.0028","0.0014"
"35.0400","2.9152","3.4314","27.0880","0.0015","0.0007"
"35.1200","2.9217","3.4490","27.2265","0.0030","0.0015"
"35.2000","2.9286","3.4722","27.4096","0.0039","0.0020"
"35.2800","2.9355","3.4966","27.6026","0.0047","0.0024"
"35.3600","2.9422","3.5198","27.7860","0.0084","0.0042"
"35.4400","2.9486","3.5393","27.9400","0.0069","0.0035"
"35.5200","2.9551","3.5585","28.0910","0.0088","0.0044"
"35.6000","2.9619","3.5833","28.2872","0.0097","0.0049"
"35.6800","2.9687","3.6081","28.4825","0.0101","0.0051"
"35.7600","2.9753","3.6310","28.6638","0.0111","0.0056"
"35.8400","2.9820","3.6511","28.8221","0.0125","0.0063"
"35.9200","2.9886","3.6711","28.9802","0.0143","0.0072"
"36.0000","2.9953","3.6960","29.1768","0.0151","0.0076"
"36.0800","3.0018","3.7202","29.3680","0.0170","0.0085"
"36.1600","3.0084","3.7424","29.5425","0.0163","0.0082"
"36.2400","3.0151","3.7616","29.6946","0.0170","0.0086"
"36.3200","3.0219","3.7847","29.8766","0.0191","0.0096"
"36.4000","3.0288","3.8122","30.0938","0.0211","0.0106"
"36.4800","3.0354","3.8336","30.2630","0.0217","0.0109"
"36.5600","3.0418","3.8528","30.4141","0.0230","0.0116"
"36.6400","3.0484","3.8734","30.5769","0.0209","0.0105"
"36.7200","3.0553","3.9010","30.7950","0.0243","0.0122"
"36.8000","3.0621","3.9259","30.9916","0.0234","0.0118"
"36.8800","3.0686","3.9464","31.1530","0.0244","0.0123"
"36.9600","3.0752","3.9665","31.3120","0.0246","0.0124"
"37.0400","3.0820","3.9898","31.4956","0.0261","0.0131"
"37.1200","3.0887","4.0143","31.6893","0.0275","0.0139"
"37.2000","3.0951","4.0380","31.8765","0.0290","0.0146"
"37.2800","3.1016","4.0590","32.0425","0.0302","0.0152"
"37.3600","3.1086","4.0815","32.2195","0.0291","0.0146"
"37.4400","3.1152","4.1040","32.3977","0.0300","0.0151"
"37.5200","3.1221","4.1322","32.6200","0.0322","0.0162"
"37.6000","3.1288","4.1553","32.8026","0.0323","0.0162"
"37.6800","3.1352","4.1718","32.9325","0.0337","0.0170"
"37.7600","3.1419","4.1956","33.1209","0.0364","0.0183"
"37.8400","3.1487","4.2230","33.3364","0.0354","0.0178"
"37.9200","3.1554","4.2475","33.5299","0.0356","0.0179"
"38.0000","3.1618","4.2666","33.6809","0.0359","0.0180"
"38.0800","3.1684","4.2880","33.8502","0.0383","0.0193"
"38.1600","3.1755","4.3155","34.0669","0.0381","0.0192"
"38.2400","3.1821","4.3383","34.2469","0.0360","0.0181"
"38.3200","3.1884","4.3611","34.4273","0.0400","0.0201"
"38.4000","3.1950","4.3809","34.5832","0.0394","0.0198"
"38.4800","3.2019","4.4055","34.7776","0.0421","0.0212"
"38.5600","3.2087","4.4310","34.9789","0.0407","0.0205"
"38.6400","3.2153","4.4569","35.1828","0.0423","0.0213"
"38.7200","3.2220","4.4786","35.3542","0.0425","0.0214"
"38.8000","3.2285","4.4967","35.4973","0.0434","0.0218"
"38.8800","3.2353","4.5229","35.7043","0.0452","0.0228"
"38.9600","3.2421","4.5511","35.9269","0.0450","0.0226"
"39.0400","3.2486","4.5738","36.1058","0.0452","0.0227"
"39.1200","3.2551","4.5925","36.2540","0.0459","0.0231"
"39.2000","3.2618","4.6166","36.4439","0.0443","0.0223"
"39.2800","3.2687","4.6454","36.6711","0.0472","0.0237"
"39.3600","3.2754","4.6698","36.8641","0.0480","0.0241"
"39.4400","3.2818","4.6896","37.0200","0.0473","0.0238"
"39.5200","3.2882","4.7102","37.1827","0.0485","0.0244"
"39.6000","3.2952","4.7390","37.4102","0.0480","0.0241"
"39.6800","3.3020","4.7648","37.6139","0.0499","0.0251"
"39.7600","3.3085","4.7885","37.8005","0.0479","0.0241"
"39.8400","3.3151","4.8088","37.9613","0.0501","0.0252"
"39.9200","3.3220","4.8335","38.1558","0.0508","0.0256"
"40.0000","3.3287","4.8584","38.3528","0.0509","0.0256"
"40.0800","3.3353","4.8851","38.5637","0.0540","0.0272"
"40.1600","3.3418","4.9079","38.7437","0.0524","0.0264"
"40.2400","3.3484","4.9277","38.8999","0.0535","0.0269"
"40.3200","3.3552","4.9529","39.0989","0.0520","0.0262"
"40.4000","3.3620","4.9825","39.3322","0.0536","0.0270"
"40.4800","3.3688","5.0078","39.5319","0.0568","0.0286"
"40.5600","3.3751","5.0253","39.6704","0.0564","0.0284"
"40.6400","3.3818","5.0496","39.8622","0.0555","0.0279"
"40.7200","3.3884","5.0741","40.0558","0.0550","0.0277"
"40.8000","3.3953","5.1053","40.3014","0.0573","0.0288"
"40.8800","3.4019","5.1263","40.4678","0.0583","0.0294"
"40.9600","3.4084","5.1478","40.6375","0.0572","0.0288"
"41.0400","3.4155","5.1753","40.8540","0.0589","0.0296"
"41.1200","3.4221","5.1983","41.0361","0.0593","0.0299"
"41.2000","3.4287","5.2274","41.2659","0.0592","0.0298"
"41.2800","3.4351","5.2470","41.4201","0.0594","0.0299"
"41.3600","3.4418","5.2705","41.6062","0.0604","0.0304"
"41.4400","3.4486","5.2974","41.8181","0.0608","0.0306"
"41.5200","3.4553","5.3261","42.0447","0.0631","0.0317"
"41.6000","3.4621","5.3519","42.2486","0.0642","0.0323"
"41.6800","3.4686","5.3696","42.3886","0.0634","0.0319"
"41.7600","3.4752","5.3936","42.5779","0.0629","0.0316"
"41.8400","3.4820","5.4232","42.8110","0.0626","0.0315"
"41.9200","3.4886","5.4488","43.0134","0.0631","0.0318"
"42.0000","3.4951","5.4723","43.1988","0.0640","0.0322"
"42.0800","3.5018","5.4939","43.3695","0.0661","0.0333"
"42.1600","3.5087","5.5212","43.5851","0.0657","0.0331"
"42.2400","3.5155","5.5499","43.8112","0.0652","0.0328"
"42.3200","3.5220","5.5742","44.0035","0.0677","0.0341"
"42.4000","3.5285","5.5948","44.1659","0.0682","0.0343"
"42.4800","3.5351","5.6176","44.3458","0.0670","0.0337"
"42.5600","3.5420","5.6481","44.5866","0.0672","0.0338"
"42.6400","3.5487","5.6755","44.8028","0.0683","0.0343"
"42.7200","3.5553","5.6973","44.9754","0.0677","0.0341"
"42.8000","3.5619","5.7200","45.1542","0.0676","0.0340"
"42.8800","3.5686","5.7444","45.3467","0.0702","0.0353"
"42.9600","3.5754","5.7743","45.5827","0.0699","0.0352"
"43.0400","3.5818","5.7987","45.7758","0.0707","0.0356"
"43.1200","3.5884","5.8203","45.9461","0.0699","0.0352"
"43.2000","3.5950","5.8451","46.1416","0.0703","0.0354"
"43.2800","3.6020","5.8747","46.3758","0.0717","0.0361"
"43.3600","3.6088","5.9034","46.6020","0.0725","0.0365"
"43.4400","3.6153","5.9246","46.7697","0.0722","0.0363"
"43.5200","3.6217","5.9451","46.9310","0.0703","0.0354"
"43.6000","3.6286","5.9731","47.1520","0.0717","0.0361"
"43.6800","3.6354","6.0019","47.3794","0.0726","0.0365"
"43.7600","3.6419","6.0275","47.5817","0.0738","0.0371"
"43.8400","3.6484","6.0497","47.7566","0.0724","0.0364"
"43.9200","3.6554","6.0772","47.9738","0.0744","0.0374"
"44.0000","3.6621","6.0987","48.1437","0.0747","0.0376"
"44.0800","3.6687","6.1290","48.3832","0.0745","0.0375"
"44.1600","3.6752","6.1528","48.5708","0.0759","0.0382"
"44.2400","3.6816","6.1733","48.7329","0.0762","0.0384"
"44.3200","3.6884","6.2009","48.9505","0.0762","0.0384"
"44.4000","3.6953","6.2305","49.1842","0.0773","0.0389"
"44.4800","3.7022","6.2595","49.4134","0.0777","0.0391"
"44.5600","3.7088","6.2794","49.5704","0.0764","0.0384"
"44.6400","3.7151","6.3003","49.7349","0.0779","0.0392"
"44.7200","3.7220","6.3306","49.9741","0.0776","0.0391"
"44.8000","3.7288","6.3589","50.1975","0.0787","0.0396"
"44.8800","3.7352","6.3820","50.3801","0.0791","0.0398"
"44.9600","3.7418","6.4047","50.5590","0.0785","0.0395"
"45.0400","3.7487","6.4321","50.7753","0.0806","0.0405"
"45.1200","3.7555","6.4603","50.9983","0.0819","0.0412"
"45.2000","3.7620","6.4852","51.1949","0.0804","0.0405"
"45.2800","3.7684","6.5089","51.3815","0.0800","0.0403"
"45.3600","3.7751","6.5316","51.5612","0.0819","0.0412"
"45.4400","3.7818","6.5595","51.7810","0.0823","0.0414"
"45.5200","3.7886","6.5907","52.0280","0.0823","0.0414"
"45.6000","3.7954","6.6163","52.2300","0.0832","0.0418"
"45.6800","3.8019","6.6368","52.3915","0.0845","0.0425"
"45.7600","3.8085","6.6611","52.5832","0.0851","0.0428"
"45.8400","3.8153","6.6922","52.8290","0.0822","0.0414"
"45.9200","3.8221","6.7202","53.0499","0.0848","0.0427"
"46.0000","3.8284","6.7396","53.2031","0.0846","0.0426"
"46.0800","3.8351","6.7653","53.4062","0.0845","0.0425"
"46.1600","3.8420","6.7945","53.6367","0.0845","0.0425"
"46.2400","3.8489","6.8229","53.8606","0.0858","0.0432"
"46.3200","3.8553","6.8454","54.0387","0.0863","0.0434"
"46.4000","3.8617","6.8687","54.2224","0.0862","0.0434"
"46.4800","3.8685","6.8954","54.4329","0.0880","0.0443"
"46.5600","3.8752","6.9229","54.6504","0.0868","0.0437"
"46.6400","3.8818","6.9521","54.8804","0.0883","0.0444"
"46.7200","3.8884","6.9758","55.0679","0.0889","0.0447"
"46.8000","3.8952","7.0010","55.2668","0.0881","0.0443"
"46.8800","3.9019","7.0253","55.4587","0.0888","0.0447"
"46.9600","3.9087","7.0565","55.7051","0.0895","0.0450"
"47.0400","3.9154","7.0830","55.9140","0.0890","0.0448"
"47.1200","3.9218","7.1027","56.0692","0.0918","0.0462"
"47.2000","3.9284","7.1279","56.2683","0.0901","0.0453"
"47.2800","3.9353","7.1584","56.5088","0.0918","0.0462"
"47.3600","3.9421","7.1894","56.7540","0.0919","0.0462"
"47.4400","3.9487","7.2110","56.9247","0.0936","0.0471"
"47.5200","3.9551","7.2323","57.0926","0.0911","0.0459"
"47.6000","3.9618","7.2600","57.3114","0.0948","0.0477"
"47.6800","3.9686","7.2904","57.5510","0.0940","0.0473"
"47.7600","3.9752","7.3175","57.7654","0.0956","0.0481"
"47.8400","3.9817","7.3402","57.9440","0.0952","0.0479"
"47.9200","3.9886","7.3678","58.1618","0.0959","0.0483"
"48.0000","3.9953","7.3931","58.3616","0.0938","0.0472"
"48.0800","4.0021","7.4237","58.6036","0.0963","0.0484"
"48.1600","4.0087","7.4498","58.8097","0.0963","0.0485"
"48.2400","4.0153","7.4707","58.9746","0.0975","0.0491"
"48.3200","4.0218","7.4943","59.1606","0.0969","0.0487"
"48.4000","4.0287","7.5280","59.4269","0.0977","0.0492"
"48.4800","4.0354","7.5552","59.6414","0.0973","0.0490"
"48.5600","4.0420","7.5791","59.8303","0.0962","0.0484"
"48.6400","4.0485","7.6001","59.9958","0.0973","0.0490"
"48.7200","4.0553","7.6301","60.2330","0.0986","0.0496"
"48.8000","4.0621","7.6603","60.4716","0.0982","0.0494"
"48.8800","4.0684","7.6826","60.6475","0.0975","0.0490"
"48.9600","4.0750","7.7065","60.8358","0.0986","0.0496"
"49.0400","4.0819","7.7358","61.0674","0.0997","0.0502"
"49.1200","4.0887","7.7631","61.2831","0.1003","0.0505"
"49.2000","4.0955","7.7928","61.5172","0.1003","0.0505"
"49.2800","4.1019","7.8141","61.6849","0.0993","0.0500"
"49.3600","4.1085","7.8381","61.8751","0.0999","0.0503"
"49.4400","4.1151","7.8637","62.0767","0.1013","0.0510"
"49.5200","4.1220","7.8963","62.3343","0.1005","0.0506"
"49.6000","4.1286","7.9208","62.5280","0.0996","0.0501"
"49.6800","4.1353","7.9437","62.7085","0.1015","0.0511"
"49.7600","4.1420","7.9683","62.9029","0.1010","0.0508"
"49.8400","4.1486","7.9901","63.0745","0.1019","0.0513"
"49.9200","4.1554","8.0205","63.3150","0.0988","0.0497"
"50.0000","4.1617","8.0376","63.4497","0.1001","0.0504"
"50.0800","4.1682","8.0526","63.5680","0.0986","0.0496"
"50.1600","4.1753","8.0768","63.7591","0.0978","0.0492"
"50.2400","4.1820","8.0933","63.8891","0.0967","0.0486"
"50.3200","4.1887","8.1076","64.0019","0.0950","0.0478"
"50.4000","4.1953","8.1032","63.9675","0.0891","0.0448"
"50.4800","4.2019","8.0756","63.7493","0.0798","0.0401"
"50.5600","4.2088","7.9785","62.9828","0.0628","0.0316"
"50.6400","4.2153","7.6891","60.6989","0.0280","0.0141"
"50.7200","4.2220","7.0894","55.9648","-0.0185","-0.0093"
"50.8000","4.2288","6.4624","51.0149","-0.0401","-0.0202"
"50.8800","4.2354","6.1042","48.1872","-0.0457","-0.0230"
"50.9600","4.2422","5.9060","46.6228","-0.0488","-0.0245"
"51.0400","4.2487","5.7774","45.6077","-0.0515","-0.0259"
"51.1200","4.2553","5.6895","44.9135","-0.0541","-0.0272"
"51.2000","4.2616","5.6226","44.3852","-0.0552","-0.0278"
"51.2800","4.2685","5.5830","44.0726","-0.0565","-0.0284"
"51.3600","4.2755","5.5518","43.8268","-0.0577","-0.0290"
"51.4400","4.2821","5.5149","43.5353","-0.0585","-0.0294"
"51.5200","4.2885","5.4740","43.2125","-0.0595","-0.0299"
"51.6000","4.2953","5.4396","42.9407","-0.0599","-0.0301"
"51.6800","4.3022","5.4103","42.7096","-0.0596","-0.0300"
"51.7600","4.3087","5.3715","42.4029","-0.0612","-0.0308"
"51.8400","4.3151","5.3333","42.1017","-0.0612","-0.0308"
"51.9200","4.3220","5.2940","41.7912","-0.0609","-0.0307"
"52.0000","4.3286","5.2445","41.4009","-0.0608","-0.0306"
"52.0800","4.3355","5.1972","41.0269","-0.0589","-0.0297"
"52.1600","4.3420","5.1379","40.5589","-0.0574","-0.0289"
"52.2400","4.3486","5.0754","40.0658","-0.0569","-0.0286"
"52.3200","4.3551","5.0055","39.5137","-0.0561","-0.0282"
"52.4000","4.3619","4.9075","38.7405","-0.0510","-0.0257"
"52.4800","4.3688","4.7603","37.5783","-0.0449","-0.0226"
"52.5600","4.3754","4.5623","36.0152","-0.0373","-0.0188"
"52.6400","4.3819","4.3599","34.4174","-0.0334","-0.0168"
"52.7200","4.3887","4.2203","33.3158","-0.0328","-0.0165"
"52.8000","4.3956","4.1126","32.4654","-0.0320","-0.0161"
"52.8800","4.4021","4.0392","31.8855","-0.0332","-0.0167"
"52.9600","4.4084","3.9855","31.4619","-0.0340","-0.0171"
"53.0400","4.4152","3.9491","31.1743","-0.0343","-0.0172"
"53.1200","4.4220","3.9233","30.9713","-0.0362","-0.0182"
"53.2000","4.4287","3.9059","30.8338","-0.0356","-0.0179"
"53.2800","4.4353","3.8866","30.6813","-0.0378","-0.0190"
"53.3600","4.4419","3.8670","30.5265","-0.0386","-0.0194"
"53.4400","4.4485","3.8508","30.3984","-0.0381","-0.0192"
"53.5200","4.4552","3.8418","30.3275","-0.0403","-0.0203"
"53.6000","4.4619","3.8316","30.2469","-0.0408","-0.0205"
"53.6800","4.4685","3.8147","30.1137","-0.0422","-0.0212"
"53.7600","4.4752","3.8012","30.0069","-0.0436","-0.0220"
"53.8400","4.4820","3.7916","29.9313","-0.0427","-0.0215"
"53.9200","4.4888","3.7829","29.8623","-0.0438","-0.0220"
"54.0000","4.4954","3.7694","29.7557","-0.0442","-0.0222"
"54.0800","4.5016","3.7513","29.6131","-0.0457","-0.0230"
"54.1600","4.5085","3.7447","29.5609","-0.0465","-0.0234"
"54.2400","4.5154","3.7342","29.4785","-0.0476","-0.0239"
"54.3200","4.5220","3.7202","29.3676","-0.0494","-0.0249"
"54.4000","4.5285","3.6950","29.1683","-0.0489","-0.0246"
"54.4800","4.5352","3.6755","29.0148","-0.0507","-0.0255"
"54.5600","4.5420","3.6609","28.8996","-0.0519","-0.0261"
"54.6400","4.5486","3.6494","28.8089","-0.0528","-0.0266"
"54.7200","4.5550","3.6387","28.7242","-0.0530","-0.0267"
"54.8000","4.5618","3.6259","28.6235","-0.0540","-0.0272"
"54.8800","4.5686","3.6131","28.5222","-0.0548","-0.0276"
"54.9600","4.5754","3.6071","28.4752","-0.0568","-0.0286"
"55.0400","4.5821","3.6015","28.4303","-0.0575","-0.0289"
"55.1200","4.5887","3.5913","28.3498","-0.0570","-0.0287"
"55.2000","4.5951","3.5780","28.2448","-0.0580","-0.0292"
"55.2800","4.6018","3.5749","28.2209","-0.0580","-0.0292"
"55.3600","4.6088","3.5754","28.2249","-0.0594","-0.0299"
"55.4400","4.6154","3.5636","28.1317","-0.0606","-0.0305"
"55.5200","4.6218","3.5510","28.0319","-0.0599","-0.0302"
"55.6000","4.6286","3.5468","27.9986","-0.0622","-0.0313"
"55.6800","4.6355","3.5467","27.9978","-0.0605","-0.0305"
"55.7600","4.6420","3.5396","27.9422","-0.0631","-0.0318"
"55.8400","4.6483","3.5311","27.8749","-0.0635","-0.0319"
"55.9200","4.6549","3.5256","27.8316","-0.0634","-0.0319"
"56.0000","4.6620","3.5261","27.8355","-0.0652","-0.0328"
"56.0800","4.6688","3.5214","27.7980","-0.0646","-0.0325"
"56.1600","4.6754","3.5157","27.7535","-0.0665","-0.0334"
"56.2400","4.6820","3.5063","27.6795","-0.0686","-0.0345"
"56.3200","4.6886","3.4988","27.6200","-0.0686","-0.0345"
"56.4000","4.6953","3.4970","27.6057","-0.0689","-0.0346"
"56.4800","4.7019","3.4967","27.6030","-0.0696","-0.0350"
"56.5600","4.7086","3.4915","27.5623","-0.0703","-0.0354"
"56.6400","4.7151","3.4830","27.4949","-0.0718","-0.0361"
"56.7200","4.7220","3.4822","27.4886","-0.0713","-0.0359"
"56.8000","4.7288","3.4812","27.4810","-0.0715","-0.0360"
"56.8800","4.7354","3.4751","27.4329","-0.0733","-0.0369"
"56.9600","4.7416","3.4644","27.3487","-0.0731","-0.0368"
"57.0400","4.7484","3.4639","27.3443","-0.0742","-0.0374"
"57.1200","4.7553","3.4641","27.3462","-0.0741","-0.0373"
"57.2000","4.7621","3.4615","27.3255","-0.0760","-0.0383"
"57.2800","4.7686","3.4549","27.2733","-0.0773","-0.0389"
"57.3600","4.7752","3.4472","27.2125","-0.0785","-0.0395"
"57.4400","4.7821","3.4445","27.1909","-0.0794","-0.0400"
"57.5200","4.7887","3.4401","27.1564","-0.0801","-0.0403"
"57.6000","4.7952","3.4385","27.1436","-0.0799","-0.0402"
"57.6800","4.8019","3.4337","27.1057","-0.0819","-0.0412"
"57.7600","4.8085","3.4248","27.0357","-0.0824","-0.0414"
"57.8400","4.8153","3.4240","27.0293","-0.0836","-0.0420"
"57.9200","4.8220","3.4237","27.0272","-0.0843","-0.0424"
"58.0000","4.8287","3.4208","27.0042","-0.0846","-0.0426"
"58.0800","4.8350","3.4096","26.9158","-0.0856","-0.0431"
"58.1600","4.8415","3.4064","26.8908","-0.0863","-0.0434"
"58.2400","4.8486","3.4142","26.9520","-0.0863","-0.0434"
"58.3200","4.8555","3.4092","26.9129","-0.0875","-0.0440"
"58.4000","4.8619","3.4023","26.8581","-0.0892","-0.0449"
"58.4800","4.8686","3.3956","26.8055","-0.0899","-0.0452"
"58.5600","4.8755","3.3934","26.7880","-0.0892","-0.0449"
"58.6400","4.8821","3.3905","26.7646","-0.0922","-0.0464"
"58.7200","4.8885","3.3871","26.7383","-0.0930","-0.0468"
"58.8000","4.8951","3.3838","26.7118","-0.0916","-0.0461"
"58.8800","4.9021","3.3811","26.6909","-0.0928","-0.0467"
"58.9600","4.9087","3.3762","26.6519","-0.0954","-0.0480"
"59.0400","4.9154","3.3790","26.6741","-0.0957","-0.0481"
"59.1200","4.9221","3.3741","26.6355","-0.0948","-0.0477"
"59.2000","4.9285","3.3382","26.3520","-0.0972","-0.0489"
"59.2800","4.9351","3.3291","26.2804","-0.0971","-0.0489"
"59.3600","4.9420","3.3310","26.2951","-0.0980","-0.0493"
"59.4400","4.9487","3.3260","26.2556","-0.1000","-0.0503"
"59.5200","4.9551","3.3164","26.1801","-0.0997","-0.0502"
"59.6000","4.9619","3.3127","26.1510","-0.1025","-0.0516"
"59.6800","4.9689","3.3122","26.1468","-0.1034","-0.0520"
"59.7600","4.9755","3.3061","26.0989","-0.1048","-0.0528"
"59.8400","4.9819","3.3004","26.0541","-0.1050","-0.0529"
"59.9200","4.9884","3.2925","25.9911","-0.1055","-0.0531"
"60.0000","4.9953","3.2909","25.9784","-0.1073","-0.0540"
"60.0800","5.0020","3.2887","25.9616","-0.1074","-0.0541"
"60.1600","5.0086","3.2859","25.9390","-0.1085","-0.0546"
"60.2400","5.0153","3.2806","25.8977","-0.1093","-0.0550"
"60.3200","5.0219","3.2729","25.8368","-0.1089","-0.0548"
"60.4000","5.0285","3.2694","25.8086","-0.1096","-0.0551"
"60.4800","5.0352","3.2697","25.8115","-0.1108","-0.0557"
"60.5600","5.0419","3.2635","25.7620","-0.1115","-0.0561"
"60.6400","5.0484","3.2530","25.6794","-0.1116","-0.0562"
"60.7200","5.0552","3.2489","25.6473","-0.1135","-0.0571"
"60.8000","5.0621","3.2482","25.6414","-0.1152","-0.0580"
"60.8800","5.0688","3.2416","25.5896","-0.1155","-0.0581"
"60.9600","5.0751","3.2301","25.4990","-0.1163","-0.0585"
"61.0400","5.0818","3.2224","25.4382","-0.1166","-0.0587"
"61.1200","5.0887","3.2196","25.4158","-0.1179","-0.0593"
"61.2000","5.0954","3.2136","25.3685","-0.1181","-0.0594"
"61.2800","5.1018","3.2055","25.3048","-0.1193","-0.0600"
"61.3600","5.1086","3.1958","25.2284","-0.1208","-0.0608"
"61.4400","5.1153","3.1871","25.1594","-0.1211","-0.0609"
"61.5200","5.1220","3.1822","25.1208","-0.1222","-0.0615"
"61.6000","5.1285","3.1788","25.0937","-0.1230","-0.0619"
"61.6800","5.1350","3.1719","25.0389","-0.1237","-0.0622"
"61.7600","5.1418","3.1636","24.9740","-0.1241","-0.0624"
"61.8400","5.1485","3.1567","24.9196","-0.1265","-0.0636"
"61.9200","5.1554","3.1552","24.9078","-0.1270","-0.0639"
"62.0000","5.1622","3.1497","24.8642","-0.1286","-0.0647"
"62.0800","5.1685","3.1366","24.7603","-0.1313","-0.0660"
"62.1600","5.1752","3.1506","24.8709","-0.1283","-0.0646"
"62.2400","5.1820","3.1663","24.9949","-0.1319","-0.0664"
"62.3200","5.1888","3.1466","24.8394","-0.1326","-0.0667"
"62.4000","5.1952","3.1236","24.6584","-0.1343","-0.0676"
"62.4800","5.2018","3.1059","24.5180","-0.1354","-0.0681"
"62.5600","5.2088","3.0967","24.4453","-0.1368","-0.0688"
"62.6400","5.2154","3.0858","24.3593","-0.1369","-0.0689"
"62.7200","5.2218","3.0765","24.2865","-0.1392","-0.0700"
"62.8000","5.2282","3.0646","24.1922","-0.1392","-0.0700"
"62.8800","5.2352","3.0586","24.1452","-0.1416","-0.0712"
"62.9600","5.2420","3.0528","24.0994","-0.1422","-0.0715"
"63.0400","5.2487","3.0489","24.0682","-0.1421","-0.0715"
"63.1200","5.2554","3.0433","24.0242","-0.1442","-0.0726"
"63.2000","5.2620","3.0329","23.9422","-0.1452","-0.0731"
"63.2800","5.2686","3.0284","23.9062","-0.1439","-0.0724"
"63.3600","5.2753","3.0294","23.9143","-0.1470","-0.0740"
"63.4400","5.2820","3.0267","23.8929","-0.1476","-0.0743"
"63.5200","5.2886","3.0192","23.8338","-0.1482","-0.0746"
"63.6000","5.2952","3.0125","23.7814","-0.1477","-0.0743"
"63.6800","5.3021","3.0126","23.7815","-0.1486","-0.0748"
"63.7600","5.3088","3.0080","23.7457","-0.1505","-0.0757"
"63.8400","5.3152","3.0019","23.6973","-0.1503","-0.0757"
"63.9200","5.3217","2.9953","23.6451","-0.1518","-0.0764"
"64.0000","5.3284","2.9935","23.6310","-0.1512","-0.0761"
"64.0800","5.3353","2.9967","23.6559","-0.1518","-0.0764"
"64.1600","5.3420","2.9917","23.6167","-0.1538","-0.0774"
"64.2400","5.3486","2.9835","23.5524","-0.1543","-0.0776"
"64.3200","5.3553","2.9776","23.5058","-0.1542","-0.0776"
"64.4000","5.3620","2.9739","23.4766","-0.1556","-0.0783"
"64.4800","5.3687","2.9752","23.4869","-0.1562","-0.0786"
"64.5600","5.3752","2.9687","23.4350","-0.1568","-0.0789"
"64.6400","5.3818","2.9600","23.3669","-0.1582","-0.0796"
"64.7200","5.3885","2.9532","23.3131","-0.1592","-0.0801"
"64.8000","5.3954","2.9533","23.3136","-0.1597","-0.0804"
"64.8800","5.4022","2.9490","23.2795","-0.1598","-0.0804"
"64.9600","5.4086","2.9367","23.1823","-0.1600","-0.0805"
"65.0400","5.4150","2.9253","23.0925","-0.1617","-0.0814"
"65.1200","5.4218","2.9216","23.0632","-0.1619","-0.0814"
"65.2000","5.4287","2.9192","23.0448","-0.1642","-0.0826"
"65.2800","5.4353","2.9112","22.9813","-0.1641","-0.0826"
"65.3600","5.4418","2.9013","22.9035","-0.1645","-0.0828"
"65.4400","5.4488","2.8956","22.8580","-0.1641","-0.0826"
"65.5200","5.4554","2.8851","22.7753","-0.1659","-0.0835"
"65.6000","5.4620","2.8814","22.7461","-0.1666","-0.0838"
"65.6800","5.4685","2.8713","22.6665","-0.1679","-0.0845"
"65.7600","5.4752","2.8607","22.5828","-0.1678","-0.0844"
"65.8400","5.4819","2.8535","22.5256","-0.1679","-0.0845"
"65.9200","5.4887","2.8479","22.4812","-0.1688","-0.0849"
"66.0000","5.4955","2.8421","22.4362","-0.1691","-0.0851"
"66.0800","5.5020","2.8270","22.3163","-0.1707","-0.0859"
"66.1600","5.5084","2.8162","22.2312","-0.1706","-0.0858"
"66.2400","5.5152","2.8131","22.2072","-0.1716","-0.0864"
"66.3200","5.5221","2.8081","22.1674","-0.1717","-0.0864"
"66.4000","5.5285","2.7957","22.0694","-0.1726","-0.0869"
"66.4800","5.5350","2.7829","21.9685","-0.1725","-0.0868"
"66.5600","5.5421","2.7788","21.9364","-0.1739","-0.0875"
"66.5840","5.5441","2.7745","21.9020","-0.1737","-0.0874"