File: composites_properties_derivations/composite_tube_tests/comp_tube_wb.csv
Specimen label,"1 WB"
Force at Maximum Load,"5.60",kN
Tensile stress at Maximum Load,"44.21",MPa
Epsilon ONE Displacement at Maximum Load,"0.01",mm
Force at Break (Standard),"1.41",kN
Tensile stress at Break (Standard),"11.11",MPa
Epsilon ONE Displacement at Break (Standard),"-0.15",mm
Slope (Chord 0.05 % - 0.2 %),"-----",MPa
Modulus (Automatic Young's),"13625.51",MPa

Specimen label,"1 WB"
Thickness,"",mm
Width,"",mm
Length,"49.86",mm
Rate 1,"5.00",mm/min
Outer diameter,"15.88",mm
Wall thickness,"3.18",mm

Time,Displacement,Force,Tensile stress,Tensile strain (Epsilon ONE Displacement),Epsilon ONE Displacement
(s),(mm),(kN),(MPa),(%),(mm)
"0.0000","0.0002","0.0500","0.3948","-0.0581","-0.0290"
"0.0500","0.0003","0.0510","0.4029","-0.0575","-0.0287"
"0.1000","0.0016","0.0758","0.5985","-0.0566","-0.0282"
"0.1500","0.0037","0.1304","1.0298","-0.0583","-0.0291"
"0.2000","0.0045","0.1420","1.1211","-0.0577","-0.0288"
"0.2500","0.0097","0.2453","1.9368","-0.0582","-0.0290"
"0.3000","0.0174","0.2637","2.0816","-0.0566","-0.0282"
"0.3500","0.0224","0.2694","2.1269","-0.0534","-0.0266"
"0.4000","0.0261","0.2781","2.1954","-0.0531","-0.0265"
"0.4500","0.0303","0.2861","2.2589","-0.0568","-0.0283"
"0.5000","0.0347","0.2937","2.3187","-0.0576","-0.0287"
"0.5500","0.0388","0.3008","2.3744","-0.0560","-0.0279"
"0.6000","0.0429","0.3088","2.4380","-0.0566","-0.0282"
"0.6500","0.0469","0.3155","2.4909","-0.0569","-0.0283"
"0.7000","0.0511","0.3207","2.5315","-0.0593","-0.0296"
"0.7500","0.0554","0.3247","2.5633","-0.0588","-0.0293"
"0.8000","0.0597","0.3284","2.5925","-0.0585","-0.0292"
"0.8500","0.0637","0.3315","2.6166","-0.0569","-0.0284"
"0.9000","0.0679","0.3345","2.6407","-0.0564","-0.0281"
"0.9500","0.0719","0.3366","2.6570","-0.0569","-0.0284"
"1.0000","0.0761","0.3394","2.6789","-0.0563","-0.0281"
"1.0500","0.0803","0.3418","2.6981","-0.0573","-0.0286"
"1.1000","0.0845","0.3444","2.7189","-0.0562","-0.0280"
"1.1500","0.0885","0.3465","2.7355","-0.0583","-0.0291"
"1.2000","0.0926","0.3480","2.7474","-0.0570","-0.0284"
"1.2500","0.0967","0.3495","2.7590","-0.0586","-0.0292"
"1.3000","0.1010","0.3515","2.7746","-0.0581","-0.0290"
"1.3500","0.1053","0.3525","2.7827","-0.0596","-0.0297"
"1.4000","0.1096","0.3538","2.7930","-0.0560","-0.0279"
"1.4500","0.1136","0.3551","2.8033","-0.0587","-0.0293"
"1.5000","0.1179","0.3566","2.8148","-0.0552","-0.0275"
"1.5500","0.1219","0.3576","2.8226","-0.0567","-0.0283"
"1.6000","0.1263","0.3597","2.8395","-0.0580","-0.0289"
"1.6500","0.1304","0.3601","2.8429","-0.0589","-0.0293"
"1.7000","0.1347","0.3616","2.8544","-0.0575","-0.0287"
"1.7500","0.1384","0.3624","2.8605","-0.0552","-0.0275"
"1.8000","0.1426","0.3646","2.8781","-0.0582","-0.0290"
"1.8500","0.1468","0.3649","2.8809","-0.0579","-0.0289"
"1.9000","0.1513","0.3677","2.9024","-0.0567","-0.0283"
"1.9500","0.1555","0.3677","2.9030","-0.0547","-0.0273"
"2.0000","0.1596","0.3696","2.9178","-0.0553","-0.0276"
"2.0500","0.1635","0.3702","2.9227","-0.0570","-0.0284"
"2.1000","0.1677","0.3722","2.9379","-0.0594","-0.0296"
"2.1500","0.1719","0.3728","2.9431","-0.0552","-0.0275"
"2.2000","0.1762","0.3753","2.9625","-0.0591","-0.0295"
"2.2500","0.1803","0.3750","2.9606","-0.0577","-0.0288"
"2.3000","0.1842","0.3773","2.9782","-0.0592","-0.0295"
"2.3500","0.1884","0.3780","2.9836","-0.0568","-0.0283"
"2.4000","0.1925","0.3798","2.9981","-0.0562","-0.0280"
"2.4500","0.1969","0.3808","3.0063","-0.0597","-0.0298"
"2.5000","0.2012","0.3827","3.0211","-0.0600","-0.0299"
"2.5500","0.2054","0.3827","3.0209","-0.0583","-0.0291"
"2.6000","0.2094","0.3851","3.0402","-0.0576","-0.0287"
"2.6500","0.2137","0.3858","3.0458","-0.0586","-0.0292"
"2.7000","0.2177","0.3875","3.0589","-0.0546","-0.0272"
"2.7500","0.2221","0.3882","3.0644","-0.0578","-0.0288"
"2.8000","0.2262","0.3898","3.0773","-0.0601","-0.0300"
"2.8500","0.2304","0.3904","3.0816","-0.0583","-0.0291"
"2.9000","0.2342","0.3920","3.0943","-0.0617","-0.0308"
"2.9500","0.2386","0.3931","3.1030","-0.0626","-0.0312"
"3.0000","0.2426","0.3942","3.1120","-0.0604","-0.0301"
"3.0500","0.2471","0.3952","3.1199","-0.0591","-0.0295"
"3.1000","0.2510","0.3964","3.1290","-0.0594","-0.0296"
"3.1500","0.2554","0.3971","3.1349","-0.0622","-0.0310"
"3.2000","0.2593","0.3983","3.1444","-0.0616","-0.0307"
"3.2500","0.2637","0.3991","3.1505","-0.0610","-0.0304"
"3.3000","0.2677","0.4002","3.1596","-0.0604","-0.0301"
"3.3500","0.2721","0.4013","3.1675","-0.0607","-0.0303"
"3.4000","0.2760","0.4018","3.1720","-0.0617","-0.0308"
"3.4500","0.2802","0.4029","3.1809","-0.0630","-0.0314"
"3.5000","0.2841","0.4035","3.1854","-0.0634","-0.0316"
"3.5500","0.2886","0.4052","3.1990","-0.0643","-0.0321"
"3.6000","0.2927","0.4052","3.1986","-0.0641","-0.0320"
"3.6500","0.2971","0.4064","3.2085","-0.0662","-0.0330"
"3.7000","0.3011","0.4063","3.2074","-0.0637","-0.0318"
"3.7500","0.3054","0.4081","3.2214","-0.0622","-0.0310"
"3.8000","0.3094","0.4082","3.2226","-0.0656","-0.0327"
"3.8500","0.3138","0.4095","3.2325","-0.0659","-0.0328"
"3.9000","0.3178","0.4094","3.2315","-0.0657","-0.0328"
"3.9500","0.3222","0.4110","3.2445","-0.0688","-0.0343"
"4.0000","0.3261","0.4100","3.2366","-0.0700","-0.0349"
"4.0500","0.3302","0.4121","3.2535","-0.0685","-0.0342"
"4.1000","0.3344","0.4115","3.2481","-0.0703","-0.0350"
"4.1500","0.3387","0.4136","3.2654","-0.0712","-0.0355"
"4.2000","0.3429","0.4131","3.2614","-0.0703","-0.0350"
"4.2500","0.3471","0.4147","3.2733","-0.0725","-0.0361"
"4.3000","0.3511","0.4139","3.2673","-0.0723","-0.0360"
"4.3500","0.3552","0.4163","3.2865","-0.0739","-0.0369"
"4.4000","0.3595","0.4156","3.2807","-0.0730","-0.0364"
"4.4500","0.3636","0.4176","3.2970","-0.0723","-0.0361"
"4.5000","0.3679","0.4171","3.2924","-0.0743","-0.0370"
"4.5500","0.3720","0.4186","3.3044","-0.0710","-0.0354"
"4.6000","0.3761","0.4185","3.3037","-0.0716","-0.0357"
"4.6500","0.3800","0.4206","3.3206","-0.0708","-0.0353"
"4.7000","0.3843","0.4206","3.3203","-0.0738","-0.0368"
"4.7500","0.3884","0.4225","3.3351","-0.0747","-0.0373"
"4.8000","0.3930","0.4227","3.3366","-0.0739","-0.0369"
"4.8500","0.3970","0.4243","3.3491","-0.0761","-0.0380"
"4.9000","0.4012","0.4244","3.3502","-0.0733","-0.0366"
"4.9500","0.4052","0.4263","3.3650","-0.0768","-0.0383"
"5.0000","0.4096","0.4266","3.3680","-0.0762","-0.0380"
"5.0500","0.4136","0.4281","3.3792","-0.0765","-0.0381"
"5.1000","0.4181","0.4285","3.3826","-0.0773","-0.0385"
"5.1500","0.4219","0.4297","3.3920","-0.0757","-0.0378"
"5.2000","0.4262","0.4305","3.3987","-0.0780","-0.0389"
"5.2500","0.4300","0.4320","3.4099","-0.0776","-0.0387"
"5.3000","0.4345","0.4333","3.4204","-0.0763","-0.0381"
"5.3500","0.4386","0.4340","3.4264","-0.0772","-0.0385"
"5.4000","0.4430","0.4353","3.4365","-0.0774","-0.0386"
"5.4500","0.4469","0.4361","3.4424","-0.0812","-0.0405"
"5.5000","0.4512","0.4374","3.4530","-0.0783","-0.0391"
"5.5500","0.4551","0.4385","3.4616","-0.0824","-0.0411"
"5.6000","0.4596","0.4406","3.4780","-0.0793","-0.0395"
"5.6500","0.4637","0.4410","3.4813","-0.0810","-0.0404"
"5.7000","0.4679","0.4426","3.4936","-0.0832","-0.0415"
"5.7500","0.4717","0.4430","3.4971","-0.0805","-0.0401"
"5.8000","0.4759","0.4456","3.5177","-0.0816","-0.0407"
"5.8500","0.4800","0.4456","3.5174","-0.0830","-0.0414"
"5.9000","0.4844","0.4488","3.5429","-0.0836","-0.0417"
"5.9500","0.4887","0.4487","3.5417","-0.0819","-0.0408"
"6.0000","0.4929","0.4509","3.5592","-0.0844","-0.0421"
"6.0500","0.4968","0.4511","3.5613","-0.0857","-0.0427"
"6.1000","0.5011","0.4546","3.5885","-0.0807","-0.0402"
"6.1500","0.5053","0.4546","3.5890","-0.0844","-0.0421"
"6.2000","0.5096","0.4579","3.6146","-0.0841","-0.0420"
"6.2500","0.5138","0.4574","3.6111","-0.0846","-0.0422"
"6.3000","0.5179","0.4604","3.6343","-0.0859","-0.0428"
"6.3500","0.5219","0.4606","3.6363","-0.0847","-0.0422"
"6.4000","0.5259","0.4639","3.6618","-0.0859","-0.0428"
"6.4500","0.5302","0.4642","3.6643","-0.0861","-0.0429"
"6.5000","0.5345","0.4675","3.6906","-0.0901","-0.0449"
"6.5500","0.5388","0.4671","3.6874","-0.0894","-0.0446"
"6.6000","0.5427","0.4706","3.7148","-0.0880","-0.0439"
"6.6500","0.5469","0.4708","3.7163","-0.0906","-0.0452"
"6.7000","0.5509","0.4743","3.7438","-0.0918","-0.0458"
"6.7500","0.5554","0.4751","3.7506","-0.0905","-0.0451"
"6.8000","0.5595","0.4779","3.7727","-0.0883","-0.0440"
"6.8500","0.5637","0.4781","3.7741","-0.0890","-0.0444"
"6.9000","0.5676","0.4815","3.8010","-0.0902","-0.0450"
"6.9500","0.5719","0.4824","3.8081","-0.0930","-0.0464"
"7.0000","0.5758","0.4850","3.8283","-0.0921","-0.0459"
"7.0500","0.5803","0.4866","3.8416","-0.0946","-0.0472"
"7.1000","0.5844","0.4889","3.8596","-0.0945","-0.0471"
"7.1500","0.5888","0.4900","3.8679","-0.0941","-0.0469"
"7.2000","0.5926","0.4922","3.8853","-0.0978","-0.0487"
"7.2500","0.5970","0.4945","3.9036","-0.0938","-0.0468"
"7.3000","0.6011","0.4964","3.9189","-0.0974","-0.0486"
"7.3500","0.6056","0.4984","3.9344","-0.0950","-0.0474"
"7.4000","0.6095","0.4999","3.9465","-0.0976","-0.0487"
"7.4500","0.6139","0.5018","3.9611","-0.0968","-0.0483"
"7.5000","0.6177","0.5038","3.9770","-0.0989","-0.0493"
"7.5500","0.6220","0.5063","3.9968","-0.0987","-0.0492"
"7.6000","0.6260","0.5076","4.0073","-0.0994","-0.0496"
"7.6500","0.6305","0.5109","4.0328","-0.1017","-0.0507"
"7.7000","0.6345","0.5115","4.0382","-0.0989","-0.0493"
"7.7500","0.6387","0.5149","4.0645","-0.0998","-0.0497"
"7.8000","0.6426","0.5160","4.0735","-0.1015","-0.0506"
"7.8500","0.6470","0.5199","4.1041","-0.1026","-0.0512"
"7.9000","0.6511","0.5203","4.1070","-0.1066","-0.0532"
"7.9500","0.6555","0.5245","4.1401","-0.1049","-0.0523"
"8.0000","0.6595","0.5247","4.1418","-0.1080","-0.0538"
"8.0500","0.6637","0.5285","4.1723","-0.1078","-0.0537"
"8.1000","0.6676","0.5291","4.1765","-0.1064","-0.0530"
"8.1500","0.6718","0.5336","4.2120","-0.1091","-0.0544"
"8.2000","0.6761","0.5344","4.2184","-0.1061","-0.0529"
"8.2500","0.6804","0.5379","4.2466","-0.1100","-0.0548"
"8.3000","0.6845","0.5380","4.2474","-0.1114","-0.0555"
"8.3500","0.6886","0.5424","4.2817","-0.1138","-0.0567"
"8.4000","0.6927","0.5428","4.2850","-0.1134","-0.0565"
"8.4500","0.6970","0.5472","4.3197","-0.1137","-0.0567"
"8.5000","0.7014","0.5480","4.3257","-0.1131","-0.0564"
"8.5500","0.7056","0.5513","4.3522","-0.1163","-0.0580"
"8.6000","0.7095","0.5518","4.3560","-0.1147","-0.0572"
"8.6500","0.7136","0.5559","4.3883","-0.1165","-0.0581"
"8.7000","0.7177","0.5560","4.3893","-0.1188","-0.0592"
"8.7500","0.7218","0.5602","4.4226","-0.1196","-0.0596"
"8.8000","0.7263","0.5614","4.4314","-0.1199","-0.0598"
"8.8500","0.7303","0.5642","4.4538","-0.1205","-0.0601"
"8.9000","0.7345","0.5649","4.4592","-0.1209","-0.0603"
"8.9500","0.7384","0.5684","4.4869","-0.1219","-0.0608"
"9.0000","0.7428","0.5702","4.5009","-0.1224","-0.0610"
"9.0500","0.7469","0.5729","4.5222","-0.1245","-0.0621"
"9.1000","0.7514","0.5743","4.5332","-0.1271","-0.0634"
"9.1500","0.7553","0.5767","4.5528","-0.1261","-0.0629"
"9.2000","0.7595","0.5781","4.5634","-0.1276","-0.0636"
"9.2500","0.7633","0.5808","4.5853","-0.1271","-0.0634"
"9.3000","0.7677","0.5839","4.6095","-0.1320","-0.0658"
"9.3500","0.7717","0.5858","4.6240","-0.1309","-0.0653"
"9.4000","0.7762","0.5885","4.6458","-0.1302","-0.0649"
"9.4500","0.7801","0.5898","4.6562","-0.1335","-0.0666"
"9.5000","0.7844","0.5933","4.6835","-0.1354","-0.0675"
"9.5500","0.7884","0.5953","4.6995","-0.1358","-0.0677"
"9.6000","0.7930","0.5989","4.7280","-0.1386","-0.0691"
"9.6500","0.7971","0.6003","4.7385","-0.1351","-0.0673"
"9.7000","0.8015","0.6036","4.7646","-0.1394","-0.0695"
"9.7500","0.8052","0.6051","4.7771","-0.1413","-0.0705"
"9.8000","0.8095","0.6098","4.8138","-0.1399","-0.0697"
"9.8500","0.8134","0.6107","4.8212","-0.1412","-0.0704"
"9.9000","0.8178","0.6161","4.8635","-0.1433","-0.0714"
"9.9500","0.8219","0.6172","4.8723","-0.1481","-0.0738"
"10.0000","0.8263","0.6220","4.9100","-0.1466","-0.0731"
"10.0500","0.8302","0.6232","4.9193","-0.1467","-0.0731"
"10.1000","0.8344","0.6286","4.9626","-0.1474","-0.0735"
"10.1500","0.8386","0.6301","4.9743","-0.1487","-0.0741"
"10.2000","0.8430","0.6352","5.0142","-0.1510","-0.0753"
"10.2500","0.8470","0.6362","5.0222","-0.1513","-0.0754"
"10.3000","0.8512","0.6416","5.0652","-0.1506","-0.0751"
"10.3500","0.8551","0.6425","5.0719","-0.1540","-0.0768"
"10.4000","0.8593","0.6486","5.1202","-0.1553","-0.0774"
"10.4500","0.8634","0.6497","5.1285","-0.1542","-0.0769"
"10.5000","0.8676","0.6558","5.1771","-0.1588","-0.0792"
"10.5500","0.8719","0.6581","5.1954","-0.1588","-0.0792"
"10.6000","0.8761","0.6636","5.2382","-0.1576","-0.0786"
"10.6500","0.8802","0.6651","5.2500","-0.1579","-0.0787"
"10.7000","0.8843","0.6718","5.3032","-0.1618","-0.0807"
"10.7500","0.8888","0.6739","5.3198","-0.1628","-0.0812"
"10.8000","0.8929","0.6789","5.3597","-0.1636","-0.0816"
"10.8500","0.8971","0.6814","5.3792","-0.1637","-0.0816"
"10.9000","0.9011","0.6867","5.4208","-0.1656","-0.0826"
"10.9500","0.9053","0.6897","5.4448","-0.1671","-0.0833"
"11.0000","0.9093","0.6947","5.4841","-0.1688","-0.0841"
"11.0500","0.9137","0.6974","5.5050","-0.1682","-0.0838"
"11.1000","0.9176","0.7027","5.5471","-0.1688","-0.0842"
"11.1500","0.9221","0.7033","5.5516","-0.1714","-0.0854"
"11.2000","0.9261","0.7087","5.5944","-0.1760","-0.0877"
"11.2500","0.9304","0.7135","5.6328","-0.1761","-0.0878"
"11.3000","0.9343","0.7173","5.6626","-0.1791","-0.0893"
"11.3500","0.9389","0.7219","5.6988","-0.1797","-0.0896"
"11.4000","0.9428","0.7249","5.7226","-0.1840","-0.0917"
"11.4500","0.9472","0.7297","5.7601","-0.1853","-0.0924"
"11.5000","0.9509","0.7327","5.7838","-0.1853","-0.0924"
"11.5500","0.9553","0.7389","5.8329","-0.1838","-0.0917"
"11.6000","0.9592","0.7416","5.8544","-0.1881","-0.0938"
"11.6500","0.9637","0.7483","5.9071","-0.1856","-0.0926"
"11.7000","0.9676","0.7508","5.9271","-0.1873","-0.0934"
"11.7500","0.9721","0.7577","5.9811","-0.1921","-0.0958"
"11.8000","0.9759","0.7604","6.0027","-0.1952","-0.0973"
"11.8500","0.9804","0.7686","6.0670","-0.1960","-0.0977"
"11.9000","0.9845","0.7714","6.0897","-0.1966","-0.0980"
"11.9500","0.9889","0.7794","6.1523","-0.1992","-0.0993"
"12.0000","0.9928","0.7822","6.1747","-0.1989","-0.0992"
"12.0500","0.9971","0.7909","6.2437","-0.1995","-0.0995"
"12.1000","1.0010","0.7943","6.2706","-0.2021","-0.1008"
"12.1500","1.0053","0.8038","6.3452","-0.2032","-0.1013"
"12.2000","1.0094","0.8079","6.3778","-0.2034","-0.1014"
"12.2500","1.0137","0.8182","6.4590","-0.2050","-0.1022"
"12.3000","1.0178","0.8225","6.4933","-0.2075","-0.1035"
"12.3500","1.0219","0.8332","6.5775","-0.2081","-0.1038"
"12.4000","1.0260","0.8389","6.6226","-0.2070","-0.1032"
"12.4500","1.0302","0.8495","6.7064","-0.2112","-0.1053"
"12.5000","1.0346","0.8566","6.7620","-0.2118","-0.1056"
"12.5500","1.0388","0.8662","6.8379","-0.2178","-0.1086"
"12.6000","1.0428","0.8716","6.8802","-0.2157","-0.1075"
"12.6500","1.0468","0.8828","6.9689","-0.2163","-0.1079"
"12.7000","1.0510","0.8884","7.0128","-0.2177","-0.1086"
"12.7500","1.0550","0.8959","7.0721","-0.2178","-0.1086"
"12.8000","1.0594","0.9053","7.1467","-0.2225","-0.1109"
"12.8500","1.0636","0.9145","7.2189","-0.2247","-0.1120"
"12.9000","1.0678","0.9216","7.2754","-0.2272","-0.1133"
"12.9500","1.0717","0.9313","7.3518","-0.2245","-0.1119"
"13.0000","1.0761","0.9396","7.4170","-0.2302","-0.1148"
"13.0500","1.0801","0.9486","7.4887","-0.2313","-0.1153"
"13.1000","1.0847","0.9578","7.5609","-0.2336","-0.1165"
"13.1500","1.0887","0.9660","7.6258","-0.2332","-0.1163"
"13.2000","1.0929","0.9747","7.6947","-0.2359","-0.1176"
"13.2500","1.0968","0.9834","7.7628","-0.2385","-0.1189"
"13.3000","1.1012","0.9923","7.8333","-0.2398","-0.1196"
"13.3500","1.1051","1.0012","7.9038","-0.2383","-0.1188"
"13.4000","1.1097","1.0130","7.9968","-0.2398","-0.1196"
"13.4500","1.1137","1.0207","8.0575","-0.2438","-0.1216"
"13.5000","1.1179","1.0311","8.1393","-0.2475","-0.1234"
"13.5500","1.1216","1.0397","8.2077","-0.2428","-0.1211"
"13.6000","1.1262","1.0526","8.3097","-0.2468","-0.1231"
"13.6500","1.1303","1.0612","8.3771","-0.2475","-0.1234"
"13.7000","1.1347","1.0729","8.4695","-0.2534","-0.1263"
"13.7500","1.1385","1.0811","8.5345","-0.2527","-0.1260"
"13.8000","1.1429","1.0953","8.6462","-0.2556","-0.1274"
"13.8500","1.1467","1.1034","8.7104","-0.2571","-0.1282"
"13.9000","1.1510","1.1181","8.8265","-0.2585","-0.1289"
"13.9500","1.1550","1.1268","8.8953","-0.2613","-0.1303"
"14.0000","1.1595","1.1424","9.0186","-0.2633","-0.1313"
"14.0500","1.1635","1.1432","9.0242","-0.2629","-0.1311"
"14.1000","1.1678","1.1600","9.1570","-0.2637","-0.1315"
"14.1500","1.1718","1.1707","9.2414","-0.2672","-0.1332"
"14.2000","1.1762","1.1867","9.3683","-0.2649","-0.1321"
"14.2500","1.1804","1.1965","9.4453","-0.2676","-0.1334"
"14.3000","1.1848","1.2107","9.5574","-0.2711","-0.1352"
"14.3500","1.1886","1.2193","9.6254","-0.2732","-0.1362"
"14.4000","1.1929","1.2354","9.7520","-0.2729","-0.1361"
"14.4500","1.1969","1.2435","9.8163","-0.2774","-0.1383"
"14.5000","1.2011","1.2586","9.9352","-0.2781","-0.1387"
"14.5500","1.2053","1.2674","10.0047","-0.2809","-0.1400"
"14.6000","1.2095","1.2820","10.1199","-0.2822","-0.1407"
"14.6500","1.2136","1.2896","10.1799","-0.2793","-0.1393"
"14.7000","1.2177","1.3015","10.2738","-0.2854","-0.1423"
"14.7500","1.2219","1.3127","10.3623","-0.2838","-0.1415"
"14.8000","1.2262","1.3294","10.4943","-0.2856","-0.1424"
"14.8500","1.2306","1.3398","10.5768","-0.2868","-0.1430"
"14.9000","1.2346","1.3536","10.6857","-0.2880","-0.1436"
"14.9500","1.2387","1.3648","10.7735","-0.2881","-0.1437"
"15.0000","1.2426","1.3793","10.8880","-0.2912","-0.1452"
"15.0500","1.2469","1.3916","10.9857","-0.2954","-0.1473"
"15.1000","1.2509","1.4055","11.0951","-0.2920","-0.1456"
"15.1500","1.2554","1.4174","11.1890","-0.2969","-0.1480"
"15.2000","1.2593","1.4290","11.2809","-0.2952","-0.1472"
"15.2500","1.2637","1.4430","11.3911","-0.2990","-0.1491"
"15.3000","1.2676","1.4561","11.4948","-0.3003","-0.1498"
"15.3500","1.2721","1.4713","11.6145","-0.3004","-0.1498"
"15.4000","1.2762","1.4844","11.7182","-0.3020","-0.1506"
"15.4500","1.2806","1.4978","11.8237","-0.3058","-0.1525"
"15.5000","1.2844","1.5093","11.9143","-0.3041","-0.1516"
"15.5500","1.2887","1.5238","12.0290","-0.3077","-0.1534"
"15.6000","1.2926","1.5355","12.1211","-0.3076","-0.1534"
"15.6500","1.2970","1.5518","12.2504","-0.3106","-0.1549"
"15.7000","1.3010","1.5637","12.3441","-0.3115","-0.1553"
"15.7500","1.3055","1.5800","12.4725","-0.3108","-0.1550"
"15.8000","1.3093","1.5908","12.5582","-0.3138","-0.1564"
"15.8500","1.3137","1.6092","12.7033","-0.3137","-0.1564"
"15.9000","1.3176","1.6208","12.7949","-0.3171","-0.1581"
"15.9500","1.3222","1.6399","12.9456","-0.3169","-0.1580"
"16.0000","1.3262","1.6502","13.0265","-0.3156","-0.1574"
"16.0500","1.3305","1.6676","13.1643","-0.3155","-0.1573"
"16.1000","1.3343","1.6785","13.2505","-0.3175","-0.1583"
"16.1500","1.3385","1.6973","13.3984","-0.3224","-0.1608"
"16.2000","1.3425","1.7087","13.4884","-0.3219","-0.1605"
"16.2500","1.3469","1.7279","13.6399","-0.3198","-0.1595"
"16.3000","1.3510","1.7391","13.7286","-0.3223","-0.1607"
"16.3500","1.3552","1.7568","13.8681","-0.3262","-0.1626"
"16.4000","1.3592","1.7689","13.9635","-0.3233","-0.1612"
"16.4500","1.3635","1.7880","14.1146","-0.3277","-0.1634"
"16.5000","1.3677","1.8005","14.2133","-0.3270","-0.1630"
"16.5500","1.3720","1.8194","14.3622","-0.3306","-0.1648"
"16.6000","1.3762","1.8312","14.4554","-0.3282","-0.1636"
"16.6500","1.3803","1.8489","14.5954","-0.3297","-0.1644"
"16.7000","1.3845","1.8617","14.6964","-0.3295","-0.1643"
"16.7500","1.3886","1.8804","14.8438","-0.3317","-0.1654"
"16.8000","1.3929","1.8936","14.9483","-0.3324","-0.1657"
"16.8500","1.3970","1.9109","15.0852","-0.3344","-0.1667"
"16.9000","1.4012","1.9249","15.1951","-0.3311","-0.1651"
"16.9500","1.4052","1.9416","15.3274","-0.3355","-0.1673"
"17.0000","1.4094","1.9563","15.4431","-0.3347","-0.1669"
"17.0500","1.4134","1.9736","15.5797","-0.3331","-0.1661"
"17.1000","1.4180","1.9907","15.7145","-0.3342","-0.1666"
"17.1500","1.4221","2.0058","15.8341","-0.3370","-0.1680"
"17.2000","1.4263","2.0199","15.9449","-0.3336","-0.1663"
"17.2500","1.4301","2.0356","16.0694","-0.3347","-0.1669"
"17.3000","1.4345","2.0528","16.2051","-0.3360","-0.1675"
"17.3500","1.4384","2.0673","16.3198","-0.3346","-0.1668"
"17.4000","1.4428","2.0844","16.4546","-0.3343","-0.1667"
"17.4500","1.4467","2.0980","16.5617","-0.3365","-0.1678"
"17.5000","1.4511","2.1164","16.7068","-0.3334","-0.1662"
"17.5500","1.4550","2.1300","16.8141","-0.3332","-0.1661"
"17.6000","1.4595","2.1485","16.9608","-0.3336","-0.1663"
"17.6500","1.4635","2.1620","17.0670","-0.3339","-0.1665"
"17.7000","1.4680","2.1811","17.2179","-0.3314","-0.1652"
"17.7500","1.4720","2.1933","17.3144","-0.3334","-0.1662"
"17.8000","1.4763","2.2109","17.4534","-0.3335","-0.1663"
"17.8500","1.4801","2.2238","17.5551","-0.3313","-0.1652"
"17.9000","1.4846","2.2447","17.7199","-0.3346","-0.1668"
"17.9500","1.4886","2.2555","17.8050","-0.3333","-0.1662"
"18.0000","1.4929","2.2743","17.9538","-0.3300","-0.1646"
"18.0500","1.4968","2.2859","18.0449","-0.3313","-0.1652"
"18.1000","1.5011","2.3073","18.2137","-0.3277","-0.1634"
"18.1500","1.5052","2.3183","18.3011","-0.3285","-0.1638"
"18.2000","1.5095","2.3388","18.4627","-0.3304","-0.1647"
"18.2500","1.5136","2.3506","18.5558","-0.3280","-0.1635"
"18.3000","1.5180","2.3709","18.7164","-0.3286","-0.1638"
"18.3500","1.5219","2.3807","18.7935","-0.3255","-0.1623"
"18.4000","1.5261","2.4009","18.9530","-0.3247","-0.1619"
"18.4500","1.5301","2.4122","19.0423","-0.3248","-0.1620"
"18.5000","1.5344","2.4325","19.2026","-0.3208","-0.1600"
"18.5500","1.5385","2.4436","19.2901","-0.3248","-0.1619"
"18.6000","1.5426","2.4627","19.4408","-0.3217","-0.1604"
"18.6500","1.5468","2.4753","19.5406","-0.3179","-0.1585"
"18.7000","1.5509","2.4946","19.6928","-0.3166","-0.1579"
"18.7500","1.5553","2.5085","19.8023","-0.3165","-0.1578"
"18.8000","1.5595","2.5265","19.9446","-0.3144","-0.1567"
"18.8500","1.5638","2.5403","20.0534","-0.3148","-0.1570"
"18.9000","1.5679","2.5581","20.1936","-0.3143","-0.1567"
"18.9500","1.5721","2.5712","20.2974","-0.3110","-0.1550"
"19.0000","1.5760","2.5885","20.4336","-0.3120","-0.1555"
"19.0500","1.5804","2.6040","20.5563","-0.3084","-0.1538"
"19.1000","1.5844","2.6201","20.6830","-0.3095","-0.1543"
"19.1500","1.5887","2.6360","20.8085","-0.3050","-0.1521"
"19.2000","1.5926","2.6506","20.9242","-0.3063","-0.1527"
"19.2500","1.5970","2.6688","21.0677","-0.3042","-0.1517"
"19.3000","1.6009","2.6821","21.1730","-0.3033","-0.1512"
"19.3500","1.6053","2.7015","21.3256","-0.2996","-0.1494"
"19.4000","1.6095","2.7163","21.4429","-0.2987","-0.1489"
"19.4500","1.6139","2.7333","21.5767","-0.2982","-0.1487"
"19.5000","1.6177","2.7461","21.6778","-0.2944","-0.1468"
"19.5500","1.6220","2.7646","21.8237","-0.2939","-0.1465"
"19.6000","1.6259","2.7768","21.9207","-0.2936","-0.1464"
"19.6500","1.6302","2.7966","22.0765","-0.2896","-0.1444"
"19.7000","1.6343","2.8102","22.1840","-0.2891","-0.1441"
"19.7500","1.6386","2.8281","22.3255","-0.2871","-0.1431"
"19.8000","1.6425","2.8395","22.4149","-0.2848","-0.1420"
"19.8500","1.6469","2.8606","22.5822","-0.2817","-0.1404"
"19.9000","1.6510","2.8725","22.6756","-0.2840","-0.1416"
"19.9500","1.6554","2.8929","22.8369","-0.2821","-0.1407"
"20.0000","1.6595","2.9048","22.9307","-0.2798","-0.1395"
"20.0500","1.6638","2.9246","23.0874","-0.2794","-0.1393"
"20.1000","1.6677","2.9354","23.1727","-0.2722","-0.1357"
"20.1500","1.6720","2.9565","23.3393","-0.2734","-0.1363"
"20.2000","1.6760","2.9676","23.4265","-0.2736","-0.1364"
"20.2500","1.6804","2.9897","23.6008","-0.2691","-0.1342"
"20.3000","1.6845","3.0000","23.6819","-0.2682","-0.1337"
"20.3500","1.6886","3.0197","23.8376","-0.2666","-0.1329"
"20.4000","1.6925","3.0308","23.9258","-0.2618","-0.1305"
"20.4500","1.6969","3.0534","24.1036","-0.2603","-0.1298"
"20.5000","1.7011","3.0649","24.1945","-0.2612","-0.1302"
"20.5500","1.7054","3.0861","24.3620","-0.2594","-0.1293"
"20.6000","1.7096","3.0971","24.4488","-0.2565","-0.1279"
"20.6500","1.7137","3.1161","24.5989","-0.2565","-0.1279"
"20.7000","1.7177","3.1284","24.6957","-0.2523","-0.1258"
"20.7500","1.7219","3.1482","24.8526","-0.2494","-0.1243"
"20.8000","1.7260","3.1603","24.9476","-0.2501","-0.1247"
"20.8500","1.7302","3.1802","25.1048","-0.2498","-0.1245"
"20.9000","1.7343","3.1923","25.2000","-0.2446","-0.1219"
"20.9500","1.7384","3.2110","25.3482","-0.2447","-0.1220"
"21.0000","1.7427","3.2256","25.4635","-0.2440","-0.1217"
"21.0500","1.7468","3.2433","25.6026","-0.2453","-0.1223"
"21.1000","1.7511","3.2585","25.7229","-0.2422","-0.1208"
"21.1500","1.7553","3.2759","25.8602","-0.2386","-0.1190"
"21.2000","1.7597","3.2911","25.9800","-0.2395","-0.1194"
"21.2500","1.7637","3.3071","26.1063","-0.2379","-0.1186"
"21.3000","1.7679","3.3224","26.2273","-0.2356","-0.1175"
"21.3500","1.7719","3.3382","26.3522","-0.2365","-0.1179"
"21.4000","1.7763","3.3569","26.4999","-0.2327","-0.1160"
"21.4500","1.7802","3.3698","26.6012","-0.2277","-0.1135"
"21.5000","1.7845","3.3881","26.7460","-0.2264","-0.1129"
"21.5500","1.7885","3.4017","26.8537","-0.2260","-0.1127"
"21.6000","1.7929","3.4215","27.0097","-0.2237","-0.1115"
"21.6500","1.7969","3.4344","27.1115","-0.2260","-0.1127"
"21.7000","1.8013","3.4544","27.2691","-0.2213","-0.1103"
"21.7500","1.8053","3.4662","27.3627","-0.2225","-0.1109"
"21.8000","1.8097","3.4869","27.5259","-0.2180","-0.1087"
"21.8500","1.8136","3.4978","27.6117","-0.2144","-0.1069"
"21.9000","1.8179","3.5179","27.7705","-0.2156","-0.1075"
"21.9500","1.8218","3.5294","27.8614","-0.2129","-0.1061"
"22.0000","1.8263","3.5519","28.0393","-0.2113","-0.1053"
"22.0500","1.8302","3.5606","28.1080","-0.2107","-0.1050"
"22.1000","1.8344","3.5812","28.2705","-0.2090","-0.1042"
"22.1500","1.8383","3.5933","28.3657","-0.2070","-0.1032"
"22.2000","1.8428","3.6157","28.5423","-0.2062","-0.1028"
"22.2500","1.8468","3.6260","28.6241","-0.2026","-0.1010"
"22.3000","1.8513","3.6485","28.8013","-0.2010","-0.1002"
"22.3500","1.8554","3.6587","28.8824","-0.2032","-0.1013"
"22.4000","1.8596","3.6791","29.0428","-0.1977","-0.0986"
"22.4500","1.8635","3.6892","29.1226","-0.2013","-0.1004"
"22.5000","1.8678","3.7110","29.2950","-0.1957","-0.0976"
"22.5500","1.8720","3.7232","29.3916","-0.1924","-0.0959"
"22.6000","1.8763","3.7428","29.5464","-0.1930","-0.0963"
"22.6500","1.8802","3.7515","29.6150","-0.1894","-0.0944"
"22.7000","1.8843","3.7728","29.7826","-0.1883","-0.0939"
"22.7500","1.8885","3.7851","29.8799","-0.1880","-0.0938"
"22.8000","1.8927","3.8043","30.0315","-0.1869","-0.0932"
"22.8500","1.8970","3.8180","30.1396","-0.1838","-0.0917"
"22.9000","1.9013","3.8362","30.2833","-0.1829","-0.0912"
"22.9500","1.9055","3.8484","30.3800","-0.1827","-0.0911"
"23.0000","1.9095","3.8642","30.5046","-0.1809","-0.0902"
"23.0500","1.9136","3.8785","30.6174","-0.1771","-0.0883"
"23.1000","1.9177","3.8958","30.7541","-0.1787","-0.0891"
"23.1500","1.9221","3.9116","30.8788","-0.1768","-0.0882"
"23.2000","1.9260","3.9247","30.9821","-0.1751","-0.0873"
"23.2500","1.9302","3.9400","31.1029","-0.1731","-0.0863"
"23.3000","1.9341","3.9550","31.2214","-0.1742","-0.0868"
"23.3500","1.9385","3.9733","31.3654","-0.1724","-0.0860"
"23.4000","1.9426","3.9865","31.4695","-0.1701","-0.0848"
"23.4500","1.9472","4.0052","31.6171","-0.1674","-0.0835"
"23.5000","1.9512","4.0163","31.7048","-0.1656","-0.0826"
"23.5500","1.9554","4.0326","31.8335","-0.1639","-0.0817"
"23.6000","1.9592","4.0448","31.9299","-0.1635","-0.0815"
"23.6500","1.9637","4.0657","32.0949","-0.1640","-0.0818"
"23.7000","1.9678","4.0776","32.1891","-0.1611","-0.0803"
"23.7500","1.9722","4.0955","32.3300","-0.1585","-0.0790"
"23.8000","1.9759","4.1042","32.3992","-0.1589","-0.0792"
"23.8500","1.9803","4.1253","32.5653","-0.1564","-0.0780"
"23.9000","1.9842","4.1355","32.6464","-0.1556","-0.0776"
"23.9500","1.9887","4.1577","32.8212","-0.1562","-0.0779"
"24.0000","1.9928","4.1673","32.8973","-0.1561","-0.0778"
"24.0500","1.9972","4.1861","33.0456","-0.1549","-0.0772"
"24.1000","2.0010","4.1950","33.1155","-0.1527","-0.0761"
"24.1500","2.0054","4.2164","33.2846","-0.1507","-0.0752"
"24.2000","2.0093","4.2248","33.3508","-0.1495","-0.0746"
"24.2500","2.0137","4.2470","33.5260","-0.1494","-0.0745"
"24.3000","2.0178","4.2566","33.6018","-0.1471","-0.0733"
"24.3500","2.0219","4.2756","33.7521","-0.1467","-0.0731"
"24.4000","2.0257","4.2848","33.8247","-0.1472","-0.0734"
"24.4500","2.0301","4.3076","34.0044","-0.1465","-0.0730"
"24.5000","2.0342","4.3173","34.0813","-0.1479","-0.0738"
"24.5500","2.0386","4.3367","34.2344","-0.1449","-0.0722"
"24.6000","2.0428","4.3468","34.3144","-0.1412","-0.0704"
"24.6500","2.0470","4.3656","34.4629","-0.1420","-0.0708"
"24.7000","2.0511","4.3764","34.5474","-0.1395","-0.0695"
"24.7500","2.0553","4.3949","34.6939","-0.1385","-0.0690"
"24.8000","2.0594","4.4062","34.7828","-0.1374","-0.0685"
"24.8500","2.0638","4.4262","34.9410","-0.1372","-0.0684"
"24.9000","2.0679","4.4360","35.0186","-0.1382","-0.0689"
"24.9500","2.0719","4.4525","35.1485","-0.1359","-0.0677"
"25.0000","2.0760","4.4664","35.2581","-0.1362","-0.0679"
"25.0500","2.0802","4.4842","35.3984","-0.1326","-0.0661"
"25.1000","2.0846","4.4988","35.5137","-0.1358","-0.0677"
"25.1500","2.0887","4.5143","35.6364","-0.1325","-0.0661"
"25.2000","2.0929","4.5270","35.7362","-0.1296","-0.0646"
"25.2500","2.0969","4.5428","35.8615","-0.1277","-0.0637"
"25.3000","2.1013","4.5590","35.9895","-0.1295","-0.0646"
"25.3500","2.1053","4.5729","36.0992","-0.1255","-0.0626"
"25.4000","2.1096","4.5891","36.2265","-0.1260","-0.0628"
"25.4500","2.1135","4.6019","36.3279","-0.1251","-0.0624"
"25.5000","2.1178","4.6184","36.4581","-0.1250","-0.0623"
"25.5500","2.1216","4.6308","36.5558","-0.1203","-0.0600"
"25.6000","2.1260","4.6509","36.7145","-0.1177","-0.0587"
"25.6500","2.1300","4.6625","36.8064","-0.1176","-0.0586"
"25.7000","2.1346","4.6835","36.9721","-0.1159","-0.0578"
"25.7500","2.1385","4.6929","37.0465","-0.1164","-0.0580"
"25.8000","2.1429","4.7117","37.1947","-0.1179","-0.0588"
"25.8500","2.1468","4.7232","37.2857","-0.1155","-0.0576"
"25.9000","2.1512","4.7437","37.4470","-0.1158","-0.0577"
"25.9500","2.1551","4.7539","37.5280","-0.1152","-0.0574"
"26.0000","2.1597","4.7758","37.7004","-0.1129","-0.0563"
"26.0500","2.1637","4.7844","37.7684","-0.1136","-0.0566"
"26.1000","2.1679","4.8035","37.9193","-0.1122","-0.0560"
"26.1500","2.1717","4.8131","37.9950","-0.1120","-0.0559"
"26.2000","2.1761","4.8350","38.1682","-0.1104","-0.0550"
"26.2500","2.1801","4.8462","38.2566","-0.1071","-0.0534"
"26.3000","2.1846","4.8676","38.4254","-0.1087","-0.0542"
"26.3500","2.1886","4.8762","38.4932","-0.1058","-0.0527"
"26.4000","2.1929","4.8968","38.6562","-0.1046","-0.0521"
"26.4500","2.1969","4.9080","38.7444","-0.1046","-0.0521"
"26.5000","2.2012","4.9276","38.8992","-0.1032","-0.0515"
"26.5500","2.2052","4.9395","38.9931","-0.1031","-0.0514"
"26.6000","2.2096","4.9605","39.1586","-0.1024","-0.0511"
"26.6500","2.2135","4.9678","39.2162","-0.1024","-0.0510"
"26.7000","2.2176","4.9879","39.3746","-0.1016","-0.0507"
"26.7500","2.2217","5.0003","39.4728","-0.0993","-0.0495"
"26.8000","2.2259","5.0196","39.6253","-0.0983","-0.0490"
"26.8500","2.2302","5.0347","39.7447","-0.0941","-0.0469"
"26.9000","2.2344","5.0521","39.8818","-0.0925","-0.0461"
"26.9500","2.2386","5.0646","39.9807","-0.0883","-0.0440"
"27.0000","2.2427","5.0827","40.1231","-0.0891","-0.0444"
"27.0500","2.2470","5.0961","40.2294","-0.0918","-0.0458"
"27.1000","2.2510","5.1124","40.3580","-0.0911","-0.0454"
"27.1500","2.2554","5.1287","40.4864","-0.0875","-0.0436"
"27.2000","2.2595","5.1431","40.6003","-0.0873","-0.0435"
"27.2500","2.2637","5.1568","40.7084","-0.0823","-0.0410"
"27.3000","2.2676","5.1713","40.8229","-0.0830","-0.0414"
"27.3500","2.2719","5.1894","40.9660","-0.0837","-0.0417"
"27.4000","2.2760","5.2049","41.0877","-0.0799","-0.0398"
"27.4500","2.2804","5.2209","41.2142","-0.0777","-0.0387"
"27.5000","2.2843","5.2332","41.3118","-0.0764","-0.0381"
"27.5500","2.2887","5.2524","41.4627","-0.0769","-0.0383"
"27.6000","2.2927","5.2654","41.5657","-0.0740","-0.0369"
"27.6500","2.2971","5.2828","41.7031","-0.0722","-0.0360"
"27.7000","2.3010","5.2948","41.7981","-0.0707","-0.0353"
"27.7500","2.3055","5.3145","41.9531","-0.0697","-0.0348"
"27.8000","2.3092","5.3235","42.0240","-0.0697","-0.0348"
"27.8500","2.3136","5.3444","42.1894","-0.0695","-0.0346"
"27.9000","2.3174","5.3529","42.2562","-0.0673","-0.0336"
"27.9500","2.3218","5.3767","42.4439","-0.0649","-0.0323"
"28.0000","2.3260","5.3888","42.5398","-0.0609","-0.0304"
"28.0500","2.3304","5.4076","42.6882","-0.0629","-0.0313"
"28.1000","2.3343","5.4161","42.7550","-0.0606","-0.0302"
"28.1500","2.3388","5.4399","42.9435","-0.0575","-0.0287"
"28.2000","2.3428","5.4469","42.9987","-0.0580","-0.0289"
"28.2500","2.3471","5.4680","43.1653","-0.0572","-0.0285"
"28.3000","2.3511","5.4761","43.2292","-0.0555","-0.0277"
"28.3500","2.3555","5.4961","43.3865","-0.0481","-0.0240"
"28.4000","2.3594","5.4949","43.3770","-0.0459","-0.0229"
"28.4500","2.3637","5.4822","43.2774","-0.0353","-0.0176"
"28.5000","2.3677","5.4586","43.0910","-0.0214","-0.0107"
"28.5500","2.3720","5.4760","43.2278","-0.0126","-0.0063"
"28.6000","2.3761","5.4895","43.3348","-0.0051","-0.0026"
"28.6500","2.3804","5.5118","43.5106","0.0005","0.0003"
"28.7000","2.3845","5.5198","43.5738","0.0054","0.0027"
"28.7500","2.3887","5.5332","43.6800","0.0085","0.0042"
"28.8000","2.3928","5.5369","43.7087","0.0120","0.0060"
"28.8500","2.3970","5.5474","43.7919","0.0157","0.0078"
"28.9000","2.4012","5.5569","43.8671","0.0183","0.0091"
"28.9500","2.4053","5.5700","43.9703","0.0209","0.0104"
"29.0000","2.4093","5.5763","44.0195","0.0192","0.0096"
"29.0500","2.4133","5.5867","44.1021","0.0202","0.0101"
"29.1000","2.4177","5.5992","44.2007","0.0199","0.0099"
"29.1500","2.4219","5.5977","44.1887","0.0193","0.0096"
"29.2000","2.4263","5.5885","44.1165","0.0203","0.0101"
"29.2500","2.4303","5.5595","43.8872","0.0161","0.0080"
"29.3000","2.4346","5.5472","43.7902","0.0124","0.0062"
"29.3500","2.4386","5.5378","43.7156","0.0114","0.0057"
"29.4000","2.4430","5.5336","43.6826","0.0111","0.0055"
"29.4500","2.4470","5.4057","42.6730","0.0052","0.0026"
"29.5000","2.4515","5.2904","41.7631","-0.0044","-0.0022"
"29.5500","2.4554","5.1850","40.9308","-0.0106","-0.0053"
"29.6000","2.4596","5.1602","40.7353","-0.0122","-0.0061"
"29.6500","2.4634","5.1392","40.5696","-0.0142","-0.0071"
"29.7000","2.4678","5.1248","40.4553","-0.0148","-0.0074"
"29.7500","2.4719","5.0832","40.1273","-0.0159","-0.0079"
"29.8000","2.4764","5.0217","39.6415","-0.0172","-0.0086"
"29.8500","2.4804","4.8967","38.6548","-0.0217","-0.0108"
"29.9000","2.4847","4.7141","37.2136","-0.0224","-0.0112"
"29.9500","2.4886","4.4180","34.8761","-0.0260","-0.0130"
"30.0000","2.4934","2.5120","19.8296","-0.1047","-0.0522"
"30.0500","2.4982","1.6735","13.2105","-0.3002","-0.1497"
"30.1000","2.5017","1.7321","13.6731","-0.3046","-0.1519"
"30.1500","2.5049","1.7227","13.5992","-0.3086","-0.1538"
"30.2000","2.5093","1.7253","13.6200","-0.3134","-0.1562"
"30.2500","2.5133","1.7153","13.5407","-0.3171","-0.1581"
"30.3000","2.5178","1.7197","13.5751","-0.3192","-0.1591"
"30.3500","2.5219","1.7100","13.4993","-0.3194","-0.1593"
"30.4000","2.5262","1.7103","13.5012","-0.3204","-0.1597"
"30.4500","2.5302","1.7011","13.4290","-0.3242","-0.1616"
"30.5000","2.5345","1.7046","13.4566","-0.3275","-0.1633"
"30.5500","2.5386","1.6973","13.3988","-0.3281","-0.1636"
"30.6000","2.5430","1.7017","13.4331","-0.3274","-0.1633"
"30.6500","2.5471","1.6916","13.3533","-0.3294","-0.1642"
"30.7000","2.5512","1.6902","13.3428","-0.3301","-0.1646"
"30.7500","2.5551","1.6817","13.2758","-0.3328","-0.1659"
"30.8000","2.5593","1.6839","13.2933","-0.3328","-0.1659"
"30.8500","2.5635","1.6778","13.2448","-0.3340","-0.1665"
"30.9000","2.5679","1.6779","13.2454","-0.3350","-0.1670"
"30.9500","2.5720","1.6663","13.1540","-0.3391","-0.1691"
"31.0000","2.5761","1.6658","13.1501","-0.3392","-0.1691"
"31.0500","2.5803","1.6609","13.1114","-0.3402","-0.1696"
"31.1000","2.5845","1.6595","13.1004","-0.3428","-0.1709"
"31.1500","2.5887","1.6566","13.0770","-0.3424","-0.1707"
"31.2000","2.5929","1.6583","13.0910","-0.3423","-0.1707"
"31.2500","2.5970","1.6542","13.0584","-0.3409","-0.1700"
"31.3000","2.6010","1.6526","13.0461","-0.3441","-0.1715"
"31.3500","2.6051","1.6496","13.0224","-0.3471","-0.1730"
"31.4000","2.6091","1.6480","13.0098","-0.3438","-0.1714"
"31.4500","2.6136","1.6525","13.0447","-0.3471","-0.1731"
"31.5000","2.6177","1.6481","13.0104","-0.3445","-0.1718"
"31.5500","2.6220","1.6453","12.9884","-0.3447","-0.1718"
"31.6000","2.6259","1.6408","12.9527","-0.3462","-0.1726"
"31.6500","2.6304","1.6425","12.9658","-0.3473","-0.1731"
"31.7000","2.6346","1.6363","12.9173","-0.3457","-0.1724"
"31.7500","2.6389","1.6345","12.9028","-0.3478","-0.1734"
"31.8000","2.6428","1.6288","12.8577","-0.3459","-0.1725"
"31.8500","2.6472","1.6305","12.8710","-0.3476","-0.1733"
"31.9000","2.6510","1.6238","12.8183","-0.3490","-0.1740"
"31.9500","2.6553","1.6264","12.8389","-0.3487","-0.1739"
"32.0000","2.6592","1.6229","12.8113","-0.3472","-0.1731"
"32.0500","2.6638","1.6306","12.8718","-0.3499","-0.1744"
"32.1000","2.6678","1.6239","12.8189","-0.3464","-0.1727"
"32.1500","2.6721","1.6270","12.8434","-0.3450","-0.1720"
"32.2000","2.6760","1.6215","12.8000","-0.3472","-0.1731"
"32.2500","2.6805","1.6307","12.8730","-0.3461","-0.1726"
"32.3000","2.6845","1.6249","12.8269","-0.3485","-0.1738"
"32.3500","2.6889","1.6312","12.8768","-0.3487","-0.1739"
"32.4000","2.6927","1.6242","12.8218","-0.3488","-0.1739"
"32.4500","2.6969","1.6327","12.8885","-0.3449","-0.1720"
"32.5000","2.7008","1.6270","12.8435","-0.3466","-0.1728"
"32.5500","2.7052","1.6331","12.8920","-0.3491","-0.1741"
"32.6000","2.7093","1.6289","12.8590","-0.3473","-0.1732"
"32.6500","2.7138","1.6335","12.8948","-0.3488","-0.1739"
"32.7000","2.7178","1.6264","12.8391","-0.3477","-0.1734"
"32.7500","2.7220","1.6313","12.8780","-0.3485","-0.1737"
"32.8000","2.7261","1.6280","12.8517","-0.3474","-0.1732"
"32.8500","2.7305","1.6344","12.9021","-0.3486","-0.1738"
"32.9000","2.7346","1.6306","12.8718","-0.3481","-0.1736"
"32.9500","2.7388","1.6334","12.8938","-0.3436","-0.1713"
"33.0000","2.7427","1.6289","12.8585","-0.3452","-0.1721"
"33.0500","2.7469","1.6331","12.8920","-0.3448","-0.1719"
"33.1000","2.7510","1.6305","12.8711","-0.3457","-0.1724"
"33.1500","2.7552","1.6339","12.8982","-0.3494","-0.1742"
"33.2000","2.7596","1.6339","12.8979","-0.3465","-0.1728"
"33.2500","2.7637","1.6321","12.8839","-0.3445","-0.1718"
"33.3000","2.7678","1.6299","12.8668","-0.3448","-0.1719"
"33.3500","2.7719","1.6312","12.8768","-0.3451","-0.1720"
"33.4000","2.7761","1.6327","12.8891","-0.3438","-0.1714"
"33.4500","2.7802","1.6326","12.8877","-0.3434","-0.1712"
"33.5000","2.7847","1.6360","12.9148","-0.3429","-0.1710"
"33.5500","2.7886","1.6325","12.8872","-0.3420","-0.1705"
"33.6000","2.7928","1.6372","12.9246","-0.3434","-0.1712"
"33.6500","2.7966","1.6355","12.9110","-0.3419","-0.1704"
"33.7000","2.8010","1.6437","12.9757","-0.3417","-0.1704"
"33.7500","2.8051","1.6428","12.9684","-0.3442","-0.1716"
"33.8000","2.8096","1.6472","13.0031","-0.3384","-0.1687"
"33.8500","2.8135","1.6403","12.9488","-0.3418","-0.1704"
"33.9000","2.8178","1.6447","12.9835","-0.3394","-0.1692"
"33.9500","2.8218","1.6395","12.9421","-0.3400","-0.1695"
"34.0000","2.8263","1.6465","12.9979","-0.3404","-0.1697"
"34.0500","2.8304","1.6413","12.9569","-0.3388","-0.1689"
"34.1000","2.8347","1.6425","12.9660","-0.3371","-0.1681"
"34.1500","2.8385","1.6344","12.9019","-0.3382","-0.1686"
"34.2000","2.8428","1.6386","12.9356","-0.3381","-0.1686"
"34.2500","2.8467","1.6327","12.8885","-0.3415","-0.1702"
"34.3000","2.8512","1.6400","12.9466","-0.3370","-0.1680"
"34.3500","2.8552","1.6342","12.9004","-0.3376","-0.1683"
"34.4000","2.8596","1.6372","12.9241","-0.3378","-0.1684"
"34.4500","2.8634","1.6314","12.8788","-0.3373","-0.1682"
"34.5000","2.8679","1.6409","12.9534","-0.3353","-0.1672"
"34.5500","2.8718","1.6347","12.9048","-0.3373","-0.1682"
"34.6000","2.8762","1.6419","12.9615","-0.3345","-0.1668"
"34.6500","2.8804","1.6379","12.9298","-0.3368","-0.1679"
"34.7000","2.8846","1.6406","12.9510","-0.3376","-0.1683"
"34.7500","2.8885","1.6346","12.9034","-0.3355","-0.1673"
"34.8000","2.8927","1.6408","12.9523","-0.3353","-0.1672"
"34.8500","2.8967","1.6370","12.9227","-0.3370","-0.1680"
"34.9000","2.9010","1.6444","12.9813","-0.3329","-0.1660"
"34.9500","2.9053","1.6414","12.9571","-0.3324","-0.1657"
"35.0000","2.9094","1.6410","12.9546","-0.3324","-0.1658"
"35.0500","2.9135","1.6365","12.9187","-0.3334","-0.1662"
"35.1000","2.9177","1.6388","12.9368","-0.3317","-0.1654"
"35.1500","2.9220","1.6371","12.9233","-0.3321","-0.1656"
"35.2000","2.9263","1.6382","12.9319","-0.3304","-0.1647"
"35.2500","2.9304","1.6347","12.9048","-0.3319","-0.1655"
"35.3000","2.9345","1.6370","12.9229","-0.3301","-0.1646"
"35.3500","2.9387","1.6375","12.9264","-0.3323","-0.1657"
"35.4000","2.9427","1.6371","12.9232","-0.3304","-0.1647"
"35.4500","2.9470","1.6417","12.9598","-0.3312","-0.1651"
"35.5000","2.9511","1.6421","12.9627","-0.3277","-0.1634"
"35.5500","2.9554","1.6445","12.9816","-0.3252","-0.1621"
"35.6000","2.9593","1.6418","12.9604","-0.3321","-0.1656"
"35.6500","2.9637","1.6464","12.9969","-0.3299","-0.1645"
"35.7000","2.9677","1.6426","12.9668","-0.3317","-0.1654"
"35.7500","2.9722","1.6482","13.0113","-0.3268","-0.1629"
"35.8000","2.9762","1.6436","12.9751","-0.3279","-0.1635"
"35.8500","2.9805","1.6446","12.9824","-0.3266","-0.1629"
"35.9000","2.9843","1.6390","12.9382","-0.3267","-0.1629"
"35.9500","2.9887","1.6443","12.9800","-0.3267","-0.1629"
"36.0000","2.9925","1.6373","12.9248","-0.3234","-0.1613"
"36.0500","2.9970","1.6436","12.9746","-0.3266","-0.1628"
"36.1000","3.0010","1.6378","12.9292","-0.3256","-0.1624"
"36.1500","3.0054","1.6428","12.9688","-0.3229","-0.1610"
"36.2000","3.0093","1.6352","12.9081","-0.3232","-0.1611"
"36.2500","3.0137","1.6417","12.9595","-0.3228","-0.1610"
"36.3000","3.0178","1.6355","12.9107","-0.3237","-0.1614"
"36.3500","3.0223","1.6409","12.9535","-0.3224","-0.1608"
"36.4000","3.0262","1.6299","12.8663","-0.3246","-0.1618"
"36.4500","3.0305","1.6331","12.8921","-0.3228","-0.1609"
"36.5000","3.0343","1.6272","12.8456","-0.3207","-0.1599"
"36.5500","3.0386","1.6336","12.8961","-0.3210","-0.1601"
"36.6000","3.0426","1.6276","12.8484","-0.3232","-0.1611"
"36.6500","3.0471","1.6352","12.9084","-0.3205","-0.1598"
"36.7000","3.0512","1.6257","12.8332","-0.3216","-0.1604"
"36.7500","3.0554","1.6264","12.8388","-0.3192","-0.1591"
"36.8000","3.0593","1.6201","12.7893","-0.3232","-0.1611"
"36.8500","3.0636","1.6258","12.8346","-0.3214","-0.1602"
"36.9000","3.0679","1.6233","12.8144","-0.3227","-0.1609"
"36.9500","3.0723","1.6245","12.8238","-0.3202","-0.1596"
"37.0000","3.0762","1.6156","12.7538","-0.3208","-0.1600"
"37.0500","3.0803","1.6172","12.7666","-0.3194","-0.1592"
"37.1000","3.0843","1.6141","12.7415","-0.3207","-0.1599"
"37.1500","3.0883","1.6159","12.7559","-0.3174","-0.1583"
"37.2000","3.0927","1.6163","12.7595","-0.3190","-0.1591"
"37.2500","3.0969","1.6151","12.7500","-0.3201","-0.1596"
"37.3000","3.1011","1.6116","12.7222","-0.3222","-0.1606"
"37.3500","3.1052","1.6100","12.7096","-0.3196","-0.1593"
"37.4000","3.1095","1.6103","12.7120","-0.3204","-0.1597"
"37.4500","3.1136","1.6094","12.7049","-0.3210","-0.1600"
"37.5000","3.1181","1.6112","12.7192","-0.3186","-0.1589"
"37.5500","3.1221","1.6042","12.6636","-0.3207","-0.1599"
"37.6000","3.1262","1.6015","12.6422","-0.3158","-0.1575"
"37.6500","3.1302","1.5976","12.6114","-0.3192","-0.1591"
"37.7000","3.1344","1.5974","12.6097","-0.3165","-0.1578"
"37.7500","3.1384","1.5925","12.5715","-0.3157","-0.1574"
"37.8000","3.1429","1.5956","12.5954","-0.3164","-0.1578"
"37.8500","3.1468","1.5882","12.5373","-0.3197","-0.1594"
"37.9000","3.1511","1.5905","12.5559","-0.3182","-0.1587"
"37.9500","3.1550","1.5859","12.5190","-0.3166","-0.1579"
"38.0000","3.1596","1.5937","12.5809","-0.3142","-0.1567"
"38.0500","3.1637","1.5907","12.5571","-0.3192","-0.1592"
"38.1000","3.1681","1.5922","12.5690","-0.3180","-0.1586"
"38.1500","3.1719","1.5845","12.5086","-0.3169","-0.1580"
"38.2000","3.1762","1.5893","12.5458","-0.3189","-0.1590"
"38.2500","3.1800","1.5831","12.4971","-0.3133","-0.1562"
"38.3000","3.1844","1.5889","12.5430","-0.3153","-0.1572"
"38.3500","3.1884","1.5849","12.5114","-0.3142","-0.1567"
"38.4000","3.1929","1.5931","12.5761","-0.3149","-0.1570"
"38.4500","3.1968","1.5874","12.5307","-0.3170","-0.1580"
"38.5000","3.2011","1.5927","12.5729","-0.3167","-0.1579"
"38.5500","3.2051","1.5885","12.5396","-0.3161","-0.1576"
"38.6000","3.2096","1.5941","12.5840","-0.3174","-0.1582"
"38.6500","3.2137","1.5882","12.5375","-0.3144","-0.1568"
"38.7000","3.2181","1.5896","12.5482","-0.3160","-0.1576"
"38.7500","3.2219","1.5800","12.4726","-0.3165","-0.1578"
"38.8000","3.2262","1.5842","12.5059","-0.3124","-0.1558"
"38.8500","3.2302","1.5789","12.4639","-0.3148","-0.1570"
"38.9000","3.2345","1.5829","12.4959","-0.3174","-0.1583"
"38.9500","3.2386","1.5792","12.4664","-0.3114","-0.1553"
"39.0000","3.2428","1.5813","12.4826","-0.3111","-0.1551"
"39.0500","3.2469","1.5755","12.4369","-0.3134","-0.1563"
"39.1000","3.2511","1.5780","12.4571","-0.3137","-0.1564"
"39.1500","3.2553","1.5751","12.4343","-0.3148","-0.1570"
"39.2000","3.2596","1.5772","12.4507","-0.3147","-0.1569"
"39.2500","3.2638","1.5719","12.4091","-0.3128","-0.1560"
"39.3000","3.2678","1.5722","12.4111","-0.3108","-0.1549"
"39.3500","3.2720","1.5707","12.3993","-0.3133","-0.1562"
"39.4000","3.2760","1.5691","12.3869","-0.3118","-0.1555"
"39.4500","3.2803","1.5697","12.3917","-0.3137","-0.1564"
"39.5000","3.2843","1.5670","12.3704","-0.3127","-0.1559"
"39.5500","3.2886","1.5669","12.3696","-0.3126","-0.1559"
"39.6000","3.2926","1.5637","12.3442","-0.3124","-0.1557"
"39.6500","3.2970","1.5647","12.3518","-0.3093","-0.1542"
"39.7000","3.3010","1.5604","12.3181","-0.3115","-0.1553"
"39.7500","3.3055","1.5617","12.3281","-0.3130","-0.1561"
"39.8000","3.3095","1.5552","12.2769","-0.3139","-0.1565"
"39.8500","3.3139","1.5528","12.2578","-0.3128","-0.1560"
"39.9000","3.3177","1.5446","12.1929","-0.3108","-0.1550"
"39.9500","3.3220","1.5446","12.1929","-0.3119","-0.1555"
"40.0000","3.3260","1.5378","12.1396","-0.3100","-0.1546"
"40.0500","3.3304","1.5407","12.1628","-0.3140","-0.1566"
"40.1000","3.3344","1.5346","12.1145","-0.3117","-0.1554"
"40.1500","3.3387","1.5365","12.1290","-0.3107","-0.1549"
"40.2000","3.3426","1.5286","12.0667","-0.3134","-0.1562"
"40.2500","3.3470","1.5331","12.1026","-0.3129","-0.1560"
"40.3000","3.3511","1.5245","12.0342","-0.3118","-0.1555"
"40.3500","3.3556","1.5255","12.0428","-0.3108","-0.1550"
"40.4000","3.3596","1.5168","11.9736","-0.3135","-0.1563"
"40.4500","3.3638","1.5168","11.9736","-0.3088","-0.1540"
"40.5000","3.3676","1.5103","11.9228","-0.3093","-0.1542"
"40.5500","3.3719","1.5165","11.9714","-0.3083","-0.1537"
"40.6000","3.3759","1.5088","11.9104","-0.3053","-0.1522"
"40.6500","3.3802","1.5115","11.9319","-0.3089","-0.1540"
"40.7000","3.3843","1.5012","11.8508","-0.3089","-0.1540"
"40.7500","3.3885","1.4999","11.8406","-0.3090","-0.1541"
"40.8000","3.3925","1.4923","11.7804","-0.3104","-0.1548"
"40.8500","3.3969","1.4930","11.7860","-0.3096","-0.1544"
"40.9000","3.4011","1.4865","11.7342","-0.3089","-0.1540"
"40.9500","3.4055","1.4866","11.7358","-0.3098","-0.1545"
"41.0000","3.4096","1.4779","11.6670","-0.3068","-0.1530"
"41.0500","3.4137","1.4777","11.6652","-0.3063","-0.1527"
"41.1000","3.4178","1.4729","11.6272","-0.3061","-0.1526"
"41.1500","3.4219","1.4748","11.6422","-0.3069","-0.1530"
"41.2000","3.4261","1.4716","11.6166","-0.3050","-0.1521"
"41.2500","3.4304","1.4732","11.6295","-0.3047","-0.1519"
"41.3000","3.4345","1.4677","11.5858","-0.3050","-0.1521"
"41.3500","3.4385","1.4679","11.5880","-0.3026","-0.1509"
"41.4000","3.4427","1.4660","11.5729","-0.3039","-0.1515"
"41.4500","3.4469","1.4663","11.5753","-0.3052","-0.1522"
"41.5000","3.4513","1.4651","11.5657","-0.3042","-0.1517"
"41.5500","3.4554","1.4634","11.5526","-0.3020","-0.1506"
"41.6000","3.4595","1.4580","11.5095","-0.3050","-0.1521"
"41.6500","3.4635","1.4577","11.5071","-0.3067","-0.1529"
"41.7000","3.4677","1.4578","11.5083","-0.3044","-0.1518"
"41.7500","3.4717","1.4561","11.4947","-0.3069","-0.1530"
"41.8000","3.4761","1.4566","11.4983","-0.3039","-0.1515"
"41.8500","3.4801","1.4515","11.4581","-0.3022","-0.1507"
"41.9000","3.4844","1.4517","11.4602","-0.3013","-0.1502"
"41.9500","3.4884","1.4476","11.4276","-0.3006","-0.1499"
"42.0000","3.4928","1.4480","11.4306","-0.2980","-0.1486"
"42.0500","3.4968","1.4436","11.3958","-0.3003","-0.1497"
"42.1000","3.5014","1.4462","11.4163","-0.3025","-0.1508"
"42.1500","3.5054","1.4367","11.3418","-0.3022","-0.1507"
"42.2000","3.5096","1.4358","11.3340","-0.3033","-0.1512"
"42.2500","3.5134","1.4308","11.2947","-0.2988","-0.1490"
"42.3000","3.5179","1.4354","11.3316","-0.2991","-0.1491"
"42.3500","3.5219","1.4289","11.2799","-0.3001","-0.1497"
"42.4000","3.5264","1.4315","11.3002","-0.3021","-0.1506"
"42.4500","3.5302","1.4226","11.2304","-0.3020","-0.1506"
"42.5000","3.5346","1.4280","11.2727","-0.3000","-0.1496"
"42.5500","3.5385","1.4217","11.2231","-0.2959","-0.1476"
"42.6000","3.5429","1.4267","11.2622","-0.2964","-0.1478"
"42.6500","3.5469","1.4222","11.2266","-0.2995","-0.1493"
"42.7000","3.5514","1.4273","11.2672","-0.2961","-0.1476"
"42.7500","3.5553","1.4183","11.1961","-0.2986","-0.1489"
"42.8000","3.5595","1.4227","11.2306","-0.2973","-0.1482"
"42.8500","3.5635","1.4163","11.1801","-0.2983","-0.1487"
"42.9000","3.5678","1.4188","11.1999","-0.2987","-0.1489"
"42.9500","3.5719","1.4125","11.1503","-0.2973","-0.1482"
"43.0000","3.5762","1.4125","11.1502","-0.3000","-0.1496"
"43.0500","3.5801","1.4042","11.0846","-0.3002","-0.1497"
"43.1000","3.5844","1.4075","11.1109","-0.2988","-0.1490"
"43.1500","3.5885","1.4006","11.0563","-0.2978","-0.1485"
"43.1530","3.5887","1.3999","11.0513","-0.2977","-0.1484"