File: composites_properties_derivations/composite_tube_tests/comp_tube_nb.csv
Specimen label,"1 NB"
Force at Maximum Load,"3.56",kN
Tensile stress at Maximum Load,"28.11",MPa
Epsilon ONE Displacement at Maximum Load,"-0.01",mm
Force at Break (Standard),"0.90",kN
Tensile stress at Break (Standard),"7.07",MPa
Epsilon ONE Displacement at Break (Standard),"0.02",mm
Slope (Chord 0.05 % - 0.2 %),"-----",MPa
Modulus (Automatic Young's),"39134.99",MPa

Specimen label,"1 NB"
Thickness,"",mm
Width,"",mm
Length,"49.96",mm
Rate 1,"5.00",mm/min
Outer diameter,"15.88",mm
Wall thickness,"3.18",mm

Time,Displacement,Force,Tensile stress,Tensile strain (Epsilon ONE Displacement),Epsilon ONE Displacement
(s),(mm),(kN),(MPa),(%),(mm)
"0.0000","0.0004","0.0500","0.3951","-0.0006","-0.0003"
"0.0700","0.0011","0.0622","0.4913","0.0003","0.0001"
"0.1400","0.0039","0.1164","0.9192","0.0016","0.0008"
"0.2100","0.0071","0.1643","1.2970","0.0015","0.0007"
"0.2800","0.0180","0.2093","1.6525","0.0018","0.0009"
"0.3500","0.0234","0.2038","1.6090","0.0018","0.0009"
"0.4200","0.0295","0.2068","1.6327","0.0027","0.0013"
"0.4900","0.0355","0.2101","1.6582","0.0041","0.0020"
"0.5600","0.0412","0.2126","1.6785","0.0044","0.0022"
"0.6300","0.0471","0.2154","1.7002","0.0053","0.0026"
"0.7000","0.0528","0.2192","1.7300","0.0078","0.0039"
"0.7700","0.0585","0.2220","1.7524","0.0069","0.0035"
"0.8400","0.0645","0.2249","1.7754","0.0078","0.0039"
"0.9100","0.0704","0.2289","1.8071","0.0089","0.0044"
"0.9800","0.0760","0.2319","1.8306","0.0094","0.0047"
"1.0500","0.0822","0.2350","1.8553","0.0104","0.0052"
"1.1200","0.0882","0.2393","1.8889","0.0124","0.0062"
"1.1900","0.0937","0.2428","1.9168","0.0116","0.0058"
"1.2600","0.0995","0.2459","1.9410","0.0137","0.0068"
"1.3300","0.1055","0.2501","1.9740","0.0146","0.0073"
"1.4000","0.1112","0.2545","2.0087","0.0143","0.0072"
"1.4700","0.1170","0.2574","2.0316","0.0151","0.0076"
"1.5400","0.1230","0.2621","2.0692","0.0153","0.0077"
"1.6100","0.1288","0.2664","2.1030","0.0165","0.0082"
"1.6800","0.1348","0.2696","2.1281","0.0185","0.0093"
"1.7500","0.1405","0.2729","2.1544","0.0190","0.0095"
"1.8200","0.1461","0.2777","2.1922","0.0192","0.0096"
"1.8900","0.1518","0.2808","2.2163","0.0192","0.0096"
"1.9600","0.1579","0.2849","2.2491","0.0208","0.0104"
"2.0300","0.1636","0.2891","2.2825","0.0219","0.0110"
"2.1000","0.1693","0.2928","2.3111","0.0227","0.0113"
"2.1700","0.1754","0.2969","2.3438","0.0215","0.0108"
"2.2400","0.1815","0.3017","2.3816","0.0224","0.0112"
"2.3100","0.1870","0.3053","2.4097","0.0252","0.0126"
"2.3800","0.1929","0.3093","2.4419","0.0246","0.0123"
"2.4500","0.1988","0.3143","2.4815","0.0250","0.0125"
"2.5200","0.2046","0.3185","2.5142","0.0247","0.0123"
"2.5900","0.2104","0.3221","2.5424","0.0258","0.0129"
"2.6600","0.2163","0.3274","2.5844","0.0246","0.0123"
"2.7300","0.2219","0.3324","2.6243","0.0277","0.0138"
"2.8000","0.2280","0.3363","2.6547","0.0281","0.0141"
"2.8700","0.2339","0.3415","2.6958","0.0291","0.0145"
"2.9400","0.2394","0.3475","2.7429","0.0278","0.0139"
"3.0100","0.2452","0.3520","2.7785","0.0296","0.0148"
"3.0800","0.2513","0.3579","2.8257","0.0300","0.0150"
"3.1500","0.2569","0.3642","2.8748","0.0328","0.0164"
"3.2200","0.2626","0.3698","2.9193","0.0335","0.0167"
"3.2900","0.2687","0.3765","2.9723","0.0337","0.0168"
"3.3600","0.2747","0.3841","3.0322","0.0331","0.0165"
"3.4300","0.2805","0.3897","3.0760","0.0338","0.0169"
"3.5000","0.2863","0.3959","3.1256","0.0347","0.0173"
"3.5700","0.2921","0.4042","3.1907","0.0353","0.0176"
"3.6400","0.2979","0.4103","3.2391","0.0351","0.0175"
"3.7100","0.3038","0.4172","3.2932","0.0365","0.0182"
"3.7800","0.3097","0.4256","3.3596","0.0359","0.0179"
"3.8500","0.3153","0.4318","3.4088","0.0375","0.0187"
"3.9200","0.3213","0.4391","3.4666","0.0373","0.0186"
"3.9900","0.3274","0.4481","3.5374","0.0388","0.0194"
"4.0600","0.3328","0.4554","3.5947","0.0389","0.0194"
"4.1300","0.3386","0.4623","3.6494","0.0395","0.0197"
"4.2000","0.3446","0.4719","3.7255","0.0426","0.0213"
"4.2700","0.3503","0.4809","3.7960","0.0412","0.0206"
"4.3400","0.3560","0.4872","3.8459","0.0421","0.0210"
"4.4100","0.3621","0.4934","3.8950","0.0415","0.0207"
"4.4800","0.3678","0.5083","4.0126","0.0425","0.0212"
"4.5500","0.3739","0.5179","4.0882","0.0433","0.0216"
"4.6200","0.3798","0.5291","4.1765","0.0450","0.0225"
"4.6900","0.3854","0.5416","4.2756","0.0453","0.0226"
"4.7600","0.3911","0.5505","4.3460","0.0458","0.0229"
"4.8300","0.3973","0.5612","4.4303","0.0487","0.0243"
"4.9000","0.4029","0.5727","4.5213","0.0467","0.0233"
"4.9700","0.4085","0.5817","4.5917","0.0487","0.0243"
"5.0400","0.4145","0.5868","4.6322","0.0474","0.0237"
"5.1100","0.4207","0.5961","4.7054","0.0513","0.0256"
"5.1800","0.4262","0.6066","4.7882","0.0503","0.0251"
"5.2500","0.4320","0.6155","4.8588","0.0510","0.0255"
"5.3200","0.4379","0.6264","4.9446","0.0508","0.0254"
"5.3900","0.4437","0.6353","5.0149","0.0510","0.0255"
"5.4600","0.4494","0.6439","5.0828","0.0521","0.0260"
"5.5300","0.4553","0.6554","5.1742","0.0507","0.0253"
"5.6000","0.4610","0.6644","5.2446","0.0536","0.0268"
"5.6700","0.4671","0.6734","5.3161","0.0543","0.0271"
"5.7400","0.4732","0.6839","5.3988","0.0549","0.0274"
"5.8100","0.4787","0.6936","5.4755","0.0575","0.0287"
"5.8800","0.4845","0.7008","5.5320","0.0576","0.0288"
"5.9500","0.4907","0.7120","5.6203","0.0589","0.0295"
"6.0200","0.4963","0.7214","5.6945","0.0587","0.0293"
"6.0900","0.5018","0.7286","5.7516","0.0599","0.0299"
"6.1600","0.5079","0.7392","5.8351","0.0605","0.0302"
"6.2300","0.5138","0.7498","5.9192","0.0616","0.0308"
"6.3000","0.5197","0.7567","5.9734","0.0610","0.0305"
"6.3700","0.5254","0.7653","6.0412","0.0629","0.0314"
"6.4400","0.5311","0.7771","6.1347","0.0639","0.0319"
"6.5100","0.5369","0.7843","6.1915","0.0653","0.0326"
"6.5800","0.5429","0.7929","6.2590","0.0651","0.0326"
"6.6500","0.5486","0.8042","6.3488","0.0648","0.0324"
"6.7200","0.5542","0.8119","6.4090","0.0666","0.0333"
"6.7900","0.5605","0.8203","6.4759","0.0658","0.0329"
"6.8600","0.5666","0.8307","6.5577","0.0668","0.0334"
"6.9300","0.5721","0.8384","6.6180","0.0672","0.0336"
"7.0000","0.5779","0.8454","6.6736","0.0662","0.0331"
"7.0700","0.5840","0.8561","6.7582","0.0673","0.0336"
"7.1400","0.5896","0.8643","6.8229","0.0680","0.0340"
"7.2100","0.5952","0.8711","6.8765","0.0688","0.0344"
"7.2800","0.6013","0.8822","6.9639","0.0685","0.0342"
"7.3500","0.6071","0.8917","7.0391","0.0699","0.0349"
"7.4200","0.6128","0.8981","7.0896","0.0694","0.0347"
"7.4900","0.6190","0.9088","7.1740","0.0696","0.0348"
"7.5600","0.6247","0.9180","7.2468","0.0703","0.0351"
"7.6300","0.6302","0.9249","7.3011","0.0691","0.0345"
"7.7000","0.6363","0.9346","7.3780","0.0712","0.0356"
"7.7700","0.6419","0.9451","7.4605","0.0709","0.0354"
"7.8400","0.6475","0.9527","7.5207","0.0726","0.0363"
"7.9100","0.6539","0.9619","7.5934","0.0721","0.0360"
"7.9800","0.6598","0.9728","7.6792","0.0731","0.0365"
"8.0500","0.6653","0.9811","7.7446","0.0722","0.0361"
"8.1200","0.6713","0.9894","7.8107","0.0719","0.0359"
"8.1900","0.6772","1.0012","7.9032","0.0734","0.0367"
"8.2600","0.6829","1.0104","7.9759","0.0729","0.0364"
"8.3300","0.6887","1.0178","8.0344","0.0738","0.0369"
"8.4000","0.6945","1.0301","8.1314","0.0757","0.0378"
"8.4700","0.7003","1.0396","8.2064","0.0755","0.0377"
"8.5400","0.7063","1.0474","8.2685","0.0765","0.0382"
"8.6100","0.7122","1.0573","8.3464","0.0761","0.0380"
"8.6800","0.7178","1.0665","8.4193","0.0766","0.0383"
"8.7500","0.7237","1.0733","8.4727","0.0745","0.0372"
"8.8200","0.7297","1.0827","8.5471","0.0751","0.0375"
"8.8900","0.7353","1.0946","8.6413","0.0760","0.0380"
"8.9600","0.7409","1.1025","8.7030","0.0764","0.0382"
"9.0300","0.7471","1.1133","8.7884","0.0760","0.0380"
"9.1000","0.7529","1.1244","8.8761","0.0773","0.0386"
"9.1700","0.7586","1.1321","8.9370","0.0766","0.0383"
"9.2400","0.7646","1.1426","9.0201","0.0777","0.0388"
"9.3100","0.7704","1.1556","9.1227","0.0776","0.0388"
"9.3800","0.7762","1.1647","9.1943","0.0778","0.0389"
"9.4500","0.7821","1.1738","9.2664","0.0770","0.0385"
"9.5200","0.7878","1.1872","9.3717","0.0779","0.0389"
"9.5900","0.7934","1.1967","9.4469","0.0785","0.0392"
"9.6600","0.7995","1.2058","9.5183","0.0773","0.0386"
"9.7300","0.8056","1.2183","9.6175","0.0791","0.0395"
"9.8000","0.8111","1.2288","9.7005","0.0796","0.0398"
"9.8700","0.8169","1.2370","9.7653","0.0797","0.0398"
"9.9400","0.8230","1.2507","9.8733","0.0801","0.0400"
"10.0100","0.8288","1.2624","9.9652","0.0801","0.0400"
"10.0800","0.8342","1.2711","10.0340","0.0808","0.0404"
"10.1500","0.8403","1.2850","10.1438","0.0812","0.0406"
"10.2200","0.8461","1.2970","10.2386","0.0817","0.0408"
"10.2900","0.8521","1.3068","10.3156","0.0818","0.0409"
"10.3600","0.8581","1.3185","10.4080","0.0832","0.0415"
"10.4300","0.8638","1.3319","10.5138","0.0830","0.0415"
"10.5000","0.8695","1.3416","10.5905","0.0838","0.0419"
"10.5700","0.8757","1.3541","10.6895","0.0858","0.0429"
"10.6400","0.8812","1.3671","10.7924","0.0858","0.0429"
"10.7100","0.8868","1.3784","10.8816","0.0855","0.0427"
"10.7800","0.8929","1.3905","10.9771","0.0872","0.0436"
"10.8500","0.8990","1.4050","11.0914","0.0886","0.0443"
"10.9200","0.9046","1.4146","11.1669","0.0869","0.0434"
"10.9900","0.9105","1.4266","11.2619","0.0887","0.0443"
"11.0600","0.9164","1.4416","11.3802","0.0894","0.0446"
"11.1300","0.9220","1.4530","11.4701","0.0921","0.0460"
"11.2000","0.9278","1.4633","11.5517","0.0918","0.0459"
"11.2700","0.9337","1.4797","11.6806","0.0926","0.0463"
"11.3400","0.9393","1.4922","11.7794","0.0935","0.0467"
"11.4100","0.9454","1.5035","11.8687","0.0941","0.0470"
"11.4800","0.9514","1.5197","11.9966","0.0960","0.0479"
"11.5500","0.9572","1.5343","12.1116","0.0959","0.0479"
"11.6200","0.9628","1.5440","12.1884","0.0954","0.0476"
"11.6900","0.9690","1.5592","12.3082","0.0975","0.0487"
"11.7600","0.9747","1.5723","12.4122","0.0975","0.0487"
"11.8300","0.9802","1.5822","12.4901","0.0978","0.0489"
"11.9000","0.9862","1.5977","12.6126","0.1000","0.0500"
"11.9700","0.9921","1.6135","12.7368","0.1000","0.0500"
"12.0400","0.9979","1.6237","12.8176","0.1008","0.0504"
"12.1100","1.0037","1.6373","12.9251","0.1017","0.0508"
"12.1800","1.0096","1.6533","13.0510","0.1024","0.0511"
"12.2500","1.0153","1.6652","13.1449","0.1013","0.0506"
"12.3200","1.0213","1.6781","13.2470","0.1029","0.0514"
"12.3900","1.0270","1.6944","13.3755","0.1035","0.0517"
"12.4600","1.0326","1.7066","13.4719","0.1042","0.0521"
"12.5300","1.0386","1.7209","13.5851","0.1058","0.0529"
"12.6000","1.0447","1.7374","13.7152","0.1079","0.0539"
"12.6700","1.0502","1.7504","13.8180","0.1066","0.0533"
"12.7400","1.0562","1.7648","13.9316","0.1097","0.0548"
"12.8100","1.0622","1.7843","14.0858","0.1084","0.0541"
"12.8800","1.0680","1.7979","14.1926","0.1101","0.0550"
"12.9500","1.0736","1.8093","14.2829","0.1114","0.0556"
"13.0200","1.0796","1.8273","14.4251","0.1121","0.0560"
"13.0900","1.0853","1.8426","14.5455","0.1123","0.0561"
"13.1600","1.0913","1.8556","14.6487","0.1134","0.0566"
"13.2300","1.0972","1.8713","14.7723","0.1127","0.0563"
"13.3000","1.1029","1.8885","14.9081","0.1142","0.0571"
"13.3700","1.1086","1.9013","15.0091","0.1152","0.0576"
"13.4400","1.1148","1.9177","15.1385","0.1163","0.0581"
"13.5100","1.1204","1.9337","15.2651","0.1165","0.0582"
"13.5800","1.1258","1.9469","15.3694","0.1170","0.0585"
"13.6500","1.1320","1.9644","15.5070","0.1192","0.0596"
"13.7200","1.1381","1.9822","15.6481","0.1180","0.0589"
"13.7900","1.1437","1.9957","15.7544","0.1185","0.0592"
"13.8600","1.1496","2.0113","15.8770","0.1198","0.0598"
"13.9300","1.1556","2.0307","16.0305","0.1196","0.0598"
"14.0000","1.1614","2.0459","16.1507","0.1208","0.0604"
"14.0700","1.1671","2.0591","16.2550","0.1203","0.0601"
"14.1400","1.1729","2.0786","16.4089","0.1225","0.0612"
"14.2100","1.1785","2.0944","16.5337","0.1229","0.0614"
"14.2800","1.1847","2.1100","16.6569","0.1235","0.0617"
"14.3500","1.1907","2.1274","16.7943","0.1235","0.0617"
"14.4200","1.1962","2.1452","16.9346","0.1243","0.0621"
"14.4900","1.2020","2.1584","17.0390","0.1237","0.0618"
"14.5600","1.2082","2.1785","17.1974","0.1247","0.0623"
"14.6300","1.2138","2.1951","17.3282","0.1250","0.0625"
"14.7000","1.2193","2.2085","17.4341","0.1262","0.0630"
"14.7700","1.2254","2.2284","17.5915","0.1266","0.0632"
"14.8400","1.2313","2.2476","17.7424","0.1252","0.0626"
"14.9100","1.2370","2.2605","17.8449","0.1265","0.0632"
"14.9800","1.2430","2.2783","17.9854","0.1279","0.0639"
"15.0500","1.2489","2.2987","18.1465","0.1258","0.0629"
"15.1200","1.2546","2.3127","18.2564","0.1283","0.0641"
"15.1900","1.2605","2.3293","18.3877","0.1291","0.0645"
"15.2600","1.2663","2.3493","18.5456","0.1295","0.0647"
"15.3300","1.2718","2.3639","18.6608","0.1291","0.0645"
"15.4000","1.2779","2.3818","18.8020","0.1299","0.0649"
"15.4700","1.2839","2.4010","18.9535","0.1317","0.0658"
"15.5400","1.2894","2.4168","19.0783","0.1314","0.0657"
"15.6100","1.2953","2.4329","19.2055","0.1316","0.0657"
"15.6800","1.3014","2.4530","19.3642","0.1323","0.0661"
"15.7500","1.3071","2.4694","19.4937","0.1328","0.0664"
"15.8200","1.3127","2.4833","19.6034","0.1331","0.0665"
"15.8900","1.3186","2.5044","19.7702","0.1335","0.0667"
"15.9600","1.3244","2.5218","19.9074","0.1342","0.0670"
"16.0300","1.3303","2.5365","20.0232","0.1341","0.0670"
"16.1000","1.3363","2.5557","20.1752","0.1335","0.0667"
"16.1700","1.3420","2.5746","20.3241","0.1334","0.0667"
"16.2400","1.3478","2.5894","20.4412","0.1344","0.0672"
"16.3100","1.3539","2.6082","20.5890","0.1352","0.0676"
"16.3800","1.3596","2.6271","20.7383","0.1328","0.0663"
"16.4500","1.3652","2.6416","20.8527","0.1347","0.0673"
"16.5200","1.3711","2.6600","20.9984","0.1346","0.0673"
"16.5900","1.3772","2.6814","21.1676","0.1347","0.0673"
"16.6600","1.3827","2.6956","21.2794","0.1340","0.0670"
"16.7300","1.3887","2.7131","21.4174","0.1345","0.0672"
"16.8000","1.3947","2.7343","21.5845","0.1338","0.0669"
"16.8700","1.4004","2.7502","21.7101","0.1332","0.0666"
"16.9400","1.4061","2.7650","21.8272","0.1340","0.0670"
"17.0100","1.4120","2.7875","22.0051","0.1323","0.0661"
"17.0800","1.4175","2.8029","22.1265","0.1305","0.0652"
"17.1500","1.4236","2.8206","22.2658","0.1320","0.0659"
"17.2200","1.4296","2.8398","22.4177","0.1312","0.0655"
"17.2900","1.4354","2.8594","22.5723","0.1316","0.0657"
"17.3600","1.4412","2.8733","22.6825","0.1311","0.0655"
"17.4300","1.4473","2.8945","22.8491","0.1313","0.0656"
"17.5000","1.4530","2.9145","23.0073","0.1304","0.0652"
"17.5700","1.4587","2.9336","23.1585","0.1290","0.0644"
"17.6400","1.4646","2.9578","23.3490","0.1301","0.0650"
"17.7100","1.4704","2.9811","23.5333","0.1282","0.0640"
"17.7800","1.4762","2.9968","23.6572","0.1296","0.0647"
"17.8500","1.4821","3.0144","23.7960","0.1274","0.0637"
"17.9200","1.4880","3.0355","23.9627","0.1268","0.0634"
"17.9900","1.4938","3.0493","24.0713","0.1256","0.0628"
"18.0600","1.4997","3.0669","24.2106","0.1259","0.0629"
"18.1300","1.5055","3.0870","24.3690","0.1254","0.0627"
"18.2000","1.5109","3.1018","24.4859","0.1244","0.0622"
"18.2700","1.5170","3.1197","24.6276","0.1236","0.0618"
"18.3400","1.5230","3.1413","24.7977","0.1236","0.0618"
"18.4100","1.5286","3.1563","24.9161","0.1228","0.0614"
"18.4800","1.5345","3.1727","25.0453","0.1210","0.0605"
"18.5500","1.5407","3.1939","25.2127","0.1197","0.0598"
"18.6200","1.5464","3.2100","25.3402","0.1186","0.0593"
"18.6900","1.5521","3.2233","25.4449","0.1186","0.0593"
"18.7600","1.5580","3.2417","25.5900","0.1149","0.0574"
"18.8300","1.5636","3.2517","25.6695","0.1141","0.0570"
"18.9000","1.5695","3.2267","25.4719","0.1060","0.0530"
"18.9700","1.5755","3.2209","25.4261","0.0946","0.0473"
"19.0400","1.5813","3.1652","24.9860","0.0799","0.0399"
"19.1100","1.5871","3.1052","24.5124","0.0654","0.0327"
"19.1800","1.5931","3.0957","24.4379","0.0555","0.0277"
"19.2500","1.5988","3.1124","24.5696","0.0456","0.0228"
"19.3200","1.6043","3.1347","24.7458","0.0378","0.0189"
"19.3900","1.6103","3.1680","25.0088","0.0315","0.0158"
"19.4600","1.6162","3.2002","25.2626","0.0250","0.0125"
"19.5300","1.6219","3.2229","25.4417","0.0193","0.0096"
"19.6000","1.6278","3.2509","25.6626","0.0130","0.0065"
"19.6700","1.6339","3.2611","25.7431","0.0088","0.0044"
"19.7400","1.6396","3.2686","25.8023","0.0060","0.0030"
"19.8100","1.6454","3.2811","25.9016","0.0007","0.0003"
"19.8800","1.6513","3.3001","26.0513","-0.0009","-0.0005"
"19.9500","1.6568","3.3116","26.1424","-0.0038","-0.0019"
"20.0200","1.6628","3.3264","26.2591","-0.0041","-0.0021"
"20.0900","1.6690","3.3432","26.3918","-0.0067","-0.0033"
"20.1600","1.6745","3.3566","26.4970","-0.0083","-0.0041"
"20.2300","1.6803","3.3678","26.5857","-0.0097","-0.0048"
"20.3000","1.6864","3.3858","26.7276","-0.0110","-0.0055"
"20.3700","1.6921","3.3999","26.8388","-0.0133","-0.0066"
"20.4400","1.6977","3.4110","26.9271","-0.0138","-0.0069"
"20.5100","1.7036","3.4345","27.1122","-0.0151","-0.0076"
"20.5800","1.7094","3.4547","27.2715","-0.0167","-0.0084"
"20.6500","1.7153","3.4661","27.3620","-0.0174","-0.0087"
"20.7200","1.7212","3.4811","27.4805","-0.0197","-0.0098"
"20.7900","1.7271","3.4990","27.6216","-0.0186","-0.0093"
"20.8600","1.7330","3.5056","27.6737","-0.0205","-0.0102"
"20.9300","1.7389","3.5131","27.7329","-0.0203","-0.0101"
"21.0000","1.7447","3.5289","27.8575","-0.0217","-0.0108"
"21.0700","1.7502","3.5343","27.8999","-0.0224","-0.0112"
"21.1400","1.7562","3.5442","27.9785","-0.0245","-0.0122"
"21.2100","1.7623","3.5547","28.0613","-0.0246","-0.0123"
"21.2800","1.7678","3.5545","28.0595","-0.0254","-0.0127"
"21.3500","1.7736","3.5570","28.0791","-0.0255","-0.0128"
"21.4200","1.7798","3.5572","28.0807","-0.0276","-0.0138"
"21.4900","1.7855","3.5275","27.8467","-0.0272","-0.0136"
"21.5600","1.7911","3.4788","27.4620","-0.0283","-0.0141"
"21.6300","1.7970","3.4302","27.0787","-0.0280","-0.0140"
"21.7000","1.8027","3.3713","26.6135","-0.0280","-0.0140"
"21.7700","1.8087","3.3191","26.2011","-0.0288","-0.0144"
"21.8400","1.8147","3.2805","25.8963","-0.0287","-0.0143"
"21.9100","1.8204","3.2450","25.6163","-0.0281","-0.0140"
"21.9800","1.8262","3.2175","25.3989","-0.0282","-0.0141"
"22.0500","1.8324","3.1973","25.2401","-0.0278","-0.0139"
"22.1200","1.8380","3.1703","25.0269","-0.0284","-0.0142"
"22.1900","1.8436","3.1395","24.7835","-0.0286","-0.0143"
"22.2600","1.8497","3.1157","24.5953","-0.0293","-0.0147"
"22.3300","1.8555","3.0827","24.3350","-0.0292","-0.0146"
"22.4000","1.8611","3.0394","23.9930","-0.0316","-0.0158"
"22.4700","1.8671","2.9986","23.6714","-0.0324","-0.0162"
"22.5400","1.8730","2.9623","23.3848","-0.0302","-0.0151"
"22.6100","1.8788","2.9242","23.0841","-0.0312","-0.0156"
"22.6800","1.8846","2.8944","22.8484","-0.0333","-0.0166"
"22.7500","1.8904","2.8738","22.6858","-0.0322","-0.0161"
"22.8200","1.8959","2.8479","22.4816","-0.0331","-0.0165"
"22.8900","1.9020","2.8374","22.3984","-0.0315","-0.0157"
"22.9600","1.9080","2.8292","22.3339","-0.0329","-0.0164"
"23.0300","1.9136","2.8169","22.2366","-0.0326","-0.0163"
"23.1000","1.9194","2.8091","22.1752","-0.0326","-0.0163"
"23.1700","1.9256","2.8135","22.2100","-0.0323","-0.0161"
"23.2400","1.9314","2.8049","22.1422","-0.0316","-0.0158"
"23.3100","1.9370","2.7960","22.0720","-0.0324","-0.0162"
"23.3800","1.9429","2.7983","22.0897","-0.0322","-0.0161"
"23.4500","1.9487","2.7985","22.0914","-0.0324","-0.0162"
"23.5200","1.9545","2.7933","22.0507","-0.0329","-0.0164"
"23.5900","1.9603","2.7955","22.0677","-0.0327","-0.0163"
"23.6600","1.9661","2.7976","22.0849","-0.0325","-0.0162"
"23.7300","1.9720","2.7955","22.0680","-0.0318","-0.0159"
"23.8000","1.9780","2.7913","22.0344","-0.0317","-0.0159"
"23.8700","1.9839","2.7922","22.0416","-0.0303","-0.0151"
"23.9400","1.9894","2.7862","21.9943","-0.0318","-0.0159"
"24.0100","1.9952","2.7856","21.9897","-0.0319","-0.0159"
"24.0800","2.0013","2.7923","22.0424","-0.0322","-0.0161"
"24.1500","2.0070","2.7841","21.9783","-0.0310","-0.0155"
"24.2200","2.0127","2.7784","21.9331","-0.0321","-0.0160"
"24.2900","2.0189","2.7824","21.9649","-0.0306","-0.0153"
"24.3600","2.0248","2.7743","21.9007","-0.0308","-0.0154"
"24.4300","2.0303","2.7650","21.8268","-0.0307","-0.0154"
"24.5000","2.0364","2.7710","21.8746","-0.0302","-0.0151"
"24.5700","2.0420","2.7669","21.8419","-0.0300","-0.0150"
"24.6400","2.0478","2.7660","21.8353","-0.0281","-0.0141"
"24.7100","2.0538","2.7715","21.8782","-0.0289","-0.0144"
"24.7800","2.0595","2.7720","21.8828","-0.0299","-0.0149"
"24.8500","2.0653","2.7721","21.8836","-0.0288","-0.0144"
"24.9200","2.0715","2.7797","21.9433","-0.0315","-0.0158"
"24.9900","2.0772","2.7806","21.9506","-0.0295","-0.0147"
"25.0600","2.0827","2.7763","21.9167","-0.0286","-0.0143"
"25.1300","2.0887","2.7837","21.9750","-0.0286","-0.0143"
"25.2000","2.0946","2.7887","22.0141","-0.0288","-0.0144"
"25.2700","2.1002","2.7876","22.0053","-0.0291","-0.0145"
"25.3400","2.1062","2.7922","22.0416","-0.0295","-0.0147"
"25.4100","2.1122","2.7969","22.0792","-0.0301","-0.0150"
"25.4800","2.1179","2.7914","22.0358","-0.0288","-0.0144"
"25.5500","2.1238","2.7912","22.0340","-0.0283","-0.0141"
"25.6200","2.1297","2.7958","22.0704","-0.0258","-0.0129"
"25.6900","2.1354","2.7922","22.0418","-0.0277","-0.0138"
"25.7600","2.1411","2.7921","22.0413","-0.0267","-0.0134"
"25.8300","2.1471","2.8015","22.1151","-0.0262","-0.0131"
"25.9000","2.1528","2.8021","22.1197","-0.0262","-0.0131"
"25.9700","2.1586","2.8039","22.1339","-0.0262","-0.0131"
"26.0400","2.1648","2.8115","22.1946","-0.0262","-0.0131"
"26.1100","2.1705","2.8113","22.1924","-0.0258","-0.0129"
"26.1800","2.1761","2.8081","22.1674","-0.0260","-0.0130"
"26.2500","2.1821","2.8163","22.2321","-0.0266","-0.0133"
"26.3200","2.1878","2.8195","22.2572","-0.0256","-0.0128"
"26.3900","2.1935","2.8191","22.2541","-0.0267","-0.0133"
"26.4600","2.1995","2.8277","22.3225","-0.0263","-0.0131"
"26.5300","2.2054","2.8342","22.3733","-0.0257","-0.0128"
"26.6000","2.2112","2.8338","22.3703","-0.0254","-0.0127"
"26.6700","2.2172","2.8394","22.4141","-0.0234","-0.0117"
"26.7400","2.2231","2.8455","22.4626","-0.0247","-0.0124"
"26.8100","2.2286","2.8428","22.4417","-0.0240","-0.0120"
"26.8800","2.2345","2.8504","22.5017","-0.0236","-0.0118"
"26.9500","2.2406","2.8602","22.5785","-0.0239","-0.0120"
"27.0200","2.2460","2.8579","22.5606","-0.0242","-0.0121"
"27.0900","2.2519","2.8641","22.6092","-0.0233","-0.0117"
"27.1600","2.2580","2.8756","22.7006","-0.0240","-0.0120"
"27.2300","2.2640","2.8784","22.7224","-0.0223","-0.0111"
"27.3000","2.2696","2.8739","22.6870","-0.0214","-0.0107"
"27.3700","2.2755","2.8838","22.7649","-0.0229","-0.0114"
"27.4400","2.2811","2.8872","22.7917","-0.0206","-0.0103"
"27.5100","2.2869","2.8898","22.8123","-0.0217","-0.0109"
"27.5800","2.2929","2.9011","22.9015","-0.0201","-0.0100"
"27.6500","2.2987","2.9093","22.9659","-0.0186","-0.0093"
"27.7200","2.3044","2.9133","22.9975","-0.0193","-0.0096"
"27.7900","2.3107","2.9272","23.1073","-0.0170","-0.0085"
"27.8600","2.3165","2.9310","23.1375","-0.0174","-0.0087"
"27.9300","2.3219","2.9308","23.1360","-0.0175","-0.0088"
"28.0000","2.3280","2.9421","23.2250","-0.0175","-0.0087"
"28.0700","2.3339","2.9499","23.2867","-0.0166","-0.0083"
"28.1400","2.3394","2.9485","23.2760","-0.0146","-0.0073"
"28.2100","2.3454","2.9577","23.3484","-0.0164","-0.0082"
"28.2800","2.3513","2.9671","23.4223","-0.0144","-0.0072"
"28.3500","2.3572","2.9710","23.4532","-0.0158","-0.0079"
"28.4200","2.3630","2.9743","23.4793","-0.0135","-0.0068"
"28.4900","2.3688","2.9824","23.5436","-0.0150","-0.0075"
"28.5600","2.3744","2.9850","23.5636","-0.0135","-0.0068"
"28.6300","2.3804","2.9912","23.6130","-0.0128","-0.0064"
"28.7000","2.3862","2.9985","23.6705","-0.0130","-0.0065"
"28.7700","2.3918","3.0019","23.6975","-0.0118","-0.0059"
"28.8400","2.3978","3.0071","23.7381","-0.0122","-0.0061"
"28.9100","2.4039","3.0172","23.8180","-0.0103","-0.0051"
"28.9800","2.4096","3.0194","23.8354","-0.0109","-0.0054"
"29.0500","2.4153","3.0191","23.8334","-0.0114","-0.0057"
"29.1200","2.4213","3.0303","23.9211","-0.0096","-0.0048"
"29.1900","2.4272","3.0360","23.9667","-0.0117","-0.0058"
"29.2600","2.4328","3.0350","23.9586","-0.0104","-0.0052"
"29.3300","2.4387","3.0447","24.0355","-0.0113","-0.0057"
"29.4000","2.4446","3.0536","24.1057","-0.0109","-0.0054"
"29.4700","2.4504","3.0560","24.1243","-0.0104","-0.0052"
"29.5400","2.4564","3.0640","24.1878","-0.0103","-0.0051"
"29.6100","2.4621","3.0704","24.2381","-0.0093","-0.0046"
"29.6800","2.4677","3.0723","24.2531","-0.0091","-0.0045"
"29.7500","2.4737","3.0812","24.3230","-0.0101","-0.0050"
"29.8200","2.4796","3.0886","24.3815","-0.0079","-0.0039"
"29.8900","2.4851","3.0896","24.3898","-0.0083","-0.0042"
"29.9600","2.4911","3.0977","24.4534","-0.0076","-0.0038"
"30.0300","2.4971","3.1075","24.5310","-0.0074","-0.0037"
"30.1000","2.5029","3.1098","24.5490","-0.0070","-0.0035"
"30.1700","2.5086","3.1130","24.5741","-0.0068","-0.0034"
"30.2400","2.5147","3.1243","24.6632","-0.0060","-0.0030"
"30.3100","2.5204","3.1269","24.6842","-0.0057","-0.0028"
"30.3800","2.5262","3.1296","24.7056","-0.0061","-0.0031"
"30.4500","2.5321","3.1378","24.7700","-0.0061","-0.0030"
"30.5200","2.5378","3.1435","24.8151","-0.0060","-0.0030"
"30.5900","2.5436","3.1449","24.8261","-0.0058","-0.0029"
"30.6600","2.5497","3.1562","24.9157","-0.0053","-0.0027"
"30.7300","2.5555","3.1596","24.9420","-0.0053","-0.0026"
"30.8000","2.5611","3.1585","24.9336","-0.0048","-0.0024"
"30.8700","2.5670","3.1672","25.0021","-0.0041","-0.0020"
"30.9400","2.5730","3.1758","25.0703","-0.0044","-0.0022"
"31.0100","2.5785","3.1735","25.0521","-0.0053","-0.0027"
"31.0800","2.5845","3.1820","25.1189","-0.0021","-0.0011"
"31.1500","2.5904","3.1903","25.1842","-0.0028","-0.0014"
"31.2200","2.5963","3.1925","25.2023","-0.0035","-0.0017"
"31.2900","2.6021","3.1940","25.2136","-0.0038","-0.0019"
"31.3600","2.6081","3.2028","25.2835","-0.0026","-0.0013"
"31.4300","2.6137","3.2042","25.2940","-0.0032","-0.0016"
"31.5000","2.6198","3.2111","25.3485","-0.0016","-0.0008"
"31.5700","2.6256","3.2161","25.3884","-0.0001","-0.0001"
"31.6400","2.6311","3.2191","25.4123","-0.0017","-0.0009"
"31.7100","2.6369","3.2260","25.4662","-0.0020","-0.0010"
"31.7800","2.6431","3.2398","25.5756","-0.0008","-0.0004"
"31.8500","2.6489","3.2413","25.5874","-0.0002","-0.0001"
"31.9200","2.6545","3.2420","25.5923","-0.0016","-0.0008"
"31.9900","2.6605","3.2523","25.6741","-0.0010","-0.0005"
"32.0600","2.6663","3.2597","25.7327","-0.0002","-0.0001"
"32.1300","2.6719","3.2583","25.7216","0.0002","0.0001"
"32.2000","2.6778","3.2689","25.8051","0.0002","0.0001"
"32.2700","2.6836","3.2774","25.8718","0.0005","0.0003"
"32.3400","2.6895","3.2814","25.9039","0.0008","0.0004"
"32.4100","2.6955","3.2863","25.9421","0.0021","0.0011"
"32.4800","2.7015","3.2946","26.0082","-0.0003","-0.0002"
"32.5500","2.7071","3.2929","25.9942","0.0020","0.0010"
"32.6200","2.7129","3.2982","26.0367","0.0004","0.0002"
"32.6900","2.7189","3.3065","26.1020","0.0019","0.0009"
"32.7600","2.7244","3.3055","26.0940","0.0008","0.0004"
"32.8300","2.7303","3.3115","26.1415","0.0014","0.0007"
"32.9000","2.7363","3.3194","26.2033","0.0018","0.0009"
"32.9700","2.7421","3.3205","26.2121","0.0022","0.0011"
"33.0400","2.7479","3.3230","26.2324","0.0013","0.0007"
"33.1100","2.7538","3.3274","26.2671","0.0029","0.0015"
"33.1800","2.7595","3.3284","26.2745","0.0026","0.0013"
"33.2500","2.7653","3.3302","26.2891","0.0028","0.0014"
"33.3200","2.7711","3.3347","26.3242","0.0040","0.0020"
"33.3900","2.7769","3.3375","26.3466","0.0029","0.0014"
"33.4600","2.7827","3.3352","26.3284","0.0047","0.0023"
"33.5300","2.7889","3.3388","26.3565","0.0040","0.0020"
"33.6000","2.7947","3.3351","26.3275","0.0035","0.0017"
"33.6700","2.8003","3.3326","26.3082","0.0028","0.0014"
"33.7400","2.8063","3.3387","26.3563","0.0049","0.0024"
"33.8100","2.8123","3.3460","26.4140","0.0053","0.0026"
"33.8800","2.8177","3.3385","26.3543","0.0059","0.0029"
"33.9500","2.8236","3.3444","26.4009","0.0060","0.0030"
"34.0200","2.8296","3.3521","26.4617","0.0067","0.0033"
"34.0900","2.8354","3.3501","26.4461","0.0072","0.0036"
"34.1600","2.8413","3.3495","26.4414","0.0059","0.0029"
"34.2300","2.8472","3.3549","26.4836","0.0060","0.0030"
"34.3000","2.8528","3.3505","26.4494","0.0062","0.0031"
"34.3700","2.8587","3.3525","26.4653","0.0059","0.0030"
"34.4400","2.8647","3.3540","26.4772","0.0062","0.0031"
"34.5100","2.8702","3.3511","26.4542","0.0063","0.0032"
"34.5800","2.8760","3.3527","26.4665","0.0060","0.0030"
"34.6500","2.8823","3.3631","26.5484","0.0064","0.0032"
"34.7200","2.8881","3.3597","26.5218","0.0063","0.0031"
"34.7900","2.8936","3.3518","26.4595","0.0075","0.0038"
"34.8600","2.8997","3.3568","26.4992","0.0068","0.0034"
"34.9300","2.9056","3.3572","26.5019","0.0076","0.0038"
"35.0000","2.9113","3.3479","26.4288","0.0064","0.0032"
"35.0700","2.9170","3.3452","26.4073","0.0062","0.0031"
"35.1400","2.9229","3.3466","26.4188","0.0080","0.0040"
"35.2100","2.9288","3.3420","26.3823","0.0069","0.0035"
"35.2800","2.9347","3.3346","26.3236","0.0061","0.0031"
"35.3500","2.9406","3.3285","26.2758","0.0070","0.0035"
"35.4200","2.9462","3.3142","26.1624","0.0061","0.0030"
"35.4900","2.9522","3.3103","26.1320","0.0066","0.0033"
"35.5600","2.9580","3.3066","26.1026","0.0064","0.0032"
"35.6300","2.9634","3.2967","26.0246","0.0075","0.0037"
"35.7000","2.9694","3.2877","25.9532","0.0068","0.0034"
"35.7700","2.9755","3.2662","25.7835","0.0070","0.0035"
"35.8400","2.9813","3.2123","25.3582","0.0063","0.0032"
"35.9100","2.9870","3.1712","25.0340","0.0067","0.0033"
"35.9800","2.9931","3.1663","24.9953","0.0073","0.0036"
"36.0500","2.9989","3.1612","24.9549","0.0063","0.0031"
"36.1200","3.0046","3.1536","24.8950","0.0085","0.0042"
"36.1900","3.0104","3.1550","24.9056","0.0071","0.0035"
"36.2600","3.0161","3.1539","24.8970","0.0073","0.0037"
"36.3300","3.0219","3.1529","24.8895","0.0071","0.0036"
"36.4000","3.0280","3.1568","24.9198","0.0071","0.0036"
"36.4700","3.0338","3.1575","24.9254","0.0061","0.0031"
"36.5400","3.0395","3.1547","24.9036","0.0072","0.0036"
"36.6100","3.0455","3.1581","24.9301","0.0064","0.0032"
"36.6800","3.0513","3.1586","24.9341","0.0077","0.0038"
"36.7500","3.0568","3.1508","24.8727","0.0092","0.0046"
"36.8200","3.0627","3.1523","24.8848","0.0078","0.0039"
"36.8900","3.0687","3.1550","24.9058","0.0082","0.0041"
"36.9600","3.0745","3.1489","24.8574","0.0081","0.0040"
"37.0300","3.0804","3.1440","24.8191","0.0091","0.0046"
"37.1000","3.0863","3.1443","24.8217","0.0104","0.0052"
"37.1700","3.0921","3.1381","24.7729","0.0091","0.0045"
"37.2400","3.0980","3.1351","24.7489","0.0091","0.0045"
"37.3100","3.1039","3.1348","24.7461","0.0090","0.0045"
"37.3800","3.1093","3.1268","24.6833","0.0096","0.0048"
"37.4500","3.1153","3.1254","24.6721","0.0106","0.0053"
"37.5200","3.1214","3.1274","24.6882","0.0099","0.0050"
"37.5900","3.1271","3.1210","24.6375","0.0096","0.0048"
"37.6600","3.1327","3.1140","24.5822","0.0096","0.0048"
"37.7300","3.1388","3.1180","24.6139","0.0111","0.0055"
"37.8000","3.1447","3.1153","24.5924","0.0106","0.0053"
"37.8700","3.1503","3.1053","24.5138","0.0116","0.0058"
"37.9400","3.1560","3.1020","24.4873","0.0111","0.0055"
"38.0100","3.1619","3.1021","24.4886","0.0117","0.0058"
"38.0800","3.1678","3.0976","24.4529","0.0113","0.0056"
"38.1500","3.1739","3.0936","24.4212","0.0115","0.0058"
"38.2200","3.1797","3.0889","24.3844","0.0112","0.0056"
"38.2900","3.1853","3.0799","24.3127","0.0114","0.0057"
"38.3600","3.1914","3.0784","24.3011","0.0113","0.0057"
"38.4300","3.1974","3.0764","24.2852","0.0107","0.0054"
"38.5000","3.2027","3.0617","24.1692","0.0122","0.0061"
"38.5700","3.2086","3.0591","24.1487","0.0125","0.0063"
"38.6400","3.2147","3.0637","24.1848","0.0121","0.0060"
"38.7100","3.2205","3.0525","24.0966","0.0121","0.0061"
"38.7800","3.2262","3.0417","24.0116","0.0106","0.0053"
"38.8500","3.2323","3.0422","24.0158","0.0140","0.0070"
"38.9200","3.2379","3.0311","23.9276","0.0120","0.0060"
"38.9900","3.2438","3.0215","23.8518","0.0111","0.0055"
"39.0600","3.2496","3.0173","23.8187","0.0122","0.0061"
"39.1300","3.2552","3.0092","23.7551","0.0119","0.0060"
"39.2000","3.2610","3.0016","23.6947","0.0113","0.0056"
"39.2700","3.2673","3.0042","23.7151","0.0129","0.0065"
"39.3400","3.2729","2.9961","23.6512","0.0135","0.0067"
"39.4100","3.2787","2.9874","23.5827","0.0123","0.0061"
"39.4800","3.2847","2.9854","23.5669","0.0130","0.0065"
"39.5500","3.2907","2.9845","23.5602","0.0130","0.0065"
"39.6200","3.2962","2.9696","23.4427","0.0134","0.0067"
"39.6900","3.3020","2.9649","23.4055","0.0146","0.0073"
"39.7600","3.3079","2.9649","23.4056","0.0129","0.0065"
"39.8300","3.3137","2.9567","23.3402","0.0126","0.0063"
"39.9000","3.3195","2.9493","23.2820","0.0122","0.0061"
"39.9700","3.3255","2.9501","23.2884","0.0124","0.0062"
"40.0400","3.3312","2.9417","23.2219","0.0114","0.0057"
"40.1100","3.3372","2.9393","23.2035","0.0129","0.0064"
"40.1800","3.3430","2.9366","23.1817","0.0121","0.0060"
"40.2500","3.3484","2.9293","23.1241","0.0143","0.0071"
"40.3200","3.3544","2.9290","23.1220","0.0133","0.0066"
"40.3900","3.3605","2.9306","23.1347","0.0147","0.0074"
"40.4600","3.3662","2.9234","23.0773","0.0132","0.0066"
"40.5300","3.3720","2.9152","23.0130","0.0138","0.0069"
"40.6000","3.3780","2.9166","23.0242","0.0149","0.0074"
"40.6700","3.3839","2.9161","23.0196","0.0143","0.0072"
"40.7400","3.3896","2.9071","22.9487","0.0138","0.0069"
"40.8100","3.3954","2.9033","22.9191","0.0144","0.0072"
"40.8800","3.4011","2.9038","22.9229","0.0142","0.0071"
"40.9500","3.4070","2.8976","22.8743","0.0146","0.0073"
"41.0200","3.4131","2.8940","22.8452","0.0132","0.0066"
"41.0900","3.4189","2.8895","22.8101","0.0139","0.0069"
"41.1600","3.4244","2.8790","22.7270","0.0131","0.0066"
"41.2300","3.4304","2.8770","22.7112","0.0139","0.0069"
"41.3000","3.4365","2.8771","22.7122","0.0146","0.0073"
"41.3700","3.4418","2.8632","22.6024","0.0146","0.0073"
"41.4400","3.4475","2.8610","22.5854","0.0137","0.0069"
"41.5100","3.4537","2.8692","22.6497","0.0143","0.0071"
"41.5800","3.4597","2.8640","22.6086","0.0140","0.0070"
"41.6500","3.4652","2.8512","22.5079","0.0159","0.0079"
"41.7200","3.4714","2.8566","22.5501","0.0145","0.0072"
"41.7900","3.4773","2.8502","22.5001","0.0140","0.0070"
"41.8600","3.4830","2.8392","22.4128","0.0152","0.0076"
"41.9300","3.4888","2.8361","22.3882","0.0150","0.0075"
"42.0000","3.4944","2.8318","22.3541","0.0141","0.0070"
"42.0700","3.5002","2.8254","22.3041","0.0145","0.0073"
"42.1400","3.5065","2.8273","22.3191","0.0147","0.0073"
"42.2100","3.5122","2.8183","22.2476","0.0143","0.0071"
"42.2800","3.5177","2.8077","22.1644","0.0147","0.0073"
"42.3500","3.5239","2.8120","22.1979","0.0156","0.0078"
"42.4200","3.5298","2.8093","22.1768","0.0157","0.0078"
"42.4900","3.5353","2.7980","22.0876","0.0143","0.0071"
"42.5600","3.5410","2.7966","22.0769","0.0151","0.0075"
"42.6300","3.5470","2.7996","22.1006","0.0153","0.0076"
"42.7000","3.5528","2.7921","22.0413","0.0149","0.0074"
"42.7700","3.5587","2.7853","21.9871","0.0144","0.0072"
"42.8400","3.5647","2.7852","21.9869","0.0155","0.0077"
"42.9100","3.5704","2.7784","21.9330","0.0146","0.0073"
"42.9800","3.5764","2.7739","21.8977","0.0145","0.0072"
"43.0500","3.5823","2.7724","21.8860","0.0156","0.0078"
"43.1200","3.5877","2.7631","21.8118","0.0151","0.0075"
"43.1900","3.5936","2.7649","21.8263","0.0149","0.0074"
"43.2600","3.5997","2.7673","21.8452","0.0146","0.0073"
"43.3300","3.6054","2.7622","21.8052","0.0148","0.0074"
"43.4000","3.6111","2.7547","21.7462","0.0150","0.0075"
"43.4700","3.6172","2.7554","21.7518","0.0159","0.0079"
"43.5400","3.6231","2.7486","21.6975","0.0149","0.0074"
"43.6100","3.6287","2.7334","21.5781","0.0162","0.0081"
"43.6800","3.6345","2.7272","21.5292","0.0153","0.0077"
"43.7500","3.6403","2.7216","21.4844","0.0155","0.0077"
"43.8200","3.6461","2.7054","21.3566","0.0140","0.0070"
"43.8900","3.6521","2.6929","21.2581","0.0137","0.0068"
"43.9600","3.6579","2.6839","21.1871","0.0133","0.0066"
"44.0300","3.6636","2.6715","21.0891","0.0139","0.0069"
"44.1000","3.6697","2.6659","21.0451","0.0147","0.0074"
"44.1700","3.6756","2.6618","21.0124","0.0137","0.0068"
"44.2400","3.6811","2.6507","20.9250","0.0136","0.0068"
"44.3100","3.6870","2.6453","20.8822","0.0130","0.0065"
"44.3800","3.6930","2.6442","20.8738","0.0129","0.0065"
"44.4500","3.6987","2.6341","20.7935","0.0118","0.0059"
"44.5200","3.7044","2.6236","20.7109","0.0135","0.0067"
"44.5900","3.7105","2.6264","20.7333","0.0126","0.0063"
"44.6600","3.7163","2.6191","20.6756","0.0131","0.0066"
"44.7300","3.7220","2.6089","20.5953","0.0126","0.0063"
"44.8000","3.7280","2.6079","20.5873","0.0136","0.0068"
"44.8700","3.7335","2.6021","20.5410","0.0135","0.0067"
"44.9400","3.7392","2.5940","20.4771","0.0128","0.0064"
"45.0100","3.7455","2.5971","20.5020","0.0128","0.0064"
"45.0800","3.7512","2.5887","20.4352","0.0126","0.0063"
"45.1500","3.7569","2.5790","20.3589","0.0133","0.0066"
"45.2200","3.7630","2.5783","20.3533","0.0138","0.0069"
"45.2900","3.7691","2.5744","20.3226","0.0138","0.0069"
"45.3600","3.7745","2.5601","20.2093","0.0124","0.0062"
"45.4300","3.7804","2.5572","20.1869","0.0126","0.0063"
"45.5000","3.7862","2.5557","20.1752","0.0116","0.0058"
"45.5700","3.7921","2.5508","20.1360","0.0116","0.0058"
"45.6400","3.7979","2.5434","20.0779","0.0106","0.0053"
"45.7100","3.8038","2.5443","20.0850","0.0122","0.0061"
"45.7800","3.8095","2.5371","20.0282","0.0109","0.0054"
"45.8500","3.8156","2.5342","20.0050","0.0119","0.0059"
"45.9200","3.8214","2.5301","19.9728","0.0101","0.0050"
"45.9900","3.8269","2.5208","19.8993","0.0101","0.0050"
"46.0600","3.8326","2.5137","19.8430","0.0106","0.0053"
"46.1300","3.8388","2.5184","19.8807","0.0106","0.0053"
"46.2000","3.8446","2.5085","19.8023","0.0109","0.0054"
"46.2700","3.8503","2.4995","19.7311","0.0107","0.0053"
"46.3400","3.8563","2.4987","19.7252","0.0105","0.0052"
"46.4100","3.8623","2.4961","19.7047","0.0104","0.0052"
"46.4800","3.8679","2.4842","19.6106","0.0105","0.0053"
"46.5500","3.8738","2.4806","19.5820","0.0102","0.0051"
"46.6200","3.8796","2.4802","19.5789","0.0101","0.0051"
"46.6900","3.8853","2.4713","19.5089","0.0110","0.0055"
"46.7600","3.8913","2.4694","19.4940","0.0100","0.0050"
"46.8300","3.8973","2.4676","19.4796","0.0106","0.0053"
"46.9000","3.9028","2.4549","19.3790","0.0095","0.0047"
"46.9700","3.9088","2.4524","19.3595","0.0110","0.0055"
"47.0400","3.9147","2.4484","19.3278","0.0100","0.0050"
"47.1100","3.9203","2.4370","19.2379","0.0111","0.0056"
"47.1800","3.9261","2.4285","19.1708","0.0106","0.0053"
"47.2500","3.9320","2.4239","19.1343","0.0117","0.0058"
"47.3200","3.9377","2.4125","19.0443","0.0118","0.0059"
"47.3900","3.9437","2.4045","18.9813","0.0120","0.0060"
"47.4600","3.9497","2.3941","18.8996","0.0113","0.0056"
"47.5300","3.9554","2.3796","18.7845","0.0111","0.0055"
"47.6000","3.9613","2.3659","18.6763","0.0114","0.0057"
"47.6700","3.9672","2.3559","18.5976","0.0104","0.0052"
"47.7400","3.9729","2.3462","18.5211","0.0111","0.0055"
"47.8100","3.9786","2.3308","18.3993","0.0121","0.0060"
"47.8800","3.9847","2.3268","18.3684","0.0134","0.0067"
"47.9500","3.9904","2.3159","18.2823","0.0114","0.0057"
"48.0200","3.9960","2.3019","18.1714","0.0123","0.0062"
"48.0900","4.0021","2.2975","18.1364","0.0139","0.0069"
"48.1600","4.0082","2.2925","18.0971","0.0141","0.0071"
"48.2300","4.0137","2.2746","17.9559","0.0143","0.0072"
"48.3000","4.0195","2.2651","17.8809","0.0135","0.0068"
"48.3700","4.0253","2.2608","17.8467","0.0140","0.0070"
"48.4400","4.0311","2.2510","17.7700","0.0132","0.0066"
"48.5100","4.0370","2.2417","17.6961","0.0144","0.0072"
"48.5800","4.0430","2.2381","17.6678","0.0132","0.0066"
"48.6500","4.0486","2.2268","17.5782","0.0137","0.0069"
"48.7200","4.0548","2.2199","17.5241","0.0140","0.0070"
"48.7900","4.0607","2.2094","17.4415","0.0134","0.0067"
"48.8600","4.0662","2.1992","17.3608","0.0135","0.0068"
"48.9300","4.0720","2.1890","17.2802","0.0122","0.0061"
"49.0000","4.0780","2.1838","17.2389","0.0140","0.0070"
"49.0700","4.0837","2.1726","17.1506","0.0136","0.0068"
"49.1400","4.0894","2.1579","17.0350","0.0128","0.0064"
"49.2100","4.0954","2.1498","16.9704","0.0140","0.0070"
"49.2800","4.1015","2.1310","16.8225","0.0131","0.0066"
"49.3500","4.1071","2.1056","16.6221","0.0124","0.0062"
"49.4200","4.1129","2.0921","16.5154","0.0125","0.0063"
"49.4900","4.1186","2.0846","16.4560","0.0114","0.0057"
"49.5600","4.1243","2.0704","16.3439","0.0126","0.0063"
"49.6300","4.1305","2.0648","16.2997","0.0119","0.0060"
"49.7000","4.1363","2.0569","16.2370","0.0134","0.0067"
"49.7700","4.1418","2.0441","16.1360","0.0128","0.0064"
"49.8400","4.1481","2.0422","16.1213","0.0130","0.0065"
"49.9100","4.1541","2.0343","16.0588","0.0140","0.0070"
"49.9800","4.1595","2.0208","15.9522","0.0129","0.0064"
"50.0500","4.1653","2.0128","15.8891","0.0133","0.0066"
"50.1200","4.1714","2.0115","15.8791","0.0156","0.0078"
"50.1900","4.1771","1.9996","15.7849","0.0152","0.0076"
"50.2600","4.1828","1.9873","15.6880","0.0145","0.0073"
"50.3300","4.1888","1.9634","15.4994","0.0154","0.0077"
"50.4000","4.1946","1.9416","15.3269","0.0157","0.0079"
"50.4700","4.2005","1.9249","15.1957","0.0172","0.0086"
"50.5400","4.2063","1.9154","15.1205","0.0183","0.0091"
"50.6100","4.2120","1.9079","15.0608","0.0192","0.0096"
"50.6800","4.2177","1.8952","14.9606","0.0174","0.0087"
"50.7500","4.2238","1.8909","14.9270","0.0179","0.0089"
"50.8200","4.2295","1.8818","14.8555","0.0183","0.0092"
"50.8900","4.2352","1.8702","14.7639","0.0196","0.0098"
"50.9600","4.2413","1.8644","14.7178","0.0187","0.0093"
"51.0300","4.2474","1.8600","14.6833","0.0185","0.0092"
"51.1000","4.2529","1.8448","14.5627","0.0194","0.0097"
"51.1700","4.2587","1.8388","14.5161","0.0192","0.0096"
"51.2400","4.2646","1.8365","14.4976","0.0186","0.0093"
"51.3100","4.2703","1.8265","14.4184","0.0199","0.0099"
"51.3800","4.2761","1.8172","14.3453","0.0186","0.0093"
"51.4500","4.2821","1.8147","14.3258","0.0190","0.0095"
"51.5200","4.2877","1.8034","14.2364","0.0194","0.0097"
"51.5900","4.2938","1.7972","14.1877","0.0189","0.0095"
"51.6600","4.2997","1.7894","14.1254","0.0195","0.0097"
"51.7300","4.3053","1.7813","14.0617","0.0198","0.0099"
"51.8000","4.3111","1.7697","13.9702","0.0190","0.0095"
"51.8700","4.3171","1.7660","13.9407","0.0189","0.0094"
"51.9400","4.3228","1.7580","13.8779","0.0198","0.0099"
"52.0100","4.3285","1.7464","13.7863","0.0194","0.0097"
"52.0800","4.3345","1.7425","13.7555","0.0199","0.0099"
"52.1500","4.3405","1.7385","13.7242","0.0189","0.0094"
"52.2200","4.3464","1.7258","13.6234","0.0199","0.0100"
"52.2900","4.3521","1.7157","13.5438","0.0200","0.0100"
"52.3600","4.3579","1.7122","13.5167","0.0200","0.0100"
"52.4300","4.3637","1.7013","13.4305","0.0194","0.0097"
"52.5000","4.3696","1.6915","13.3529","0.0199","0.0100"
"52.5700","4.3754","1.6858","13.3075","0.0215","0.0107"
"52.6400","4.3811","1.6738","13.2129","0.0211","0.0105"
"52.7100","4.3871","1.6686","13.1720","0.0208","0.0104"
"52.7800","4.3932","1.6629","13.1272","0.0218","0.0109"
"52.8500","4.3987","1.6510","13.0335","0.0221","0.0111"
"52.9200","4.4046","1.6436","12.9748","0.0210","0.0105"
"52.9900","4.4105","1.6406","12.9507","0.0214","0.0107"
"53.0600","4.4162","1.6313","12.8774","0.0224","0.0112"
"53.1300","4.4219","1.6225","12.8079","0.0231","0.0115"
"53.2000","4.4280","1.6207","12.7938","0.0236","0.0118"
"53.2700","4.4337","1.6118","12.7235","0.0228","0.0114"
"53.3400","4.4397","1.6012","12.6398","0.0228","0.0114"
"53.4100","4.4456","1.5944","12.5863","0.0235","0.0118"
"53.4800","4.4513","1.5882","12.5372","0.0231","0.0116"
"53.5500","4.4570","1.5765","12.4453","0.0246","0.0123"
"53.6200","4.4630","1.5718","12.4081","0.0247","0.0123"
"53.6900","4.4687","1.5670","12.3701","0.0235","0.0117"
"53.7600","4.4743","1.5558","12.2817","0.0239","0.0120"
"53.8300","4.4804","1.5518","12.2499","0.0240","0.0120"
"53.9000","4.4864","1.5466","12.2093","0.0248","0.0124"
"53.9700","4.4921","1.5328","12.0999","0.0241","0.0121"
"54.0400","4.4979","1.5252","12.0402","0.0262","0.0131"
"54.1100","4.5038","1.5219","12.0143","0.0262","0.0131"
"54.1800","4.5094","1.5102","11.9217","0.0258","0.0129"
"54.2500","4.5152","1.5042","11.8742","0.0271","0.0136"
"54.3200","4.5212","1.5009","11.8479","0.0266","0.0133"
"54.3900","4.5269","1.4906","11.7671","0.0265","0.0132"
"54.4600","4.5328","1.4831","11.7074","0.0264","0.0132"
"54.5300","4.5390","1.4807","11.6892","0.0264","0.0132"
"54.6000","4.5446","1.4701","11.6054","0.0273","0.0136"
"54.6700","4.5503","1.4599","11.5250","0.0271","0.0135"
"54.7400","4.5564","1.4594","11.5208","0.0274","0.0137"
"54.8100","4.5620","1.4512","11.4561","0.0286","0.0143"
"54.8800","4.5677","1.4414","11.3789","0.0272","0.0136"
"54.9500","4.5739","1.4395","11.3632","0.0284","0.0142"
"55.0200","4.5796","1.4339","11.3190","0.0265","0.0132"
"55.0900","4.5855","1.4214","11.2211","0.0280","0.0140"
"55.1600","4.5914","1.4151","11.1711","0.0276","0.0138"
"55.2300","4.5972","1.4103","11.1329","0.0281","0.0140"
"55.3000","4.6027","1.3968","11.0268","0.0273","0.0136"
"55.3700","4.6087","1.3905","10.9771","0.0267","0.0134"
"55.4400","4.6145","1.3871","10.9497","0.0290","0.0145"
"55.5100","4.6202","1.3758","10.8608","0.0282","0.0141"
"55.5800","4.6262","1.3694","10.8105","0.0296","0.0148"
"55.6500","4.6323","1.3662","10.7846","0.0286","0.0143"
"55.7200","4.6378","1.3555","10.7001","0.0286","0.0143"
"55.7900","4.6437","1.3494","10.6523","0.0298","0.0149"
"55.8600","4.6498","1.3470","10.6331","0.0298","0.0149"
"55.9300","4.6554","1.3363","10.5490","0.0296","0.0148"
"56.0000","4.6612","1.3269","10.4748","0.0292","0.0146"
"56.0700","4.6672","1.3246","10.4564","0.0294","0.0147"
"56.1400","4.6729","1.3175","10.4006","0.0297","0.0148"
"56.2100","4.6789","1.3087","10.3308","0.0304","0.0152"
"56.2800","4.6848","1.3026","10.2832","0.0286","0.0143"
"56.3500","4.6903","1.2968","10.2371","0.0306","0.0153"
"56.4200","4.6960","1.2860","10.1520","0.0301","0.0150"
"56.4900","4.7022","1.2827","10.1258","0.0292","0.0146"
"56.5600","4.7079","1.2749","10.0643","0.0322","0.0161"
"56.6300","4.7134","1.2621","9.9635","0.0332","0.0166"
"56.7000","4.7197","1.2585","9.9344","0.0319","0.0159"
"56.7700","4.7257","1.2498","9.8659","0.0325","0.0162"
"56.8400","4.7312","1.2367","9.7628","0.0326","0.0163"
"56.9100","4.7371","1.2304","9.7126","0.0331","0.0165"
"56.9800","4.7430","1.2270","9.6859","0.0332","0.0166"
"57.0500","4.7488","1.2172","9.6087","0.0338","0.0169"
"57.1200","4.7545","1.2050","9.5125","0.0337","0.0168"
"57.1900","4.7604","1.2035","9.5009","0.0351","0.0175"
"57.2600","4.7660","1.1934","9.4208","0.0337","0.0168"
"57.3300","4.7722","1.1843","9.3487","0.0344","0.0172"
"57.4000","4.7782","1.1770","9.2911","0.0354","0.0177"
"57.4700","4.7837","1.1703","9.2381","0.0353","0.0176"
"57.5400","4.7894","1.1596","9.1543","0.0365","0.0182"
"57.6100","4.7955","1.1561","9.1261","0.0358","0.0179"
"57.6800","4.8012","1.1463","9.0489","0.0360","0.0180"
"57.7500","4.8067","1.1346","8.9567","0.0366","0.0183"
"57.8200","4.8128","1.1306","8.9249","0.0373","0.0186"
"57.8900","4.8188","1.1244","8.8763","0.0360","0.0180"
"57.9600","4.8246","1.1126","8.7831","0.0365","0.0182"
"58.0300","4.8304","1.1054","8.7258","0.0381","0.0190"
"58.1000","4.8363","1.1036","8.7121","0.0371","0.0185"
"58.1700","4.8421","1.0927","8.6257","0.0393","0.0196"
"58.2400","4.8480","1.0844","8.5603","0.0379","0.0189"
"58.3100","4.8537","1.0825","8.5451","0.0397","0.0198"
"58.3800","4.8593","1.0728","8.4688","0.0378","0.0189"
"58.4500","4.8654","1.0654","8.4100","0.0377","0.0188"
"58.5200","4.8715","1.0606","8.3726","0.0380","0.0190"
"58.5900","4.8770","1.0514","8.2997","0.0380","0.0190"
"58.6600","4.8827","1.0424","8.2291","0.0381","0.0190"
"58.7300","4.8888","1.0422","8.2271","0.0374","0.0187"
"58.8000","4.8946","1.0330","8.1547","0.0385","0.0193"
"58.8700","4.9000","1.0229","8.0747","0.0386","0.0193"
"58.9400","4.9061","1.0231","8.0762","0.0364","0.0182"
"59.0100","4.9120","1.0164","8.0232","0.0384","0.0192"
"59.0800","4.9179","1.0052","7.9354","0.0377","0.0189"
"59.1500","4.9239","1.0002","7.8953","0.0393","0.0196"
"59.2200","4.9296","0.9966","7.8675","0.0400","0.0200"
"59.2900","4.9354","0.9866","7.7886","0.0388","0.0194"
"59.3600","4.9414","0.9814","7.7470","0.0372","0.0186"
"59.4300","4.9471","0.9785","7.7246","0.0391","0.0195"
"59.5000","4.9527","0.9699","7.6566","0.0390","0.0195"
"59.5700","4.9588","0.9657","7.6231","0.0394","0.0197"
"59.6400","4.9648","0.9630","7.6019","0.0384","0.0192"
"59.7100","4.9704","0.9538","7.5293","0.0402","0.0201"
"59.7800","4.9762","0.9493","7.4939","0.0393","0.0197"
"59.8500","4.9821","0.9495","7.4951","0.0389","0.0194"
"59.9200","4.9879","0.9418","7.4345","0.0398","0.0199"
"59.9900","4.9936","0.9325","7.3611","0.0409","0.0204"
"60.0600","4.9995","0.9336","7.3702","0.0400","0.0200"
"60.1300","5.0052","0.9260","7.3101","0.0387","0.0194"
"60.2000","5.0113","0.9197","7.2605","0.0396","0.0198"
"60.2700","5.0173","0.9150","7.2231","0.0390","0.0195"
"60.3400","5.0229","0.9119","7.1983","0.0361","0.0181"
"60.4100","5.0288","0.9017","7.1184","0.0379","0.0189"
"60.4800","5.0349","0.9001","7.1055","0.0372","0.0186"
"60.5500","5.0405","0.8947","7.0630","0.0378","0.0189"
"60.5900","5.0438","0.8901","7.0266","0.0387","0.0194"