File: composites_properties_derivations/composite_tube_tests/comp_tube_2.csv
Specimen label,"2"
Force at Maximum Load,"8.85",kN
Tensile stress at Maximum Load,"69.86",MPa
Epsilon ONE Displacement at Maximum Load,"0.09",mm
Force at Break (Standard),"2.68",kN
Tensile stress at Break (Standard),"21.13",MPa
Epsilon ONE Displacement at Break (Standard),"0.03",mm
Slope (Chord 0.05 % - 0.2 %),"-----",MPa
Modulus (Automatic Young's),"68236.98",MPa

Specimen label,"2"
Thickness,"",mm
Width,"",mm
Length,"52.93",mm
Rate 1,"5.00",mm/min
Outer diameter,"15.88",mm
Wall thickness,"3.18",mm

Time,Displacement,Force,Tensile stress,Tensile strain (Epsilon ONE Displacement),Epsilon ONE Displacement
(s),(mm),(kN),(MPa),(%),(mm)
"0.0000","0.0000","0.0701","0.5535","0.0001","0.0001"
"0.0600","0.0003","0.0750","0.5924","0.0005","0.0003"
"0.1200","0.0032","0.1337","1.0552","0.0006","0.0003"
"0.1800","0.0040","0.1461","1.1530","0.0007","0.0004"
"0.2400","0.0099","0.2459","1.9413","0.0011","0.0006"
"0.3000","0.0191","0.3012","2.3778","0.0027","0.0014"
"0.3600","0.0233","0.3298","2.6034","0.0035","0.0018"
"0.4200","0.0283","0.3669","2.8961","0.0037","0.0020"
"0.4800","0.0334","0.4055","3.2009","0.0036","0.0019"
"0.5400","0.0385","0.4462","3.5224","0.0058","0.0031"
"0.6000","0.0435","0.4873","3.8465","0.0060","0.0032"
"0.6600","0.0485","0.5289","4.1755","0.0060","0.0032"
"0.7200","0.0537","0.5736","4.5281","0.0071","0.0038"
"0.7800","0.0586","0.6164","4.8659","0.0075","0.0040"
"0.8400","0.0635","0.6603","5.2124","0.0085","0.0045"
"0.9000","0.0684","0.7045","5.5611","0.0080","0.0042"
"0.9600","0.0733","0.7480","5.9045","0.0083","0.0044"
"1.0200","0.0784","0.7919","6.2511","0.0090","0.0048"
"1.0800","0.0833","0.8314","6.5632","0.0100","0.0053"
"1.1400","0.0884","0.8646","6.8249","0.0105","0.0056"
"1.2000","0.0934","0.8862","6.9959","0.0102","0.0054"
"1.2600","0.0985","0.9050","7.1443","0.0105","0.0055"
"1.3200","0.1036","0.9219","7.2776","0.0123","0.0065"
"1.3800","0.1086","0.9373","7.3989","0.0127","0.0067"
"1.4400","0.1136","0.9502","7.5006","0.0117","0.0062"
"1.5000","0.1184","0.9647","7.6154","0.0121","0.0064"
"1.5600","0.1234","0.9771","7.7132","0.0129","0.0068"
"1.6200","0.1286","0.9902","7.8168","0.0120","0.0064"
"1.6800","0.1334","1.0028","7.9158","0.0137","0.0072"
"1.7400","0.1384","1.0137","8.0021","0.0130","0.0069"
"1.8000","0.1434","1.0273","8.1093","0.0145","0.0077"
"1.8600","0.1486","1.0381","8.1948","0.0131","0.0069"
"1.9200","0.1538","1.0499","8.2877","0.0135","0.0071"
"1.9800","0.1585","1.0605","8.3715","0.0135","0.0072"
"2.0400","0.1635","1.0706","8.4515","0.0131","0.0069"
"2.1000","0.1684","1.0833","8.5516","0.0125","0.0066"
"2.1600","0.1734","1.0921","8.6215","0.0132","0.0070"
"2.2200","0.1784","1.1053","8.7250","0.0130","0.0069"
"2.2800","0.1832","1.1147","8.7994","0.0123","0.0065"
"2.3400","0.1885","1.1266","8.8931","0.0127","0.0067"
"2.4000","0.1934","1.1385","8.9875","0.0137","0.0073"
"2.4600","0.1988","1.1484","9.0652","0.0125","0.0066"
"2.5200","0.2037","1.1610","9.1651","0.0140","0.0074"
"2.5800","0.2084","1.1698","9.2346","0.0131","0.0069"
"2.6400","0.2136","1.1829","9.3379","0.0144","0.0076"
"2.7000","0.2184","1.1935","9.4215","0.0136","0.0072"
"2.7600","0.2236","1.2044","9.5075","0.0142","0.0075"
"2.8200","0.2284","1.2170","9.6068","0.0146","0.0077"
"2.8800","0.2334","1.2264","9.6814","0.0141","0.0075"
"2.9400","0.2386","1.2400","9.7890","0.0143","0.0076"
"3.0000","0.2435","1.2505","9.8715","0.0140","0.0074"
"3.0600","0.2488","1.2618","9.9610","0.0145","0.0077"
"3.1200","0.2534","1.2741","10.0579","0.0143","0.0076"
"3.1800","0.2585","1.2836","10.1329","0.0154","0.0082"
"3.2400","0.2635","1.2980","10.2464","0.0143","0.0076"
"3.3000","0.2683","1.3068","10.3157","0.0136","0.0072"
"3.3600","0.2735","1.3203","10.4224","0.0149","0.0079"
"3.4200","0.2782","1.3315","10.5111","0.0148","0.0078"
"3.4800","0.2835","1.3265","10.4713","0.0137","0.0072"
"3.5400","0.2885","1.3295","10.4953","0.0139","0.0074"
"3.6000","0.2935","1.3468","10.6319","0.0144","0.0076"
"3.6600","0.2986","1.3628","10.7582","0.0152","0.0080"
"3.7200","0.3033","1.3751","10.8551","0.0143","0.0076"
"3.7800","0.3086","1.3893","10.9672","0.0158","0.0084"
"3.8400","0.3135","1.4042","11.0852","0.0154","0.0082"
"3.9000","0.3185","1.4147","11.1681","0.0161","0.0085"
"3.9600","0.3235","1.4299","11.2879","0.0155","0.0082"
"4.0200","0.3283","1.4404","11.3703","0.0159","0.0084"
"4.0800","0.3336","1.4546","11.4829","0.0161","0.0085"
"4.1400","0.3385","1.4666","11.5775","0.0156","0.0083"
"4.2000","0.3436","1.4780","11.6671","0.0167","0.0088"
"4.2600","0.3485","1.4919","11.7772","0.0176","0.0093"
"4.3200","0.3534","1.5029","11.8641","0.0176","0.0093"
"4.3800","0.3586","1.5172","11.9770","0.0179","0.0095"
"4.4400","0.3633","1.5281","12.0628","0.0182","0.0097"
"4.5000","0.3685","1.5412","12.1661","0.0180","0.0095"
"4.5600","0.3732","1.5545","12.2712","0.0188","0.0099"
"4.6200","0.3783","1.5657","12.3598","0.0178","0.0094"
"4.6800","0.3835","1.5808","12.4790","0.0175","0.0093"
"4.7400","0.3884","1.5915","12.5635","0.0188","0.0099"
"4.8000","0.3936","1.6050","12.6700","0.0181","0.0096"
"4.8600","0.3983","1.6185","12.7764","0.0185","0.0098"
"4.9200","0.4035","1.6304","12.8702","0.0184","0.0097"
"4.9800","0.4086","1.6458","12.9922","0.0191","0.0101"
"5.0400","0.4135","1.6560","13.0730","0.0190","0.0100"
"5.1000","0.4186","1.6713","13.1931","0.0193","0.0102"
"5.1600","0.4233","1.6832","13.2877","0.0199","0.0105"
"5.2200","0.4285","1.6958","13.3870","0.0196","0.0104"
"5.2800","0.4335","1.7117","13.5124","0.0196","0.0103"
"5.3400","0.4385","1.7223","13.5958","0.0195","0.0103"
"5.4000","0.4436","1.7374","13.7153","0.0200","0.0106"
"5.4600","0.4483","1.7491","13.8078","0.0207","0.0110"
"5.5200","0.4535","1.7632","13.9188","0.0203","0.0107"
"5.5800","0.4584","1.7781","14.0365","0.0201","0.0106"
"5.6400","0.4635","1.7884","14.1179","0.0212","0.0112"
"5.7000","0.4684","1.8057","14.2545","0.0211","0.0112"
"5.7600","0.4733","1.8161","14.3362","0.0219","0.0116"
"5.8200","0.4785","1.8325","14.4656","0.0216","0.0114"
"5.8800","0.4835","1.8461","14.5730","0.0220","0.0116"
"5.9400","0.4886","1.8575","14.6636","0.0220","0.0116"
"6.0000","0.4935","1.8744","14.7964","0.0221","0.0117"
"6.0600","0.4985","1.8847","14.8783","0.0224","0.0119"
"6.1200","0.5037","1.9024","15.0179","0.0227","0.0120"
"6.1800","0.5086","1.9141","15.1104","0.0241","0.0127"
"6.2400","0.5136","1.9270","15.2117","0.0229","0.0121"
"6.3000","0.5183","1.9429","15.3374","0.0247","0.0131"
"6.3600","0.5234","1.9552","15.4346","0.0232","0.0123"
"6.4200","0.5286","1.9725","15.5713","0.0240","0.0127"
"6.4800","0.5335","1.9834","15.6574","0.0233","0.0123"
"6.5400","0.5387","1.9994","15.7835","0.0252","0.0133"
"6.6000","0.5434","2.0127","15.8883","0.0241","0.0128"
"6.6600","0.5485","2.0260","15.9936","0.0250","0.0132"
"6.7200","0.5536","2.0446","16.1403","0.0254","0.0135"
"6.7800","0.5584","2.0540","16.2147","0.0257","0.0136"
"6.8400","0.5634","2.0722","16.3582","0.0255","0.0135"
"6.9000","0.5682","2.0841","16.4524","0.0248","0.0131"
"6.9600","0.5735","2.1006","16.5820","0.0256","0.0135"
"7.0200","0.5786","2.1162","16.7055","0.0259","0.0137"
"7.0800","0.5835","2.1265","16.7865","0.0264","0.0140"
"7.1400","0.5887","2.1457","16.9384","0.0253","0.0134"
"7.2000","0.5934","2.1562","17.0213","0.0269","0.0143"
"7.2600","0.5986","2.1727","17.1518","0.0268","0.0142"
"7.3200","0.6035","2.1876","17.2694","0.0262","0.0139"
"7.3800","0.6084","2.1995","17.3633","0.0265","0.0140"
"7.4400","0.6134","2.2183","17.5112","0.0270","0.0143"
"7.5000","0.6183","2.2290","17.5958","0.0267","0.0142"
"7.5600","0.6236","2.2479","17.7451","0.0279","0.0148"
"7.6200","0.6285","2.2604","17.8441","0.0286","0.0152"
"7.6800","0.6337","2.2754","17.9622","0.0293","0.0155"
"7.7400","0.6386","2.2923","18.0954","0.0299","0.0158"
"7.8000","0.6434","2.3032","18.1815","0.0301","0.0159"
"7.8600","0.6486","2.3230","18.3377","0.0307","0.0163"
"7.9200","0.6533","2.3345","18.4284","0.0305","0.0161"
"7.9800","0.6584","2.3510","18.5589","0.0309","0.0163"
"8.0400","0.6632","2.3669","18.6843","0.0313","0.0166"
"8.1000","0.6685","2.3824","18.8073","0.0313","0.0166"
"8.1600","0.6736","2.4010","18.9537","0.0317","0.0168"
"8.2200","0.6785","2.4120","19.0403","0.0320","0.0169"
"8.2800","0.6837","2.4301","19.1833","0.0322","0.0170"
"8.3400","0.6884","2.4443","19.2954","0.0333","0.0176"
"8.4000","0.6936","2.4586","19.4087","0.0326","0.0173"
"8.4600","0.6987","2.4780","19.5616","0.0339","0.0179"
"8.5200","0.7035","2.4872","19.6340","0.0331","0.0175"
"8.5800","0.7085","2.5073","19.7925","0.0332","0.0176"
"8.6400","0.7131","2.5194","19.8884","0.0342","0.0181"
"8.7000","0.7185","2.5378","20.0339","0.0338","0.0179"
"8.7600","0.7235","2.5541","20.1621","0.0344","0.0182"
"8.8200","0.7285","2.5662","20.2575","0.0340","0.0180"
"8.8800","0.7336","2.5861","20.4149","0.0351","0.0186"
"8.9400","0.7383","2.5968","20.4993","0.0354","0.0187"
"9.0000","0.7436","2.6164","20.6545","0.0361","0.0191"
"9.0600","0.7485","2.6310","20.7695","0.0362","0.0192"
"9.1200","0.7534","2.6429","20.8629","0.0373","0.0197"
"9.1800","0.7583","2.6635","21.0259","0.0365","0.0193"
"9.2400","0.7632","2.6754","21.1196","0.0377","0.0200"
"9.3000","0.7687","2.6958","21.2812","0.0390","0.0206"
"9.3600","0.7736","2.7091","21.3857","0.0380","0.0201"
"9.4200","0.7786","2.7232","21.4975","0.0404","0.0214"
"9.4800","0.7834","2.7418","21.6443","0.0394","0.0209"
"9.5400","0.7885","2.7554","21.7513","0.0404","0.0214"
"9.6000","0.7937","2.7758","21.9124","0.0398","0.0211"
"9.6600","0.7985","2.7869","22.0004","0.0395","0.0209"
"9.7200","0.8035","2.8042","22.1368","0.0400","0.0212"
"9.7800","0.8083","2.8213","22.2719","0.0407","0.0215"
"9.8400","0.8136","2.8370","22.3957","0.0418","0.0221"
"9.9000","0.8187","2.8557","22.5435","0.0413","0.0219"
"9.9600","0.8235","2.8670","22.6324","0.0419","0.0222"
"10.0200","0.8287","2.8880","22.7980","0.0421","0.0223"
"10.0800","0.8334","2.9016","22.9059","0.0419","0.0222"
"10.1400","0.8386","2.9183","23.0370","0.0408","0.0216"
"10.2000","0.8436","2.9367","23.1829","0.0419","0.0222"
"10.2600","0.8483","2.9476","23.2689","0.0424","0.0225"
"10.3200","0.8534","2.9701","23.4460","0.0424","0.0224"
"10.3800","0.8582","2.9826","23.5451","0.0439","0.0233"
"10.4400","0.8637","3.0027","23.7033","0.0430","0.0228"
"10.5000","0.8686","3.0185","23.8283","0.0420","0.0223"
"10.5600","0.8734","3.0310","23.9267","0.0426","0.0226"
"10.6200","0.8785","3.0537","24.1061","0.0443","0.0235"
"10.6800","0.8835","3.0658","24.2015","0.0455","0.0241"
"10.7400","0.8888","3.0847","24.3510","0.0439","0.0232"
"10.8000","0.8935","3.0998","24.4700","0.0439","0.0232"
"10.8600","0.8984","3.1148","24.5884","0.0440","0.0233"
"10.9200","0.9034","3.1351","24.7487","0.0450","0.0238"
"10.9800","0.9084","3.1482","24.8526","0.0455","0.0241"
"11.0400","0.9136","3.1688","25.0152","0.0457","0.0242"
"11.1000","0.9184","3.1827","25.1246","0.0467","0.0247"
"11.1600","0.9236","3.2009","25.2685","0.0466","0.0247"
"11.2200","0.9285","3.2183","25.4057","0.0474","0.0251"
"11.2800","0.9336","3.2323","25.5160","0.0483","0.0256"
"11.3400","0.9386","3.2524","25.6751","0.0481","0.0255"
"11.4000","0.9433","3.2641","25.7673","0.0480","0.0254"
"11.4600","0.9484","3.2852","25.9336","0.0488","0.0258"
"11.5200","0.9532","3.3002","26.0520","0.0494","0.0262"
"11.5800","0.9585","3.3181","26.1936","0.0493","0.0261"
"11.6400","0.9635","3.3369","26.3417","0.0500","0.0265"
"11.7000","0.9684","3.3496","26.4421","0.0503","0.0266"
"11.7600","0.9736","3.3712","26.6127","0.0497","0.0263"
"11.8200","0.9784","3.3851","26.7220","0.0508","0.0269"
"11.8800","0.9837","3.4035","26.8679","0.0516","0.0273"
"11.9400","0.9886","3.4212","27.0077","0.0507","0.0268"
"12.0000","0.9933","3.4335","27.1043","0.0523","0.0277"
"12.0600","0.9984","3.4571","27.2908","0.0519","0.0274"
"12.1200","1.0033","3.4703","27.3950","0.0529","0.0280"
"12.1800","1.0086","3.4901","27.5513","0.0534","0.0283"
"12.2400","1.0134","3.5057","27.6742","0.0533","0.0282"
"12.3000","1.0184","3.5212","27.7965","0.0534","0.0283"
"12.3600","1.0235","3.5432","27.9703","0.0533","0.0282"
"12.4200","1.0284","3.5567","28.0769","0.0543","0.0287"
"12.4800","1.0337","3.5801","28.2620","0.0545","0.0289"
"12.5400","1.0384","3.5943","28.3741","0.0555","0.0294"
"12.6000","1.0433","3.6100","28.4978","0.0558","0.0295"
"12.6600","1.0482","3.6324","28.6746","0.0562","0.0298"
"12.7200","1.0534","3.6465","28.7862","0.0560","0.0296"
"12.7800","1.0587","3.6690","28.9637","0.0565","0.0299"
"12.8400","1.0634","3.6807","29.0558","0.0565","0.0299"
"12.9000","1.0686","3.7006","29.2127","0.0575","0.0304"
"12.9600","1.0734","3.7187","29.3554","0.0579","0.0306"
"13.0200","1.0786","3.7346","29.4815","0.0582","0.0308"
"13.0800","1.0838","3.7561","29.6511","0.0583","0.0309"
"13.1400","1.0883","3.7656","29.7260","0.0571","0.0302"
"13.2000","1.0935","3.7901","29.9195","0.0583","0.0309"
"13.2600","1.0983","3.8042","30.0308","0.0586","0.0310"
"13.3200","1.1037","3.8243","30.1892","0.0596","0.0316"
"13.3800","1.1086","3.8425","30.3330","0.0585","0.0310"
"13.4400","1.1134","3.8547","30.4292","0.0591","0.0313"
"13.5000","1.1187","3.8795","30.6255","0.0598","0.0316"
"13.5600","1.1234","3.8911","30.7169","0.0597","0.0316"
"13.6200","1.1288","3.9130","30.8899","0.0598","0.0316"
"13.6800","1.1334","3.9283","31.0101","0.0609","0.0322"
"13.7400","1.1384","3.9436","31.1308","0.0601","0.0318"
"13.8000","1.1433","3.9666","31.3131","0.0612","0.0324"
"13.8600","1.1482","3.9798","31.4168","0.0624","0.0330"
"13.9200","1.1537","4.0038","31.6062","0.0615","0.0326"
"13.9800","1.1584","4.0165","31.7065","0.0621","0.0328"
"14.0400","1.1635","4.0349","31.8521","0.0626","0.0331"
"14.1000","1.1686","4.0565","32.0227","0.0635","0.0336"
"14.1600","1.1734","4.0690","32.1207","0.0642","0.0340"
"14.2200","1.1788","4.0931","32.3114","0.0650","0.0344"
"14.2800","1.1834","4.1049","32.4048","0.0642","0.0340"
"14.3400","1.1885","4.1244","32.5584","0.0644","0.0341"
"14.4000","1.1933","4.1439","32.7126","0.0653","0.0346"
"14.4600","1.1985","4.1604","32.8425","0.0656","0.0347"
"14.5200","1.2036","4.1822","33.0147","0.0651","0.0344"
"14.5800","1.2083","4.1945","33.1118","0.0653","0.0346"
"14.6400","1.2136","4.2170","33.2897","0.0671","0.0355"
"14.7000","1.2185","4.2343","33.4259","0.0669","0.0354"
"14.7600","1.2236","4.2523","33.5683","0.0678","0.0359"
"14.8200","1.2286","4.2727","33.7289","0.0673","0.0356"
"14.8800","1.2332","4.2853","33.8284","0.0678","0.0359"
"14.9400","1.2384","4.3115","34.0351","0.0671","0.0355"
"15.0000","1.2433","4.3253","34.1444","0.0682","0.0361"
"15.0600","1.2486","4.3455","34.3038","0.0679","0.0360"
"15.1200","1.2535","4.3643","34.4519","0.0688","0.0364"
"15.1800","1.2584","4.3783","34.5630","0.0689","0.0364"
"15.2400","1.2636","4.4022","34.7514","0.0696","0.0369"
"15.3000","1.2684","4.4155","34.8567","0.0705","0.0373"
"15.3600","1.2738","4.4384","35.0374","0.0713","0.0378"
"15.4200","1.2785","4.4531","35.1533","0.0711","0.0376"
"15.4800","1.2834","4.4682","35.2725","0.0719","0.0381"
"15.5400","1.2884","4.4932","35.4694","0.0720","0.0381"
"15.6000","1.2934","4.5072","35.5807","0.0721","0.0381"
"15.6600","1.2988","4.5304","35.7638","0.0725","0.0384"
"15.7200","1.3034","4.5440","35.8710","0.0729","0.0386"
"15.7800","1.3085","4.5629","36.0201","0.0730","0.0387"
"15.8400","1.3135","4.5849","36.1938","0.0736","0.0390"
"15.9000","1.3185","4.5993","36.3075","0.0740","0.0392"
"15.9600","1.3237","4.6218","36.4849","0.0749","0.0396"
"16.0200","1.3282","4.6341","36.5817","0.0745","0.0395"
"16.0800","1.3333","4.6546","36.7435","0.0753","0.0399"
"16.1400","1.3381","4.6780","36.9285","0.0755","0.0400"
"16.2000","1.3435","4.6972","37.0805","0.0753","0.0398"
"16.2600","1.3486","4.7171","37.2370","0.0762","0.0403"
"16.3200","1.3532","4.7303","37.3414","0.0767","0.0406"
"16.3800","1.3587","4.7558","37.5429","0.0783","0.0414"
"16.4400","1.3636","4.7733","37.6810","0.0786","0.0416"
"16.5000","1.3687","4.7888","37.8030","0.0774","0.0409"
"16.5600","1.3736","4.8108","37.9769","0.0781","0.0413"
"16.6200","1.3783","4.8253","38.0912","0.0783","0.0414"
"16.6800","1.3834","4.8518","38.3008","0.0793","0.0420"
"16.7400","1.3883","4.8679","38.4274","0.0783","0.0414"
"16.8000","1.3937","4.8892","38.5957","0.0797","0.0422"
"16.8600","1.3986","4.9067","38.7336","0.0802","0.0424"
"16.9200","1.4034","4.9217","38.8526","0.0808","0.0428"
"16.9800","1.4086","4.9486","39.0651","0.0800","0.0424"
"17.0400","1.4136","4.9618","39.1691","0.0806","0.0427"
"17.1000","1.4187","4.9828","39.3348","0.0811","0.0429"
"17.1600","1.4233","4.9994","39.4659","0.0814","0.0431"
"17.2200","1.4283","5.0172","39.6062","0.0810","0.0429"
"17.2800","1.4333","5.0424","39.8054","0.0823","0.0435"
"17.3400","1.4384","5.0567","39.9182","0.0824","0.0436"
"17.4000","1.4437","5.0806","40.1067","0.0830","0.0439"
"17.4600","1.4483","5.0941","40.2133","0.0829","0.0439"
"17.5200","1.4535","5.1160","40.3864","0.0840","0.0445"
"17.5800","1.4586","5.1389","40.5666","0.0848","0.0449"
"17.6400","1.4636","5.1526","40.6748","0.0848","0.0449"
"17.7000","1.4687","5.1756","40.8567","0.0851","0.0450"
"17.7600","1.4733","5.1892","40.9638","0.0852","0.0451"
"17.8200","1.4785","5.2129","41.1511","0.0851","0.0450"
"17.8800","1.4834","5.2322","41.3032","0.0862","0.0456"
"17.9400","1.4885","5.2484","41.4315","0.0870","0.0460"
"18.0000","1.4936","5.2725","41.6213","0.0868","0.0459"
"18.0600","1.4983","5.2852","41.7217","0.0869","0.0460"
"18.1200","1.5036","5.3120","41.9337","0.0874","0.0463"
"18.1800","1.5085","5.3290","42.0677","0.0875","0.0463"
"18.2400","1.5136","5.3475","42.2134","0.0875","0.0463"
"18.3000","1.5185","5.3693","42.3855","0.0890","0.0471"
"18.3600","1.5233","5.3844","42.5049","0.0895","0.0473"
"18.4200","1.5284","5.4110","42.7153","0.0902","0.0477"
"18.4800","1.5333","5.4256","42.8306","0.0888","0.0470"
"18.5400","1.5385","5.4474","43.0022","0.0905","0.0479"
"18.6000","1.5433","5.4656","43.1462","0.0905","0.0479"
"18.6600","1.5484","5.4847","43.2964","0.0914","0.0484"
"18.7200","1.5536","5.5093","43.4912","0.0908","0.0481"
"18.7800","1.5585","5.5227","43.5966","0.0916","0.0485"
"18.8400","1.5637","5.5460","43.7804","0.0925","0.0490"
"18.9000","1.5683","5.5606","43.8962","0.0921","0.0488"
"18.9600","1.5735","5.5817","44.0629","0.0929","0.0492"
"19.0200","1.5785","5.6048","44.2447","0.0939","0.0497"
"19.0800","1.5834","5.6189","44.3562","0.0934","0.0494"
"19.1400","1.5886","5.6433","44.5492","0.0932","0.0493"
"19.2000","1.5932","5.6570","44.6573","0.0942","0.0498"
"19.2600","1.5986","5.6817","44.8516","0.0957","0.0507"
"19.3200","1.6036","5.7015","45.0086","0.0954","0.0505"
"19.3800","1.6085","5.7161","45.1233","0.0952","0.0504"
"19.4400","1.6136","5.7405","45.3160","0.0962","0.0509"
"19.5000","1.6182","5.7531","45.4159","0.0960","0.0508"
"19.5600","1.6233","5.7771","45.6054","0.0963","0.0510"
"19.6200","1.6282","5.7970","45.7619","0.0976","0.0516"
"19.6800","1.6335","5.8167","45.9179","0.0968","0.0512"
"19.7400","1.6384","5.8377","46.0834","0.0980","0.0519"
"19.8000","1.6433","5.8533","46.2062","0.0985","0.0521"
"19.8600","1.6486","5.8794","46.4127","0.0993","0.0525"
"19.9200","1.6536","5.8961","46.5443","0.1008","0.0533"
"19.9800","1.6587","5.9136","46.6829","0.1014","0.0537"
"20.0400","1.6635","5.9357","46.8574","0.1003","0.0531"
"20.1000","1.6684","5.9509","46.9768","0.1016","0.0538"
"20.1600","1.6735","5.9769","47.1824","0.1017","0.0538"
"20.2200","1.6784","5.9931","47.3098","0.1008","0.0534"
"20.2800","1.6837","6.0155","47.4870","0.1040","0.0550"
"20.3400","1.6884","6.0341","47.6334","0.1036","0.0549"
"20.4000","1.6934","6.0545","47.7947","0.1042","0.0551"
"20.4600","1.6986","6.0806","48.0007","0.1049","0.0555"
"20.5200","1.7036","6.0936","48.1039","0.1047","0.0554"
"20.5800","1.7087","6.1167","48.2859","0.1047","0.0554"
"20.6400","1.7133","6.1315","48.4024","0.1051","0.0556"
"20.7000","1.7184","6.1536","48.5773","0.1053","0.0557"
"20.7600","1.7233","6.1757","48.7516","0.1059","0.0560"
"20.8200","1.7284","6.1933","48.8903","0.1058","0.0560"
"20.8800","1.7335","6.2173","49.0801","0.1069","0.0566"
"20.9400","1.7383","6.2321","49.1970","0.1074","0.0568"
"21.0000","1.7436","6.2578","49.3999","0.1073","0.0568"
"21.0600","1.7486","6.2802","49.5768","0.1082","0.0572"
"21.1200","1.7537","6.2958","49.6996","0.1085","0.0574"
"21.1800","1.7586","6.3184","49.8777","0.1093","0.0578"
"21.2400","1.7633","6.3331","49.9944","0.1089","0.0576"
"21.3000","1.7686","6.3600","50.2067","0.1087","0.0575"
"21.3600","1.7733","6.3761","50.3332","0.1101","0.0582"
"21.4200","1.7785","6.3973","50.5006","0.1109","0.0587"
"21.4800","1.7836","6.4201","50.6807","0.1129","0.0598"
"21.5400","1.7884","6.4337","50.7882","0.1130","0.0598"
"21.6000","1.7936","6.4596","50.9929","0.1137","0.0602"
"21.6600","1.7985","6.4760","51.1223","0.1135","0.0601"
"21.7200","1.8036","6.4969","51.2868","0.1149","0.0608"
"21.7800","1.8084","6.5173","51.4484","0.1141","0.0604"
"21.8400","1.8133","6.5339","51.5790","0.1147","0.0607"
"21.9000","1.8184","6.5583","51.7718","0.1156","0.0612"
"21.9600","1.8232","6.5733","51.8902","0.1159","0.0614"
"22.0200","1.8285","6.6019","52.1161","0.1164","0.0616"
"22.0800","1.8335","6.6182","52.2447","0.1162","0.0615"
"22.1400","1.8385","6.6378","52.3996","0.1166","0.0617"
"22.2000","1.8437","6.6623","52.5927","0.1175","0.0622"
"22.2600","1.8485","6.6755","52.6972","0.1178","0.0623"
"22.3200","1.8537","6.7005","52.8945","0.1185","0.0627"
"22.3800","1.8583","6.7146","53.0057","0.1195","0.0633"
"22.4400","1.8635","6.7396","53.2028","0.1198","0.0634"
"22.5000","1.8684","6.7600","53.3642","0.1198","0.0634"
"22.5600","1.8735","6.7764","53.4937","0.1205","0.0638"
"22.6200","1.8786","6.8015","53.6915","0.1206","0.0638"
"22.6800","1.8833","6.8150","53.7982","0.1209","0.0640"
"22.7400","1.8886","6.8421","54.0122","0.1211","0.0641"
"22.8000","1.8936","6.8628","54.1753","0.1206","0.0638"
"22.8600","1.8986","6.8782","54.2972","0.1218","0.0645"
"22.9200","1.9035","6.9034","54.4963","0.1225","0.0648"
"22.9800","1.9082","6.9175","54.6077","0.1224","0.0648"
"23.0400","1.9134","6.9453","54.8266","0.1236","0.0654"
"23.1000","1.9183","6.9633","54.9693","0.1238","0.0655"
"23.1600","1.9235","6.9851","55.1407","0.1233","0.0653"
"23.2200","1.9284","7.0069","55.3129","0.1247","0.0660"
"23.2800","1.9333","7.0229","55.4392","0.1262","0.0668"
"23.3400","1.9387","7.0519","55.6680","0.1262","0.0668"
"23.4000","1.9437","7.0683","55.7977","0.1268","0.0671"
"23.4600","1.9486","7.0856","55.9345","0.1279","0.0677"
"23.5200","1.9535","7.1078","56.1095","0.1263","0.0668"
"23.5800","1.9584","7.1255","56.2497","0.1280","0.0678"
"23.6400","1.9635","7.1512","56.4527","0.1280","0.0678"
"23.7000","1.9684","7.1659","56.5680","0.1287","0.0681"
"23.7600","1.9736","7.1914","56.7700","0.1290","0.0683"
"23.8200","1.9783","7.2080","56.9006","0.1292","0.0684"
"23.8800","1.9835","7.2296","57.0716","0.1300","0.0688"
"23.9400","1.9887","7.2563","57.2820","0.1303","0.0690"
"24.0000","1.9936","7.2682","57.3761","0.1318","0.0697"
"24.0600","1.9986","7.2930","57.5714","0.1318","0.0698"
"24.1200","2.0032","7.3070","57.6821","0.1328","0.0703"
"24.1800","2.0084","7.3330","57.8876","0.1331","0.0704"
"24.2400","2.0134","7.3541","58.0539","0.1329","0.0704"
"24.3000","2.0184","7.3710","58.1875","0.1333","0.0706"
"24.3600","2.0235","7.3981","58.4010","0.1332","0.0705"
"24.4200","2.0283","7.4111","58.5039","0.1342","0.0710"
"24.4800","2.0337","7.4417","58.7454","0.1352","0.0716"
"24.5400","2.0387","7.4584","58.8774","0.1357","0.0718"
"24.6000","2.0436","7.4734","58.9958","0.1363","0.0722"
"24.6600","2.0485","7.4992","59.1992","0.1371","0.0725"
"24.7200","2.0533","7.5148","59.3229","0.1372","0.0726"
"24.7800","2.0587","7.5436","59.5496","0.1386","0.0734"
"24.8400","2.0634","7.5576","59.6605","0.1378","0.0729"
"24.9000","2.0685","7.5804","59.8403","0.1389","0.0735"
"24.9600","2.0734","7.6021","60.0119","0.1392","0.0737"
"25.0200","2.0784","7.6205","60.1573","0.1390","0.0736"
"25.0800","2.0837","7.6484","60.3769","0.1394","0.0738"
"25.1400","2.0885","7.6607","60.4747","0.1401","0.0742"
"25.2000","2.0935","7.6843","60.6610","0.1401","0.0741"
"25.2600","2.0983","7.7043","60.8182","0.1416","0.0749"
"25.3200","2.1034","7.7242","60.9755","0.1410","0.0746"
"25.3800","2.1085","7.7494","61.1745","0.1419","0.0751"
"25.4400","2.1133","7.7635","61.2860","0.1412","0.0748"
"25.5000","2.1185","7.7909","61.5021","0.1423","0.0753"
"25.5600","2.1234","7.8079","61.6365","0.1426","0.0755"
"25.6200","2.1285","7.8305","61.8147","0.1431","0.0757"
"25.6800","2.1337","7.8551","62.0087","0.1430","0.0757"
"25.7400","2.1386","7.8687","62.1160","0.1454","0.0769"
"25.8000","2.1436","7.8960","62.3317","0.1451","0.0768"
"25.8600","2.1483","7.9102","62.4437","0.1451","0.0768"
"25.9200","2.1535","7.9374","62.6585","0.1462","0.0774"
"25.9800","2.1584","7.9566","62.8102","0.1459","0.0772"
"26.0400","2.1634","7.9748","62.9539","0.1469","0.0778"
"26.1000","2.1685","8.0012","63.1626","0.1464","0.0775"
"26.1600","2.1732","8.0129","63.2544","0.1480","0.0783"
"26.2200","2.1787","8.0451","63.5087","0.1481","0.0784"
"26.2800","2.1836","8.0611","63.6349","0.1479","0.0783"
"26.3400","2.1885","8.0773","63.7633","0.1493","0.0790"
"26.4000","2.1934","8.1032","63.9676","0.1486","0.0786"
"26.4600","2.1983","8.1196","64.0966","0.1494","0.0791"
"26.5200","2.2035","8.1464","64.3088","0.1499","0.0793"
"26.5800","2.2082","8.1607","64.4214","0.1500","0.0794"
"26.6400","2.2134","8.1861","64.6220","0.1509","0.0798"
"26.7000","2.2183","8.2079","64.7943","0.1513","0.0801"
"26.7600","2.2233","8.2258","64.9355","0.1519","0.0804"
"26.8200","2.2287","8.2557","65.1715","0.1520","0.0805"
"26.8800","2.2336","8.2687","65.2736","0.1525","0.0807"
"26.9400","2.2386","8.2896","65.4392","0.1544","0.0817"
"27.0000","2.2434","8.3095","65.5957","0.1544","0.0817"
"27.0600","2.2485","8.3318","65.7724","0.1545","0.0818"
"27.1200","2.2536","8.3566","65.9675","0.1546","0.0818"
"27.1800","2.2583","8.3685","66.0622","0.1555","0.0823"
"27.2400","2.2636","8.3992","66.3040","0.1566","0.0829"
"27.3000","2.2683","8.4133","66.4156","0.1567","0.0830"
"27.3600","2.2736","8.4390","66.6182","0.1552","0.0821"
"27.4200","2.2787","8.4616","66.7968","0.1570","0.0831"
"27.4800","2.2835","8.4739","66.8940","0.1574","0.0833"
"27.5400","2.2886","8.5026","67.1206","0.1581","0.0837"
"27.6000","2.2934","8.5170","67.2344","0.1590","0.0842"
"27.6600","2.2986","8.5426","67.4364","0.1599","0.0846"
"27.7200","2.3033","8.5593","67.5683","0.1603","0.0848"
"27.7800","2.3083","8.5803","67.7335","0.1603","0.0849"
"27.8400","2.3135","8.6073","67.9472","0.1603","0.0848"
"27.9000","2.3183","8.6216","68.0601","0.1617","0.0856"
"27.9600","2.3237","8.6520","68.3001","0.1619","0.0857"
"28.0200","2.3286","8.6667","68.4160","0.1624","0.0860"
"28.0800","2.3336","8.6860","68.5683","0.1630","0.0863"
"28.1400","2.3386","8.7102","68.7593","0.1633","0.0864"
"28.2000","2.3434","8.7255","68.8796","0.1638","0.0867"
"28.2600","2.3486","8.7530","69.0968","0.1640","0.0868"
"28.3200","2.3532","8.7634","69.1794","0.1650","0.0873"
"28.3800","2.3585","8.7908","69.3958","0.1658","0.0877"
"28.4400","2.3634","8.8079","69.5302","0.1662","0.0879"
"28.5000","2.3685","8.8236","69.6543","0.1675","0.0887"
"28.5600","2.3737","8.8453","69.8254","0.1680","0.0889"
"28.6200","2.3785","8.8464","69.8346","0.1684","0.0891"
"28.6800","2.3836","8.8417","69.7970","0.1691","0.0895"
"28.7400","2.3884","8.4229","66.4913","0.1700","0.0900"
"28.8000","2.3940","7.4434","58.7586","0.1737","0.0920"
"28.8600","2.3986","7.4402","58.7339","0.1752","0.0927"
"28.9200","2.4032","7.4379","58.7154","0.1770","0.0937"
"28.9800","2.4085","7.4603","58.8924","0.1768","0.0936"
"29.0400","2.4133","7.4584","58.8773","0.1782","0.0943"
"29.1000","2.4186","7.4532","58.8361","0.1796","0.0951"
"29.1600","2.4236","7.4097","58.4929","0.1791","0.0948"
"29.2200","2.4286","7.3194","57.7800","0.1775","0.0939"
"29.2800","2.4337","7.1611","56.5302","0.1753","0.0928"
"29.3400","2.4385","6.8969","54.4448","0.1704","0.0902"
"29.4000","2.4438","6.5388","51.6182","0.1634","0.0865"
"29.4600","2.4486","6.0530","47.7833","0.1540","0.0815"
"29.5200","2.4540","3.3760","26.6504","0.1026","0.0543"
"29.5800","2.4599","2.6714","21.0879","0.0479","0.0254"
"29.6400","2.4635","2.7422","21.6476","0.0514","0.0272"
"29.7000","2.4687","2.7731","21.8908","0.0513","0.0272"
"29.7600","2.4735","2.7853","21.9871","0.0518","0.0274"
"29.8200","2.4786","2.8035","22.1314","0.0517","0.0273"
"29.8800","2.4835","2.8140","22.2139","0.0537","0.0284"
"29.9400","2.4884","2.8161","22.2309","0.0531","0.0281"
"30.0000","2.4936","2.8267","22.3146","0.0534","0.0282"
"30.0600","2.4982","2.8177","22.2435","0.0531","0.0281"
"30.1200","2.5035","2.8262","22.3106","0.0508","0.0269"
"30.1800","2.5084","2.8194","22.2567","0.0518","0.0274"
"30.2400","2.5135","2.8138","22.2123","0.0517","0.0274"
"30.3000","2.5187","2.8151","22.2227","0.0514","0.0272"
"30.3600","2.5235","2.8035","22.1307","0.0509","0.0270"
"30.4200","2.5287","2.8034","22.1301","0.0505","0.0267"
"30.4800","2.5334","2.7938","22.0546","0.0517","0.0273"
"30.5400","2.5386","2.7915","22.0364","0.0509","0.0270"
"30.6000","2.5436","2.7846","21.9818","0.0518","0.0274"
"30.6600","2.5484","2.7716","21.8793","0.0512","0.0271"
"30.7200","2.5536","2.7642","21.8206","0.0510","0.0270"
"30.7800","2.5584","2.7174","21.4511","0.0512","0.0271"
"30.8400","2.5638","2.6966","21.2871","0.0499","0.0264"
"30.9000","2.5687","2.6858","21.2017","0.0497","0.0263"
"30.9600","2.5735","2.6762","21.1259","0.0494","0.0261"
"31.0200","2.5785","2.6804","21.1594","0.0498","0.0264"
"31.0800","2.5833","2.6721","21.0936","0.0493","0.0261"
"31.1400","2.5887","2.6759","21.1239","0.0499","0.0264"
"31.2000","2.5934","2.6635","21.0263","0.0499","0.0264"
"31.2600","2.5983","2.6596","20.9953","0.0507","0.0268"
"31.3200","2.6034","2.6548","20.9575","0.0513","0.0272"
"31.3800","2.6086","2.6317","20.7749","0.0505","0.0267"
"31.4400","2.6139","2.6265","20.7340","0.0507","0.0268"
"31.5000","2.6184","2.6137","20.6326","0.0502","0.0266"
"31.5600","2.6236","2.6180","20.6665","0.0502","0.0266"
"31.6200","2.6285","2.6178","20.6651","0.0501","0.0265"
"31.6800","2.6335","2.6151","20.6436","0.0491","0.0260"
"31.7400","2.6388","2.6178","20.6651","0.0496","0.0263"
"31.8000","2.6433","2.6075","20.5842","0.0501","0.0265"
"31.8600","2.6485","2.6123","20.6217","0.0500","0.0265"
"31.9200","2.6533","2.6089","20.5950","0.0497","0.0263"
"31.9800","2.6586","2.6090","20.5953","0.0495","0.0262"
"32.0400","2.6637","2.6090","20.5960","0.0489","0.0259"
"32.1000","2.6684","2.6004","20.5280","0.0497","0.0263"
"32.1600","2.6736","2.6069","20.5793","0.0477","0.0253"
"32.2200","2.6783","2.6019","20.5401","0.0477","0.0253"
"32.2800","2.6836","2.6062","20.5734","0.0486","0.0257"
"32.3400","2.6884","2.6035","20.5525","0.0501","0.0265"
"32.4000","2.6932","2.5999","20.5240","0.0497","0.0263"
"32.4600","2.6984","2.6071","20.5807","0.0493","0.0261"
"32.5200","2.7033","2.6014","20.5355","0.0492","0.0261"
"32.5800","2.7087","2.6068","20.5782","0.0490","0.0259"
"32.6400","2.7135","2.6011","20.5333","0.0502","0.0266"
"32.7000","2.7184","2.5989","20.5156","0.0499","0.0264"
"32.7600","2.7236","2.6059","20.5710","0.0497","0.0263"
"32.8200","2.7285","2.6007","20.5299","0.0493","0.0261"
"32.8800","2.7337","2.6031","20.5489","0.0481","0.0254"
"32.9400","2.7382","2.5944","20.4807","0.0484","0.0256"
"33.0000","2.7434","2.5995","20.5209","0.0485","0.0257"
"33.0600","2.7484","2.6018","20.5391","0.0494","0.0261"
"33.1200","2.7534","2.5991","20.5176","0.0482","0.0255"
"33.1800","2.7588","2.6031","20.5495","0.0482","0.0255"
"33.2400","2.7634","2.5934","20.4725","0.0487","0.0258"
"33.3000","2.7685","2.5935","20.4736","0.0489","0.0259"
"33.3600","2.7734","2.5907","20.4509","0.0497","0.0263"
"33.4200","2.7785","2.5891","20.4389","0.0493","0.0261"
"33.4800","2.7836","2.5878","20.4282","0.0502","0.0266"
"33.5400","2.7880","2.5777","20.3485","0.0485","0.0257"
"33.6000","2.7934","2.5881","20.4308","0.0498","0.0263"
"33.6600","2.7983","2.5860","20.4141","0.0496","0.0262"
"33.7200","2.8036","2.5863","20.4167","0.0495","0.0262"
"33.7800","2.8086","2.5876","20.4271","0.0488","0.0258"
"33.8400","2.8134","2.5823","20.3849","0.0497","0.0263"
"33.9000","2.8186","2.5878","20.4284","0.0498","0.0264"
"33.9600","2.8235","2.5828","20.3889","0.0506","0.0268"
"34.0200","2.8288","2.5841","20.3991","0.0494","0.0262"
"34.0800","2.8335","2.5789","20.3583","0.0499","0.0264"
"34.1400","2.8383","2.5760","20.3349","0.0499","0.0264"
"34.2000","2.8435","2.5849","20.4057","0.0502","0.0266"
"34.2600","2.8485","2.5827","20.3880","0.0499","0.0264"
"34.3200","2.8537","2.5856","20.4112","0.0501","0.0265"
"34.3800","2.8585","2.5833","20.3927","0.0495","0.0262"
"34.4400","2.8635","2.5850","20.4063","0.0492","0.0260"
"34.5000","2.8685","2.5883","20.4323","0.0495","0.0262"
"34.5600","2.8735","2.5856","20.4109","0.0500","0.0264"
"34.6200","2.8786","2.5901","20.4463","0.0503","0.0266"
"34.6800","2.8832","2.5845","20.4023","0.0490","0.0259"
"34.7400","2.8884","2.5919","20.4605","0.0491","0.0260"
"34.8000","2.8934","2.5923","20.4637","0.0482","0.0255"
"34.8600","2.8986","2.5915","20.4578","0.0487","0.0258"
"34.9200","2.9037","2.5928","20.4678","0.0497","0.0263"
"34.9800","2.9084","2.5841","20.3991","0.0490","0.0259"
"35.0400","2.9137","2.5887","20.4358","0.0503","0.0266"
"35.1000","2.9186","2.5854","20.4093","0.0489","0.0259"
"35.1600","2.9237","2.5834","20.3939","0.0486","0.0257"
"35.2200","2.9286","2.5838","20.3967","0.0493","0.0261"
"35.2800","2.9333","2.5761","20.3360","0.0495","0.0262"
"35.3400","2.9385","2.5829","20.3893","0.0500","0.0265"
"35.4000","2.9434","2.5793","20.3615","0.0496","0.0262"
"35.4600","2.9487","2.5816","20.3791","0.0488","0.0258"
"35.5200","2.9536","2.5806","20.3719","0.0501","0.0265"
"35.5800","2.9584","2.5766","20.3403","0.0495","0.0262"
"35.6400","2.9636","2.5831","20.3914","0.0498","0.0264"
"35.7000","2.9684","2.5781","20.3516","0.0493","0.0261"
"35.7600","2.9735","2.5802","20.3680","0.0492","0.0260"
"35.8200","2.9783","2.5779","20.3503","0.0485","0.0257"
"35.8800","2.9833","2.5784","20.3542","0.0492","0.0260"
"35.9400","2.9884","2.5825","20.3863","0.0485","0.0257"
"36.0000","2.9933","2.5794","20.3624","0.0485","0.0257"
"36.0600","2.9986","2.5846","20.4032","0.0483","0.0256"
"36.1200","3.0034","2.5789","20.3583","0.0484","0.0256"
"36.1800","3.0086","2.5816","20.3794","0.0489","0.0259"
"36.2400","3.0136","2.5833","20.3931","0.0498","0.0264"
"36.3000","3.0186","2.5781","20.3519","0.0492","0.0260"
"36.3600","3.0237","2.5812","20.3763","0.0502","0.0266"
"36.4200","3.0283","2.5732","20.3134","0.0490","0.0259"
"36.4800","3.0335","2.5802","20.3684","0.0494","0.0261"
"36.5400","3.0383","2.5805","20.3706","0.0485","0.0257"
"36.6000","3.0434","2.5799","20.3660","0.0477","0.0252"
"36.6600","3.0486","2.5843","20.4010","0.0487","0.0258"
"36.7200","3.0534","2.5768","20.3417","0.0498","0.0264"
"36.7800","3.0586","2.5825","20.3868","0.0497","0.0263"
"36.8400","3.0635","2.5796","20.3639","0.0496","0.0262"
"36.9000","3.0686","2.5790","20.3592","0.0500","0.0265"
"36.9600","3.0734","2.5788","20.3571","0.0496","0.0262"
"37.0200","3.0781","2.5743","20.3216","0.0499","0.0264"
"37.0800","3.0834","2.5827","20.3883","0.0486","0.0257"
"37.1400","3.0884","2.5796","20.3638","0.0487","0.0258"
"37.2000","3.0937","2.5821","20.3830","0.0490","0.0259"
"37.2600","3.0986","2.5792","20.3606","0.0479","0.0253"
"37.3200","3.1035","2.5767","20.3405","0.0489","0.0259"
"37.3800","3.1086","2.5810","20.3748","0.0496","0.0263"
"37.4400","3.1135","2.5769","20.3424","0.0496","0.0263"
"37.5000","3.1187","2.5814","20.3778","0.0489","0.0259"
"37.5600","3.1234","2.5771","20.3440","0.0493","0.0261"
"37.6200","3.1283","2.5769","20.3421","0.0478","0.0253"
"37.6800","3.1335","2.5826","20.3873","0.0492","0.0260"
"37.7400","3.1386","2.5784","20.3541","0.0491","0.0260"
"37.8000","3.1437","2.5776","20.3481","0.0483","0.0256"
"37.8600","3.1485","2.5723","20.3064","0.0493","0.0261"
"37.9200","3.1536","2.5741","20.3203","0.0486","0.0257"
"37.9800","3.1585","2.5749","20.3268","0.0492","0.0260"
"38.0400","3.1636","2.5723","20.3061","0.0489","0.0259"
"38.1000","3.1686","2.5760","20.3351","0.0492","0.0260"
"38.1600","3.1732","2.5701","20.2889","0.0489","0.0259"
"38.2200","3.1784","2.5788","20.3575","0.0510","0.0270"
"38.2800","3.1834","2.5796","20.3636","0.0506","0.0268"
"38.3400","3.1886","2.5776","20.3480","0.0500","0.0265"
"38.4000","3.1936","2.5804","20.3701","0.0507","0.0268"
"38.4600","3.1984","2.5749","20.3269","0.0512","0.0271"
"38.5200","3.2037","2.5822","20.3842","0.0509","0.0269"
"38.5800","3.2086","2.5789","20.3581","0.0512","0.0271"
"38.6400","3.2137","2.5772","20.3444","0.0497","0.0263"
"38.7000","3.2185","2.5783","20.3535","0.0498","0.0264"
"38.7600","3.2232","2.5740","20.3196","0.0508","0.0269"
"38.8200","3.2286","2.5845","20.4025","0.0513","0.0271"
"38.8800","3.2335","2.5800","20.3666","0.0532","0.0282"
"38.9400","3.2387","2.5804","20.3701","0.0508","0.0269"
"39.0000","3.2434","2.5797","20.3642","0.0494","0.0262"
"39.0600","3.2485","2.5795","20.3631","0.0497","0.0263"
"39.1200","3.2536","2.5844","20.4015","0.0495","0.0262"
"39.1800","3.2585","2.5779","20.3506","0.0499","0.0264"
"39.2400","3.2636","2.5810","20.3748","0.0494","0.0262"
"39.3000","3.2682","2.5768","20.3412","0.0488","0.0258"
"39.3600","3.2734","2.5816","20.3794","0.0487","0.0258"
"39.4200","3.2784","2.5843","20.4011","0.0491","0.0260"
"39.4800","3.2834","2.5813","20.3767","0.0499","0.0264"
"39.5400","3.2885","2.5850","20.4060","0.0493","0.0261"
"39.6000","3.2933","2.5811","20.3754","0.0483","0.0256"
"39.6600","3.2986","2.5870","20.4223","0.0487","0.0258"
"39.7200","3.3036","2.5865","20.4179","0.0488","0.0258"
"39.7800","3.3086","2.5833","20.3926","0.0490","0.0259"
"39.8400","3.3136","2.5866","20.4191","0.0474","0.0251"
"39.9000","3.3182","2.5814","20.3774","0.0487","0.0258"
"39.9600","3.3236","2.5913","20.4557","0.0480","0.0254"
"40.0200","3.3285","2.5882","20.4316","0.0483","0.0256"
"40.0800","3.3334","2.5850","20.4066","0.0492","0.0260"
"40.1400","3.3384","2.5894","20.4413","0.0479","0.0254"
"40.2000","3.3433","2.5865","20.4177","0.0476","0.0252"
"40.2600","3.3486","2.5929","20.4684","0.0480","0.0254"
"40.3200","3.3535","2.5875","20.4259","0.0486","0.0257"
"40.3800","3.3585","2.5862","20.4157","0.0484","0.0256"
"40.4400","3.3633","2.5868","20.4203","0.0479","0.0253"
"40.5000","3.3682","2.5842","20.4002","0.0493","0.0261"
"40.5600","3.3735","2.5923","20.4639","0.0490","0.0259"
"40.6200","3.3784","2.5883","20.4324","0.0495","0.0262"
"40.6800","3.3835","2.5893","20.4405","0.0491","0.0260"
"40.7400","3.3884","2.5901","20.4468","0.0479","0.0253"
"40.8000","3.3935","2.5907","20.4515","0.0493","0.0261"
"40.8600","3.3988","2.5972","20.5029","0.0496","0.0262"
"40.9200","3.4036","2.5877","20.4273","0.0497","0.0263"
"40.9800","3.4087","2.5906","20.4507","0.0506","0.0268"
"41.0400","3.4133","2.5854","20.4097","0.0500","0.0265"
"41.1000","3.4184","2.5886","20.4345","0.0496","0.0263"
"41.1600","3.4236","2.5928","20.4678","0.0495","0.0262"
"41.2200","3.4285","2.5864","20.4174","0.0487","0.0258"
"41.2800","3.4336","2.5901","20.4464","0.0496","0.0262"
"41.3400","3.4384","2.5870","20.4221","0.0499","0.0264"
"41.4000","3.4437","2.5928","20.4678","0.0498","0.0263"
"41.4600","3.4487","2.5932","20.4711","0.0502","0.0266"
"41.5200","3.4535","2.5884","20.4331","0.0493","0.0261"
"41.5800","3.4585","2.5941","20.4782","0.0491","0.0260"
"41.6400","3.4632","2.5892","20.4397","0.0493","0.0261"
"41.7000","3.4685","2.5996","20.5213","0.0499","0.0264"
"41.7600","3.4735","2.5989","20.5156","0.0504","0.0267"
"41.8200","3.4785","2.5976","20.5058","0.0499","0.0264"
"41.8800","3.4835","2.6026","20.5449","0.0488","0.0259"
"41.9400","3.4884","2.6000","20.5244","0.0487","0.0258"
"42.0000","3.4937","2.6081","20.5888","0.0479","0.0253"
"42.0600","3.4986","2.6050","20.5639","0.0474","0.0251"
"42.1200","3.5036","2.6045","20.5598","0.0494","0.0262"
"42.1800","3.5085","2.6080","20.5876","0.0506","0.0268"
"42.2400","3.5132","2.6044","20.5598","0.0502","0.0266"
"42.3000","3.5185","2.6155","20.6470","0.0499","0.0264"
"42.3600","3.5234","2.6126","20.6242","0.0497","0.0263"
"42.4200","3.5286","2.6167","20.6564","0.0498","0.0263"
"42.4800","3.5334","2.6150","20.6433","0.0496","0.0263"
"42.5400","3.5385","2.6169","20.6579","0.0499","0.0264"
"42.6000","3.5437","2.6223","20.7006","0.0493","0.0261"
"42.6600","3.5485","2.6151","20.6440","0.0492","0.0261"
"42.7200","3.5535","2.6202","20.6841","0.0496","0.0263"
"42.7800","3.5582","2.6164","20.6542","0.0497","0.0263"
"42.8400","3.5633","2.6230","20.7065","0.0495","0.0262"
"42.9000","3.5685","2.6280","20.7458","0.0495","0.0262"
"42.9600","3.5734","2.6247","20.7196","0.0502","0.0266"
"43.0200","3.5786","2.6297","20.7593","0.0502","0.0266"
"43.0800","3.5833","2.6251","20.7225","0.0498","0.0264"
"43.1400","3.5886","2.6324","20.7802","0.0488","0.0258"
"43.2000","3.5936","2.6315","20.7733","0.0489","0.0259"
"43.2600","3.5985","2.6276","20.7427","0.0487","0.0258"
"43.3200","3.6036","2.6332","20.7870","0.0492","0.0260"
"43.3800","3.6082","2.6263","20.7323","0.0493","0.0261"
"43.4400","3.6135","2.6373","20.8189","0.0495","0.0262"
"43.5000","3.6185","2.6358","20.8075","0.0487","0.0258"
"43.5600","3.6235","2.6353","20.8034","0.0499","0.0264"
"43.6200","3.6285","2.6387","20.8302","0.0498","0.0263"
"43.6800","3.6334","2.6372","20.8186","0.0500","0.0264"
"43.7400","3.6387","2.6447","20.8777","0.0501","0.0265"
"43.8000","3.6435","2.6390","20.8325","0.0502","0.0265"
"43.8600","3.6484","2.6400","20.8405","0.0509","0.0270"
"43.9200","3.6533","2.6434","20.8670","0.0511","0.0270"
"43.9800","3.6582","2.6430","20.8645","0.0502","0.0265"
"44.0400","3.6636","2.6530","20.9430","0.0495","0.0262"
"44.1000","3.6685","2.6479","20.9025","0.0483","0.0255"
"44.1600","3.6735","2.6496","20.9162","0.0488","0.0258"
"44.2200","3.6783","2.6504","20.9222","0.0483","0.0256"
"44.2800","3.6836","2.6536","20.9479","0.0494","0.0261"
"44.3400","3.6888","2.6581","20.9834","0.0491","0.0260"
"44.4000","3.6936","2.6495","20.9157","0.0491","0.0260"
"44.4600","3.6986","2.6545","20.9551","0.0475","0.0251"
"44.5200","3.7033","2.6517","20.9330","0.0485","0.0257"
"44.5800","3.7085","2.6576","20.9793","0.0490","0.0259"
"44.6400","3.7137","2.6621","21.0150","0.0496","0.0263"
"44.7000","3.7185","2.6564","20.9696","0.0476","0.0252"
"44.7600","3.7236","2.6615","21.0103","0.0489","0.0259"
"44.8200","3.7283","2.6572","20.9760","0.0496","0.0262"
"44.8800","3.7337","2.6681","21.0620","0.0487","0.0258"
"44.9400","3.7387","2.6660","21.0457","0.0491","0.0260"
"45.0000","3.7435","2.6602","20.9997","0.0486","0.0257"
"45.0600","3.7485","2.6666","21.0504","0.0489","0.0259"
"45.1200","3.7532","2.6616","21.0113","0.0490","0.0259"
"45.1800","3.7586","2.6728","21.0993","0.0484","0.0256"
"45.2400","3.7634","2.6685","21.0653","0.0483","0.0256"
"45.3000","3.7685","2.6688","21.0674","0.0490","0.0259"
"45.3600","3.7734","2.6706","21.0820","0.0494","0.0261"
"45.4200","3.7784","2.6681","21.0619","0.0497","0.0263"
"45.4800","3.7838","2.6767","21.1300","0.0489","0.0259"
"45.5400","3.7886","2.6687","21.0673","0.0490","0.0259"
"45.5640","3.7907","2.6720","21.0929","0.0491","0.0260"